Workbook

Sheet Planilha2
A1: tipo | B1: cod SOX | C1: nome | D1: unidade | E1: pc
A2: 1 | B2: 1068 | C2: ABRACADEIRA DE NYLON | D2: UN | E2: 33
A3: 1 | B3: 376 | C3: ABRACADEIRA GALVANIZADA TIPO U | D3: UN | E3: 33
A4: 1 | B4: 377 | C4: ABRACADEIRA GALVANIZADA TIPO U 2 POL. | D4: UN | E4: 33
A5: 1 | B5: 631 | C5: ABRACADEIRA TIPO COPO 1 1/4 | D5: UN | E5: 33
A6: 1 | B6: 608 | C6: ACETILENO | D6: KG | E6: 33
A7: 1 | B7: 183 | C7: ACO / TELA, INCLUSIVE CORTE E DOBRA | D7: VB | E7: 34
A8: 1 | B8: 795 | C8: ACO CA 25 X 16MM - LISO | D8: KG | E8: 34
A9: 1 | B9: 889 | C9: ACO CA 25 X 8MM | D9: KG | E9: 34
A10: 1 | B10: 432 | C10: ACO CA-50 25MM | D10: KG | E10: 34
A11: 1 | B11: 12 | C11: ACO CA-50 X 10MM | D11: KG | E11: 34
A12: 1 | B12: 13 | C12: ACO CA-50 X 12MM | D12: KG | E12: 34
A13: 1 | B13: 14 | C13: ACO CA-50 X 16MM | D13: KG | E13: 34
... A1074: 1 | B1074: 387 | C1074: ZARCAO | D1074: UN | E1074: 33
A1075: 2 | C1075: venda fabricação | E1075: 118
A1076: 2 | C1076: venda montagem | E1076: 118
A1077: 2 | C1077: ICMS | E1077: 103
A1078: 2 | C1078: PIS | E1078: 100
A1079: 2 | C1079: CONFINS | E1079: 99
A1080: 2 | C1080: IR | E1080: 101
A1081: 2 | C1081: CSLL | E1081: 102
A1082: 2 | C1082: royalities | E1082: 141
A1083: 2 | C1083: investimentos | E1083: 109
A1084: 2 | C1084: lucro previsto | E1084: 0
A1085: 2 | C1085: imposto previsto | E1085: 0
A1086: 2 | C1086: CHAPA AÇO 500 x 300 x 3/16' | D1086: unid. | E1086: 163
A1087: 2 | C1087: CIMENTO PORTLAND ( SACO 50 kg ) | D1087: sacos | E1087: 33
A1088: 2 | C1088: AREIA MÉDIA | D1088: m³ | E1088: 33
A1089: 2 | C1089: PARABOLT 5/8" x 6" | D1089: unid. | E1089: 33
A1090: 2 | C1090: PARABOLT 5/8" x 6" | D1090: unid. | E1090: 33
A1091: 2 | C1091: PARAFUSO p/ escora M16 x 1 1/2" | D1091: unid. | E1091: 33
A1092: 2 | C1092: PARAFUSO p/ Nivelam. M30 x 85 | D1092: unid. | E1092: 33
A1093: 2 | C1093: PARAFUSO SEXTAVADO M12 x 45 mm | D1093: unid. | E1093: 33
A1094: 2 | C1094: ARRUELA 16 mm | D1094: unid. | E1094: 33
A1095: 2 | C1095: BROCA SDS Plus DIÂMETRO 16 mm x 210 mm | D1095: unid. | E1095: 33
A1096: 2 | C1096: SELANTE FLEXÍVEL PU 40 ( sachê 600 ml ) | D1096: unid. | E1096: 165
A1097: 2 | C1097: D11 ( MC-BAUCHIMIE ) - primer para substrados absorventes ( embalagem: galão de 4 litros ) | D1097: galão de 4 litros | E1097: 33
... A1143: 2 | C1143: CONCRETO FCK 40 MPa em 24 horas AUTOADENSÁVEL | D1143: m³ | E1143: 0
A1144: 2 | C1144: CHAPA DE ANCORAGEM - ASTM A 572-GR50 (200 X 120 X 19 mm) | E1144: 125
A1145: 2 | C1145: AÇO CA-50 | D1145: kg | E1145: 34
...

Sheet Planilha3
A1: Nome | B1: Categoria | C1: Unidade | D1: Plano de Conta | E1: Código ERP
A2: ABAFADOR TIPO CONCHA ARCO | B2: EPI | C2: UND | D2: 60
A3: ABAFADOR TIPO CONCHA PARA CAPACETE MSA | B3: EPI | C3: UND | D3: 60
A4: ÁLCOOL EM GEL 5LT | B4: Insumo | C4: UND | D4: 40
A5: ARAME DE SOLDA MIG 1,2MM SOLIDO | B5: Matéria-prima | C5: KG | D5: 33
A6: ARAME RECOZIDO 18 - 1,24 MM - TRANCADO | B6: Matéria-prima | C6: KG | D6: 34
A7: ARGAMASSA AP60 | B7: Matéria-prima | C7: KG | D7: 33
A8: AVENTAL BARBEIRO RASPA 120 X 60 | B8: EPI | C8: UND | D8: 60
A9: AVENTAL DE RASPA 1,00 X 0,60 MT S/EMENDA | B9: EPI | C9: UND | D9: 60
A10: AVENTAL IMPERMEAVEL PARA LIMPEZA PESADA | B10: EPI | C10: UND | D10: 60
A11: AVENTAL PVC 1.20X60CM BRANCO | B11: EPI | C11: UND | D11: 60
A12: AVENTAL PVC IMPERMEÁVEL P/ LAVAGEM EM GERAL PRETO - USO PROFISSIONAL | B12: EPI | C12: UND | D12: 60
A13: AVENTAL RASPA 1.20X60CM | B13: EPI | C13: UND | D13: 60
... A304: ESQUADRO 30CM STANLEY | B304: Ferramenta | C304: UND | D304: 33

Sheet Pedido 1
B3: Data | C3: 45714
B4: CC | C4: 0015-00
A5: Nome | B5: Unidade | C5: Quantidade
A6: REBITE DE REPUXO 4,8 X 30 | B6: =VLOOKUP(A6,Planilha3!A:D,2,FALSE) -> Insumo | C6: 9300
A7: CORD 7 FIOS NUA CP 190 RB 12,70mm PRO | B7: =VLOOKUP(A7,Planilha3!A:D,2,FALSE) -> Matéria-prima | C7: 69000
A8: LIXA PARA MADEIRA N 220 | B8: =VLOOKUP(A8,Planilha3!A:D,2,FALSE) -> Insumo | C8: 750
A9: FOLHA LIXA FERRO GR.60 | B9: =VLOOKUP(A9,Planilha3!A:D,2,FALSE) -> Insumo | C9: 750
A10: LIMPA BAÚ DESENCRUSTANTE | B10: =VLOOKUP(A10,Planilha3!A:D,2,FALSE) -> Insumo | C10: 50
A11: SHAMPOO NEUTRALIZANTE DESENGRAXANTE | B11: =VLOOKUP(A11,Planilha3!A:D,2,FALSE) -> Insumo | C11: 50
A12: REMOVEDOR DE CONCRETO (BITONEX) | B12: =VLOOKUP(A12,Planilha3!A:D,2,FALSE) -> Insumo | C12: 50
A13: TELA VIVEIRO METAL | B13: =VLOOKUP(A13,Planilha3!A:D,2,FALSE) -> Matéria-prima | C13: 112
A14: TUBO CORRUGADO 1 1/2'' | B14: =VLOOKUP(A14,Planilha3!A:D,2,FALSE) -> Insumo | C14: 150
A15: ESPACADOR TIPO CADEIRINHA SCP30-45 | B15: =VLOOKUP(A15,Planilha3!A:D,2,FALSE) -> Matéria-prima | C15: 14200
A16: ARAME DE SOLDA MIG 1,2MM SOLIDO | B16: =VLOOKUP(A16,Planilha3!A:D,2,FALSE) -> Matéria-prima | C16: 315
B17: =VLOOKUP(A17,Planilha3!A:D,2,FALSE) -> #N/A
B18: =VLOOKUP(A18,Planilha3!A:D,2,FALSE) -> #N/A
B19: =VLOOKUP(A19,Planilha3!A:D,2,FALSE) -> #N/A
B20: =VLOOKUP(A20,Planilha3!A:D,2,FALSE) -> #N/A
B21: =VLOOKUP(A21,Planilha3!A:D,2,FALSE) -> #N/A
B22: =VLOOKUP(A22,Planilha3!A:D,2,FALSE) -> #N/A
B23: =VLOOKUP(A23,Planilha3!A:D,2,FALSE) -> #N/A
B24: =VLOOKUP(A24,Planilha3!A:D,2,FALSE) -> #N/A
B25: =VLOOKUP(A25,Planilha3!A:D,2,FALSE) -> #N/A

Sheet Pedido 1 CSN
B3: Data | C3: 45714
A4: CSN CIMENTOS | B4: CC | C4: 0015-00
A5: Nome | B5: Unidade | C5: Quantidade
A6: CIMENTO CP III 40 RS U FORTE AVI0 GRANEL | B6: =VLOOKUP(A6,Planilha3!A:D,2,FALSE) -> Matéria-prima | C6: 860
A7: CIMENTO CP V ARI PLUS U RAPIDO APL0 GRAN | B7: =VLOOKUP(A7,Planilha3!A:D,2,FALSE) -> Matéria-prima | C7: 460
B8: =VLOOKUP(A8,Planilha3!A:D,2,FALSE) -> #N/A
B9: =VLOOKUP(A9,Planilha3!A:D,2,FALSE) -> #N/A
B10: =VLOOKUP(A10,Planilha3!A:D,2,FALSE) -> #N/A
B11: =VLOOKUP(A11,Planilha3!A:D,2,FALSE) -> #N/A
B12: =VLOOKUP(A12,Planilha3!A:D,2,FALSE) -> #N/A
B13: =VLOOKUP(A13,Planilha3!A:D,2,FALSE) -> #N/A
B14: =VLOOKUP(A14,Planilha3!A:D,2,FALSE) -> #N/A
B15: =VLOOKUP(A15,Planilha3!A:D,2,FALSE) -> #N/A
B16: =VLOOKUP(A16,Planilha3!A:D,2,FALSE) -> #N/A
B17: =VLOOKUP(A17,Planilha3!A:D,2,FALSE) -> #N/A
B18: =VLOOKUP(A18,Planilha3!A:D,2,FALSE) -> #N/A
B19: =VLOOKUP(A19,Planilha3!A:D,2,FALSE) -> #N/A
... B25: =VLOOKUP(A25,Planilha3!A:D,2,FALSE) -> #N/A

Sheet Pedido 1 MCBAUCHIMIE
B3: Data | C3: 45714
A4: MC BAUCHEMIE | B4: CC | C4: 0015-00
A5: Nome | B5: Unidade | C5: Quantidade
A6: MC ORTOLAN CLASSIC 711 - 200 L (OLEO DESMOLDANTE) | B6: =VLOOKUP(A6,Planilha3!A:D,2,FALSE) -> Matéria-prima | C6: 200
A7: MC-POWERTOP F CINZA - 25 KG | B7: =VLOOKUP(A7,Planilha3!A:D,2,FALSE) -> Matéria-prima | C7: 1350
A8: MC-INJEKT 1264 COMPACT - KIT 6 X 1 KG | B8: =VLOOKUP(A8,Planilha3!A:D,2,FALSE) -> Insumo
A9: MC D 11 - 3,6 KG | B9: =VLOOKUP(A9,Planilha3!A:D,2,FALSE) -> Matéria-prima
A10: MC EMCORIL TRAFFIC - 1000 KG (IBC) | B10: =VLOOKUP(A10,Planilha3!A:D,2,FALSE) -> Matéria-prima | C10: 1000
A11: MC EMCORIL TRAFFIC - 200 KG | B11: =VLOOKUP(A11,Planilha3!A:D,2,FALSE) -> Matéria-prima | C11: 400
B12: =VLOOKUP(A12,Planilha3!A:D,2,FALSE) -> #N/A
B13: =VLOOKUP(A13,Planilha3!A:D,2,FALSE) -> #N/A
B14: =VLOOKUP(A14,Planilha3!A:D,2,FALSE) -> #N/A
B15: =VLOOKUP(A15,Planilha3!A:D,2,FALSE) -> #N/A
B16: =VLOOKUP(A16,Planilha3!A:D,2,FALSE) -> #N/A
B17: =VLOOKUP(A17,Planilha3!A:D,2,FALSE) -> #N/A
B18: =VLOOKUP(A18,Planilha3!A:D,2,FALSE) -> #N/A
B19: =VLOOKUP(A19,Planilha3!A:D,2,FALSE) -> #N/A
B20: =VLOOKUP(A20,Planilha3!A:D,2,FALSE) -> #N/A
B21: =VLOOKUP(A21,Planilha3!A:D,2,FALSE) -> #N/A
B22: =VLOOKUP(A22,Planilha3!A:D,2,FALSE) -> #N/A
B23: =VLOOKUP(A23,Planilha3!A:D,2,FALSE) -> #N/A
... B25: =VLOOKUP(A25,Planilha3!A:D,2,FALSE) -> #N/A

Sheet Pedido 1 TECNOSIL
B3: Data | C3: 45714
A4: TECNOSIL | B4: CC | C4: 0015-00
A5: Nome | B5: Unidade | C5: Quantidade
A6: SILICA ATIVA | B6: =VLOOKUP(A6,Planilha3!A:D,2,FALSE) -> Matéria-prima | C6: 55000
B7: =VLOOKUP(A7,Planilha3!A:D,2,FALSE) -> #N/A
B8: =VLOOKUP(A8,Planilha3!A:D,2,FALSE) -> #N/A
B9: =VLOOKUP(A9,Planilha3!A:D,2,FALSE) -> #N/A
B10: =VLOOKUP(A10,Planilha3!A:D,2,FALSE) -> #N/A
B11: =VLOOKUP(A11,Planilha3!A:D,2,FALSE) -> #N/A
B12: =VLOOKUP(A12,Planilha3!A:D,2,FALSE) -> #N/A
B13: =VLOOKUP(A13,Planilha3!A:D,2,FALSE) -> #N/A
B14: =VLOOKUP(A14,Planilha3!A:D,2,FALSE) -> #N/A
B15: =VLOOKUP(A15,Planilha3!A:D,2,FALSE) -> #N/A
B16: =VLOOKUP(A16,Planilha3!A:D,2,FALSE) -> #N/A
B17: =VLOOKUP(A17,Planilha3!A:D,2,FALSE) -> #N/A
B18: =VLOOKUP(A18,Planilha3!A:D,2,FALSE) -> #N/A
... B25: =VLOOKUP(A25,Planilha3!A:D,2,FALSE) -> #N/A

Sheet Pedido IMOBILIZADOS
B3: Data | C3: 45714
A4: TECNOSIL | B4: CC | C4: 0200-00
A5: Nome | B5: Unidade | C5: Quantidade
A6: ESMERILHADEIRA BOSCH 5 GWS 18V-10 + 2BAT + LBX | B6: =VLOOKUP(A6,Planilha3!A:D,2,FALSE) -> Equipamento | C6: 1
A7: BATERIA BOSCH PROCORE 18V 8.0AH 1600A016GK P010 | B7: =VLOOKUP(A7,Planilha3!A:D,2,FALSE) -> Equipamento | C7: 2
A8: SERRA MARMORE | B8: =VLOOKUP(A8,Planilha3!A:D,2,FALSE) -> Equipamento | C8: 1
A9: ESMERILHADEIRA BOSCH 18F1.0 220V GWS 2200-180 | B9: =VLOOKUP(A9,Planilha3!A:D,2,FALSE) -> Equipamento | C9: 2
A10: ESMERILHADEIRA ANG BOSCH 17A3.1 GWS 18-125-PL 220V | B10: =VLOOKUP(A10,Planilha3!A:D,2,FALSE) -> Equipamento | C10: 1
A11: REBITADOR PNEUM PDR PRO-316 3/16 | B11: =VLOOKUP(A11,Planilha3!A:D,2,FALSE) -> Equipamento | C11: 2
B12: =VLOOKUP(A12,Planilha3!A:D,2,FALSE) -> #N/A
B13: =VLOOKUP(A13,Planilha3!A:D,2,FALSE) -> #N/A
B14: =VLOOKUP(A14,Planilha3!A:D,2,FALSE) -> #N/A
B15: =VLOOKUP(A15,Planilha3!A:D,2,FALSE) -> #N/A

Sheet Pedido IMOBILIZADOS (2)
B3: Data | C3: 45714
A4: TECNOSIL | B4: CC | C4: 0200-00
A5: Nome | B5: Unidade | C5: Quantidade
A6: REGUA DE ALUMINIO 100X50X6000 | B6: =VLOOKUP(A6,Planilha3!A:D,2,FALSE) -> Insumo | C6: 1
A7: REGUA DE ALUMINIO 50X25X6000 | B7: =VLOOKUP(A7,Planilha3!A:D,2,FALSE) -> Insumo | C7: 1
A8: COLHER PEDREIRO RETA N06 PACETTA | B8: =VLOOKUP(A8,Planilha3!A:D,2,FALSE) -> Ferramenta | C8: 10
A9: BALDE ACO P/CONCRETO 12LT | B9: =VLOOKUP(A9,Planilha3!A:D,2,FALSE) -> Insumo | C9: 4
A10: BALDE GRADUADO DE AÇO | B10: =VLOOKUP(A10,Planilha3!A:D,2,FALSE) -> Insumo | C10: 1
A11: PONTEIRO SDS 400MM | B11: =VLOOKUP(A11,Planilha3!A:D,2,FALSE) -> Insumo | C11: 2
A12: LIMA CHATA 8'' | B12: =VLOOKUP(A12,Planilha3!A:D,2,FALSE) -> Insumo | C12: 2
A13: ESQUADRO 30CM STANLEY | B13: =VLOOKUP(A13,Planilha3!A:D,2,FALSE) -> Ferramenta | C13: 2
B14: =VLOOKUP(A14,Planilha3!A:D,2,FALSE) -> #N/A
B15: =VLOOKUP(A15,Planilha3!A:D,2,FALSE) -> #N/A
B16: =VLOOKUP(A16,Planilha3!A:D,2,FALSE) -> #N/A
B17: =VLOOKUP(A17,Planilha3!A:D,2,FALSE) -> #N/A
B18: =VLOOKUP(A18,Planilha3!A:D,2,FALSE) -> #N/A
B19: =VLOOKUP(A19,Planilha3!A:D,2,FALSE) -> #N/A
