Workbook

Sheet CAPA DAS OBRAS
B1: NEREDA | C1: PROJETO | D1: EXECUÇÃO (concretado) | F1: ACABAMENTO (PRONTO) | H1: TRANSPORTE (EM VIAGEM)
C2: NEREDA | D2: QTDE | E2: % | F2: QTDE | G2: % | H2: QTDE | I2: %
B3: TOTAL DE PLACAS NORMAIS | C3: =COUNTIF(' CADASTRO'!$F$2:$F$745,"PN") -> 642 | D3: =SUMIFS(' CADASTRO'!$D$2:$D$745,' CADASTRO'!$F$2:$F$745,"PN") -> 235 | E3: =D3/C3 -> 0.36604361 | F3: =SUMIFS(' CADASTRO'!$T$2:$T$745,' CADASTRO'!$F$2:$F$745,"PN") -> 156 | G3: =F3/C3 -> 0.24299065 | H3: =SUMIFS(' CADASTRO'!$X$2:$X$745,' CADASTRO'!$F$2:$F$745,"PN") -> 104 | I3: =H3/C3 -> 0.16199377
B4: TOTAL PLACAS ESPECIAIS | C4: =COUNTIF(' CADASTRO'!$F$2:$F$745,"PE") -> 78 | D4: =SUMIFS(' CADASTRO'!$D$2:$D$745,' CADASTRO'!$F$2:$F$745,"PE") -> 30 | E4: =D4/C4 -> 0.38461538 | F4: =SUMIFS(' CADASTRO'!$T$2:$T$745,' CADASTRO'!$F$2:$F$745,"PE") -> 19 | G4: =F4/C4 -> 0.24358974 | H4: =SUMIFS(' CADASTRO'!$X$2:$X$745,' CADASTRO'!$F$2:$F$745,"PE") -> 13 | I4: =H4/C4 -> 0.16666667
B5: TOTAL DE PLACAS FECHO | C5: =COUNTIF(' CADASTRO'!$F$2:$F$745,"PF") -> 24 | D5: =SUMIFS(' CADASTRO'!$D$2:$D$745,' CADASTRO'!$F$2:$F$745,"PF") -> 6 | E5: =D5/C5 -> 0.25 | F5: =SUMIFS(' CADASTRO'!$T$2:$T$745,' CADASTRO'!$F$2:$F$745,"PF") -> 6 | G5: =F5/C5 -> 0.25 | H5: =SUMIFS(' CADASTRO'!$X$2:$X$745,' CADASTRO'!$F$2:$F$745,"PF") -> 4 | I5: =H5/C5 -> 0.16666667
B6: TOTAIS | C6: =SUM(C3:C5) -> 744 | D6: =SUM(D3:D5) -> 271 | E6: =D6/C6 -> 0.36424731
B9: PRIMARIO | C9: PROJETO | D9: EXECUÇÃO (concretado) | F9: ACABAMENTO (PRONTO) | H9: TRANSPORTE (EM VIAGEM)
C10: PRIMARIO | D10: QTDE | E10: % | F10: QTDE | G10: % | H10: QTDE | I10: %
B11: TOTAL DE PLACAS NORMAIS | C11: =COUNTIF(' CADASTRO'!$F$746:$F$895,"PN") -> 105 | D11: =SUMIFS(' CADASTRO'!$D$746:$D$895,' CADASTRO'!$F$746:$F$895,"PN") -> 75 | E11: =D11/C11 -> 0.71428571 | F11: =SUMIFS(' CADASTRO'!$T$746:$T$895,' CADASTRO'!$F$746:$F$895,"PN") -> 40 | G11: =F11/C11 -> 0.38095238 | H11: =SUMIFS(' CADASTRO'!$X$746:$X$895,' CADASTRO'!$F$746:$F$895,"PN") -> 28 | I11: =H11/C11 -> 0.26666667
B12: TOTAL PLACAS ESPECIAIS | C12: ='CALCULOS '!A8 -> 37 | D12: =SUM(' CADASTRO'!$D$746:$D$893)-'CAPA DAS OBRAS'!D11-'CAPA DAS OBRAS'!D13 -> 11 | E12: =D12/C12 -> 0.2972973 | F12: =SUM(' CADASTRO'!$T$746:$T$893,-(F11+F13)) -> 1 | G12: =F12/C12 -> 0.027027027 | H12: =SUM(' CADASTRO'!$X$746:$X$893)-(H11+H13) -> 0 | I12: =H12/C12 -> 0
B13: TOTAL DE PLACAS FECHO | C13: =COUNTIF(' CADASTRO'!$F$746:$F$895,"PF") -> 6 | D13: =SUMIFS(' CADASTRO'!$D$746:$D$895,' CADASTRO'!$F$746:$F$895,"PF") -> 6 | E13: =D13/C13 -> 1 | F13: =SUMIFS(' CADASTRO'!$T$746:$T$895,' CADASTRO'!$F$746:$F$895,"PF") -> 1 | G13: =F13/C13 -> 0.16666667 | H13: =SUMIFS(' CADASTRO'!$X$746:$X$895,' CADASTRO'!$F$746:$F$895,"PF") -> 0 | I13: =H13/C13 -> 0
B14: TOTAIS | C14: =SUM(C11:C13) -> 148 | D14: =SUM(D11:D13) -> 92 | E14: =D14/C14 -> 0.62162162

Sheet  CADASTRO
A1: ITEM | B1: data | C1: se concretada marque "x" | D1: se concretado | E1: IDENT. TANQUE | F1: PLACA | J1: TIPO | K1: #3/8-1620X1620 | L1: #3/8-1120X1120 | M1: #3/8-1200X1200 | N1: #3/8-530X530 | O1: #3/8 X150X150 | P1: A DEFINIR | Q1: CHAPA DE | R1: data do acabamento finalizado | S1: pista | T1: se | U1: DATA TRANS. | V1: PLACA CARRETA | W1: NF: | X1: SE TRANSPORTADO | Y1: altura de escora
A2: 1 | B2: 45797 | C2: 29 | D2: =IF(B2>0,1,"") -> 1 | E2: REATOR 1 | F2: PF | G2: - | H2: 01 | I2: =_xlfn.CONCAT(F2,G2,H2) -> PF-01 | J2: PF | K2: =IF(J2="","SEM #CH",VLOOKUP(J2,#REF!,2,0)) -> #REF! | L2: =IF(J2="","SEM #CH",VLOOKUP(J2,#REF!,3,0)) -> #REF! | M2: =IF(J2="","SEM #CH",VLOOKUP(J2,#REF!,4,0)) -> #REF! | N2: =IF(J2="","SEM #CH",VLOOKUP(J2,#REF!,5,0)) -> #REF! | O2: =IF(J2="","SEM #CH",VLOOKUP(J2,#REF!,6,0)) -> #REF! | P2: =IF(J2="","SEM #CH",VLOOKUP(J2,#REF!,7,0)) -> #REF! | Q2: =VLOOKUP(J2,'p1'!$B$2:$C$30,2,0) -> SEM CHAPA | R2: 45799 | S2: PN-001 | T2: =IF(R2=0,"",1) -> 1 | U2: 45824 | V2: - | W2: 2387 | X2: =IF(U2>0,1,"") -> 1
A3: 2 | B3: 45733 | C3: 1 | D3: =IF(B3>0,1,"") -> 1 | E3: REATOR 1 | F3: PN | G3: - | H3: 02 | I3: =_xlfn.CONCAT(F3,G3,H3) -> PN-02 | J3: P | K3: =IF(J3="","SEM #CH",VLOOKUP(J3,#REF!,2,0)) -> #REF! | L3: =IF(J3="","SEM #CH",VLOOKUP(J3,#REF!,3,0)) -> #REF! | M3: =IF(J3="","SEM #CH",VLOOKUP(J3,#REF!,4,0)) -> #REF! | N3: =IF(J3="","SEM #CH",VLOOKUP(J3,#REF!,5,0)) -> #REF! | O3: =IF(J3="","SEM #CH",VLOOKUP(J3,#REF!,6,0)) -> #REF! | P3: =IF(J3="","SEM #CH",VLOOKUP(J3,#REF!,7,0)) -> #REF! | Q3: =VLOOKUP(J3,'p1'!$B$2:$C$30,2,0) -> NÃO TEM CHAPA | R3: 45738 | S3: PN-001 | T3: =IF(R3=0,"",1) -> 1 | U3: 45818 | V3: - | W3: 2373 | X3: =IF(U3>0,1,"") -> 1
A4: 3 | B4: 45733 | C4: 1 | D4: =IF(B4>0,1,"") -> 1 | E4: REATOR 1 | F4: PN | G4: - | H4: 03 | I4: =_xlfn.CONCAT(F4,G4,H4) -> PN-03 | J4: P | K4: =IF(J4="","SEM #CH",VLOOKUP(J4,#REF!,2,0)) -> #REF! | L4: =IF(J4="","SEM #CH",VLOOKUP(J4,#REF!,3,0)) -> #REF! | M4: =IF(J4="","SEM #CH",VLOOKUP(J4,#REF!,4,0)) -> #REF! | N4: =IF(J4="","SEM #CH",VLOOKUP(J4,#REF!,5,0)) -> #REF! | O4: =IF(J4="","SEM #CH",VLOOKUP(J4,#REF!,6,0)) -> #REF! | P4: =IF(J4="","SEM #CH",VLOOKUP(J4,#REF!,7,0)) -> #REF! | Q4: =VLOOKUP(J4,'p1'!$B$2:$C$30,2,0) -> NÃO TEM CHAPA | R4: 45738 | S4: PN-001 | T4: =IF(R4=0,"",1) -> 1 | U4: 45818 | V4: - | W4: 2373 | X4: =IF(U4>0,1,"") -> 1
A5: 4 | B5: 45733 | C5: 1 | D5: =IF(B5>0,1,"") -> 1 | E5: REATOR 1 | F5: PN | G5: - | H5: 04 | I5: =_xlfn.CONCAT(F5,G5,H5) -> PN-04 | J5: P | K5: =IF(J5="","SEM #CH",VLOOKUP(J5,#REF!,2,0)) -> #REF! | L5: =IF(J5="","SEM #CH",VLOOKUP(J5,#REF!,3,0)) -> #REF! | M5: =IF(J5="","SEM #CH",VLOOKUP(J5,#REF!,4,0)) -> #REF! | N5: =IF(J5="","SEM #CH",VLOOKUP(J5,#REF!,5,0)) -> #REF! | O5: =IF(J5="","SEM #CH",VLOOKUP(J5,#REF!,6,0)) -> #REF! | P5: =IF(J5="","SEM #CH",VLOOKUP(J5,#REF!,7,0)) -> #REF! | Q5: =VLOOKUP(J5,'p1'!$B$2:$C$30,2,0) -> NÃO TEM CHAPA | R5: 45743 | S5: PN-001 | T5: =IF(R5=0,"",1) -> 1 | U5: 45824 | V5: - | W5: 2387 | X5: =IF(U5>0,1,"") -> 1
A6: 5 | B6: 45733 | C6: 1 | D6: =IF(B6>0,1,"") -> 1 | E6: REATOR 1 | F6: PN | G6: - | H6: 05 | I6: =_xlfn.CONCAT(F6,G6,H6) -> PN-05 | J6: P | K6: =IF(J6="","SEM #CH",VLOOKUP(J6,#REF!,2,0)) -> #REF! | L6: =IF(J6="","SEM #CH",VLOOKUP(J6,#REF!,3,0)) -> #REF! | M6: =IF(J6="","SEM #CH",VLOOKUP(J6,#REF!,4,0)) -> #REF! | N6: =IF(J6="","SEM #CH",VLOOKUP(J6,#REF!,5,0)) -> #REF! | O6: =IF(J6="","SEM #CH",VLOOKUP(J6,#REF!,6,0)) -> #REF! | P6: =IF(J6="","SEM #CH",VLOOKUP(J6,#REF!,7,0)) -> #REF! | Q6: =VLOOKUP(J6,'p1'!$B$2:$C$30,2,0) -> NÃO TEM CHAPA | R6: 45741 | S6: PN-001 | T6: =IF(R6=0,"",1) -> 1 | U6: 45818 | V6: - | W6: 2373 | X6: =IF(U6>0,1,"") -> 1
A7: 6 | B7: 45733 | C7: 1 | D7: =IF(B7>0,1,"") -> 1 | E7: REATOR 1 | F7: PN | G7: - | H7: 06 | I7: =_xlfn.CONCAT(F7,G7,H7) -> PN-06 | J7: P | K7: =IF(J7="","SEM #CH",VLOOKUP(J7,#REF!,2,0)) -> #REF! | L7: =IF(J7="","SEM #CH",VLOOKUP(J7,#REF!,3,0)) -> #REF! | M7: =IF(J7="","SEM #CH",VLOOKUP(J7,#REF!,4,0)) -> #REF! | N7: =IF(J7="","SEM #CH",VLOOKUP(J7,#REF!,5,0)) -> #REF! | O7: =IF(J7="","SEM #CH",VLOOKUP(J7,#REF!,6,0)) -> #REF! | P7: =IF(J7="","SEM #CH",VLOOKUP(J7,#REF!,7,0)) -> #REF! | Q7: =VLOOKUP(J7,'p1'!$B$2:$C$30,2,0) -> NÃO TEM CHAPA | R7: 45741 | S7: PN-001 | T7: =IF(R7=0,"",1) -> 1 | U7: 45818 | V7: - | W7: 2372 | X7: =IF(U7>0,1,"") -> 1
A8: 7 | B8: 45806 | C8: 31 | D8: =IF(B8>0,1,"") -> 1 | E8: REATOR 1 | F8: PE | G8: - | H8: 07 | I8: =_xlfn.CONCAT(F8,G8,H8) -> PE-07 | J8: T2 | K8: =IF(J8="","SEM #CH",VLOOKUP(J8,#REF!,2,0)) -> #REF! | L8: =IF(J8="","SEM #CH",VLOOKUP(J8,#REF!,3,0)) -> #REF! | M8: =IF(J8="","SEM #CH",VLOOKUP(J8,#REF!,4,0)) -> #REF! | N8: =IF(J8="","SEM #CH",VLOOKUP(J8,#REF!,5,0)) -> #REF! | O8: =IF(J8="","SEM #CH",VLOOKUP(J8,#REF!,6,0)) -> #REF! | P8: =IF(J8="","SEM #CH",VLOOKUP(J8,#REF!,7,0)) -> #REF! | Q8: =VLOOKUP(J8,'p1'!$B$2:$C$30,2,0) -> #3/8-1315X1315 | R8: 45812 | S8: PN-001 | T8: =IF(R8=0,"",1) -> 1 | U8: 45821 | V8: - | W8: 2383 | X8: =IF(U8>0,1,"") -> 1
A9: 8 | B9: 45806 | C9: 31 | D9: =IF(B9>0,1,"") -> 1 | E9: REATOR 1 | F9: PE | G9: - | H9: 08 | I9: =_xlfn.CONCAT(F9,G9,H9) -> PE-08 | J9: T1 | K9: =IF(J9="","SEM #CH",VLOOKUP(J9,#REF!,2,0)) -> #REF! | L9: =IF(J9="","SEM #CH",VLOOKUP(J9,#REF!,3,0)) -> #REF! | M9: =IF(J9="","SEM #CH",VLOOKUP(J9,#REF!,4,0)) -> #REF! | N9: =IF(J9="","SEM #CH",VLOOKUP(J9,#REF!,5,0)) -> #REF! | O9: =IF(J9="","SEM #CH",VLOOKUP(J9,#REF!,6,0)) -> #REF! | P9: =IF(J9="","SEM #CH",VLOOKUP(J9,#REF!,7,0)) -> #REF! | Q9: =VLOOKUP(J9,'p1'!$B$2:$C$30,2,0) -> #3/8-1620X1620 | R9: 45813 | S9: PN-001 | T9: =IF(R9=0,"",1) -> 1 | U9: 45814 | V9: IOO3D34 | W9: 2367 | X9: =IF(U9>0,1,"") -> 1
A10: 9 | B10: 45806 | C10: 31 | D10: =IF(B10>0,1,"") -> 1 | E10: REATOR 1 | F10: PE | G10: - | H10: 09 | I10: =_xlfn.CONCAT(F10,G10,H10) -> PE-09 | J10: T3 | K10: =IF(J10="","SEM #CH",VLOOKUP(J10,#REF!,2,0)) -> #REF! | L10: =IF(J10="","SEM #CH",VLOOKUP(J10,#REF!,3,0)) -> #REF! | M10: =IF(J10="","SEM #CH",VLOOKUP(J10,#REF!,4,0)) -> #REF! | N10: =IF(J10="","SEM #CH",VLOOKUP(J10,#REF!,5,0)) -> #REF! | O10: =IF(J10="","SEM #CH",VLOOKUP(J10,#REF!,6,0)) -> #REF! | P10: =IF(J10="","SEM #CH",VLOOKUP(J10,#REF!,7,0)) -> #REF! | Q10: =VLOOKUP(J10,'p1'!$B$2:$C$30,2,0) -> #3/8-1200X1200 | R10: 45810 | S10: PN-001 | T10: =IF(R10=0,"",1) -> 1 | U10: 45817 | V10: - | W10: 2370 | X10: =IF(U10>0,1,"") -> 1
A11: 10 | B11: 45733 | C11: 1 | D11: =IF(B11>0,1,"") -> 1 | E11: REATOR 1 | F11: PN | G11: - | H11: 10 | I11: =_xlfn.CONCAT(F11,G11,H11) -> PN-10 | J11: P | K11: =IF(J11="","SEM #CH",VLOOKUP(J11,#REF!,2,0)) -> #REF! | L11: =IF(J11="","SEM #CH",VLOOKUP(J11,#REF!,3,0)) -> #REF! | M11: =IF(J11="","SEM #CH",VLOOKUP(J11,#REF!,4,0)) -> #REF! | N11: =IF(J11="","SEM #CH",VLOOKUP(J11,#REF!,5,0)) -> #REF! | O11: =IF(J11="","SEM #CH",VLOOKUP(J11,#REF!,6,0)) -> #REF! | P11: =IF(J11="","SEM #CH",VLOOKUP(J11,#REF!,7,0)) -> #REF! | Q11: =VLOOKUP(J11,'p1'!$B$2:$C$30,2,0) -> NÃO TEM CHAPA | R11: 45740 | S11: PN-001 | T11: =IF(R11=0,"",1) -> 1 | U11: 45818 | V11: - | W11: 2372 | X11: =IF(U11>0,1,"") -> 1
A12: 11 | B12: 45733 | C12: 1 | D12: =IF(B12>0,1,"") -> 1 | E12: REATOR 1 | F12: PN | G12: - | H12: 11 | I12: =_xlfn.CONCAT(F12,G12,H12) -> PN-11 | J12: P | K12: =IF(J12="","SEM #CH",VLOOKUP(J12,#REF!,2,0)) -> #REF! | L12: =IF(J12="","SEM #CH",VLOOKUP(J12,#REF!,3,0)) -> #REF! | M12: =IF(J12="","SEM #CH",VLOOKUP(J12,#REF!,4,0)) -> #REF! | N12: =IF(J12="","SEM #CH",VLOOKUP(J12,#REF!,5,0)) -> #REF! | O12: =IF(J12="","SEM #CH",VLOOKUP(J12,#REF!,6,0)) -> #REF! | P12: =IF(J12="","SEM #CH",VLOOKUP(J12,#REF!,7,0)) -> #REF! | Q12: =VLOOKUP(J12,'p1'!$B$2:$C$30,2,0) -> NÃO TEM CHAPA | R12: 45740 | S12: PN-001 | T12: =IF(R12=0,"",1) -> 1 | U12: 45759 | V12: - | W12: 2373 | X12: =IF(U12>0,1,"") -> 1
A13: 12 | B13: 45741 | C13: 2 | D13: =IF(B13>0,1,"") -> 1 | E13: REATOR 1 | F13: PN | G13: - | H13: 12 | I13: =_xlfn.CONCAT(F13,G13,H13) -> PN-12 | J13: P | K13: =IF(J13="","SEM #CH",VLOOKUP(J13,#REF!,2,0)) -> #REF! | L13: =IF(J13="","SEM #CH",VLOOKUP(J13,#REF!,3,0)) -> #REF! | M13: =IF(J13="","SEM #CH",VLOOKUP(J13,#REF!,4,0)) -> #REF! | N13: =IF(J13="","SEM #CH",VLOOKUP(J13,#REF!,5,0)) -> #REF! | O13: =IF(J13="","SEM #CH",VLOOKUP(J13,#REF!,6,0)) -> #REF! | P13: =IF(J13="","SEM #CH",VLOOKUP(J13,#REF!,7,0)) -> #REF! | Q13: =VLOOKUP(J13,'p1'!$B$2:$C$30,2,0) -> NÃO TEM CHAPA | R13: 45743 | S13: PN-001 | T13: =IF(R13=0,"",1) -> 1 | U13: 45831 | V13: - | W13: 2405 | X13: =IF(U13>0,1,"") -> 1
... A16: 15 | B16: 45741 | C16: 2 | D16: =IF(B16>0,1,"") -> 1 | E16: REATOR 1 | F16: PN | G16: - | H16: 15 | I16: =_xlfn.CONCAT(F16,G16,H16) -> PN-15 | J16: P | K16: =IF(J16="","SEM #CH",VLOOKUP(J16,#REF!,2,0)) -> #REF! | L16: =IF(J16="","SEM #CH",VLOOKUP(J16,#REF!,3,0)) -> #REF! | M16: =IF(J16="","SEM #CH",VLOOKUP(J16,#REF!,4,0)) -> #REF! | N16: =IF(J16="","SEM #CH",VLOOKUP(J16,#REF!,5,0)) -> #REF! | O16: =IF(J16="","SEM #CH",VLOOKUP(J16,#REF!,6,0)) -> #REF! | P16: =IF(J16="","SEM #CH",VLOOKUP(J16,#REF!,7,0)) -> #REF! | Q16: =VLOOKUP(J16,'p1'!$B$2:$C$30,2,0) -> NÃO TEM CHAPA | R16: 45745 | S16: PN-001 | T16: =IF(R16=0,"",1) -> 1 | U16: 45818 | V16: - | W16: 2372 | X16: =IF(U16>0,1,"") -> 1
A17: 16 | B17: 45741 | C17: 2 | D17: =IF(B17>0,1,"") -> 1 | E17: REATOR 1 | F17: PN | G17: - | H17: 16 | I17: =_xlfn.CONCAT(F17,G17,H17) -> PN-16 | J17: P | K17: =IF(J17="","SEM #CH",VLOOKUP(J17,#REF!,2,0)) -> #REF! | L17: =IF(J17="","SEM #CH",VLOOKUP(J17,#REF!,3,0)) -> #REF! | M17: =IF(J17="","SEM #CH",VLOOKUP(J17,#REF!,4,0)) -> #REF! | N17: =IF(J17="","SEM #CH",VLOOKUP(J17,#REF!,5,0)) -> #REF! | O17: =IF(J17="","SEM #CH",VLOOKUP(J17,#REF!,6,0)) -> #REF! | P17: =IF(J17="","SEM #CH",VLOOKUP(J17,#REF!,7,0)) -> #REF! | Q17: =VLOOKUP(J17,'p1'!$B$2:$C$30,2,0) -> NÃO TEM CHAPA | R17: 45745 | S17: PN-001 | T17: =IF(R17=0,"",1) -> 1 | X17: =IF(U17>0,1,"")
A18: 17 | B18: 45741 | C18: 2 | D18: =IF(B18>0,1,"") -> 1 | E18: REATOR 1 | F18: PN | G18: - | H18: 17 | I18: =_xlfn.CONCAT(F18,G18,H18) -> PN-17 | J18: P | K18: =IF(J18="","SEM #CH",VLOOKUP(J18,#REF!,2,0)) -> #REF! | L18: =IF(J18="","SEM #CH",VLOOKUP(J18,#REF!,3,0)) -> #REF! | M18: =IF(J18="","SEM #CH",VLOOKUP(J18,#REF!,4,0)) -> #REF! | N18: =IF(J18="","SEM #CH",VLOOKUP(J18,#REF!,5,0)) -> #REF! | O18: =IF(J18="","SEM #CH",VLOOKUP(J18,#REF!,6,0)) -> #REF! | P18: =IF(J18="","SEM #CH",VLOOKUP(J18,#REF!,7,0)) -> #REF! | Q18: =VLOOKUP(J18,'p1'!$B$2:$C$30,2,0) -> NÃO TEM CHAPA | R18: 45744 | S18: PN-001 | T18: =IF(R18=0,"",1) -> 1 | X18: =IF(U18>0,1,"")
A19: 18 | B19: 45741 | C19: 2 | D19: =IF(B19>0,1,"") -> 1 | E19: REATOR 1 | F19: PN | G19: - | H19: 18 | I19: =_xlfn.CONCAT(F19,G19,H19) -> PN-18 | J19: P | K19: =IF(J19="","SEM #CH",VLOOKUP(J19,#REF!,2,0)) -> #REF! | L19: =IF(J19="","SEM #CH",VLOOKUP(J19,#REF!,3,0)) -> #REF! | M19: =IF(J19="","SEM #CH",VLOOKUP(J19,#REF!,4,0)) -> #REF! | N19: =IF(J19="","SEM #CH",VLOOKUP(J19,#REF!,5,0)) -> #REF! | O19: =IF(J19="","SEM #CH",VLOOKUP(J19,#REF!,6,0)) -> #REF! | P19: =IF(J19="","SEM #CH",VLOOKUP(J19,#REF!,7,0)) -> #REF! | Q19: =VLOOKUP(J19,'p1'!$B$2:$C$30,2,0) -> NÃO TEM CHAPA | R19: 45775 | S19: PN-001 | T19: =IF(R19=0,"",1) -> 1 | U19: 45833 | V19: - | W19: 2416 | X19: =IF(U19>0,1,"") -> 1
A20: 19 | B20: 45742 | C20: 3 | D20: =IF(B20>0,1,"") -> 1 | E20: REATOR 1 | F20: PN | G20: - | H20: 19 | I20: =_xlfn.CONCAT(F20,G20,H20) -> PN-19 | J20: P | K20: =IF(J20="","SEM #CH",VLOOKUP(J20,#REF!,2,0)) -> #REF! | L20: =IF(J20="","SEM #CH",VLOOKUP(J20,#REF!,3,0)) -> #REF! | M20: =IF(J20="","SEM #CH",VLOOKUP(J20,#REF!,4,0)) -> #REF! | N20: =IF(J20="","SEM #CH",VLOOKUP(J20,#REF!,5,0)) -> #REF! | O20: =IF(J20="","SEM #CH",VLOOKUP(J20,#REF!,6,0)) -> #REF! | P20: =IF(J20="","SEM #CH",VLOOKUP(J20,#REF!,7,0)) -> #REF! | Q20: =VLOOKUP(J20,'p1'!$B$2:$C$30,2,0) -> NÃO TEM CHAPA | R20: 45751 | S20: PN-002 | T20: =IF(R20=0,"",1) -> 1 | U20: 45811 | V20: ibc0i59 | W20: 2364 | X20: =IF(U20>0,1,"") -> 1
A21: 20 | B21: 45742 | C21: 3 | D21: =IF(B21>0,1,"") -> 1 | E21: REATOR 1 | F21: PN | G21: - | H21: 20 | I21: =_xlfn.CONCAT(F21,G21,H21) -> PN-20 | J21: P | K21: =IF(J21="","SEM #CH",VLOOKUP(J21,#REF!,2,0)) -> #REF! | L21: =IF(J21="","SEM #CH",VLOOKUP(J21,#REF!,3,0)) -> #REF! | M21: =IF(J21="","SEM #CH",VLOOKUP(J21,#REF!,4,0)) -> #REF! | N21: =IF(J21="","SEM #CH",VLOOKUP(J21,#REF!,5,0)) -> #REF! | O21: =IF(J21="","SEM #CH",VLOOKUP(J21,#REF!,6,0)) -> #REF! | P21: =IF(J21="","SEM #CH",VLOOKUP(J21,#REF!,7,0)) -> #REF! | Q21: =VLOOKUP(J21,'p1'!$B$2:$C$30,2,0) -> NÃO TEM CHAPA | R21: 45751 | S21: PN-002 | T21: =IF(R21=0,"",1) -> 1 | U21: 45811 | V21: jac2h97 | W21: 2365 | X21: =IF(U21>0,1,"") -> 1
A22: 21 | B22: 45742 | C22: 3 | D22: =IF(B22>0,1,"") -> 1 | E22: REATOR 1 | F22: PN | G22: - | H22: 21 | I22: =_xlfn.CONCAT(F22,G22,H22) -> PN-21 | J22: P | K22: =IF(J22="","SEM #CH",VLOOKUP(J22,#REF!,2,0)) -> #REF! | L22: =IF(J22="","SEM #CH",VLOOKUP(J22,#REF!,3,0)) -> #REF! | M22: =IF(J22="","SEM #CH",VLOOKUP(J22,#REF!,4,0)) -> #REF! | N22: =IF(J22="","SEM #CH",VLOOKUP(J22,#REF!,5,0)) -> #REF! | O22: =IF(J22="","SEM #CH",VLOOKUP(J22,#REF!,6,0)) -> #REF! | P22: =IF(J22="","SEM #CH",VLOOKUP(J22,#REF!,7,0)) -> #REF! | Q22: =VLOOKUP(J22,'p1'!$B$2:$C$30,2,0) -> NÃO TEM CHAPA | R22: 45749 | S22: PN-002 | T22: =IF(R22=0,"",1) -> 1 | U22: 45811 | V22: jac2h97 | W22: 2365 | X22: =IF(U22>0,1,"") -> 1
A23: 22 | B23: 45742 | C23: 3 | D23: =IF(B23>0,1,"") -> 1 | E23: REATOR 1 | F23: PN | G23: - | H23: 22 | I23: =_xlfn.CONCAT(F23,G23,H23) -> PN-22 | J23: P | K23: =IF(J23="","SEM #CH",VLOOKUP(J23,#REF!,2,0)) -> #REF! | L23: =IF(J23="","SEM #CH",VLOOKUP(J23,#REF!,3,0)) -> #REF! | M23: =IF(J23="","SEM #CH",VLOOKUP(J23,#REF!,4,0)) -> #REF! | N23: =IF(J23="","SEM #CH",VLOOKUP(J23,#REF!,5,0)) -> #REF! | O23: =IF(J23="","SEM #CH",VLOOKUP(J23,#REF!,6,0)) -> #REF! | P23: =IF(J23="","SEM #CH",VLOOKUP(J23,#REF!,7,0)) -> #REF! | Q23: =VLOOKUP(J23,'p1'!$B$2:$C$30,2,0) -> NÃO TEM CHAPA | R23: 45748 | S23: PN-002 | T23: =IF(R23=0,"",1) -> 1 | U23: 45811 | V23: jac2h97 | W23: 2365 | X23: =IF(U23>0,1,"") -> 1
A24: 23 | B24: 45742 | C24: 3 | D24: =IF(B24>0,1,"") -> 1 | E24: REATOR 1 | F24: PN | G24: - | H24: 23 | I24: =_xlfn.CONCAT(F24,G24,H24) -> PN-23 | J24: P | K24: =IF(J24="","SEM #CH",VLOOKUP(J24,#REF!,2,0)) -> #REF! | L24: =IF(J24="","SEM #CH",VLOOKUP(J24,#REF!,3,0)) -> #REF! | M24: =IF(J24="","SEM #CH",VLOOKUP(J24,#REF!,4,0)) -> #REF! | N24: =IF(J24="","SEM #CH",VLOOKUP(J24,#REF!,5,0)) -> #REF! | O24: =IF(J24="","SEM #CH",VLOOKUP(J24,#REF!,6,0)) -> #REF! | P24: =IF(J24="","SEM #CH",VLOOKUP(J24,#REF!,7,0)) -> #REF! | Q24: =VLOOKUP(J24,'p1'!$B$2:$C$30,2,0) -> NÃO TEM CHAPA | R24: 45748 | S24: PN-002 | T24: =IF(R24=0,"",1) -> 1 | U24: 45818 | V24: - | W24: 2374 | X24: =IF(U24>0,1,"") -> 1
A25: 24 | B25: 45806 | C25: 31 | D25: =IF(B25>0,1,"") -> 1 | E25: REATOR 1 | F25: PE | G25: - | H25: 24 | I25: =_xlfn.CONCAT(F25,G25,H25) -> PE-24 | J25: T4 | K25: =IF(J25="","SEM #CH",VLOOKUP(J25,#REF!,2,0)) -> #REF! | L25: =IF(J25="","SEM #CH",VLOOKUP(J25,#REF!,3,0)) -> #REF! | M25: =IF(J25="","SEM #CH",VLOOKUP(J25,#REF!,4,0)) -> #REF! | N25: =IF(J25="","SEM #CH",VLOOKUP(J25,#REF!,5,0)) -> #REF! | O25: =IF(J25="","SEM #CH",VLOOKUP(J25,#REF!,6,0)) -> #REF! | P25: =IF(J25="","SEM #CH",VLOOKUP(J25,#REF!,7,0)) -> #REF! | Q25: =VLOOKUP(J25,'p1'!$B$2:$C$30,2,0) -> #3/8-530X530 | R25: 45810 | S25: PN-001 | T25: =IF(R25=0,"",1) -> 1 | X25: =IF(U25>0,1,"")
A26: 25 | B26: 45742 | C26: 3 | D26: =IF(B26>0,1,"") -> 1 | E26: REATOR 1 | F26: PN | G26: - | H26: 25 | I26: =_xlfn.CONCAT(F26,G26,H26) -> PN-25 | J26: P | K26: =IF(J26="","SEM #CH",VLOOKUP(J26,#REF!,2,0)) -> #REF! | L26: =IF(J26="","SEM #CH",VLOOKUP(J26,#REF!,3,0)) -> #REF! | M26: =IF(J26="","SEM #CH",VLOOKUP(J26,#REF!,4,0)) -> #REF! | N26: =IF(J26="","SEM #CH",VLOOKUP(J26,#REF!,5,0)) -> #REF! | O26: =IF(J26="","SEM #CH",VLOOKUP(J26,#REF!,6,0)) -> #REF! | P26: =IF(J26="","SEM #CH",VLOOKUP(J26,#REF!,7,0)) -> #REF! | Q26: =VLOOKUP(J26,'p1'!$B$2:$C$30,2,0) -> NÃO TEM CHAPA | R26: 45745 | S26: PN-002 | T26: =IF(R26=0,"",1) -> 1 | U26: 45818 | V26: - | W26: 2374 | X26: =IF(U26>0,1,"") -> 1
A27: 26 | B27: 45742 | C27: 3 | D27: =IF(B27>0,1,"") -> 1 | E27: REATOR 1 | F27: PN | G27: - | H27: 26 | I27: =_xlfn.CONCAT(F27,G27,H27) -> PN-26 | J27: P | K27: =IF(J27="","SEM #CH",VLOOKUP(J27,#REF!,2,0)) -> #REF! | L27: =IF(J27="","SEM #CH",VLOOKUP(J27,#REF!,3,0)) -> #REF! | M27: =IF(J27="","SEM #CH",VLOOKUP(J27,#REF!,4,0)) -> #REF! | N27: =IF(J27="","SEM #CH",VLOOKUP(J27,#REF!,5,0)) -> #REF! | O27: =IF(J27="","SEM #CH",VLOOKUP(J27,#REF!,6,0)) -> #REF! | P27: =IF(J27="","SEM #CH",VLOOKUP(J27,#REF!,7,0)) -> #REF! | Q27: =VLOOKUP(J27,'p1'!$B$2:$C$30,2,0) -> NÃO TEM CHAPA | R27: 45749 | S27: PN-002 | T27: =IF(R27=0,"",1) -> 1 | U27: 45818 | V27: - | W27: 2374 | X27: =IF(U27>0,1,"") -> 1
A28: 27 | B28: 45743 | C28: 4 | D28: =IF(B28>0,1,"") -> 1 | E28: REATOR 1 | F28: PN | G28: - | H28: 27 | I28: =_xlfn.CONCAT(F28,G28,H28) -> PN-27 | J28: P | K28: =IF(J28="","SEM #CH",VLOOKUP(J28,#REF!,2,0)) -> #REF! | L28: =IF(J28="","SEM #CH",VLOOKUP(J28,#REF!,3,0)) -> #REF! | M28: =IF(J28="","SEM #CH",VLOOKUP(J28,#REF!,4,0)) -> #REF! | N28: =IF(J28="","SEM #CH",VLOOKUP(J28,#REF!,5,0)) -> #REF! | O28: =IF(J28="","SEM #CH",VLOOKUP(J28,#REF!,6,0)) -> #REF! | P28: =IF(J28="","SEM #CH",VLOOKUP(J28,#REF!,7,0)) -> #REF! | Q28: =VLOOKUP(J28,'p1'!$B$2:$C$30,2,0) -> NÃO TEM CHAPA | T28: =IF(R28=0,"",1) | X28: =IF(U28>0,1,"")
A29: 28 | B29: 45743 | C29: 4 | D29: =IF(B29>0,1,"") -> 1 | E29: REATOR 1 | F29: PN | G29: - | H29: 28 | I29: =_xlfn.CONCAT(F29,G29,H29) -> PN-28 | J29: P | K29: =IF(J29="","SEM #CH",VLOOKUP(J29,#REF!,2,0)) -> #REF! | L29: =IF(J29="","SEM #CH",VLOOKUP(J29,#REF!,3,0)) -> #REF! | M29: =IF(J29="","SEM #CH",VLOOKUP(J29,#REF!,4,0)) -> #REF! | N29: =IF(J29="","SEM #CH",VLOOKUP(J29,#REF!,5,0)) -> #REF! | O29: =IF(J29="","SEM #CH",VLOOKUP(J29,#REF!,6,0)) -> #REF! | P29: =IF(J29="","SEM #CH",VLOOKUP(J29,#REF!,7,0)) -> #REF! | Q29: =VLOOKUP(J29,'p1'!$B$2:$C$30,2,0) -> NÃO TEM CHAPA | R29: 45752 | S29: PN-001 | T29: =IF(R29=0,"",1) -> 1 | U29: 45817 | V29: - | W29: 2371 | X29: =IF(U29>0,1,"") -> 1
A30: 29 | B30: 45743 | C30: 4 | D30: =IF(B30>0,1,"") -> 1 | E30: REATOR 1 | F30: PN | G30: - | H30: 29 | I30: =_xlfn.CONCAT(F30,G30,H30) -> PN-29 | J30: P | K30: =IF(J30="","SEM #CH",VLOOKUP(J30,#REF!,2,0)) -> #REF! | L30: =IF(J30="","SEM #CH",VLOOKUP(J30,#REF!,3,0)) -> #REF! | M30: =IF(J30="","SEM #CH",VLOOKUP(J30,#REF!,4,0)) -> #REF! | N30: =IF(J30="","SEM #CH",VLOOKUP(J30,#REF!,5,0)) -> #REF! | O30: =IF(J30="","SEM #CH",VLOOKUP(J30,#REF!,6,0)) -> #REF! | P30: =IF(J30="","SEM #CH",VLOOKUP(J30,#REF!,7,0)) -> #REF! | Q30: =VLOOKUP(J30,'p1'!$B$2:$C$30,2,0) -> NÃO TEM CHAPA | R30: 45752 | S30: PN-001 | T30: =IF(R30=0,"",1) -> 1 | X30: =IF(U30>0,1,"")
A31: 30 | B31: 45743 | C31: 4 | D31: =IF(B31>0,1,"") -> 1 | E31: REATOR 1 | F31: PN | G31: - | H31: 30 | I31: =_xlfn.CONCAT(F31,G31,H31) -> PN-30 | J31: P | K31: =IF(J31="","SEM #CH",VLOOKUP(J31,#REF!,2,0)) -> #REF! | L31: =IF(J31="","SEM #CH",VLOOKUP(J31,#REF!,3,0)) -> #REF! | M31: =IF(J31="","SEM #CH",VLOOKUP(J31,#REF!,4,0)) -> #REF! | N31: =IF(J31="","SEM #CH",VLOOKUP(J31,#REF!,5,0)) -> #REF! | O31: =IF(J31="","SEM #CH",VLOOKUP(J31,#REF!,6,0)) -> #REF! | P31: =IF(J31="","SEM #CH",VLOOKUP(J31,#REF!,7,0)) -> #REF! | Q31: =VLOOKUP(J31,'p1'!$B$2:$C$30,2,0) -> NÃO TEM CHAPA | R31: 45750 | S31: PN-001 | T31: =IF(R31=0,"",1) -> 1 | U31: 45814 | V31: - | W31: 2369 | X31: =IF(U31>0,1,"") -> 1
A32: 31 | B32: 45743 | C32: 4 | D32: =IF(B32>0,1,"") -> 1 | E32: REATOR 1 | F32: PN | G32: - | H32: 31 | I32: =_xlfn.CONCAT(F32,G32,H32) -> PN-31 | J32: P | K32: =IF(J32="","SEM #CH",VLOOKUP(J32,#REF!,2,0)) -> #REF! | L32: =IF(J32="","SEM #CH",VLOOKUP(J32,#REF!,3,0)) -> #REF! | M32: =IF(J32="","SEM #CH",VLOOKUP(J32,#REF!,4,0)) -> #REF! | N32: =IF(J32="","SEM #CH",VLOOKUP(J32,#REF!,5,0)) -> #REF! | O32: =IF(J32="","SEM #CH",VLOOKUP(J32,#REF!,6,0)) -> #REF! | P32: =IF(J32="","SEM #CH",VLOOKUP(J32,#REF!,7,0)) -> #REF! | Q32: =VLOOKUP(J32,'p1'!$B$2:$C$30,2,0) -> NÃO TEM CHAPA | R32: 45750 | S32: PN-001 | T32: =IF(R32=0,"",1) -> 1 | U32: 45814 | V32: - | W32: 2369 | X32: =IF(U32>0,1,"") -> 1
A33: 32 | B33: 45800 | C33: 30 | D33: =IF(B33>0,1,"") -> 1 | E33: REATOR 1 | F33: PF | G33: - | H33: 32 | I33: =_xlfn.CONCAT(F33,G33,H33) -> PF-32 | J33: PF | K33: =IF(J33="","SEM #CH",VLOOKUP(J33,#REF!,2,0)) -> #REF! | L33: =IF(J33="","SEM #CH",VLOOKUP(J33,#REF!,3,0)) -> #REF! | M33: =IF(J33="","SEM #CH",VLOOKUP(J33,#REF!,4,0)) -> #REF! | N33: =IF(J33="","SEM #CH",VLOOKUP(J33,#REF!,5,0)) -> #REF! | O33: =IF(J33="","SEM #CH",VLOOKUP(J33,#REF!,6,0)) -> #REF! | P33: =IF(J33="","SEM #CH",VLOOKUP(J33,#REF!,7,0)) -> #REF! | Q33: =VLOOKUP(J33,'p1'!$B$2:$C$30,2,0) -> SEM CHAPA | R33: 45804 | S33: PN-001 | T33: =IF(R33=0,"",1) -> 1 | U33: 45818 | V33: - | W33: 2375 | X33: =IF(U33>0,1,"") -> 1
A34: 33 | B34: 45743 | C34: 4 | D34: =IF(B34>0,1,"") -> 1 | E34: REATOR 1 | F34: PN | G34: - | H34: 33 | I34: =_xlfn.CONCAT(F34,G34,H34) -> PN-33 | J34: P | K34: =IF(J34="","SEM #CH",VLOOKUP(J34,#REF!,2,0)) -> #REF! | L34: =IF(J34="","SEM #CH",VLOOKUP(J34,#REF!,3,0)) -> #REF! | M34: =IF(J34="","SEM #CH",VLOOKUP(J34,#REF!,4,0)) -> #REF! | N34: =IF(J34="","SEM #CH",VLOOKUP(J34,#REF!,5,0)) -> #REF! | O34: =IF(J34="","SEM #CH",VLOOKUP(J34,#REF!,6,0)) -> #REF! | P34: =IF(J34="","SEM #CH",VLOOKUP(J34,#REF!,7,0)) -> #REF! | Q34: =VLOOKUP(J34,'p1'!$B$2:$C$30,2,0) -> NÃO TEM CHAPA | R34: 45748 | S34: PN-001 | T34: =IF(R34=0,"",1) -> 1 | U34: 45814 | V34: IOO3D34 | W34: 2367 | X34: =IF(U34>0,1,"") -> 1
A35: 34 | B35: 45743 | C35: 4 | D35: =IF(B35>0,1,"") -> 1 | E35: REATOR 1 | F35: PN | G35: - | H35: 34 | I35: =_xlfn.CONCAT(F35,G35,H35) -> PN-34 | J35: P | K35: =IF(J35="","SEM #CH",VLOOKUP(J35,#REF!,2,0)) -> #REF! | L35: =IF(J35="","SEM #CH",VLOOKUP(J35,#REF!,3,0)) -> #REF! | M35: =IF(J35="","SEM #CH",VLOOKUP(J35,#REF!,4,0)) -> #REF! | N35: =IF(J35="","SEM #CH",VLOOKUP(J35,#REF!,5,0)) -> #REF! | O35: =IF(J35="","SEM #CH",VLOOKUP(J35,#REF!,6,0)) -> #REF! | P35: =IF(J35="","SEM #CH",VLOOKUP(J35,#REF!,7,0)) -> #REF! | Q35: =VLOOKUP(J35,'p1'!$B$2:$C$30,2,0) -> NÃO TEM CHAPA | R35: 45748 | S35: PN-001 | T35: =IF(R35=0,"",1) -> 1 | U35: 45814 | V35: IOO3D34 | W35: 2367 | X35: =IF(U35>0,1,"") -> 1
A36: 35 | B36: 45744 | C36: 5 | D36: =IF(B36>0,1,"") -> 1 | E36: REATOR 1 | F36: PN | G36: - | H36: 35 | I36: =_xlfn.CONCAT(F36,G36,H36) -> PN-35 | J36: P | K36: =IF(J36="","SEM #CH",VLOOKUP(J36,#REF!,2,0)) -> #REF! | L36: =IF(J36="","SEM #CH",VLOOKUP(J36,#REF!,3,0)) -> #REF! | M36: =IF(J36="","SEM #CH",VLOOKUP(J36,#REF!,4,0)) -> #REF! | N36: =IF(J36="","SEM #CH",VLOOKUP(J36,#REF!,5,0)) -> #REF! | O36: =IF(J36="","SEM #CH",VLOOKUP(J36,#REF!,6,0)) -> #REF! | P36: =IF(J36="","SEM #CH",VLOOKUP(J36,#REF!,7,0)) -> #REF! | Q36: =VLOOKUP(J36,'p1'!$B$2:$C$30,2,0) -> NÃO TEM CHAPA | R36: 45752 | S36: PN-002 | T36: =IF(R36=0,"",1) -> 1 | U36: 45828 | V36: - | W36: 2398 | X36: =IF(U36>0,1,"") -> 1
A37: 36 | B37: 45744 | C37: 5 | D37: =IF(B37>0,1,"") -> 1 | E37: REATOR 1 | F37: PN | G37: - | H37: 36 | I37: =_xlfn.CONCAT(F37,G37,H37) -> PN-36 | J37: P | K37: =IF(J37="","SEM #CH",VLOOKUP(J37,#REF!,2,0)) -> #REF! | L37: =IF(J37="","SEM #CH",VLOOKUP(J37,#REF!,3,0)) -> #REF! | M37: =IF(J37="","SEM #CH",VLOOKUP(J37,#REF!,4,0)) -> #REF! | N37: =IF(J37="","SEM #CH",VLOOKUP(J37,#REF!,5,0)) -> #REF! | O37: =IF(J37="","SEM #CH",VLOOKUP(J37,#REF!,6,0)) -> #REF! | P37: =IF(J37="","SEM #CH",VLOOKUP(J37,#REF!,7,0)) -> #REF! | Q37: =VLOOKUP(J37,'p1'!$B$2:$C$30,2,0) -> NÃO TEM CHAPA | R37: 45752 | S37: PN-002 | T37: =IF(R37=0,"",1) -> 1 | U37: 45821 | V37: - | W37: 2384 | X37: =IF(U37>0,1,"") -> 1
A38: 37 | B38: 45744 | C38: 5 | D38: =IF(B38>0,1,"") -> 1 | E38: REATOR 1 | F38: PN | G38: - | H38: 37 | I38: =_xlfn.CONCAT(F38,G38,H38) -> PN-37 | J38: P | K38: =IF(J38="","SEM #CH",VLOOKUP(J38,#REF!,2,0)) -> #REF! | L38: =IF(J38="","SEM #CH",VLOOKUP(J38,#REF!,3,0)) -> #REF! | M38: =IF(J38="","SEM #CH",VLOOKUP(J38,#REF!,4,0)) -> #REF! | N38: =IF(J38="","SEM #CH",VLOOKUP(J38,#REF!,5,0)) -> #REF! | O38: =IF(J38="","SEM #CH",VLOOKUP(J38,#REF!,6,0)) -> #REF! | P38: =IF(J38="","SEM #CH",VLOOKUP(J38,#REF!,7,0)) -> #REF! | Q38: =VLOOKUP(J38,'p1'!$B$2:$C$30,2,0) -> NÃO TEM CHAPA | R38: 45754 | S38: PN-002 | T38: =IF(R38=0,"",1) -> 1 | U38: 45820 | V38: - | W38: 2382 | X38: =IF(U38>0,1,"") -> 1
A39: 38 | B39: 45744 | C39: 5 | D39: =IF(B39>0,1,"") -> 1 | E39: REATOR 1 | F39: PN | G39: - | H39: 38 | I39: =_xlfn.CONCAT(F39,G39,H39) -> PN-38 | J39: P | K39: =IF(J39="","SEM #CH",VLOOKUP(J39,#REF!,2,0)) -> #REF! | L39: =IF(J39="","SEM #CH",VLOOKUP(J39,#REF!,3,0)) -> #REF! | M39: =IF(J39="","SEM #CH",VLOOKUP(J39,#REF!,4,0)) -> #REF! | N39: =IF(J39="","SEM #CH",VLOOKUP(J39,#REF!,5,0)) -> #REF! | O39: =IF(J39="","SEM #CH",VLOOKUP(J39,#REF!,6,0)) -> #REF! | P39: =IF(J39="","SEM #CH",VLOOKUP(J39,#REF!,7,0)) -> #REF! | Q39: =VLOOKUP(J39,'p1'!$B$2:$C$30,2,0) -> NÃO TEM CHAPA | R39: 45754 | S39: PN-002 | T39: =IF(R39=0,"",1) -> 1 | U39: 45821 | V39: - | W39: 2384 | X39: =IF(U39>0,1,"") -> 1
A40: 39 | B40: 45806 | C40: 31 | D40: =IF(B40>0,1,"") -> 1 | E40: REATOR 1 | F40: PE | G40: - | H40: 39 | I40: =_xlfn.CONCAT(F40,G40,H40) -> PE-39 | J40: T2 | K40: =IF(J40="","SEM #CH",VLOOKUP(J40,#REF!,2,0)) -> #REF! | L40: =IF(J40="","SEM #CH",VLOOKUP(J40,#REF!,3,0)) -> #REF! | M40: =IF(J40="","SEM #CH",VLOOKUP(J40,#REF!,4,0)) -> #REF! | N40: =IF(J40="","SEM #CH",VLOOKUP(J40,#REF!,5,0)) -> #REF! | O40: =IF(J40="","SEM #CH",VLOOKUP(J40,#REF!,6,0)) -> #REF! | P40: =IF(J40="","SEM #CH",VLOOKUP(J40,#REF!,7,0)) -> #REF! | Q40: =VLOOKUP(J40,'p1'!$B$2:$C$30,2,0) -> #3/8-1315X1315 | R40: 45812 | S40: PN-001 | T40: =IF(R40=0,"",1) -> 1 | U40: 45814 | V40: - | W40: 2369 | X40: =IF(U40>0,1,"") -> 1
A41: 40 | B41: 45744 | C41: 5 | D41: =IF(B41>0,1,"") -> 1 | E41: REATOR 1 | F41: PN | G41: - | H41: 40 | I41: =_xlfn.CONCAT(F41,G41,H41) -> PN-40 | J41: P | K41: =IF(J41="","SEM #CH",VLOOKUP(J41,#REF!,2,0)) -> #REF! | L41: =IF(J41="","SEM #CH",VLOOKUP(J41,#REF!,3,0)) -> #REF! | M41: =IF(J41="","SEM #CH",VLOOKUP(J41,#REF!,4,0)) -> #REF! | N41: =IF(J41="","SEM #CH",VLOOKUP(J41,#REF!,5,0)) -> #REF! | O41: =IF(J41="","SEM #CH",VLOOKUP(J41,#REF!,6,0)) -> #REF! | P41: =IF(J41="","SEM #CH",VLOOKUP(J41,#REF!,7,0)) -> #REF! | Q41: =VLOOKUP(J41,'p1'!$B$2:$C$30,2,0) -> NÃO TEM CHAPA | R41: 45758 | S41: PN-002 | T41: =IF(R41=0,"",1) -> 1 | X41: =IF(U41>0,1,"")
A42: 41 | B42: 45744 | C42: 5 | D42: =IF(B42>0,1,"") -> 1 | E42: REATOR 1 | F42: PN | G42: - | H42: 41 | I42: =_xlfn.CONCAT(F42,G42,H42) -> PN-41 | J42: P | K42: =IF(J42="","SEM #CH",VLOOKUP(J42,#REF!,2,0)) -> #REF! | L42: =IF(J42="","SEM #CH",VLOOKUP(J42,#REF!,3,0)) -> #REF! | M42: =IF(J42="","SEM #CH",VLOOKUP(J42,#REF!,4,0)) -> #REF! | N42: =IF(J42="","SEM #CH",VLOOKUP(J42,#REF!,5,0)) -> #REF! | O42: =IF(J42="","SEM #CH",VLOOKUP(J42,#REF!,6,0)) -> #REF! | P42: =IF(J42="","SEM #CH",VLOOKUP(J42,#REF!,7,0)) -> #REF! | Q42: =VLOOKUP(J42,'p1'!$B$2:$C$30,2,0) -> NÃO TEM CHAPA | R42: 45756 | S42: PN-002 | T42: =IF(R42=0,"",1) -> 1 | U42: 45820 | V42: - | W42: 2382 | X42: =IF(U42>0,1,"") -> 1
...

Sheet CALCULOS 
A2: =COUNTIF(' CADASTRO'!$F$746:$F$895,B2) -> 12 | B2: PE
A3: =COUNTIF(' CADASTRO'!$F$746:$F$895,B3) -> 1 | B3: PE(I)
A4: =COUNTIF(' CADASTRO'!$F$746:$F$895,B4) -> 3 | B4: PEI(V)
A5: =COUNTIF(' CADASTRO'!$F$746:$F$895,B5) -> 0 | B5: PEV
A6: =COUNTIF(' CADASTRO'!$F$746:$F$895,B6) -> 0 | B6: TEB
A7: =COUNTIF(' CADASTRO'!$F$746:$F$895,B7) -> 21 | B7: PNI
A8: =SUM(A2:A7) -> 37

Sheet SC-10 PN1
E1: BETONEIRA | W1: BT1 | AI1: data | AJ1: se concretada marque "x" | AK1: se concretado | AL1: IDENT. TANQUE | AM1: PLACA | AQ1: TIPO
W2: NF=> | Y2: =Y3-378 -> 809 | AA2: FLOW=> | AD2: vol(m³) | AF2: 1 | AG2: X | AH2: 48 | AI2: {=_xlfn._xlws.FILTER(' CADASTRO'!B:J,' CADASTRO'!C:C='SC-10 PN1'!AH2,)} -> 45853 | AJ2: 48 | AK2: 1 | AL2: REATOR 5 | AM2: PN | AN2: - | AO2: 264 | AP2: PN-264 | AQ2: P
B3: NUMERO CONCRETAGEM | D3: =MAX(' CADASTRO'!C2:C1000) -> 48 | E3: QUAL É A OBRA | F3: NEREDA | H3: NEREDA | J3: NEREDA | L3: NEREDA | N3: NEREDA | P3: NEREDA | R3: NEREDA | T3: PRIMARIO | W3: SERIE=> | Y3: 1187 | AA3: HORA LANÇ => | AF3: 2 | AG3: X | AI3: 45853 | AJ3: 48 | AK3: 1 | AL3: REATOR 5 | AM3: PN | AN3: - | AO3: 265 | AP3: PN-265 | AQ3: P
A4: data: | C4: =TODAY() -> 45853 | E4: Placa n° => | F4: PN-264 | H4: PN-265 | J4: PE-351 | L4: PN-266 | N4: PN-267 | P4: PN-268 | R4: PN-269 | T4: PR_PN-106 | W4: HORA ROMP. | Y4: CP1 (20H) | AA4: CP2 (20H) | AC4: CP3 (28D) | AD4: CP4 (28D) | AF4: 3 | AG4: X | AI4: 45853 | AJ4: 48 | AK4: 1 | AL4: REATOR 5 | AM4: PN | AN4: - | AO4: 266 | AP4: PN-266 | AQ4: P
E5: TIPO | F5: =VLOOKUP(F4,' CADASTRO'!$I$2:$J$1000,2,0) -> P | H5: =VLOOKUP(H4,' CADASTRO'!$I$2:$J$1000,2,0) -> P | J5: =VLOOKUP(J4,' CADASTRO'!$I$2:$J$1000,2,0) -> T4 | L5: =VLOOKUP(L4,' CADASTRO'!$I$2:$J$1000,2,0) -> P | N5: =VLOOKUP(N4,' CADASTRO'!$I$2:$J$1000,2,0) -> P | P5: =VLOOKUP(P4,' CADASTRO'!$I$2:$J$1000,2,0) -> P | R5: =VLOOKUP(R4,' CADASTRO'!$I$2:$J$1000,2,0) -> P | T5: =VLOOKUP(T4,' CADASTRO'!$I$2:$J$1000,2,0) -> P | W5: RESIST. | AF5: 4 | AG5: X | AI5: 45853 | AJ5: 48 | AK5: 1 | AL5: REATOR 5 | AM5: PN | AN5: - | AO5: 267 | AP5: PN-267 | AQ5: P
A6: HORA INICIO | E6: INSERTS | F6: =VLOOKUP(F4,' CADASTRO'!$I$2:$Q$994,9,0) -> NÃO TEM CHAPA | H6: =VLOOKUP(H4,' CADASTRO'!$I$2:$Q$994,9,0) -> NÃO TEM CHAPA | J6: =VLOOKUP(J4,' CADASTRO'!$I$2:$Q$994,9,0) -> #3/8-530X530 | L6: =VLOOKUP(L4,' CADASTRO'!$I$2:$Q$994,9,0) -> NÃO TEM CHAPA | N6: =VLOOKUP(N4,' CADASTRO'!$I$2:$Q$994,9,0) -> NÃO TEM CHAPA | P6: =VLOOKUP(P4,' CADASTRO'!$I$2:$Q$994,9,0) -> NÃO TEM CHAPA | R6: =VLOOKUP(R4,' CADASTRO'!$I$2:$Q$994,9,0) -> NÃO TEM CHAPA | T6: =VLOOKUP(T4,' CADASTRO'!$I$2:$Q$994,9,0) -> NÃO TEM CHAPA | W6: BT2 | AF6: 5 | AG6: X | AI6: 45853 | AJ6: 48 | AK6: 1 | AL6: REATOR 5 | AM6: PN | AN6: - | AO6: 268 | AP6: PN-268 | AQ6: P
C7: PISTA -001 | AF7: 6 | AI7: 45853 | AJ7: 48 | AK7: 1 | AL7: REATOR 5 | AM7: PN | AN7: - | AO7: 269 | AP7: PN-269 | AQ7: P
E8: FORMAS | F8: F1 | H8: F2 | J8: F3 | L8: F4 | N8: F5 | P8: F6 | R8: F7 | T8: F8 | W8: NF=> | Y8: =IF(Y9="","",Y9-378) -> 810 | AA8: FLOW=> | AD8: vol(m³) | AI8: 45853 | AJ8: 48 | AK8: 1 | AL8: REATOR 6 | AM8: PE | AN8: - | AO8: 351 | AP8: PE-351 | AQ8: T4
B9: item | C9: descrição das inspeções | F9: ok | G9: corrigir | H9: ok | I9: corrigir | J9: ok | K9: corrigir | L9: ok | M9: corrigir | N9: ok | O9: corrigir | P9: ok | Q9: corrigir | R9: ok | S9: corrigir | T9: ok | U9: corrigir | W9: SERIE=> | Y9: =IF(AG3="X",Y3+1,"") -> 1188 | AA9: HORA LANÇ => | AI9: 45853 | AJ9: 48 | AK9: 1 | AL9: PRIMARIO 2 | AM9: PN | AN9: - | AO9: 106 | AP9: PR_PN-106 | AQ9: P
W10: HORA ROMP. | Y10: CP1 (20H) | AA10: CP2 (20H) | AC10: CP3 (28D) | AD10: CP4 (28D)
B11: 1 | C11: QTDE DE CABOS E ALONGAMENTOS 16 C 321A356 | W11: RESIST.
B12: 2 | C12: PÉ 2X M24 | W12: BT3
B13: 3 | C13: INJETOR 1X | W13: NF=> | Y13: =IF(Y14="","",Y14-378) -> 811 | AA13: FLOW=> | AD13: vol(m³)
B14: 4 | C14: TELA VIVEIRO E REFORÇO 16 MM EM CIMA DOS PINOS IÇAMENTOS 2X 7,5 TON/300 3 "u" 10 MM E 1 BARRA 1 MTS | W14: SERIE=> | Y14: =IF(AG4="X",$Y$3+2,"") -> 1189 | AA14: HORA LANÇ =>
B15: 5 | C15: JUNÇÃO 3/8 X 25 MM FLUTUADOR 2X | W15: HORA ROMP. | Y15: CP1 (20H) | AA15: CP2 (20H) | AC15: CP3 (28D) | AD15: CP4 (28D)
B16: 6 | C16: ESCORA 5,50 DO PÉ 5/8 | W16: RESIST.
B17: 7 | C17: RECOBRIMENTO SUPERIOR/ INFERIOR E LATERIAS
B18: 8 | C18: VIGAS LATERAIAS (ESTRIBOS E BARRAS) | W18: BT4
B19: 9 | C19: ÂNGULO DE A CADA 5 CONCRETAGEM | W19: NF=> | Y19: =IF(Y20="","",Y20-378) -> 812 | AA19: FLOW=> | AD19: vol(m³)
B20: 10 | C20: REFORÇO DE CABEÇA E PE | W20: SERIE => | Y20: =IF(AG5="X",$Y$3+3,"") -> 1190 | AA20: HORA LANÇ =>
B21: 11 | C21: ESPAÇADOR DE TELA A TELA E VIGA (36X) | W21: HORA ROMP. | Y21: CP1 (20H) | AA21: CP2 (20H) | AC21: CP3 (28D) | AD21: CP4 (28D)
B22: 12 | C22: FECHAMENTO FORMA LATERAL (PINAGEM) (dois lados) | W22: RESIST.
B23: 13 | C23: DIMENSÕES DA PLACA (DIVISORIA ESCOSTADAS NA TRAVA)
B24: 14 | C24: TELAS SUPERIOR E INFERIOR ESTAO ATADAS | W24: BT5
B25: 15 | C25: QTDE DE BAINHAS (12 NO NEREDA E 6 NO PRIMARIO) E SE ESTAO ATADAS NA ZONA | W25: NF=> | Y25: =IF(Y26="","",Y26-378) -> 813 | AA25: FLOW=> | AD25: vol(m³)
B26: 16 | C26: MEDIDAS DE TOPO DE FORMA (2380 NO PRIMARIO); (2375 NO NEREDA) | W26: SERIE=> | Y26: =IF(AG6="X",$Y$3+4,"") -> 1191 | AA26: HORA LANÇ =>
B27: 17 | C27: CHAPAS DE INSERTOS | W27: HORA ROMP. | Y27: CP1 (20H) | AA27: CP2 (20H) | AC27: CP3 (28D) | AD27: CP4 (28D)
B28: 18 | C28: SIKASWELL CHAPA DE TUBULAÇÃO | W28: RESIST.
B29: 19 | C29: LIMPEZA : SOPRAGEM E COLETA DE ARRAMES
B30: 20 | C30: MOV: 4 X 5TON X 125CB - NEREDA | W30: BT6
B31: 21 | C31: MOV: 4 X 5TON X 125CB + 4 X 5TON X 125ESF. PRIMARIO | W31: NF => | Y31: =IF(Y32="","",Y32-378) | AA31: FLOW=> | AD31: vol(m³)
B32: 22 | C32: EMENDAS | W32: SERIE=> | Y32: =IF(AG7="X",$Y$3+5,"") | AA32: HORA LANÇ =>
F33: CABO 1 | H33: CABO 2 | J33: CABO 3 | L33: CABO 4 | N33: CABO 5 | P33: CABO 6 | R33: CABO 7 | T33: CABO 8 | W33: HORA ROMP. | Y33: CP1 (20H) | AA33: CP2 (20H) | AC33: CP3 (28D) | AD33: CP4 (28D)
W34: RESIST.
F36: CABO 09 | H36: CABO 10 | J36: CABO 11 | L36: CABO 12 | N36: CABO 13 | P36: CABO 14 | R36: CABO 15 | T36: CABO 16
F38: BOBINA N° | J38: 1062072197
F39: DATA: | J39: 46014
B41: NUMERO CONCRETAGEM | D41: =D3 -> 48 | E41: QUAL É A OBRA | F41: NEREDA | H41: NEREDA | J41: NEREDA | L41: NEREDA | N41: NEREDA | P41: NEREDA | R41: NEREDA | T41: PRIMARIO
A42: data: | E42: Placa n° => | F42: =F4 -> PN-264 | H42: =H4 -> PN-265 | J42: =J4 -> PE-351 | L42: =L4 -> PN-266 | N42: =N4 -> PN-267 | P42: =P4 -> PN-268 | R42: =R4 -> PN-269 | T42: =T4 -> PR_PN-106
E43: TIPO | F43: =F5 -> P | H43: =H5 -> P | J43: =J5 -> T4 | L43: =L5 -> P | N43: =N5 -> P | P43: =P5 -> P | R43: =R5 -> P | T43: =T5 -> P
...

Sheet SC-10 PN2
E1: BETONEIRA | W1: BT1 | AI1: data | AJ1: se concretada marque "x" | AK1: se concretado | AL1: IDENT. TANQUE | AM1: PLACA | AQ1: TIPO
W2: NF=> | Y2: =Y3-378 -> 777 | AA2: FLOW=> | AD2: vol(m³) | AF2: 1 | AG2: X | AH2: 43 | AI2: {=_xlfn._xlws.FILTER(' CADASTRO'!B:J,' CADASTRO'!C:C='SC-10 PN2'!AH2,)} -> 45839 | AJ2: 43 | AK2: 1 | AL2: REATOR 3 | AM2: PF | AN2: - | AO2: 156 | AP2: PF-156 | AQ2: PF
B3: NUMERO CONCRETAGEM | D3: =MAX(' CADASTRO'!C2:C1000) -> 48 | E3: QUAL É A OBRA | F3: NEREDA | H3: NEREDA | J3: NEREDA | L3: NEREDA | N3: NEREDA | P3: NEREDA | R3: NEREDA | T3: PRIMARIO | W3: SERIE=> | Y3: 1155 | AA3: HORA LANÇ => | AF3: 2 | AG3: X | AI3: 45839 | AJ3: 43 | AK3: 1 | AL3: PRIMARIO 2 | AM3: PF | AN3: - | AO3: 144 | AP3: PR_PF-144 | AQ3: PF
A4: data: | C4: =TODAY() -> 45853 | E4: Placa n° => | F4: PN-235 | H4: PN-236 | J4: PN-237 | L4: PE-288 | N4: PN-238 | P4: PN-239 | R4: PN-240 | T4: PN-62 | W4: HORA ROMP. | Y4: CP1 (20H) | AA4: CP2 (20H) | AC4: CP3 (28D) | AD4: CP4 (28D) | AF4: 3 | AG4: X
E5: TIPO | F5: =VLOOKUP(F4,' CADASTRO'!$I$2:$J$1000,2,0) -> P | H5: =VLOOKUP(H4,' CADASTRO'!$I$2:$J$1000,2,0) -> P | J5: =VLOOKUP(J4,' CADASTRO'!$I$2:$J$1000,2,0) -> P | L5: =VLOOKUP(L4,' CADASTRO'!$I$2:$J$1000,2,0) -> T4 | N5: =VLOOKUP(N4,' CADASTRO'!$I$2:$J$1000,2,0) -> P | P5: =VLOOKUP(P4,' CADASTRO'!$I$2:$J$1000,2,0) -> P | R5: =VLOOKUP(R4,' CADASTRO'!$I$2:$J$1000,2,0) -> P | T5: =VLOOKUP(T4,' CADASTRO'!$I$2:$J$1000,2,0) -> P | W5: RESIST. | AF5: 4 | AG5: X
A6: HORA INICIO | E6: INSERTS | F6: =VLOOKUP(F4,' CADASTRO'!$I$2:$Q$994,9,0) -> NÃO TEM CHAPA | H6: =VLOOKUP(H4,' CADASTRO'!$I$2:$Q$994,9,0) -> NÃO TEM CHAPA | J6: =VLOOKUP(J4,' CADASTRO'!$I$2:$Q$994,9,0) -> NÃO TEM CHAPA | L6: =VLOOKUP(L4,' CADASTRO'!$I$2:$Q$994,9,0) -> #3/8-530X530 | N6: =VLOOKUP(N4,' CADASTRO'!$I$2:$Q$994,9,0) -> NÃO TEM CHAPA | P6: =VLOOKUP(P4,' CADASTRO'!$I$2:$Q$994,9,0) -> NÃO TEM CHAPA | R6: =VLOOKUP(R4,' CADASTRO'!$I$2:$Q$994,9,0) -> NÃO TEM CHAPA | T6: =VLOOKUP(T4,' CADASTRO'!$I$2:$Q$994,9,0) -> NÃO TEM CHAPA | W6: BT2 | AF6: 5 | AG6: X
C7: PISTA -001 | AF7: 6 | AG7: X
E8: FORMAS | F8: F1 | H8: F2 | J8: F3 | L8: F4 | N8: F5 | P8: F6 | R8: F7 | T8: F8 | W8: NF=> | Y8: =IF(Y9="","",Y9-378) -> 778 | AA8: FLOW=> | AD8: vol(m³)
B9: item | C9: descrição das inspeções | F9: ok | G9: corrigir | H9: ok | I9: corrigir | J9: ok | K9: corrigir | L9: ok | M9: corrigir | N9: ok | O9: corrigir | P9: ok | Q9: corrigir | R9: ok | S9: corrigir | T9: ok | U9: corrigir | W9: SERIE=> | Y9: =IF(AG3="X",Y3+1,"") -> 1156 | AA9: HORA LANÇ =>
W10: HORA ROMP. | Y10: CP1 (20H) | AA10: CP2 (20H) | AC10: CP3 (28D) | AD10: CP4 (28D)
B11: 1 | C11: QTDE DE CABOS E ALONGAMENTOS 16 C 321A356 | W11: RESIST.
B12: 2 | C12: PÉ 2X M24 | W12: BT3
B13: 3 | C13: INJETOR 1X | W13: NF=> | Y13: =IF(Y14="","",Y14-378) -> 779 | AA13: FLOW=> | AD13: vol(m³)
B14: 4 | C14: TELA VIVEIRO E REFORÇO 16 MM EM CIMA DOS PINOS IÇAMENTOS 2X 7,5 TON/300 3 "u" 10 MM E 1 BARRA 1 MTS | W14: SERIE=> | Y14: =IF(AG4="X",$Y$3+2,"") -> 1157 | AA14: HORA LANÇ =>
B15: 5 | C15: JUNÇÃO 3/8 X 25 MM FLUTUADOR 2X | W15: HORA ROMP. | Y15: CP1 (20H) | AA15: CP2 (20H) | AC15: CP3 (28D) | AD15: CP4 (28D)
B16: 6 | C16: ESCORA 5,50 DO PÉ 5/8 | W16: RESIST.
B17: 7 | C17: RECOBRIMENTO SUPERIOR/ INFERIOR E LATERIAS
B18: 8 | C18: VIGAS LATERAIAS (ESTRIBOS E BARRAS) | W18: BT4
B19: 9 | C19: ÂNGULO DE A CADA 5 CONCRETAGEM | W19: NF=> | Y19: =IF(Y20="","",Y20-378) -> 780 | AA19: FLOW=> | AD19: vol(m³)
B20: 10 | C20: REFORÇO DE CABEÇA E PE | W20: SERIE => | Y20: =IF(AG5="X",$Y$3+3,"") -> 1158 | AA20: HORA LANÇ =>
B21: 11 | C21: ESPAÇADOR DE TELA A TELA E VIGA (36X) | W21: HORA ROMP. | Y21: CP1 (20H) | AA21: CP2 (20H) | AC21: CP3 (28D) | AD21: CP4 (28D)
B22: 12 | C22: FECHAMENTO FORMA LATERAL (PINAGEM) (dois lados) | W22: RESIST.
B23: 13 | C23: DIMENSÕES DA PLACA (DIVISORIA ESCOSTADAS NA TRAVA)
B24: 14 | C24: TELAS SUPERIOR E INFERIOR ESTAO ATADAS | W24: BT5
B25: 15 | C25: QTDE DE BAINHAS (12 NO NEREDA E 6 NO PRIMARIO) E SE ESTAO ATADAS NA ZONA | W25: NF=> | Y25: =IF(Y26="","",Y26-378) -> 781 | AA25: FLOW=> | AD25: vol(m³)
B26: 16 | C26: MEDIDAS DE TOPO DE FORMA (2380 NO PRIMARIO); (2375 NO NEREDA) | W26: SERIE=> | Y26: =IF(AG6="X",$Y$3+4,"") -> 1159 | AA26: HORA LANÇ =>
B27: 17 | C27: CHAPAS DE INSERTOS | W27: HORA ROMP. | Y27: CP1 (20H) | AA27: CP2 (20H) | AC27: CP3 (28D) | AD27: CP4 (28D)
B28: 18 | C28: SIKASWELL CHAPA DE TUBULAÇÃO | W28: RESIST.
B29: 19 | C29: LIMPEZA : SOPRAGEM E COLETA DE ARRAMES
B30: 20 | C30: MOV: 4 X 5TON X 125CB - NEREDA | W30: BT6
B31: 21 | C31: MOV: 4 X 5TON X 125CB + 4 X 5TON X 125ESF. PRIMARIO | W31: NF => | Y31: =IF(Y32="","",Y32-378) -> 782 | AA31: FLOW=> | AD31: vol(m³)
B32: 22 | C32: EMENDAS | W32: SERIE=> | Y32: =IF(AG7="X",$Y$3+5,"") -> 1160 | AA32: HORA LANÇ =>
F33: CABO 1 | H33: CABO 2 | J33: CABO 3 | L33: CABO 4 | N33: CABO 5 | P33: CABO 6 | R33: CABO 7 | T33: CABO 8 | W33: HORA ROMP. | Y33: CP1 (20H) | AA33: CP2 (20H) | AC33: CP3 (28D) | AD33: CP4 (28D)
W34: RESIST.
F36: CABO 09 | H36: CABO 10 | J36: CABO 11 | L36: CABO 12 | N36: CABO 13 | P36: CABO 14 | R36: CABO 15 | T36: CABO 16
F39: BOBINA N° | J39: 1062266407
F40: DATA: | J40: 45690
B42: NUMERO CONCRETAGEM | D42: =D3 -> 48 | E42: QUAL É A OBRA | F42: NEREDA | H42: NEREDA | J42: NEREDA | L42: NEREDA | N42: NEREDA | P42: NEREDA | R42: NEREDA | T42: PRIMARIO
A43: data: | E43: Placa n° => | F43: =F4 -> PN-235 | H43: =H4 -> PN-236 | J43: =J4 -> PN-237 | L43: =L4 -> PE-288 | N43: =N4 -> PN-238 | P43: =P4 -> PN-239 | R43: =R4 -> PN-240 | T43: =T4 -> PN-62
E44: TIPO | F44: =F5 -> P | H44: =H5 -> P | J44: =J5 -> P | L44: =L5 -> T4 | N44: =N5 -> P | P44: =P5 -> P | R44: =R5 -> P | T44: =T5 -> P
...

Sheet SC-10 PN2 PRIMARIO
E1: BETONEIRA | AE1: BT1 | AQ1: data | AR1: se concretada marque "x" | AS1: se concretado | AT1: IDENT. TANQUE | AU1: PLACA | AY1: TIPO
AE2: NF=> | AG2: =AG3-378 -> 791 | AI2: FLOW=> | AL2: vol(m³) | AN2: 1 | AO2: X
B3: NUMERO CONCRETAGEM | D3: =MAX(' CADASTRO'!C2:C1000) -> 48 | E3: QUAL É A OBRA | F3: PRIMARIO | H3: PRIMARIO | J3: PRIMARIO | L3: PRIMARIO | N3: PRIMARIO | P3: PRIMARIO | R3: PRIMARIO | T3: PRIMARIO | V3: PRIMARIO | X3: PRIMARIO | Z3: PRIMARIO | AB3: PRIMARIO | AE3: SERIE=> | AG3: 1169 | AI3: HORA LANÇ => | AN3: 2 | AO3: X
A4: data: | C4: =TODAY()+1 -> 45854 | E4: Placa n° => | F4: PR_PN-89 | H4: PR_PN-90 | J4: PR_PN-91 | L4: PR_PN-92 | N4: PR_PN-94 | P4: PR_PN-96 | R4: PR_PN-100 | T4: PR_PN-101 | V4: PR_PNI-63 | X4: PR_PN-102 | Z4: PR_PNI-69 | AB4: PR_PNI-75 | AE4: HORA ROMP. | AG4: CP1 (20H) | AI4: CP2 (20H) | AK4: CP3 (28D) | AL4: CP4 (28D) | AN4: 3 | AO4: X
E5: TIPO | F5: =VLOOKUP(F4,' CADASTRO'!$I$2:$J$1000,2,0) -> P | H5: =VLOOKUP(H4,' CADASTRO'!$I$2:$J$1000,2,0) -> P | J5: =VLOOKUP(J4,' CADASTRO'!$I$2:$J$1000,2,0) -> P | L5: =VLOOKUP(L4,' CADASTRO'!$I$2:$J$1000,2,0) -> P | N5: =VLOOKUP(N4,' CADASTRO'!$I$2:$J$1000,2,0) -> P | P5: =VLOOKUP(P4,' CADASTRO'!$I$2:$J$1000,2,0) -> P | R5: =VLOOKUP(R4,' CADASTRO'!$I$2:$J$1000,2,0) -> P | T5: =VLOOKUP(T4,' CADASTRO'!$I$2:$J$1000,2,0) -> P | V5: =VLOOKUP(V4,' CADASTRO'!$I$2:$J$1000,2,0) -> PNI | X5: =VLOOKUP(X4,' CADASTRO'!$I$2:$J$1000,2,0) -> P | Z5: =VLOOKUP(Z4,' CADASTRO'!$I$2:$J$1000,2,0) -> PNI | AB5: =VLOOKUP(AB4,' CADASTRO'!$I$2:$J$1000,2,0) -> PNI | AE5: RESIST. | AN5: 4 | AO5: X
A6: HORA INICIO | E6: INSERTS | F6: =VLOOKUP(F4,' CADASTRO'!$I$2:$Q$994,9,0) -> NÃO TEM CHAPA | H6: =VLOOKUP(H4,' CADASTRO'!$I$2:$Q$994,9,0) -> NÃO TEM CHAPA | J6: =VLOOKUP(J4,' CADASTRO'!$I$2:$Q$994,9,0) -> NÃO TEM CHAPA | L6: =VLOOKUP(L4,' CADASTRO'!$I$2:$Q$994,9,0) -> NÃO TEM CHAPA | N6: =VLOOKUP(N4,' CADASTRO'!$I$2:$Q$994,9,0) -> NÃO TEM CHAPA | P6: =VLOOKUP(P4,' CADASTRO'!$I$2:$Q$994,9,0) -> NÃO TEM CHAPA | R6: =VLOOKUP(R4,' CADASTRO'!$I$2:$Q$994,9,0) -> NÃO TEM CHAPA | T6: =VLOOKUP(T4,' CADASTRO'!$I$2:$Q$994,9,0) -> NÃO TEM CHAPA | V6: =VLOOKUP(V4,' CADASTRO'!$I$2:$Q$994,9,0) -> 02- 150X150 #3/8 | X6: =VLOOKUP(X4,' CADASTRO'!$I$2:$Q$994,9,0) -> NÃO TEM CHAPA | Z6: =VLOOKUP(Z4,' CADASTRO'!$I$2:$Q$994,9,0) -> 02- 150X150 #3/8 | AB6: =VLOOKUP(AB4,' CADASTRO'!$I$2:$Q$994,9,0) -> 02- 150X150 #3/8 | AE6: BT2 | AN6: 5 | AO6: X
C7: PISTA -002 | AN7: 6 | AO7: X
E8: FORMAS | F8: F1 | H8: F2 | J8: F3 | L8: F4 | N8: F5 | P8: F6 | R8: F7 | T8: F8 | V8: F9 | X8: F10 | Z8: F11 | AB8: F12 | AE8: NF=> | AG8: =IF(AG9="","",AG9-378) -> 792 | AI8: FLOW=> | AL8: vol(m³)
B9: item | C9: descrição das inspeções | F9: ok | G9: corrigir | H9: ok | I9: corrigir | J9: ok | K9: corrigir | L9: ok | M9: corrigir | N9: ok | O9: corrigir | P9: ok | Q9: corrigir | R9: ok | S9: corrigir | T9: ok | U9: corrigir | V9: ok | W9: corrigir | X9: ok | Y9: corrigir | Z9: ok | AA9: corrigir | AB9: ok | AC9: corrigir | AE9: SERIE=> | AG9: =IF(AO3="X",AG3+1,"") -> 1170 | AI9: HORA LANÇ =>
AE10: HORA ROMP. | AG10: CP1 (20H) | AI10: CP2 (20H) | AK10: CP3 (28D) | AL10: CP4 (28D)
B11: 1 | C11: QTDE DE CABOS E ALONGAMENTOS 16 C 321A356 | AE11: RESIST.
B12: 2 | C12: PÉ 2X M24 | AE12: BT3
B13: 3 | C13: INJETOR 1X | AE13: NF=> | AG13: =IF(AG14="","",AG14-378) -> 793 | AI13: FLOW=> | AL13: vol(m³)
B14: 4 | C14: VERIFICAR MEDIDA TPO PLACA ATE CANALETA 1,225 | AE14: SERIE=> | AG14: =IF(AO4="X",$AG$3+2,"") -> 1171 | AI14: HORA LANÇ =>
B15: 5 | C15: JUNÇÃO 3/8 X 25 MM FLUTUADOR 2X | AE15: HORA ROMP. | AG15: CP1 (20H) | AI15: CP2 (20H) | AK15: CP3 (28D) | AL15: CP4 (28D)
B16: 6 | C16: ESCORA 5,50 DO PÉ 5/8 | AE16: RESIST.
B17: 7 | C17: RECOBRIMENTO SUPERIOR/ INFERIOR E LATERIAS
B18: 8 | C18: VIGAS LATERAIAS (ESTRIBOS E BARRAS) | AE18: BT4
B19: 9 | C19: ÂNGULO DE A CADA 5 CONCRETAGEM | AE19: NF=> | AG19: =IF(AG20="","",AG20-378) -> 794 | AI19: FLOW=> | AL19: vol(m³)
B20: 10 | C20: REFORÇO DE CABEÇA E PE | AE20: SERIE => | AG20: =IF(AO5="X",$AG$3+3,"") -> 1172 | AI20: HORA LANÇ =>
B21: 11 | C21: ESPAÇADOR DE TELA A TELA E VIGA | AE21: HORA ROMP. | AG21: CP1 (20H) | AI21: CP2 (20H) | AK21: CP3 (28D) | AL21: CP4 (28D)
B22: 12 | C22: FECHAMENTO FORMA LATERAL (PINAGEM) (dois lados) | AE22: RESIST.
B23: 13 | C23: DIMENSÕES DA PLACA (DIVISORIA ESCOSTADAS NA TRAVA)
B24: 14 | C24: TELAS SUPERIOR E INFERIOR ESTAO ATADAS | AE24: BT5
B25: 15 | C25: QTDE DE BAINHAS (12 NO NEREDA E 6 NO PRIMARIO) E SE ESTAO ATADAS NA ZONA | AE25: NF=> | AI25: FLOW=> | AL25: vol(m³)
B26: 16 | C26: MEDIDAS DE TOPO DE FORMA (2380 NO PRIMARIO); (2375 NO NEREDA) | AE26: SERIE=> | AI26: HORA LANÇ =>
B27: 17 | C27: CHAPAS DE INSERTOS | AE27: HORA ROMP. | AG27: CP1 (20H) | AI27: CP2 (20H) | AK27: CP3 (28D) | AL27: CP4 (28D)
B28: 18 | C28: SIKASWELL CHAPA DE TUBULAÇÃO | AE28: RESIST.
B29: 19 | C29: LIMPEZA : SOPRAGEM E COLETA DE ARRAMES
B30: 20 | AE30: BT6
B31: 21 | C31: MOV: 4 X 5TON X 125CB + 4 X 5TON X 125ESF. PRIMARIO | AE31: NF => | AI31: FLOW=> | AL31: vol(m³)
B32: 22 | C32: EMENDAS | AE32: SERIE=> | AI32: HORA LANÇ =>
F33: CABO 1 | H33: CABO 2 | J33: CABO 3 | L33: CABO 4 | N33: CABO 5 | P33: CABO 6 | R33: CABO 7 | T33: CABO 8 | AE33: HORA ROMP. | AG33: CP1 (20H) | AI33: CP2 (20H) | AK33: CP3 (28D) | AL33: CP4 (28D)
AE34: RESIST.
F36: CABO 09 | H36: CABO 10 | J36: CABO 11 | L36: CABO 12 | N36: CABO 13 | P36: CABO 14 | R36: CABO 15 | T36: CABO 16
F39: BOBINA N° | J39: 1062631306 | R39: BOBINA N° | V39: 1062631306
F40: DATA: | J40: 45760 | R40: DATA: | V40: 45760
B42: NUMERO CONCRETAGEM | D42: =D3 -> 48 | E42: QUAL É A OBRA | F42: NEREDA | H42: NEREDA | J42: NEREDA | L42: NEREDA | N42: NEREDA | P42: NEREDA | R42: NEREDA | T42: NEREDA | V42: NEREDA | X42: NEREDA | Z42: NEREDA | AB42: PRIMARIO
A43: data: | E43: Placa n° => | F43: =F4 -> PR_PN-89 | H43: =H4 -> PR_PN-90 | J43: =J4 -> PR_PN-91 | L43: =L4 -> PR_PN-92 | N43: =N4 -> PR_PN-94 | P43: =P4 -> PR_PN-96 | R43: =R4 -> PR_PN-100 | T43: =T4 -> PR_PN-101 | V43: =V4 -> PR_PNI-63 | X43: =X4 -> PR_PN-102 | Z43: =Z4 -> PR_PNI-69 | AB43: =AB4 -> PR_PNI-75
E44: TIPO | F44: =F5 -> P | H44: =H5 -> P | J44: =J5 -> P | L44: =L5 -> P | N44: =N5 -> P | P44: =P5 -> P | R44: =R5 -> P | T44: =T5 -> P | V44: =V5 -> PNI | X44: =X5 -> P | Z44: =Z5 -> PNI | AB44: =AB5 -> PNI
...

Sheet SC10(pf)
B1: NUMERO CONCRETAGEM | D1: =MAX(' CADASTRO'!C:C) -> 48 | E1: QUAL É A OBRA | F1: PRIMARIO | H1: NEREDA | M1: CERTIFICADO | R1: vol(m3) | S1: flow | T1: NF
A2: data: | C2: =TODAY() -> 45853 | E2: Placa n° => | F2: PR_PF-144 | H2: PF-156 | M2: 1062266407 | Q2: bt1
E3: TIPO | F3: P | H3: P | M3: DATA DE FAB | Q3: bt2
A4: HORA INICIO | E4: INSERTS | F4: =VLOOKUP(F2,' CADASTRO'!$I$2:$Q$994,9,0) -> SEM CHAPA | H4: =VLOOKUP(H2,' CADASTRO'!$I$2:$Q$994,9,0) -> SEM CHAPA | M4: 45690
C5: PISTA -PF
E6: FORMAS | F6: F1 | H6: F2
B7: item | C7: descrição das inspeções | F7: ok | G7: corrigir | H7: ok | I7: corrigir | J7: ok | K7: corrigir | V7: BT1 | W7: SERIE: | X7: 1169
B9: 1 | C9: QTDE DE CABOS E ALONGAMENTOS 18 Cabos 105A120 | M9: CABO | N9: ALONG. | P9: ok | Q9: observação | V9: CP1
B10: 2 | C10: PÉ 2X M24 | M10: CABO 1 | Q10: ** inserir luva #5/8 para escora aparatir de 1,50mts de altura, desixando recuado 5 mm para dentro da placa
B11: 3 | C11: INJETOR 1X | M11: CABO 2 | Q11: ** chapa de ancoragem 100x220x19 mm 1 em cada bainha | V11: CP1
B12: 4 | C12: TELA VIVEIRO E REFORÇO 16 MM EM CIMA DOS PINOS IÇAMENTOS 2X 10 TON/340 3 "u" 10 MM E 1 BARRA 1 MTS - nereda | M12: CABO 3 | Q12: ** verificar se molas não estao tocando o fundo do painels
B13: 5 | C13: JUNÇÃO 3/8 X 25 MM FLUTUADOR 2X | M13: CABO 4 | Q13: ** verificar se total bainhas estao bem vedadas, para não entra concreto nelas,
B14: 6 | C14: ESCORA 5,50 DO PÉ 5/8 | M14: CABO 5 | Q14: ** verificar e total toquinho de madeiras foram devidademente envelopados com lona - ajuda na desforma | V14: BT2 | W14: SERIE: | X14: =X7+1 -> 1170
B15: 7 | C15: RECOBRIMENTO SUPERIOR/ INFERIOR E LATERIAS | M15: CABO 6 | V15: CP1
B16: 8 | C16: VIGAS LATERAIAS (ESTRIBOS E BARRAS) | M16: CABO 7
B17: 9 | C17: ÂNGULO DE A CADA CONCRETAGEM | M17: CABO 8 | V17: CP1
B18: 10 | C18: REFORÇO DE CABEÇA E PE | M18: CABO 9
B19: 11 | C19: ESPAÇADOR DE TELA A TELA E VIGA (36X) | M19: CABO 10
B20: 12 | C20: FECHAMENTO FORMA LATERAL (PINAGEM) (dois lados) | M20: CABO 11 | V20: BT3 | W20: SERIE:
B21: 13 | C21: DIMENSÕES DA PLACA (DIVISORIA ESCOSTADAS NA TRAVA) | M21: CABO 12 | V21: CP1
B22: 14 | C22: TELAS SUPERIOR E INFERIOR ESTAO ATADAS | M22: CABO 13
B23: 15 | C23: QTDE DE BAINHAS (12 NO NEREDA E 6 NO PRIMARIO) E SE ESTAO ATADAS NA ZONA | M23: CABO 14 | V23: CP1
B24: 16 | C24: MEDIDAS DE TOPO DE FORMA (2380 NO PRIMARIO); (2375 NO NEREDA) | M24: CABO 15
B25: 17 | C25: CHAPAS DE INSERTOS | M25: CABO 16
B26: 18 | C26: SIKASWELL CHAPA DE TUBULAÇÃO | M26: CABO 17
B27: 19 | C27: LIMPEZA : SOPRAGEM E COLETA DE ARRAMES | M27: CABO 18
B28: 20 | C28: MOV: 4 X 7,55TON X 125CB - NEREDA
B29: 21 | C29: verti. MOV: 6 X 7,5TON x 300 esf. PRIMARIO
B30: 22 | C30: EMENDAS
B40: NUMERO CONCRETAGEM | D40: =D1 -> 48 | E40: QUAL É A OBRA | F40: NEREDA | H40: NEREDA | J40: NEREDA | L40: NEREDA | N40: NEREDA | P40: NEREDA | R40: NEREDA | T40: PRIMARIO
A41: data: | E41: Placa n° => | F41: =F2 -> PR_PF-144 | H41: =H2 -> PF-156 | J41: =J2 -> 0 | L41: =L2 -> 0 | N41: =N2 -> 0 | P41: =P2 -> 0 | R41: =R2 -> 0 | T41: =T2 -> 0
E42: TIPO | F42: =F3 -> P | H42: =H3 -> P | J42: =J3 -> 0 | L42: =L3 -> 0 | N42: =N3 -> 0 | P42: =P3 -> 0 | R42: =R3 -> 0 | T42: =T3 -> 0
B43: RELATORIO POS ROMPIMENTO
B44: 1 | D44: VISTORIA SUPERFICIAL SE HÁ FISSURAS
B45: 2 | D45: VERIFICAR SE HÁ QUEBRAS DURANTE A DESFORMA
B46: 3 | D46: VERIFICAR SE FORAM ARMAZENDAS CORRETAMENTE
B47: 4 | D47: VERIFICAR SE ALGUMA IMPERFEIÇÃO NOTAVEM NO ATO DA DESFORMA
B48: 5 | D48: VERIFICAR SE BOLHAS DE AR LADO DIREITO
B49: 6 | D49: VERIFICAR SE MICROFISSURAS SUPERFICIAIS NA PLACA
B50: 7
...

Sheet PRODUÇÃO SEMANA
I1: NEREDA | J1: =J4-J2 -> 315 | S1: estimado semana
I2: PRIMARIO | J2: =MAX(' CADASTRO'!C745:C894) -> 48 | S2: primario | T2: nereda
S3: 5 | T3: 35
B4: INICIO | I4: T´REMINIO | J4: =SUM(J5:J28) -> 363 | L4: =TEXT(B5,"DDD") -> seg | M4: =TEXT(D5,"DDD") -> ter | N4: =TEXT(E5,"DDD") -> qua | O4: =TEXT(F5,"DDD") -> qui | P4: =TEXT(G5,"DDD") -> sex | Q4: =TEXT(H5,"DDD") -> sáb | R4: =TEXT(I5,"DDD") -> dom
A5: SEMANA 1 | B5: 45733 | C5: 6 | D5: =B5+1 -> 45734 | E5: =D5+1 -> 45735 | F5: =E5+1 -> 45736 | G5: =F5+1 -> 45737 | H5: =G5+1 -> 45738 | I5: =B5+C5 -> 45739 | J5: =COUNTIFS(' CADASTRO'!$B$2:$B$994,'PRODUÇÃO SEMANA'!B5)+COUNTIFS(' CADASTRO'!$B$2:$B$994,D5)+COUNTIFS(' CADASTRO'!$B$2:$B$994,E5)+COUNTIFS(' CADASTRO'!$B$2:$B$994,F5)+COUNTIFS(' CADASTRO'!$B$2:$B$994,G5)+COUNTIFS(' CADASTRO'!$B$2:$B$994,H5)+COUNTIFS(' CADASTRO'!$B$2:$B$994,I5) -> 8 | L5: =IF(B5="","",COUNTIFS(' CADASTRO'!$B$2:$B$994,'PRODUÇÃO SEMANA'!B5)) -> 8 | M5: =IF(D5=0,"",COUNTIFS(' CADASTRO'!$B$2:B$994,'PRODUÇÃO SEMANA'!D5)) -> 0 | N5: =COUNTIFS(' CADASTRO'!$B$2:B$994,'PRODUÇÃO SEMANA'!E5) -> 0 | O5: =COUNTIFS(' CADASTRO'!$B$2:B$994,'PRODUÇÃO SEMANA'!F5) -> 0 | P5: =COUNTIFS(' CADASTRO'!$B$2:B$994,'PRODUÇÃO SEMANA'!G5) -> 0 | Q5: =COUNTIFS(' CADASTRO'!$B$2:B$994,'PRODUÇÃO SEMANA'!H5) -> 0 | R5: =COUNTIFS(' CADASTRO'!$B$2:B$994,'PRODUÇÃO SEMANA'!I5) -> 0 | S5: =SUM(L5:Q5)/($S$3+$T$3) -> 0.2
A6: SEMANA 2 | B6: =I5+1 -> 45740 | C6: 6 | D6: =B6+1 -> 45741 | E6: =D6+1 -> 45742 | F6: =E6+1 -> 45743 | G6: =F6+1 -> 45744 | H6: =G6+1 -> 45745 | I6: =B6+C6 -> 45746 | J6: =COUNTIFS(' CADASTRO'!$B$2:$B$994,'PRODUÇÃO SEMANA'!B6)+COUNTIFS(' CADASTRO'!$B$2:$B$994,D6)+COUNTIFS(' CADASTRO'!$B$2:$B$994,E6)+COUNTIFS(' CADASTRO'!$B$2:$B$994,F6)+COUNTIFS(' CADASTRO'!$B$2:$B$994,G6)+COUNTIFS(' CADASTRO'!$B$2:$B$994,H6)+COUNTIFS(' CADASTRO'!$B$2:$B$994,I6) -> 32 | L6: =IF(B6="","",COUNTIFS(' CADASTRO'!$B$2:$B$994,'PRODUÇÃO SEMANA'!B6)) -> 0 | M6: =IF(D6=0,"",COUNTIFS(' CADASTRO'!$B$2:B$994,'PRODUÇÃO SEMANA'!D6)) -> 8 | N6: =COUNTIFS(' CADASTRO'!$B$2:B$994,'PRODUÇÃO SEMANA'!E6) -> 8 | O6: =COUNTIFS(' CADASTRO'!$B$2:B$994,'PRODUÇÃO SEMANA'!F6) -> 8 | P6: =COUNTIFS(' CADASTRO'!$B$2:B$994,'PRODUÇÃO SEMANA'!G6) -> 8 | Q6: =COUNTIFS(' CADASTRO'!$B$2:B$994,'PRODUÇÃO SEMANA'!H6) -> 0 | R6: =COUNTIFS(' CADASTRO'!$B$2:B$994,'PRODUÇÃO SEMANA'!I6) -> 0 | S6: =SUM(L6:Q6)/($S$3+$T$3) -> 0.8
A7: SEMANA 3 | B7: =I6+1 -> 45747 | C7: 6 | D7: =B7+1 -> 45748 | E7: =D7+1 -> 45749 | F7: =E7+1 -> 45750 | G7: =F7+1 -> 45751 | H7: =G7+1 -> 45752 | I7: =B7+C7 -> 45753 | J7: =COUNTIFS(' CADASTRO'!$B$2:$B$994,'PRODUÇÃO SEMANA'!B7)+COUNTIFS(' CADASTRO'!$B$2:$B$994,D7)+COUNTIFS(' CADASTRO'!$B$2:$B$994,E7)+COUNTIFS(' CADASTRO'!$B$2:$B$994,F7)+COUNTIFS(' CADASTRO'!$B$2:$B$994,G7)+COUNTIFS(' CADASTRO'!$B$2:$B$994,H7)+COUNTIFS(' CADASTRO'!$B$2:$B$994,I7) -> 32 | L7: =IF(B7="","",COUNTIFS(' CADASTRO'!$B$2:$B$994,'PRODUÇÃO SEMANA'!B7)) -> 8 | M7: =IF(D7=0,"",COUNTIFS(' CADASTRO'!$B$2:B$994,'PRODUÇÃO SEMANA'!D7)) -> 0 | N7: =COUNTIFS(' CADASTRO'!$B$2:B$994,'PRODUÇÃO SEMANA'!E7) -> 8 | O7: =COUNTIFS(' CADASTRO'!$B$2:B$994,'PRODUÇÃO SEMANA'!F7) -> 8 | P7: =COUNTIFS(' CADASTRO'!$B$2:B$994,'PRODUÇÃO SEMANA'!G7) -> 0 | Q7: =COUNTIFS(' CADASTRO'!$B$2:B$994,'PRODUÇÃO SEMANA'!H7) -> 8 | R7: =COUNTIFS(' CADASTRO'!$B$2:B$994,'PRODUÇÃO SEMANA'!I7) -> 0 | S7: =SUM(L7:Q7)/($S$3+$T$3) -> 0.8
A8: SEMANA 4 | B8: =I7+1 -> 45754 | C8: 6 | D8: =B8+1 -> 45755 | E8: =D8+1 -> 45756 | F8: =E8+1 -> 45757 | G8: =F8+1 -> 45758 | H8: =G8+1 -> 45759 | I8: =B8+C8 -> 45760 | J8: =COUNTIFS(' CADASTRO'!$B$2:$B$994,'PRODUÇÃO SEMANA'!B8)+COUNTIFS(' CADASTRO'!$B$2:$B$994,D8)+COUNTIFS(' CADASTRO'!$B$2:$B$994,E8)+COUNTIFS(' CADASTRO'!$B$2:$B$994,F8)+COUNTIFS(' CADASTRO'!$B$2:$B$994,G8)+COUNTIFS(' CADASTRO'!$B$2:$B$994,H8)+COUNTIFS(' CADASTRO'!$B$2:$B$994,I8) -> 32 | L8: =IF(B8="","",COUNTIFS(' CADASTRO'!$B$2:$B$994,'PRODUÇÃO SEMANA'!B8)) -> 8 | M8: =IF(D8=0,"",COUNTIFS(' CADASTRO'!$B$2:B$994,'PRODUÇÃO SEMANA'!D8)) -> 8 | N8: =COUNTIFS(' CADASTRO'!$B$2:B$994,'PRODUÇÃO SEMANA'!E8) -> 0 | O8: =COUNTIFS(' CADASTRO'!$B$2:B$994,'PRODUÇÃO SEMANA'!F8) -> 8 | P8: =COUNTIFS(' CADASTRO'!$B$2:B$994,'PRODUÇÃO SEMANA'!G8) -> 8 | Q8: =COUNTIFS(' CADASTRO'!$B$2:B$994,'PRODUÇÃO SEMANA'!H8) -> 0 | R8: =COUNTIFS(' CADASTRO'!$B$2:B$994,'PRODUÇÃO SEMANA'!I8) -> 0 | S8: =SUM(L8:Q8)/($S$3+$T$3) -> 0.8
A9: SEMANA 5 | B9: =I8+1 -> 45761 | C9: 6 | D9: =B9+1 -> 45762 | E9: =D9+1 -> 45763 | F9: =E9+1 -> 45764 | G9: =F9+1 -> 45765 | H9: =G9+1 -> 45766 | I9: =B9+C9 -> 45767 | J9: =COUNTIFS(' CADASTRO'!$B$2:$B$994,'PRODUÇÃO SEMANA'!B9)+COUNTIFS(' CADASTRO'!$B$2:$B$994,D9)+COUNTIFS(' CADASTRO'!$B$2:$B$994,E9)+COUNTIFS(' CADASTRO'!$B$2:$B$994,F9)+COUNTIFS(' CADASTRO'!$B$2:$B$994,G9)+COUNTIFS(' CADASTRO'!$B$2:$B$994,H9)+COUNTIFS(' CADASTRO'!$B$2:$B$994,I9) -> 31 | L9: =IF(B9="","",COUNTIFS(' CADASTRO'!$B$2:$B$994,'PRODUÇÃO SEMANA'!B9)) -> 7 | M9: =IF(D9=0,"",COUNTIFS(' CADASTRO'!$B$2:B$994,'PRODUÇÃO SEMANA'!D9)) -> 8 | N9: =COUNTIFS(' CADASTRO'!$B$2:B$994,'PRODUÇÃO SEMANA'!E9) -> 0 | O9: =COUNTIFS(' CADASTRO'!$B$2:B$994,'PRODUÇÃO SEMANA'!F9) -> 16 | P9: =COUNTIFS(' CADASTRO'!$B$2:B$994,'PRODUÇÃO SEMANA'!G9) -> 0 | Q9: =COUNTIFS(' CADASTRO'!$B$2:B$994,'PRODUÇÃO SEMANA'!H9) -> 0 | R9: =COUNTIFS(' CADASTRO'!$B$2:B$994,'PRODUÇÃO SEMANA'!I9) -> 0 | S9: =SUM(L9:Q9)/($S$3+$T$3) -> 0.775
A10: SEMANA 6 | B10: =I9+1 -> 45768 | C10: 6 | D10: =B10+1 -> 45769 | E10: =D10+1 -> 45770 | F10: =E10+1 -> 45771 | G10: =F10+1 -> 45772 | H10: =G10+1 -> 45773 | I10: =B10+C10 -> 45774 | J10: =COUNTIFS(' CADASTRO'!$B$2:$B$994,'PRODUÇÃO SEMANA'!B10)+COUNTIFS(' CADASTRO'!$B$2:$B$994,D10)+COUNTIFS(' CADASTRO'!$B$2:$B$994,E10)+COUNTIFS(' CADASTRO'!$B$2:$B$994,F10)+COUNTIFS(' CADASTRO'!$B$2:$B$994,G10)+COUNTIFS(' CADASTRO'!$B$2:$B$994,H10)+COUNTIFS(' CADASTRO'!$B$2:$B$994,I10) -> 24 | L10: =IF(B10="","",COUNTIFS(' CADASTRO'!$B$2:$B$994,'PRODUÇÃO SEMANA'!B10)) -> 0 | M10: =IF(D10=0,"",COUNTIFS(' CADASTRO'!$B$2:B$994,'PRODUÇÃO SEMANA'!D10)) -> 0 | N10: =COUNTIFS(' CADASTRO'!$B$2:B$994,'PRODUÇÃO SEMANA'!E10) -> 8 | O10: =COUNTIFS(' CADASTRO'!$B$2:B$994,'PRODUÇÃO SEMANA'!F10) -> 8 | P10: =COUNTIFS(' CADASTRO'!$B$2:B$994,'PRODUÇÃO SEMANA'!G10) -> 0 | Q10: =COUNTIFS(' CADASTRO'!$B$2:B$994,'PRODUÇÃO SEMANA'!H10) -> 8 | R10: =COUNTIFS(' CADASTRO'!$B$2:B$994,'PRODUÇÃO SEMANA'!I10) -> 0 | S10: =SUM(L10:Q10)/($S$3+$T$3) -> 0.6
A11: SEMANA 7 | B11: =I10+1 -> 45775 | C11: 6 | D11: =B11+1 -> 45776 | E11: =D11+1 -> 45777 | F11: =E11+1 -> 45778 | G11: =F11+1 -> 45779 | H11: =G11+1 -> 45780 | I11: =B11+C11 -> 45781 | J11: =COUNTIFS(' CADASTRO'!$B$2:$B$994,'PRODUÇÃO SEMANA'!B11)+COUNTIFS(' CADASTRO'!$B$2:$B$994,D11)+COUNTIFS(' CADASTRO'!$B$2:$B$994,E11)+COUNTIFS(' CADASTRO'!$B$2:$B$994,F11)+COUNTIFS(' CADASTRO'!$B$2:$B$994,G11)+COUNTIFS(' CADASTRO'!$B$2:$B$994,H11)+COUNTIFS(' CADASTRO'!$B$2:$B$994,I11) -> 24 | L11: =IF(B11="","",COUNTIFS(' CADASTRO'!$B$2:$B$994,'PRODUÇÃO SEMANA'!B11)) -> 0 | M11: =IF(D11=0,"",COUNTIFS(' CADASTRO'!$B$2:B$994,'PRODUÇÃO SEMANA'!D11)) -> 8 | N11: =COUNTIFS(' CADASTRO'!$B$2:B$994,'PRODUÇÃO SEMANA'!E11) -> 8 | O11: =COUNTIFS(' CADASTRO'!$B$2:B$994,'PRODUÇÃO SEMANA'!F11) -> 0 | P11: =COUNTIFS(' CADASTRO'!$B$2:B$994,'PRODUÇÃO SEMANA'!G11) -> 0 | Q11: =COUNTIFS(' CADASTRO'!$B$2:B$994,'PRODUÇÃO SEMANA'!H11) -> 8 | R11: =COUNTIFS(' CADASTRO'!$B$2:B$994,'PRODUÇÃO SEMANA'!I11) -> 0 | S11: =SUM(L11:Q11)/($S$3+$T$3) -> 0.6
