Workbook

Sheet plan de data
D1: 4 | E1: 5 | F1: 6 | G1: 7 | H1: 8 | I1: 9 | J1: 10 | K1: 11 | L1: 12 | M1: 13 | N1: 14 | O1: 15 | P1: 16 | Q1: 17 | R1: 18 | S1: 19 | T1: 20 | U1: 21 | V1: 22 | W1: 23 | X1: 24 | Y1: 25 | Z1: 26 | AA1: 27 | AD1: 30 | AE1: 31 | AF1: 32 | AG1: 33 | AH1: 34
A2: folha | B2: data | C2: FMRC NUMEROS | D2: FORMA 1 | E2: TP1 | F2: FORMA 2 | G2: TP2 | H2: FORMA 3 | I2: TP3 | J2: FORMA 4 | K2: TP4 | L2: FORMA 5 | M2: TP5 | N2: FORMA 6 | O2: TP6 | P2: FORMA 7 | Q2: TP7 | R2: FORMA 8 | S2: TP8 | T2: FORMA 9 | U2: TP9 | V2: FORMA 10 | W2: TP10 | X2: FORMA 11 | Y2: TP11 | Z2: FORMA 12 | AA2: TP12 | AB2: FORMA 13 | AC2: TP13 | AE2: MESA | AF2: cliente | AG2: obra | AH2: descrição do tanque
A3: 1 | B3: 45733 | C3: 982-983-984-985 | D3: PN-02 | E3: P | F3: PN-03 | G3: P | H3: PN-04 | I3: P | J3: PN-05 | K3: P | L3: PN-06 | M3: P | N3: PN-10 | O3: P | P3: PN-11 | Q3: P | AE3: PN-001 | AF3: CONSÓRCIO NOVA ETE - PARQUE NOVO MUNDO | AG3: ETE - PARQUE NOVO MUNDO | AH3: REATORES NEREDA
A4: 2 | B4: 45741 | C4: 987-988-989-990 | D4: PN-12 | E4: P | F4: PN-13 | G4: P | H4: PN-14 | I4: P | J4: PN-15 | K4: P | L4: PN-16 | M4: P | N4: PN-17 | O4: P | P4: PN-18 | Q4: P | AE4: PN-001 | AF4: CONSÓRCIO NOVA ETE - PARQUE NOVO MUNDO | AG4: ETE - PARQUE NOVO MUNDO | AH4: REATORES NEREDA
A5: 3 | B5: 45742 | C5: 992-993-994-995 | F5: PN-19 | G5: P | H5: PN-20 | I5: P | J5: PN-21 | K5: P | L5: PN-22 | M5: P | N5: PN-23 | O5: P | P5: PN-25 | Q5: P | R5: PN-26 | S5: P | AE5: PN-002 | AF5: CONSÓRCIO NOVA ETE - PARQUE NOVO MUNDO | AG5: ETE - PARQUE NOVO MUNDO | AH5: REATORES NEREDA
A6: 4 | B6: 45743 | C6: 997-998-999-1000 | D6: PN-27 | E6: P | F6: PN-28 | G6: p | H6: PN-29 | I6: P | J6: PN-30 | K6: P | L6: PN-31 | M6: P | N6: PN-33 | O6: P | P6: PN-34 | Q6: P | AE6: PN-001 | AF6: CONSÓRCIO NOVA ETE - PARQUE NOVO MUNDO | AG6: ETE - PARQUE NOVO MUNDO | AH6: REATORES NEREDA
A7: 5 | B7: 45744 | C7: 1002-1003-1004-1005 | F7: PN-36 | G7: P | H7: PN-37 | I7: P | J7: PN-38 | K7: P | L7: PN-40 | M7: P | N7: PN-41 | O7: P | P7: PN-42 | Q7: P | R7: PN-35 | S7: P | AE7: PN-002 | AF7: CONSÓRCIO NOVA ETE - PARQUE NOVO MUNDO | AG7: ETE - PARQUE NOVO MUNDO | AH7: REATORES NEREDA
A8: 6 | B8: 45747 | C8: 1006-1007-1008-1009 | D8: PN-43 | E8: P | F8: PN-44 | G8: P | H8: PN-45 | I8: P | J8: PN-46 | K8: P | L8: PN-47 | M8: P | N8: PN-48 | O8: P | P8: PN-49 | Q8: P | AE8: PN-001 | AF8: CONSÓRCIO NOVA ETE - PARQUE NOVO MUNDO | AG8: ETE - PARQUE NOVO MUNDO | AH8: REATORES NEREDA
A9: 7 | B9: 45749 | C9: 1011-1012-1013-1014 | F9: PN-51 | G9: P | H9: PN-52 | I9: P | J9: PN-53 | K9: P | L9: PN-54 | M9: P | N9: PN-56 | O9: P | P9: PN-57 | Q9: P | R9: PN-50 | S9: P | AE9: PN-002 | AF9: CONSÓRCIO NOVA ETE - PARQUE NOVO MUNDO | AG9: ETE - PARQUE NOVO MUNDO | AH9: REATORES NEREDA
A10: 8 | B10: 45750 | C10: 1016-1017-1018 | D10: PN-58 | E10: P | F10: PN-59 | G10: P | H10: PN-60 | I10: P | J10: PN61 | K10: P | L10: PN-62 | M10: P | N10: PN-64 | O10: P | P10: PN-65 | Q10: P | AE10: PN-001 | AF10: CONSÓRCIO NOVA ETE - PARQUE NOVO MUNDO | AG10: ETE - PARQUE NOVO MUNDO | AH10: REATORES NEREDA
A11: 9 | B11: 45752 | C11: 1020-1021-1022-1023 | F11: PN-66 | G11: P | H11: PN-67 | I11: P | J11: PN-68 | K11: P | L11: PN-72 | M11: P | N11: PN-73 | O11: P | P11: PN-74 | Q11: P | R11: PN-75 | S11: P | AE11: PN-002 | AF11: CONSÓRCIO NOVA ETE - PARQUE NOVO MUNDO | AG11: ETE - PARQUE NOVO MUNDO | AH11: REATORES NEREDA
A12: 10 | B12: 45754 | C12: 1025-1026-1027-1028 | D12: PN-76 | E12: P | F12: PN-77 | G12: P | H12: PN-78 | I12: P | J12: PN-79 | K12: P | L12: PN-80 | M12: P | N12: PN-81 | O12: P | P12: PN-82 | Q12: P | AE12: PN-001 | AF12: CONSÓRCIO NOVA ETE - PARQUE NOVO MUNDO | AG12: ETE - PARQUE NOVO MUNDO | AH12: REATORES NEREDA
A13: 11 | B13: 45755 | C13: 1030-1031-1032-1033 | F13: PN-83 | G13: P | H13: PN-84 | I13: P | J13: PN-85 | K13: P | L13: PN-87 | M13: P | N13: PN-88 | O13: P | P13: PN-89 | Q13: P | R13: PN-90 | S13: P | AE13: PN-002 | AF13: CONSÓRCIO NOVA ETE - PARQUE NOVO MUNDO | AG13: ETE - PARQUE NOVO MUNDO | AH13: REATORES NEREDA
A14: 12 | B14: 45757 | C14: 1034-1035-1036-1037 | F14: PN-91 | G14: P | H14: PN92 | I14: P | J14: PN-93 | K14: P | L14: PN-95 | M14: P | N14: PN-96 | O14: P | P14: PN-97 | Q14: P | R14: PN-98 | S14: p | AE14: PN-002 | AF14: CONSÓRCIO NOVA ETE - PARQUE NOVO MUNDO | AG14: ETE - PARQUE NOVO MUNDO | AH14: REATORES NEREDA
A15: 13 | B15: 45758 | C15: 1039-1040-1041-1042 | D15: PN-99 | E15: P | F15: PN-100 | G15: P | H15: PN-102 | I15: P | J15: PN-103 | K15: P | L15: PN-104 | M15: P | N15: PN-105 | O15: P | P15: PN-106 | Q15: P | AE15: PN-001 | AF15: CONSÓRCIO NOVA ETE - PARQUE NOVO MUNDO | AG15: ETE - PARQUE NOVO MUNDO | AH15: REATORES NEREDA
A16: 14 | B16: 45761 | C16: 1044-1045-1046 | F16: PN-108 | G16: P | H16: PN-109 | I16: P | J16: PN-110 | K16: P | L16: PN-111 | M16: P | N16: PN-112 | O16: P | P16: PN-113 | Q16: P | AE16: PN-001 | AF16: CONSÓRCIO NOVA ETE - PARQUE NOVO MUNDO | AG16: ETE - PARQUE NOVO MUNDO | AH16: REATORES NEREDA
A17: 15 | B17: 45762 | C17: 1048-1049-1050-1051 | F17: PN-107 | G17: P | H17: PN-114 | I17: P | J17: PN-115 | K17: P | L17: PN-116 | M17: P | N17: PN-118 | O17: P | P17: PN-119 | Q17: P | R17: PN-120 | S17: P | AE17: PN-002 | AF17: CONSÓRCIO NOVA ETE - PARQUE NOVO MUNDO | AG17: ETE - PARQUE NOVO MUNDO | AH17: REATORES NEREDA
A18: 16 | B18: 45764 | C18: 1052-1053-1054-1055 | D18: PN-121 | E18: P | F18: PN-122 | G18: P | H18: PN-123 | I18: P | J18: PN-124 | K18: P | L18: PN-126 | M18: P | N18: PN-127 | O18: P | P18: PN-128 | Q18: P | AE18: PN-001 | AF18: CONSÓRCIO NOVA ETE - PARQUE NOVO MUNDO | AG18: ETE - PARQUE NOVO MUNDO | AH18: REATORES NEREDA
A19: 17 | B19: 45764 | C19: 1056-1057-1058-1059 | F19: PN-129 | G19: P | H19: PN-130 | I19: P | J19: PN-131 | K19: P | L19: PN-132 | M19: P | N19: PN-134 | O19: P | P19: PN-135 | Q19: P | R19: PN-136 | S19: P | AE19: PN-002 | AF19: CONSÓRCIO NOVA ETE - PARQUE NOVO MUNDO | AG19: ETE - PARQUE NOVO MUNDO | AH19: REATORES NEREDA
A20: 18 | B20: 45770 | C20: 1060-1061-1062-1063 | F20: PN-137 | G20: P | H20: PN-138 | I20: P | J20: PN-139 | K20: P | L20: PN-140 | M20: P | N20: PN-141 | O20: P | P20: PN-142 | Q20: P | R20: PN-143 | S20: P | AE20: PN-002 | AF20: CONSÓRCIO NOVA ETE - PARQUE NOVO MUNDO | AG20: ETE - PARQUE NOVO MUNDO | AH20: REATORES NEREDA
A21: 19 | B21: 45771 | C21: 1064-1065-1066-1067 | D21: PN-144 | E21: P | F21: PN-145 | G21: P | H21: PN-146 | I21: P | J21: PN-147 | K21: P | L21: PN-151 | M21: P | N21: PN-152 | O21: P | P21: PN-153 | Q21: P | AE21: PN-001 | AF21: CONSÓRCIO NOVA ETE - PARQUE NOVO MUNDO | AG21: ETE - PARQUE NOVO MUNDO | AH21: REATORES NEREDA
A22: 20 | B22: 45773 | C22: 1069-1070-1071-1072 | F22: PN-154 | G22: P | H22: PN-155 | I22: P | J22: PN-157 | K22: P | L22: PN-158 | M22: P | N22: PN-159 | O22: P | P22: PN-160 | Q22: P | R22: PN-161 | S22: P | AE22: PN-002 | AF22: CONSÓRCIO NOVA ETE - PARQUE NOVO MUNDO | AG22: ETE - PARQUE NOVO MUNDO | AH22: REATORES NEREDA
A23: 21 | B23: 45776 | C23: 1074-1075-1076-1077 | D23: PN-162 | E23: P | F23: PN-163 | G23: P | H23: PN-165 | I23: P | J23: PN-166 | K23: P | L23: PN-167 | M23: P | N23: PN-168 | O23: P | P23: PN-169 | Q23: P | AE23: PN-001 | AF23: CONSÓRCIO NOVA ETE - PARQUE NOVO MUNDO | AG23: ETE - PARQUE NOVO MUNDO | AH23: REATORES NEREDA
A24: 22 | B24: 45777 | C24: 1079-1080-1081-1082 | F24: PN-170 | G24: P | H24: PN-171 | I24: P | J24: PN-172 | K24: P | L24: PN-173 | M24: P | N24: PN-174 | O24: P | P24: PN-175 | Q24: P | R24: PN-176 | S24: P | AE24: PN-002 | AF24: CONSÓRCIO NOVA ETE - PARQUE NOVO MUNDO | AG24: ETE - PARQUE NOVO MUNDO | AH24: REATORES NEREDA
A25: 23 | B25: 45780 | C25: 1084-1085-1086 | D25: PN-177 | E25: P | F25: PN-178 | G25: P | H25: PN-179 | I25: P | J25: PN-181 | K25: P | L25: PN-182 | M25: P | N25: PN-183 | O25: P | P25: PN-184 | Q25: P | AE25: PN-001 | AF25: CONSÓRCIO NOVA ETE - PARQUE NOVO MUNDO | AG25: ETE - PARQUE NOVO MUNDO | AH25: REATORES NEREDA
A26: 24 | B26: 45782 | C26: 1088-1089-1090-1091 | F26: PN-185 | G26: P | H26: PN-186 | I26: P | J26: PN-188 | K26: P | L26: PN-189 | M26: P | N26: PN-190 | O26: P | P26: PN-191 | Q26: P | R26: PN-192 | S26: P | AE26: PN-002 | AF26: CONSÓRCIO NOVA ETE - PARQUE NOVO MUNDO | AG26: ETE - PARQUE NOVO MUNDO | AH26: REATORES NEREDA
A27: 25 | B27: 45783 | C27: 1093-1094-1095-1096 | D27: PN-193 | E27: P | F27: PN-194 | G27: P | H27: PN-196 | I27: P | J27: PN-197 | K27: P | L27: PN-198 | M27: P | N27: PN-199 | O27: P | P27: PN-200 | Q27: P | AE27: PN-001 | AF27: CONSÓRCIO NOVA ETE - PARQUE NOVO MUNDO | AG27: ETE - PARQUE NOVO MUNDO | AH27: REATORES NEREDA
A28: 26 | B28: 45785 | C28: 1098-1099-1100-1101 | F28: PN-201 | G28: P | H28: PN-202 | I28: P | J28: PN-203 | K28: P | L28: PN-204 | M28: P | N28: PN-205 | O28: P | P28: PN-206 | Q28: P | R28: PN-207 | S28: P | AE28: PN-002 | AF28: CONSÓRCIO NOVA ETE - PARQUE NOVO MUNDO | AG28: ETE - PARQUE NOVO MUNDO | AH28: REATORES NEREDA
A29: 27 | B29: 45786 | C29: 1103-1104-1105-1106 | D29: PN-208 | E29: P | F29: PN-209 | G29: P | H29: PN-210 | I29: P | J29: PN-212 | K29: P | L29: PN-213 | M29: P | N29: PN-214 | O29: P | P29: PN-215 | Q29: P | AE29: PN-001 | AF29: CONSÓRCIO NOVA ETE - PARQUE NOVO MUNDO | AG29: ETE - PARQUE NOVO MUNDO | AH29: REATORES NEREDA
A30: 28 | B30: 45789 | C30: 1107-1108-1109-1110 | F30: PN-216 | G30: P | H30: PN-217 | I30: P | J30: PN-219 | K30: P | L30: PN-220 | M30: P | N30: PN-221 | O30: P | P30: PN-222 | Q30: P | R30: PN-223 | S30: P | AE30: PN-002 | AF30: CONSÓRCIO NOVA ETE - PARQUE NOVO MUNDO | AG30: ETE - PARQUE NOVO MUNDO | AH30: REATORES NEREDA
A31: 29 | B31: 45796 | C31: 1112-A / 1113 | D31: PF-01 | E31: PF | AE31: PF-001 | AF31: CONSÓRCIO NOVA ETE - PARQUE NOVO MUNDO | AG31: ETE - PARQUE NOVO MUNDO | AH31: REATORES NEREDA
A32: 30 | B32: 45800 | C32: 1115-A / 1116 | D32: PF-32 | E32: PF | AE32: PF-001 | AF32: CONSÓRCIO NOVA ETE - PARQUE NOVO MUNDO | AG32: ETE - PARQUE NOVO MUNDO | AH32: REATORES NEREDA
A33: 31 | B33: 45806 | C33: 1118-1119-1120 | D33: PE-09 | E33: T3 | F33: PE-08 | G33: T1 | H33: PE-24 | I33: T4 | J33: PE-55 | K33: T4 | L33: PE-07 | M33: T2 | N33: PE-39 | O33: T2 | P33: PN-224 | Q33: P | AE33: PN-001 | AF33: CONSÓRCIO NOVA ETE - PARQUE NOVO MUNDO | AG33: ETE - PARQUE NOVO MUNDO | AH33: REATORES NEREDA
A34: 32 | B34: 45812 | C34: 1123-1124-1125 | D34: PE-71 | E34: T3 | F34: PE-70 | G34: T1 | H34: PE-86 | I34: T4 | J34: PE-117 | K34: T4 | L34: PE-69 | M34: T2 | N34: PE-101 | O34: T2 | P34: PN-225 | Q34: P | AE34: PN-001 | AF34: CONSÓRCIO NOVA ETE - PARQUE NOVO MUNDO | AG34: ETE - PARQUE NOVO MUNDO | AH34: REATORES NEREDA
A35: 33 | B35: 45814 | C35: 1128 | D35: PF-63 | E35: PF | AE35: PF-001 | AF35: CONSÓRCIO NOVA ETE - PARQUE NOVO MUNDO | AG35: ETE - PARQUE NOVO MUNDO | AH35: REATORES NEREDA
A36: 34 | B36: 45818 | C36: 1129-1130-1131-1132 | D36: PE-148 | E36: T3 | F36: PE-149 | G36: T1 | H36: PE-133 | I36: T4 | J36: PE-164 | K36: T4 | L36: PE-150 | M36: T2 | N36: PE-180 | O36: T2 | P36: PN-227 | Q36: P | AE36: PN-001 | AF36: CONSÓRCIO NOVA ETE - PARQUE NOVO MUNDO | AG36: ETE - PARQUE NOVO MUNDO | AH36: REATORES NEREDA
A37: 35 | B37: 45822 | C37: 1133-1134-1135-1136 | D37: PE-241 | E37: T3 | F37: PE-242 | G37: T1 | H37: PE-195 | I37: T4 | J37: PE-226 | K37: T4 | L37: PE-211 | M37: T2 | N37: PE-243 | O37: T2 | P37: PN-228 | Q37: P | AE37: PN-001 | AF37: CONSÓRCIO NOVA ETE - PARQUE NOVO MUNDO | AG37: ETE - PARQUE NOVO MUNDO | AH37: REATORES NEREDA
A38: 36 | B38: 45825 | C38: 1138 | D38: PF-94 | E38: PF | AE38: PF-001 | AF38: CONSÓRCIO NOVA ETE - PARQUE NOVO MUNDO | AG38: ETE - PARQUE NOVO MUNDO | AH38: REATORES NEREDA
A39: 37 | B39: 45827 | C39: 1139-1140-1141-1142 | D39: PN-229 | E39: P | F39: PN-230 | G39: P | H39: PE-257 | I39: T4 | J39: PN-231 | K39: P | L39: PN-232 | M39: P | N39: PN-233 | O39: P | P39: PN-234 | Q39: P | AE39: PN-001 | AF39: CONSÓRCIO NOVA ETE - PARQUE NOVO MUNDO | AG39: ETE - PARQUE NOVO MUNDO | AH39: REATORES NEREDA
A40: 38 | B40: 45833 | C40: 1150-1151-1152-1153 | D40: PN-235 | E40: P | F40: PN-236 | G40: P | H40: PN-237 | I40: P | J40: PE-288 | K40: T4 | L40: PN-238 | M40: P | N40: PN-239 | O40: P | P40: PN-240 | Q40: P | AE40: PN-001 | AF40: CONSÓRCIO NOVA ETE - PARQUE NOVO MUNDO | AG40: ETE - PARQUE NOVO MUNDO | AH40: REATORES NEREDA
...

Sheet Planilha1
A1: MESAS
A2: PN-001
A3: PN-002
A4: PF-001
A5: SR-06
A6: LAJES
A7: MADEIRA
A8: PILAR
A9: MESA 4
A10: SR-06/ MADEIRA
A11: PILAR /MADEIRA

Sheet CA
B1: DATA | C1: CABOS PROTENDIDOS - LANÇAR ALONGAMENTOS | Y1: N° BOBINA | Z1: DATA FAB. | AA1: CERTIFICADO | AB1: N° BOBINA | AC1: DATA FAB. | AD1: CERTIFICADO | AE1: E= | AF1: A= | AG1: E= | AH1: A= | AJ1: PN | AK1: PF
C2: C-1 | D2: C-2 | E2: C-3 | F2: C-4 | G2: C-5 | H2: C-6 | I2: C-7 | J2: C-8 | K2: C-9 | L2: C-10 | M2: C-11 | N2: C-12 | O2: C-13 | P2: C-14 | Q2: C-15 | R2: C-16 | S2: C-17 | T2: C-18 | U2: C-19 | V2: C-20 | W2: C-21 | X2: C-22
A3: ='plan de data'!A3 -> 1 | B3: ='plan de data'!B3 -> 45733 | C3: 338 | D3: 337 | E3: 340 | F3: 338 | G3: 341 | H3: 338 | I3: 340 | J3: 341 | K3: 341 | L3: 339 | M3: 340 | N3: 339 | O3: 342 | P3: 343 | Q3: 341 | R3: 340 | Y3: 1062265533 | Z3: =IF(Y3="","-",VLOOKUP(Y3,'CERT. COR'!$A$4:$E$2200,3,0)) -> 45716 | AA3: =IF(Y3="","-",VLOOKUP(Y3,'CERT. COR'!$A$4:$E$2200,2,0)) -> 81795 | AC3: =IF(AB3="","-",VLOOKUP(AB3,'CERT. COR'!$A$4:$E$2200,3,0)) -> - | AD3: =IF(AB3="","-",VLOOKUP(AB3,'CERT. COR'!$A$4:$E$2200,2,0)) -> - | AE3: =IF(Y3="","-",VLOOKUP(Y3,'CERT. COR'!$A$4:$E$2200,5,0)) -> 100 | AF3: =IF(Y3="","-",VLOOKUP(Y3,'CERT. COR'!$A$4:$E$2200,4,0)) -> 192.3 | AG3: =IF(AB3="","-",VLOOKUP(AB3,'CERT. COR'!$A$4:$E$2200,5,0)) -> - | AH3: =IF(AB3="","-",VLOOKUP(AB3,'CERT. COR'!$A$4:$E$2200,4,0)) -> - | AI3: =IF(T3="","PN","PF") -> PN | AJ3: =IF(AI3="PN",SUM(C3:R3),0) -> 5438 | AK3: =IF(AI3="PF",SUM(C3:T3),0) -> 0
A4: ='plan de data'!A4 -> 2 | B4: ='plan de data'!B4 -> 45741 | C4: 341 | D4: 342 | E4: 342 | F4: 341 | G4: 342 | H4: 342 | I4: 342 | J4: 341 | K4: 341 | L4: 342 | M4: 343 | N4: 342 | O4: 343 | P4: 341 | Q4: 344 | R4: 342 | Y4: 1062265533 | Z4: =IF(Y4="","-",VLOOKUP(Y4,'CERT. COR'!$A$4:$E$2200,3,0)) -> 45716 | AA4: =IF(Y4="","-",VLOOKUP(Y4,'CERT. COR'!$A$4:$E$2200,2,0)) -> 81795 | AC4: =IF(AB4="","-",VLOOKUP(AB4,'CERT. COR'!$A$4:$E$2200,3,0)) -> - | AD4: =IF(AB4="","-",VLOOKUP(AB4,'CERT. COR'!$A$4:$E$2200,2,0)) -> - | AE4: =IF(Y4="","-",VLOOKUP(Y4,'CERT. COR'!$A$4:$E$2200,5,0)) -> 100 | AF4: =IF(Y4="","-",VLOOKUP(Y4,'CERT. COR'!$A$4:$E$2200,4,0)) -> 192.3 | AG4: =IF(AB4="","-",VLOOKUP(AB4,'CERT. COR'!$A$4:$E$2200,5,0)) -> - | AH4: =IF(AB4="","-",VLOOKUP(AB4,'CERT. COR'!$A$4:$E$2200,4,0)) -> - | AI4: =IF(T4="","PN","PF") -> PN | AJ4: =IF(AI4="PN",SUM(C4:R4),0) -> 5471 | AK4: =IF(AI4="PF",SUM(C4:T4),0) -> 0
A5: ='plan de data'!A5 -> 3 | B5: ='plan de data'!B5 -> 45742 | C5: 341 | D5: 342 | E5: 340 | F5: 340 | G5: 344 | H5: 344 | I5: 345 | J5: 344 | K5: 343 | L5: 342 | M5: 343 | N5: 344 | O5: 347 | P5: 346 | Q5: 344 | R5: 344 | Y5: 1061132962 | Z5: =IF(Y5="","-",VLOOKUP(Y5,'CERT. COR'!$A$4:$E$2200,3,0)) -> 45539 | AA5: =IF(Y5="","-",VLOOKUP(Y5,'CERT. COR'!$A$4:$E$2200,2,0)) -> 109622 | AC5: =IF(AB5="","-",VLOOKUP(AB5,'CERT. COR'!$A$4:$E$2200,3,0)) -> - | AD5: =IF(AB5="","-",VLOOKUP(AB5,'CERT. COR'!$A$4:$E$2200,2,0)) -> - | AE5: =IF(Y5="","-",VLOOKUP(Y5,'CERT. COR'!$A$4:$E$2200,5,0)) -> 99.5 | AF5: =IF(Y5="","-",VLOOKUP(Y5,'CERT. COR'!$A$4:$E$2200,4,0)) -> 197 | AG5: =IF(AB5="","-",VLOOKUP(AB5,'CERT. COR'!$A$4:$E$2200,5,0)) -> - | AH5: =IF(AB5="","-",VLOOKUP(AB5,'CERT. COR'!$A$4:$E$2200,4,0)) -> - | AI5: =IF(T5="","PN","PF") -> PN | AJ5: =IF(AI5="PN",SUM(C5:R5),0) -> 5493 | AK5: =IF(AI5="PF",SUM(C5:T5),0) -> 0
A6: ='plan de data'!A6 -> 4 | B6: ='plan de data'!B6 -> 45743 | C6: 340 | D6: 345 | E6: 339 | F6: 338 | G6: 339 | H6: 338 | I6: 340 | J6: 340 | K6: 340 | L6: 340 | M6: 341 | N6: 341 | O6: 339 | P6: 344 | Q6: 344 | R6: 342 | Y6: 1062265533 | Z6: =IF(Y6="","-",VLOOKUP(Y6,'CERT. COR'!$A$4:$E$2200,3,0)) -> 45716 | AA6: =IF(Y6="","-",VLOOKUP(Y6,'CERT. COR'!$A$4:$E$2200,2,0)) -> 81795 | AC6: =IF(AB6="","-",VLOOKUP(AB6,'CERT. COR'!$A$4:$E$2200,3,0)) -> - | AD6: =IF(AB6="","-",VLOOKUP(AB6,'CERT. COR'!$A$4:$E$2200,2,0)) -> - | AE6: =IF(Y6="","-",VLOOKUP(Y6,'CERT. COR'!$A$4:$E$2200,5,0)) -> 100 | AF6: =IF(Y6="","-",VLOOKUP(Y6,'CERT. COR'!$A$4:$E$2200,4,0)) -> 192.3 | AG6: =IF(AB6="","-",VLOOKUP(AB6,'CERT. COR'!$A$4:$E$2200,5,0)) -> - | AH6: =IF(AB6="","-",VLOOKUP(AB6,'CERT. COR'!$A$4:$E$2200,4,0)) -> - | AI6: =IF(T6="","PN","PF") -> PN | AJ6: =IF(AI6="PN",SUM(C6:R6),0) -> 5450 | AK6: =IF(AI6="PF",SUM(C6:T6),0) -> 0
A7: ='plan de data'!A7 -> 5 | B7: ='plan de data'!B7 -> 45744 | C7: 348 | D7: 340 | E7: 341 | F7: 338 | G7: 341 | H7: 339 | I7: 342 | J7: 340 | K7: 343 | L7: 341 | M7: 342 | N7: 342 | O7: 341 | P7: 340 | Q7: 343 | R7: 340 | Y7: 1061132962 | Z7: =IF(Y7="","-",VLOOKUP(Y7,'CERT. COR'!$A$4:$E$2200,3,0)) -> 45539 | AA7: =IF(Y7="","-",VLOOKUP(Y7,'CERT. COR'!$A$4:$E$2200,2,0)) -> 109622 | AB7: 1062076102 | AC7: =IF(AB7="","-",VLOOKUP(AB7,'CERT. COR'!$A$4:$E$2200,3,0)) -> 45737 | AD7: =IF(AB7="","-",VLOOKUP(AB7,'CERT. COR'!$A$4:$E$2200,2,0)) -> 81985 | AE7: =IF(Y7="","-",VLOOKUP(Y7,'CERT. COR'!$A$4:$E$2200,5,0)) -> 99.5 | AF7: =IF(Y7="","-",VLOOKUP(Y7,'CERT. COR'!$A$4:$E$2200,4,0)) -> 197 | AG7: =IF(AB7="","-",VLOOKUP(AB7,'CERT. COR'!$A$4:$E$2200,5,0)) -> 100 | AH7: =IF(AB7="","-",VLOOKUP(AB7,'CERT. COR'!$A$4:$E$2200,4,0)) -> 198.8 | AI7: =IF(T7="","PN","PF") -> PN | AJ7: =IF(AI7="PN",SUM(C7:R7),0) -> 5461 | AK7: =IF(AI7="PF",SUM(C7:T7),0) -> 0
A8: ='plan de data'!A8 -> 6 | B8: ='plan de data'!B8 -> 45747 | C8: 339 | D8: 339 | E8: 343 | F8: 344 | G8: 340 | H8: 341 | I8: 344 | J8: 343 | K8: 343 | L8: 343 | M8: 344 | N8: 344 | O8: 339 | P8: 341 | Q8: 345 | R8: 344 | Y8: 1062076102 | Z8: =IF(Y8="","-",VLOOKUP(Y8,'CERT. COR'!$A$4:$E$2200,3,0)) -> 45737 | AA8: =IF(Y8="","-",VLOOKUP(Y8,'CERT. COR'!$A$4:$E$2200,2,0)) -> 81985 | AC8: =IF(AB8="","-",VLOOKUP(AB8,'CERT. COR'!$A$4:$E$2200,3,0)) -> - | AD8: =IF(AB8="","-",VLOOKUP(AB8,'CERT. COR'!$A$4:$E$2200,2,0)) -> - | AE8: =IF(Y8="","-",VLOOKUP(Y8,'CERT. COR'!$A$4:$E$2200,5,0)) -> 100 | AF8: =IF(Y8="","-",VLOOKUP(Y8,'CERT. COR'!$A$4:$E$2200,4,0)) -> 198.8 | AG8: =IF(AB8="","-",VLOOKUP(AB8,'CERT. COR'!$A$4:$E$2200,5,0)) -> - | AH8: =IF(AB8="","-",VLOOKUP(AB8,'CERT. COR'!$A$4:$E$2200,4,0)) -> - | AI8: =IF(T8="","PN","PF") -> PN | AJ8: =IF(AI8="PN",SUM(C8:R8),0) -> 5476 | AK8: =IF(AI8="PF",SUM(C8:T8),0) -> 0
A9: ='plan de data'!A9 -> 7 | B9: ='plan de data'!B9 -> 45749 | C9: 346 | D9: 344 | E9: 344 | F9: 344 | G9: 347 | H9: 344 | I9: 346 | J9: 345 | K9: 347 | L9: 346 | M9: 347 | N9: 346 | O9: 346 | P9: 346 | Q9: 347 | R9: 347 | Y9: 1061132929 | Z9: =IF(Y9="","-",VLOOKUP(Y9,'CERT. COR'!$A$4:$E$2200,3,0)) -> 45539 | AA9: =IF(Y9="","-",VLOOKUP(Y9,'CERT. COR'!$A$4:$E$2200,2,0)) -> 109623 | AC9: =IF(AB9="","-",VLOOKUP(AB9,'CERT. COR'!$A$4:$E$2200,3,0)) -> - | AD9: =IF(AB9="","-",VLOOKUP(AB9,'CERT. COR'!$A$4:$E$2200,2,0)) -> - | AE9: =IF(Y9="","-",VLOOKUP(Y9,'CERT. COR'!$A$4:$E$2200,5,0)) -> 100 | AF9: =IF(Y9="","-",VLOOKUP(Y9,'CERT. COR'!$A$4:$E$2200,4,0)) -> 198 | AG9: =IF(AB9="","-",VLOOKUP(AB9,'CERT. COR'!$A$4:$E$2200,5,0)) -> - | AH9: =IF(AB9="","-",VLOOKUP(AB9,'CERT. COR'!$A$4:$E$2200,4,0)) -> - | AI9: =IF(T9="","PN","PF") -> PN | AJ9: =IF(AI9="PN",SUM(C9:R9),0) -> 5532 | AK9: =IF(AI9="PF",SUM(C9:T9),0) -> 0
A10: ='plan de data'!A10 -> 8 | B10: ='plan de data'!B10 -> 45750 | C10: 346 | D10: 347 | E10: 345 | F10: 345 | G10: 345 | H10: 345 | I10: 345 | J10: 348 | K10: 345 | L10: 345 | M10: 345 | N10: 345 | O10: 345 | P10: 345 | Q10: 346 | R10: 347 | Y10: 1062076102 | Z10: =IF(Y10="","-",VLOOKUP(Y10,'CERT. COR'!$A$4:$E$2200,3,0)) -> 45737 | AA10: =IF(Y10="","-",VLOOKUP(Y10,'CERT. COR'!$A$4:$E$2200,2,0)) -> 81985 | AC10: =IF(AB10="","-",VLOOKUP(AB10,'CERT. COR'!$A$4:$E$2200,3,0)) -> - | AD10: =IF(AB10="","-",VLOOKUP(AB10,'CERT. COR'!$A$4:$E$2200,2,0)) -> - | AE10: =IF(Y10="","-",VLOOKUP(Y10,'CERT. COR'!$A$4:$E$2200,5,0)) -> 100 | AF10: =IF(Y10="","-",VLOOKUP(Y10,'CERT. COR'!$A$4:$E$2200,4,0)) -> 198.8 | AG10: =IF(AB10="","-",VLOOKUP(AB10,'CERT. COR'!$A$4:$E$2200,5,0)) -> - | AH10: =IF(AB10="","-",VLOOKUP(AB10,'CERT. COR'!$A$4:$E$2200,4,0)) -> - | AI10: =IF(T10="","PN","PF") -> PN | AJ10: =IF(AI10="PN",SUM(C10:R10),0) -> 5529 | AK10: =IF(AI10="PF",SUM(C10:T10),0) -> 0
A11: ='plan de data'!A11 -> 9 | B11: ='plan de data'!B11 -> 45752 | C11: 346 | D11: 344 | E11: 347 | F11: 347 | G11: 344 | H11: 347 | I11: 346 | J11: 348 | K11: 349 | L11: 348 | M11: 350 | N11: 350 | O11: 348 | P11: 349 | Q11: 351 | R11: 350 | Y11: 1061132929 | Z11: =IF(Y11="","-",VLOOKUP(Y11,'CERT. COR'!$A$4:$E$2200,3,0)) -> 45539 | AA11: =IF(Y11="","-",VLOOKUP(Y11,'CERT. COR'!$A$4:$E$2200,2,0)) -> 109623 | AC11: =IF(AB11="","-",VLOOKUP(AB11,'CERT. COR'!$A$4:$E$2200,3,0)) -> - | AD11: =IF(AB11="","-",VLOOKUP(AB11,'CERT. COR'!$A$4:$E$2200,2,0)) -> - | AE11: =IF(Y11="","-",VLOOKUP(Y11,'CERT. COR'!$A$4:$E$2200,5,0)) -> 100 | AF11: =IF(Y11="","-",VLOOKUP(Y11,'CERT. COR'!$A$4:$E$2200,4,0)) -> 198 | AG11: =IF(AB11="","-",VLOOKUP(AB11,'CERT. COR'!$A$4:$E$2200,5,0)) -> - | AH11: =IF(AB11="","-",VLOOKUP(AB11,'CERT. COR'!$A$4:$E$2200,4,0)) -> - | AI11: =IF(T11="","PN","PF") -> PN | AJ11: =IF(AI11="PN",SUM(C11:R11),0) -> 5564 | AK11: =IF(AI11="PF",SUM(C11:T11),0) -> 0
A12: ='plan de data'!A12 -> 10 | B12: ='plan de data'!B12 -> 45754 | C12: 341 | D12: 343 | E12: 345 | F12: 344 | G12: 342 | H12: 342 | I12: 345 | J12: 345 | K12: 345 | L12: 344 | M12: 345 | N12: 345 | O12: 340 | P12: 341 | Q12: 345 | R12: 346 | Y12: 1062076102 | Z12: =IF(Y12="","-",VLOOKUP(Y12,'CERT. COR'!$A$4:$E$2200,3,0)) -> 45737 | AA12: =IF(Y12="","-",VLOOKUP(Y12,'CERT. COR'!$A$4:$E$2200,2,0)) -> 81985 | AC12: =IF(AB12="","-",VLOOKUP(AB12,'CERT. COR'!$A$4:$E$2200,3,0)) -> - | AD12: =IF(AB12="","-",VLOOKUP(AB12,'CERT. COR'!$A$4:$E$2200,2,0)) -> - | AE12: =IF(Y12="","-",VLOOKUP(Y12,'CERT. COR'!$A$4:$E$2200,5,0)) -> 100 | AF12: =IF(Y12="","-",VLOOKUP(Y12,'CERT. COR'!$A$4:$E$2200,4,0)) -> 198.8 | AG12: =IF(AB12="","-",VLOOKUP(AB12,'CERT. COR'!$A$4:$E$2200,5,0)) -> - | AH12: =IF(AB12="","-",VLOOKUP(AB12,'CERT. COR'!$A$4:$E$2200,4,0)) -> - | AI12: =IF(T12="","PN","PF") -> PN | AJ12: =IF(AI12="PN",SUM(C12:R12),0) -> 5498 | AK12: =IF(AI12="PF",SUM(C12:T12),0) -> 0
A13: ='plan de data'!A13 -> 11 | B13: ='plan de data'!B13 -> 45755 | C13: 344 | D13: 343 | E13: 344 | F13: 344 | G13: 345 | H13: 345 | I13: 347 | J13: 347 | K13: 348 | L13: 346 | M13: 349 | N13: 348 | O13: 352 | P13: 348 | Q13: 351 | R13: 348 | Y13: 1061132929 | Z13: =IF(Y13="","-",VLOOKUP(Y13,'CERT. COR'!$A$4:$E$2200,3,0)) -> 45539 | AA13: =IF(Y13="","-",VLOOKUP(Y13,'CERT. COR'!$A$4:$E$2200,2,0)) -> 109623 | AC13: =IF(AB13="","-",VLOOKUP(AB13,'CERT. COR'!$A$4:$E$2200,3,0)) -> - | AD13: =IF(AB13="","-",VLOOKUP(AB13,'CERT. COR'!$A$4:$E$2200,2,0)) -> - | AE13: =IF(Y13="","-",VLOOKUP(Y13,'CERT. COR'!$A$4:$E$2200,5,0)) -> 100 | AF13: =IF(Y13="","-",VLOOKUP(Y13,'CERT. COR'!$A$4:$E$2200,4,0)) -> 198 | AG13: =IF(AB13="","-",VLOOKUP(AB13,'CERT. COR'!$A$4:$E$2200,5,0)) -> - | AH13: =IF(AB13="","-",VLOOKUP(AB13,'CERT. COR'!$A$4:$E$2200,4,0)) -> - | AI13: =IF(T13="","PN","PF") -> PN | AJ13: =IF(AI13="PN",SUM(C13:R13),0) -> 5549 | AK13: =IF(AI13="PF",SUM(C13:T13),0) -> 0
A14: ='plan de data'!A14 -> 12 | B14: ='plan de data'!B14 -> 45757 | C14: 341 | D14: 340 | E14: 348 | F14: 347 | G14: 343 | H14: 344 | I14: 347 | J14: 347 | K14: 348 | L14: 348 | M14: 348 | N14: 350 | O14: 345 | P14: 342 | Q14: 348 | R14: 353 | Y14: 1061132929 | Z14: =IF(Y14="","-",VLOOKUP(Y14,'CERT. COR'!$A$4:$E$2200,3,0)) -> 45539 | AA14: =IF(Y14="","-",VLOOKUP(Y14,'CERT. COR'!$A$4:$E$2200,2,0)) -> 109623 | AB14: 1062265764 | AC14: =IF(AB14="","-",VLOOKUP(AB14,'CERT. COR'!$A$4:$E$2200,3,0)) -> 45730 | AD14: =IF(AB14="","-",VLOOKUP(AB14,'CERT. COR'!$A$4:$E$2200,2,0)) -> 81902 | AE14: =IF(Y14="","-",VLOOKUP(Y14,'CERT. COR'!$A$4:$E$2200,5,0)) -> 100 | AF14: =IF(Y14="","-",VLOOKUP(Y14,'CERT. COR'!$A$4:$E$2200,4,0)) -> 198 | AG14: =IF(AB14="","-",VLOOKUP(AB14,'CERT. COR'!$A$4:$E$2200,5,0)) -> 99.6 | AH14: =IF(AB14="","-",VLOOKUP(AB14,'CERT. COR'!$A$4:$E$2200,4,0)) -> 199.3 | AI14: =IF(T14="","PN","PF") -> PN | AJ14: =IF(AI14="PN",SUM(C14:R14),0) -> 5539 | AK14: =IF(AI14="PF",SUM(C14:T14),0) -> 0
A15: ='plan de data'!A15 -> 13 | B15: ='plan de data'!B15 -> 45758 | C15: 345 | D15: 342 | E15: 342 | F15: 346 | G15: 342 | H15: 342 | I15: 342 | J15: 344 | K15: 345 | L15: 344 | M15: 341 | N15: 343 | O15: 343 | P15: 344 | Q15: 346 | R15: 344 | Y15: 1062076102 | Z15: =IF(Y15="","-",VLOOKUP(Y15,'CERT. COR'!$A$4:$E$2200,3,0)) -> 45737 | AA15: =IF(Y15="","-",VLOOKUP(Y15,'CERT. COR'!$A$4:$E$2200,2,0)) -> 81985 | AB15: 1062269468 | AC15: =IF(AB15="","-",VLOOKUP(AB15,'CERT. COR'!$A$4:$E$2200,3,0)) -> 45730 | AD15: =IF(AB15="","-",VLOOKUP(AB15,'CERT. COR'!$A$4:$E$2200,2,0)) -> 81902 | AE15: =IF(Y15="","-",VLOOKUP(Y15,'CERT. COR'!$A$4:$E$2200,5,0)) -> 100 | AF15: =IF(Y15="","-",VLOOKUP(Y15,'CERT. COR'!$A$4:$E$2200,4,0)) -> 198.8 | AG15: =IF(AB15="","-",VLOOKUP(AB15,'CERT. COR'!$A$4:$E$2200,5,0)) -> 100 | AH15: =IF(AB15="","-",VLOOKUP(AB15,'CERT. COR'!$A$4:$E$2200,4,0)) -> 200.9 | AI15: =IF(T15="","PN","PF") -> PN | AJ15: =IF(AI15="PN",SUM(C15:R15),0) -> 5495 | AK15: =IF(AI15="PF",SUM(C15:T15),0) -> 0
A16: ='plan de data'!A16 -> 14 | B16: ='plan de data'!B16 -> 45761 | C16: 349 | D16: 343 | E16: 343 | F16: 344 | G16: 345 | H16: 347 | I16: 346 | J16: 345 | K16: 346 | L16: 346 | M16: 349 | N16: 347 | O16: 350 | P16: 351 | Q16: 351 | R16: 350 | Y16: 1062269468 | Z16: =IF(Y16="","-",VLOOKUP(Y16,'CERT. COR'!$A$4:$E$2200,3,0)) -> 45730 | AA16: =IF(Y16="","-",VLOOKUP(Y16,'CERT. COR'!$A$4:$E$2200,2,0)) -> 81902 | AC16: =IF(AB16="","-",VLOOKUP(AB16,'CERT. COR'!$A$4:$E$2200,3,0)) -> - | AD16: =IF(AB16="","-",VLOOKUP(AB16,'CERT. COR'!$A$4:$E$2200,2,0)) -> - | AE16: =IF(Y16="","-",VLOOKUP(Y16,'CERT. COR'!$A$4:$E$2200,5,0)) -> 100 | AF16: =IF(Y16="","-",VLOOKUP(Y16,'CERT. COR'!$A$4:$E$2200,4,0)) -> 200.9 | AG16: =IF(AB16="","-",VLOOKUP(AB16,'CERT. COR'!$A$4:$E$2200,5,0)) -> - | AH16: =IF(AB16="","-",VLOOKUP(AB16,'CERT. COR'!$A$4:$E$2200,4,0)) -> - | AI16: =IF(T16="","PN","PF") -> PN | AJ16: =IF(AI16="PN",SUM(C16:R16),0) -> 5552 | AK16: =IF(AI16="PF",SUM(C16:T16),0) -> 0
A17: ='plan de data'!A17 -> 15 | B17: ='plan de data'!B17 -> 45762 | C17: 345 | D17: 348 | E17: 344 | F17: 345 | G17: 341 | H17: 347 | I17: 346 | J17: 347 | K17: 347 | L17: 347 | M17: 349 | N17: 348 | O17: 343 | P17: 343 | Q17: 348 | R17: 346 | Y17: 1062265764 | Z17: =IF(Y17="","-",VLOOKUP(Y17,'CERT. COR'!$A$4:$E$2200,3,0)) -> 45730 | AA17: =IF(Y17="","-",VLOOKUP(Y17,'CERT. COR'!$A$4:$E$2200,2,0)) -> 81902 | AC17: =IF(AB17="","-",VLOOKUP(AB17,'CERT. COR'!$A$4:$E$2200,3,0)) -> - | AD17: =IF(AB17="","-",VLOOKUP(AB17,'CERT. COR'!$A$4:$E$2200,2,0)) -> - | AE17: =IF(Y17="","-",VLOOKUP(Y17,'CERT. COR'!$A$4:$E$2200,5,0)) -> 99.6 | AF17: =IF(Y17="","-",VLOOKUP(Y17,'CERT. COR'!$A$4:$E$2200,4,0)) -> 199.3 | AG17: =IF(AB17="","-",VLOOKUP(AB17,'CERT. COR'!$A$4:$E$2200,5,0)) -> - | AH17: =IF(AB17="","-",VLOOKUP(AB17,'CERT. COR'!$A$4:$E$2200,4,0)) -> - | AI17: =IF(T17="","PN","PF") -> PN | AJ17: =IF(AI17="PN",SUM(C17:R17),0) -> 5534 | AK17: =IF(AI17="PF",SUM(C17:T17),0) -> 0
A18: ='plan de data'!A18 -> 16 | B18: ='plan de data'!B18 -> 45764 | C18: 349 | D18: 344 | E18: 343 | F18: 343 | G18: 347 | H18: 345 | I18: 345 | J18: 345 | K18: 346 | L18: 346 | M18: 346 | N18: 346 | O18: 348 | P18: 348 | Q18: 349 | R18: 349 | Y18: 1062269468 | Z18: =IF(Y18="","-",VLOOKUP(Y18,'CERT. COR'!$A$4:$E$2200,3,0)) -> 45730 | AA18: =IF(Y18="","-",VLOOKUP(Y18,'CERT. COR'!$A$4:$E$2200,2,0)) -> 81902 | AC18: =IF(AB18="","-",VLOOKUP(AB18,'CERT. COR'!$A$4:$E$2200,3,0)) -> - | AD18: =IF(AB18="","-",VLOOKUP(AB18,'CERT. COR'!$A$4:$E$2200,2,0)) -> - | AE18: =IF(Y18="","-",VLOOKUP(Y18,'CERT. COR'!$A$4:$E$2200,5,0)) -> 100 | AF18: =IF(Y18="","-",VLOOKUP(Y18,'CERT. COR'!$A$4:$E$2200,4,0)) -> 200.9 | AG18: =IF(AB18="","-",VLOOKUP(AB18,'CERT. COR'!$A$4:$E$2200,5,0)) -> - | AH18: =IF(AB18="","-",VLOOKUP(AB18,'CERT. COR'!$A$4:$E$2200,4,0)) -> - | AI18: =IF(T18="","PN","PF") -> PN | AJ18: =IF(AI18="PN",SUM(C18:R18),0) -> 5539 | AK18: =IF(AI18="PF",SUM(C18:T18),0) -> 0
A19: ='plan de data'!A19 -> 17 | B19: ='plan de data'!B19 -> 45764 | C19: 341 | D19: 342 | E19: 344 | F19: 343 | G19: 342 | H19: 342 | I19: 343 | J19: 345 | K19: 345 | L19: 345 | M19: 345 | N19: 344 | O19: 343 | P19: 343 | Q19: 345 | R19: 346 | Y19: 1062265764 | Z19: =IF(Y19="","-",VLOOKUP(Y19,'CERT. COR'!$A$4:$E$2200,3,0)) -> 45730 | AA19: =IF(Y19="","-",VLOOKUP(Y19,'CERT. COR'!$A$4:$E$2200,2,0)) -> 81902 | AC19: =IF(AB19="","-",VLOOKUP(AB19,'CERT. COR'!$A$4:$E$2200,3,0)) -> - | AD19: =IF(AB19="","-",VLOOKUP(AB19,'CERT. COR'!$A$4:$E$2200,2,0)) -> - | AE19: =IF(Y19="","-",VLOOKUP(Y19,'CERT. COR'!$A$4:$E$2200,5,0)) -> 99.6 | AF19: =IF(Y19="","-",VLOOKUP(Y19,'CERT. COR'!$A$4:$E$2200,4,0)) -> 199.3 | AG19: =IF(AB19="","-",VLOOKUP(AB19,'CERT. COR'!$A$4:$E$2200,5,0)) -> - | AH19: =IF(AB19="","-",VLOOKUP(AB19,'CERT. COR'!$A$4:$E$2200,4,0)) -> - | AI19: =IF(T19="","PN","PF") -> PN | AJ19: =IF(AI19="PN",SUM(C19:R19),0) -> 5498 | AK19: =IF(AI19="PF",SUM(C19:T19),0) -> 0
A20: ='plan de data'!A20 -> 18 | B20: ='plan de data'!B20 -> 45770 | C20: 346 | D20: 343 | E20: 343 | F20: 343 | G20: 345 | H20: 344 | I20: 343 | J20: 343 | K20: 345 | L20: 345 | M20: 345 | N20: 345 | O20: 345 | P20: 345 | Q20: 345 | R20: 345 | Y20: 1062265764 | Z20: =IF(Y20="","-",VLOOKUP(Y20,'CERT. COR'!$A$4:$E$2200,3,0)) -> 45730 | AA20: =IF(Y20="","-",VLOOKUP(Y20,'CERT. COR'!$A$4:$E$2200,2,0)) -> 81902 | AC20: =IF(AB20="","-",VLOOKUP(AB20,'CERT. COR'!$A$4:$E$2200,3,0)) -> - | AD20: =IF(AB20="","-",VLOOKUP(AB20,'CERT. COR'!$A$4:$E$2200,2,0)) -> - | AE20: =IF(Y20="","-",VLOOKUP(Y20,'CERT. COR'!$A$4:$E$2200,5,0)) -> 99.6 | AF20: =IF(Y20="","-",VLOOKUP(Y20,'CERT. COR'!$A$4:$E$2200,4,0)) -> 199.3 | AG20: =IF(AB20="","-",VLOOKUP(AB20,'CERT. COR'!$A$4:$E$2200,5,0)) -> - | AH20: =IF(AB20="","-",VLOOKUP(AB20,'CERT. COR'!$A$4:$E$2200,4,0)) -> - | AI20: =IF(T20="","PN","PF") -> PN | AJ20: =IF(AI20="PN",SUM(C20:R20),0) -> 5510 | AK20: =IF(AI20="PF",SUM(C20:T20),0) -> 0
A21: ='plan de data'!A21 -> 19 | B21: ='plan de data'!B21 -> 45771 | C21: 350 | D21: 345 | E21: 341 | F21: 341 | G21: 343 | H21: 341 | I21: 341 | J21: 348 | K21: 341 | L21: 342 | M21: 341 | N21: 342 | O21: 343 | P21: 344 | Q21: 344 | R21: 343 | Y21: 1062269468 | Z21: =IF(Y21="","-",VLOOKUP(Y21,'CERT. COR'!$A$4:$E$2200,3,0)) -> 45730 | AA21: =IF(Y21="","-",VLOOKUP(Y21,'CERT. COR'!$A$4:$E$2200,2,0)) -> 81902 | AC21: =IF(AB21="","-",VLOOKUP(AB21,'CERT. COR'!$A$4:$E$2200,3,0)) -> - | AD21: =IF(AB21="","-",VLOOKUP(AB21,'CERT. COR'!$A$4:$E$2200,2,0)) -> - | AE21: =IF(Y21="","-",VLOOKUP(Y21,'CERT. COR'!$A$4:$E$2200,5,0)) -> 100 | AF21: =IF(Y21="","-",VLOOKUP(Y21,'CERT. COR'!$A$4:$E$2200,4,0)) -> 200.9 | AG21: =IF(AB21="","-",VLOOKUP(AB21,'CERT. COR'!$A$4:$E$2200,5,0)) -> - | AH21: =IF(AB21="","-",VLOOKUP(AB21,'CERT. COR'!$A$4:$E$2200,4,0)) -> - | AI21: =IF(T21="","PN","PF") -> PN | AJ21: =IF(AI21="PN",SUM(C21:R21),0) -> 5490 | AK21: =IF(AI21="PF",SUM(C21:T21),0) -> 0
A22: ='plan de data'!A22 -> 20 | B22: ='plan de data'!B22 -> 45773 | C22: 344 | D22: 345 | E22: 344 | F22: 342 | G22: 343 | H22: 341 | I22: 342 | J22: 343 | K22: 347 | L22: 344 | M22: 346 | N22: 345 | O22: 349 | P22: 342 | Q22: 349 | R22: 349 | Y22: 1062552789 | Z22: =IF(Y22="","-",VLOOKUP(Y22,'CERT. COR'!$A$4:$E$2200,3,0)) -> 45764 | AA22: =IF(Y22="","-",VLOOKUP(Y22,'CERT. COR'!$A$4:$E$2200,2,0)) -> 82245 | AB22: 1062265764 | AC22: =IF(AB22="","-",VLOOKUP(AB22,'CERT. COR'!$A$4:$E$2200,3,0)) -> 45730 | AD22: =IF(AB22="","-",VLOOKUP(AB22,'CERT. COR'!$A$4:$E$2200,2,0)) -> 81902 | AE22: =IF(Y22="","-",VLOOKUP(Y22,'CERT. COR'!$A$4:$E$2200,5,0)) -> 100 | AF22: =IF(Y22="","-",VLOOKUP(Y22,'CERT. COR'!$A$4:$E$2200,4,0)) -> 199.9 | AG22: =IF(AB22="","-",VLOOKUP(AB22,'CERT. COR'!$A$4:$E$2200,5,0)) -> 99.6 | AH22: =IF(AB22="","-",VLOOKUP(AB22,'CERT. COR'!$A$4:$E$2200,4,0)) -> 199.3 | AI22: =IF(T22="","PN","PF") -> PN | AJ22: =IF(AI22="PN",SUM(C22:R22),0) -> 5515 | AK22: =IF(AI22="PF",SUM(C22:T22),0) -> 0
A23: ='plan de data'!A23 -> 21 | B23: ='plan de data'!B23 -> 45776 | C23: 344 | D23: 342 | E23: 347 | F23: 344 | G23: 342 | H23: 342 | I23: 347 | J23: 346 | K23: 348 | L23: 348 | M23: 341 | N23: 346 | O23: 342 | P23: 343 | Q23: 346 | R23: 350 | Y23: 1062269468 | Z23: =IF(Y23="","-",VLOOKUP(Y23,'CERT. COR'!$A$4:$E$2200,3,0)) -> 45730 | AA23: =IF(Y23="","-",VLOOKUP(Y23,'CERT. COR'!$A$4:$E$2200,2,0)) -> 81902 | AB23: 1062279616 | AC23: =IF(AB23="","-",VLOOKUP(AB23,'CERT. COR'!$A$4:$E$2200,3,0)) -> 45716 | AD23: =IF(AB23="","-",VLOOKUP(AB23,'CERT. COR'!$A$4:$E$2200,2,0)) -> 81795 | AE23: =IF(Y23="","-",VLOOKUP(Y23,'CERT. COR'!$A$4:$E$2200,5,0)) -> 100 | AF23: =IF(Y23="","-",VLOOKUP(Y23,'CERT. COR'!$A$4:$E$2200,4,0)) -> 200.9 | AG23: =IF(AB23="","-",VLOOKUP(AB23,'CERT. COR'!$A$4:$E$2200,5,0)) -> 99.9 | AH23: =IF(AB23="","-",VLOOKUP(AB23,'CERT. COR'!$A$4:$E$2200,4,0)) -> 200.9 | AI23: =IF(T23="","PN","PF") -> PN | AJ23: =IF(AI23="PN",SUM(C23:R23),0) -> 5518 | AK23: =IF(AI23="PF",SUM(C23:T23),0) -> 0
A24: ='plan de data'!A24 -> 22 | B24: ='plan de data'!B24 -> 45777 | C24: 345 | D24: 343 | E24: 344 | F24: 344 | G24: 344 | H24: 344 | I24: 347 | J24: 345 | K24: 348 | L24: 349 | M24: 350 | N24: 350 | O24: 345 | P24: 345 | Q24: 353 | R24: 351 | Y24: 1062552789 | Z24: =IF(Y24="","-",VLOOKUP(Y24,'CERT. COR'!$A$4:$E$2200,3,0)) -> 45764 | AA24: =IF(Y24="","-",VLOOKUP(Y24,'CERT. COR'!$A$4:$E$2200,2,0)) -> 82245 | AC24: =IF(AB24="","-",VLOOKUP(AB24,'CERT. COR'!$A$4:$E$2200,3,0)) -> - | AD24: =IF(AB24="","-",VLOOKUP(AB24,'CERT. COR'!$A$4:$E$2200,2,0)) -> - | AE24: =IF(Y24="","-",VLOOKUP(Y24,'CERT. COR'!$A$4:$E$2200,5,0)) -> 100 | AF24: =IF(Y24="","-",VLOOKUP(Y24,'CERT. COR'!$A$4:$E$2200,4,0)) -> 199.9 | AG24: =IF(AB24="","-",VLOOKUP(AB24,'CERT. COR'!$A$4:$E$2200,5,0)) -> - | AH24: =IF(AB24="","-",VLOOKUP(AB24,'CERT. COR'!$A$4:$E$2200,4,0)) -> - | AI24: =IF(T24="","PN","PF") -> PN | AJ24: =IF(AI24="PN",SUM(C24:R24),0) -> 5547 | AK24: =IF(AI24="PF",SUM(C24:T24),0) -> 0
A25: ='plan de data'!A25 -> 23 | B25: ='plan de data'!B25 -> 45780 | C25: 344 | D25: 341 | E25: 342 | F25: 339 | G25: 343 | H25: 342 | I25: 342 | J25: 341 | K25: 343 | L25: 341 | M25: 344 | N25: 344 | O25: 343 | P25: 343 | Q25: 346 | R25: 345 | Y25: 1062279616 | Z25: =IF(Y25="","-",VLOOKUP(Y25,'CERT. COR'!$A$4:$E$2200,3,0)) -> 45716 | AA25: =IF(Y25="","-",VLOOKUP(Y25,'CERT. COR'!$A$4:$E$2200,2,0)) -> 81795 | AC25: =IF(AB25="","-",VLOOKUP(AB25,'CERT. COR'!$A$4:$E$2200,3,0)) -> - | AD25: =IF(AB25="","-",VLOOKUP(AB25,'CERT. COR'!$A$4:$E$2200,2,0)) -> - | AE25: =IF(Y25="","-",VLOOKUP(Y25,'CERT. COR'!$A$4:$E$2200,5,0)) -> 99.9 | AF25: =IF(Y25="","-",VLOOKUP(Y25,'CERT. COR'!$A$4:$E$2200,4,0)) -> 200.9 | AG25: =IF(AB25="","-",VLOOKUP(AB25,'CERT. COR'!$A$4:$E$2200,5,0)) -> - | AH25: =IF(AB25="","-",VLOOKUP(AB25,'CERT. COR'!$A$4:$E$2200,4,0)) -> - | AI25: =IF(T25="","PN","PF") -> PN | AJ25: =IF(AI25="PN",SUM(C25:R25),0) -> 5483 | AK25: =IF(AI25="PF",SUM(C25:T25),0) -> 0
A26: ='plan de data'!A26 -> 24 | B26: ='plan de data'!B26 -> 45782 | C26: 342 | D26: 344 | E26: 345 | F26: 345 | G26: 348 | H26: 352 | I26: 345 | J26: 345 | K26: 346 | L26: 342 | M26: 347 | N26: 347 | O26: 345 | P26: 344 | Q26: 348 | R26: 347 | Y26: 1062552789 | Z26: =IF(Y26="","-",VLOOKUP(Y26,'CERT. COR'!$A$4:$E$2200,3,0)) -> 45764 | AA26: =IF(Y26="","-",VLOOKUP(Y26,'CERT. COR'!$A$4:$E$2200,2,0)) -> 82245 | AC26: =IF(AB26="","-",VLOOKUP(AB26,'CERT. COR'!$A$4:$E$2200,3,0)) -> - | AD26: =IF(AB26="","-",VLOOKUP(AB26,'CERT. COR'!$A$4:$E$2200,2,0)) -> - | AE26: =IF(Y26="","-",VLOOKUP(Y26,'CERT. COR'!$A$4:$E$2200,5,0)) -> 100 | AF26: =IF(Y26="","-",VLOOKUP(Y26,'CERT. COR'!$A$4:$E$2200,4,0)) -> 199.9 | AG26: =IF(AB26="","-",VLOOKUP(AB26,'CERT. COR'!$A$4:$E$2200,5,0)) -> - | AH26: =IF(AB26="","-",VLOOKUP(AB26,'CERT. COR'!$A$4:$E$2200,4,0)) -> - | AI26: =IF(T26="","PN","PF") -> PN | AJ26: =IF(AI26="PN",SUM(C26:R26),0) -> 5532 | AK26: =IF(AI26="PF",SUM(C26:T26),0) -> 0
A27: ='plan de data'!A27 -> 25 | B27: ='plan de data'!B27 -> 45783 | C27: 346 | D27: 344 | E27: 345 | F27: 344 | G27: 348 | H27: 346 | I27: 346 | J27: 346 | K27: 346 | L27: 346 | M27: 345 | N27: 345 | O27: 346 | P27: 346 | Q27: 346 | R27: 347 | Y27: 1062279616 | Z27: =IF(Y27="","-",VLOOKUP(Y27,'CERT. COR'!$A$4:$E$2200,3,0)) -> 45716 | AA27: =IF(Y27="","-",VLOOKUP(Y27,'CERT. COR'!$A$4:$E$2200,2,0)) -> 81795 | AC27: =IF(AB27="","-",VLOOKUP(AB27,'CERT. COR'!$A$4:$E$2200,3,0)) -> - | AD27: =IF(AB27="","-",VLOOKUP(AB27,'CERT. COR'!$A$4:$E$2200,2,0)) -> - | AE27: =IF(Y27="","-",VLOOKUP(Y27,'CERT. COR'!$A$4:$E$2200,5,0)) -> 99.9 | AF27: =IF(Y27="","-",VLOOKUP(Y27,'CERT. COR'!$A$4:$E$2200,4,0)) -> 200.9 | AG27: =IF(AB27="","-",VLOOKUP(AB27,'CERT. COR'!$A$4:$E$2200,5,0)) -> - | AH27: =IF(AB27="","-",VLOOKUP(AB27,'CERT. COR'!$A$4:$E$2200,4,0)) -> - | AI27: =IF(T27="","PN","PF") -> PN | AJ27: =IF(AI27="PN",SUM(C27:R27),0) -> 5532 | AK27: =IF(AI27="PF",SUM(C27:T27),0) -> 0
A28: ='plan de data'!A28 -> 26 | B28: ='plan de data'!B28 -> 45785 | C28: 348 | D28: 344 | E28: 345 | F28: 345 | G28: 345 | H28: 347 | I28: 345 | J28: 345 | K28: 346 | L28: 346 | M28: 348 | N28: 346 | O28: 346 | P28: 348 | Q28: 349 | R28: 346 | Y28: 1062552789 | Z28: =IF(Y28="","-",VLOOKUP(Y28,'CERT. COR'!$A$4:$E$2200,3,0)) -> 45764 | AA28: =IF(Y28="","-",VLOOKUP(Y28,'CERT. COR'!$A$4:$E$2200,2,0)) -> 82245 | AB28: 1062630742 | AC28: =IF(AB28="","-",VLOOKUP(AB28,'CERT. COR'!$A$4:$E$2200,3,0)) -> 45764 | AD28: =IF(AB28="","-",VLOOKUP(AB28,'CERT. COR'!$A$4:$E$2200,2,0)) -> 82245 | AE28: =IF(Y28="","-",VLOOKUP(Y28,'CERT. COR'!$A$4:$E$2200,5,0)) -> 100 | AF28: =IF(Y28="","-",VLOOKUP(Y28,'CERT. COR'!$A$4:$E$2200,4,0)) -> 199.9 | AG28: =IF(AB28="","-",VLOOKUP(AB28,'CERT. COR'!$A$4:$E$2200,5,0)) -> 99.8 | AH28: =IF(AB28="","-",VLOOKUP(AB28,'CERT. COR'!$A$4:$E$2200,4,0)) -> 200.5 | AI28: =IF(T28="","PN","PF") -> PN | AJ28: =IF(AI28="PN",SUM(C28:R28),0) -> 5539 | AK28: =IF(AI28="PF",SUM(C28:T28),0) -> 0
A29: ='plan de data'!A29 -> 27 | B29: ='plan de data'!B29 -> 45786 | C29: 342 | D29: 342 | E29: 346 | F29: 342 | G29: 345 | H29: 345 | I29: 347 | J29: 342 | K29: 342 | L29: 341 | M29: 341 | N29: 342 | O29: 345 | P29: 345 | Q29: 344 | R29: 345 | Y29: 1062279616 | Z29: =IF(Y29="","-",VLOOKUP(Y29,'CERT. COR'!$A$4:$E$2200,3,0)) -> 45716 | AA29: =IF(Y29="","-",VLOOKUP(Y29,'CERT. COR'!$A$4:$E$2200,2,0)) -> 81795 | AC29: =IF(AB29="","-",VLOOKUP(AB29,'CERT. COR'!$A$4:$E$2200,3,0)) -> - | AD29: =IF(AB29="","-",VLOOKUP(AB29,'CERT. COR'!$A$4:$E$2200,2,0)) -> - | AE29: =IF(Y29="","-",VLOOKUP(Y29,'CERT. COR'!$A$4:$E$2200,5,0)) -> 99.9 | AF29: =IF(Y29="","-",VLOOKUP(Y29,'CERT. COR'!$A$4:$E$2200,4,0)) -> 200.9 | AG29: =IF(AB29="","-",VLOOKUP(AB29,'CERT. COR'!$A$4:$E$2200,5,0)) -> - | AH29: =IF(AB29="","-",VLOOKUP(AB29,'CERT. COR'!$A$4:$E$2200,4,0)) -> - | AI29: =IF(T29="","PN","PF") -> PN | AJ29: =IF(AI29="PN",SUM(C29:R29),0) -> 5496 | AK29: =IF(AI29="PF",SUM(C29:T29),0) -> 0
A30: ='plan de data'!A30 -> 28 | B30: ='plan de data'!B30 -> 45789 | C30: 344 | D30: 341 | E30: 343 | F30: 343 | G30: 343 | H30: 345 | I30: 343 | J30: 345 | K30: 345 | L30: 344 | M30: 345 | N30: 343 | O30: 346 | P30: 350 | Q30: 346 | R30: 345 | Y30: 1062630742 | Z30: =IF(Y30="","-",VLOOKUP(Y30,'CERT. COR'!$A$4:$E$2200,3,0)) -> 45764 | AA30: =IF(Y30="","-",VLOOKUP(Y30,'CERT. COR'!$A$4:$E$2200,2,0)) -> 82245 | AC30: =IF(AB30="","-",VLOOKUP(AB30,'CERT. COR'!$A$4:$E$2200,3,0)) -> - | AD30: =IF(AB30="","-",VLOOKUP(AB30,'CERT. COR'!$A$4:$E$2200,2,0)) -> - | AE30: =IF(Y30="","-",VLOOKUP(Y30,'CERT. COR'!$A$4:$E$2200,5,0)) -> 99.8 | AF30: =IF(Y30="","-",VLOOKUP(Y30,'CERT. COR'!$A$4:$E$2200,4,0)) -> 200.5 | AG30: =IF(AB30="","-",VLOOKUP(AB30,'CERT. COR'!$A$4:$E$2200,5,0)) -> - | AH30: =IF(AB30="","-",VLOOKUP(AB30,'CERT. COR'!$A$4:$E$2200,4,0)) -> - | AI30: =IF(T30="","PN","PF") -> PN | AJ30: =IF(AI30="PN",SUM(C30:R30),0) -> 5511 | AK30: =IF(AI30="PF",SUM(C30:T30),0) -> 0
A31: ='plan de data'!A31 -> 29 | B31: ='plan de data'!B31 -> 45796 | C31: 114 | D31: 114 | E31: 113 | F31: 113 | G31: 116 | H31: 116 | I31: 115 | J31: 113 | K31: 115 | L31: 115 | M31: 117 | N31: 119 | O31: 116 | P31: 117 | Q31: 119 | R31: 118 | S31: 115 | T31: 115 | Y31: 1062279616 | Z31: =IF(Y31="","-",VLOOKUP(Y31,'CERT. COR'!$A$4:$E$2200,3,0)) -> 45716 | AA31: =IF(Y31="","-",VLOOKUP(Y31,'CERT. COR'!$A$4:$E$2200,2,0)) -> 81795 | AC31: =IF(AB31="","-",VLOOKUP(AB31,'CERT. COR'!$A$4:$E$2200,3,0)) -> - | AD31: =IF(AB31="","-",VLOOKUP(AB31,'CERT. COR'!$A$4:$E$2200,2,0)) -> - | AE31: =IF(Y31="","-",VLOOKUP(Y31,'CERT. COR'!$A$4:$E$2200,5,0)) -> 99.9 | AF31: =IF(Y31="","-",VLOOKUP(Y31,'CERT. COR'!$A$4:$E$2200,4,0)) -> 200.9 | AG31: =IF(AB31="","-",VLOOKUP(AB31,'CERT. COR'!$A$4:$E$2200,5,0)) -> - | AH31: =IF(AB31="","-",VLOOKUP(AB31,'CERT. COR'!$A$4:$E$2200,4,0)) -> - | AI31: =IF(T31="","PN","PF") -> PF | AJ31: =IF(AI31="PN",SUM(C31:R31),0) -> 0 | AK31: =IF(AI31="PF",SUM(C31:T31),0) -> 2080
A32: ='plan de data'!A32 -> 30 | B32: ='plan de data'!B32 -> 45800 | C32: 114 | D32: 115 | E32: 113 | F32: 113 | G32: 113 | H32: 115 | I32: 114 | J32: 115 | K32: 115 | L32: 115 | M32: 115 | N32: 115 | O32: 116 | P32: 117 | Q32: 116 | R32: 116 | S32: 117 | T32: 117 | Y32: 1062630742 | Z32: =IF(Y32="","-",VLOOKUP(Y32,'CERT. COR'!$A$4:$E$2200,3,0)) -> 45764 | AA32: =IF(Y32="","-",VLOOKUP(Y32,'CERT. COR'!$A$4:$E$2200,2,0)) -> 82245 | AC32: =IF(AB32="","-",VLOOKUP(AB32,'CERT. COR'!$A$4:$E$2200,3,0)) -> - | AD32: =IF(AB32="","-",VLOOKUP(AB32,'CERT. COR'!$A$4:$E$2200,2,0)) -> - | AE32: =IF(Y32="","-",VLOOKUP(Y32,'CERT. COR'!$A$4:$E$2200,5,0)) -> 99.8 | AF32: =IF(Y32="","-",VLOOKUP(Y32,'CERT. COR'!$A$4:$E$2200,4,0)) -> 200.5 | AG32: =IF(AB32="","-",VLOOKUP(AB32,'CERT. COR'!$A$4:$E$2200,5,0)) -> - | AH32: =IF(AB32="","-",VLOOKUP(AB32,'CERT. COR'!$A$4:$E$2200,4,0)) -> - | AI32: =IF(T32="","PN","PF") -> PF | AJ32: =IF(AI32="PN",SUM(C32:R32),0) -> 0 | AK32: =IF(AI32="PF",SUM(C32:T32),0) -> 2071
A33: ='plan de data'!A33 -> 31 | B33: ='plan de data'!B33 -> 45806 | C33: 348 | D33: 349 | E33: 345 | F33: 344 | G33: 349 | H33: 350 | I33: 343 | J33: 343 | K33: 345 | L33: 345 | M33: 345 | N33: 346 | O33: 348 | P33: 350 | Q33: 347 | R33: 346 | Y33: 1062153482 | Z33: =IF(Y33="","-",VLOOKUP(Y33,'CERT. COR'!$A$4:$E$2200,3,0)) -> 45716 | AA33: =IF(Y33="","-",VLOOKUP(Y33,'CERT. COR'!$A$4:$E$2200,2,0)) -> 81795 | AC33: =IF(AB33="","-",VLOOKUP(AB33,'CERT. COR'!$A$4:$E$2200,3,0)) -> - | AD33: =IF(AB33="","-",VLOOKUP(AB33,'CERT. COR'!$A$4:$E$2200,2,0)) -> - | AE33: =IF(Y33="","-",VLOOKUP(Y33,'CERT. COR'!$A$4:$E$2200,5,0)) -> 99.7 | AF33: =IF(Y33="","-",VLOOKUP(Y33,'CERT. COR'!$A$4:$E$2200,4,0)) -> 198.7 | AG33: =IF(AB33="","-",VLOOKUP(AB33,'CERT. COR'!$A$4:$E$2200,5,0)) -> - | AH33: =IF(AB33="","-",VLOOKUP(AB33,'CERT. COR'!$A$4:$E$2200,4,0)) -> - | AI33: =IF(T33="","PN","PF") -> PN | AJ33: =IF(AI33="PN",SUM(C33:R33),0) -> 5543 | AK33: =IF(AI33="PF",SUM(C33:T33),0) -> 0
A34: ='plan de data'!A34 -> 32 | B34: ='plan de data'!B34 -> 45812 | C34: 352 | D34: 345 | E34: 344 | F34: 344 | G34: 344 | H34: 346 | I34: 344 | J34: 340 | K34: 346 | L34: 344 | M34: 343 | N34: 344 | O34: 350 | P34: 347 | Q34: 346 | R34: 345 | Y34: 1062153482 | Z34: =IF(Y34="","-",VLOOKUP(Y34,'CERT. COR'!$A$4:$E$2200,3,0)) -> 45716 | AA34: =IF(Y34="","-",VLOOKUP(Y34,'CERT. COR'!$A$4:$E$2200,2,0)) -> 81795 | AC34: =IF(AB34="","-",VLOOKUP(AB34,'CERT. COR'!$A$4:$E$2200,3,0)) -> - | AD34: =IF(AB34="","-",VLOOKUP(AB34,'CERT. COR'!$A$4:$E$2200,2,0)) -> - | AE34: =IF(Y34="","-",VLOOKUP(Y34,'CERT. COR'!$A$4:$E$2200,5,0)) -> 99.7 | AF34: =IF(Y34="","-",VLOOKUP(Y34,'CERT. COR'!$A$4:$E$2200,4,0)) -> 198.7 | AG34: =IF(AB34="","-",VLOOKUP(AB34,'CERT. COR'!$A$4:$E$2200,5,0)) -> - | AH34: =IF(AB34="","-",VLOOKUP(AB34,'CERT. COR'!$A$4:$E$2200,4,0)) -> - | AI34: =IF(T34="","PN","PF") -> PN | AJ34: =IF(AI34="PN",SUM(C34:R34),0) -> 5524 | AK34: =IF(AI34="PF",SUM(C34:T34),0) -> 0
A35: ='plan de data'!A35 -> 33 | B35: ='plan de data'!B35 -> 45814 | C35: 116 | D35: 117 | E35: 115 | F35: 114 | G35: 115 | H35: 114 | I35: 116 | J35: 116 | K35: 116 | L35: 115 | M35: 115 | N35: 115 | O35: 116 | P35: 117 | Q35: 115 | R35: 116 | S35: 117 | T35: 117 | Y35: 1062630742 | Z35: =IF(Y35="","-",VLOOKUP(Y35,'CERT. COR'!$A$4:$E$2200,3,0)) -> 45764 | AA35: =IF(Y35="","-",VLOOKUP(Y35,'CERT. COR'!$A$4:$E$2200,2,0)) -> 82245 | AC35: =IF(AB35="","-",VLOOKUP(AB35,'CERT. COR'!$A$4:$E$2200,3,0)) -> - | AD35: =IF(AB35="","-",VLOOKUP(AB35,'CERT. COR'!$A$4:$E$2200,2,0)) -> - | AE35: =IF(Y35="","-",VLOOKUP(Y35,'CERT. COR'!$A$4:$E$2200,5,0)) -> 99.8 | AF35: =IF(Y35="","-",VLOOKUP(Y35,'CERT. COR'!$A$4:$E$2200,4,0)) -> 200.5 | AG35: =IF(AB35="","-",VLOOKUP(AB35,'CERT. COR'!$A$4:$E$2200,5,0)) -> - | AH35: =IF(AB35="","-",VLOOKUP(AB35,'CERT. COR'!$A$4:$E$2200,4,0)) -> - | AI35: =IF(T35="","PN","PF") -> PF | AJ35: =IF(AI35="PN",SUM(C35:R35),0) -> 0 | AK35: =IF(AI35="PF",SUM(C35:T35),0) -> 2082
A36: ='plan de data'!A36 -> 34 | B36: ='plan de data'!B36 -> 45818 | C36: 345 | D36: 341 | E36: 342 | F36: 341 | G36: 344 | H36: 343 | I36: 339 | J36: 341 | K36: 342 | L36: 342 | M36: 342 | N36: 341 | O36: 343 | P36: 344 | Q36: 343 | R36: 344 | Y36: 1062153482 | Z36: =IF(Y36="","-",VLOOKUP(Y36,'CERT. COR'!$A$4:$E$2200,3,0)) -> 45716 | AA36: =IF(Y36="","-",VLOOKUP(Y36,'CERT. COR'!$A$4:$E$2200,2,0)) -> 81795 | AC36: =IF(AB36="","-",VLOOKUP(AB36,'CERT. COR'!$A$4:$E$2200,3,0)) -> - | AD36: =IF(AB36="","-",VLOOKUP(AB36,'CERT. COR'!$A$4:$E$2200,2,0)) -> - | AE36: =IF(Y36="","-",VLOOKUP(Y36,'CERT. COR'!$A$4:$E$2200,5,0)) -> 99.7 | AF36: =IF(Y36="","-",VLOOKUP(Y36,'CERT. COR'!$A$4:$E$2200,4,0)) -> 198.7 | AG36: =IF(AB36="","-",VLOOKUP(AB36,'CERT. COR'!$A$4:$E$2200,5,0)) -> - | AH36: =IF(AB36="","-",VLOOKUP(AB36,'CERT. COR'!$A$4:$E$2200,4,0)) -> - | AI36: =IF(T36="","PN","PF") -> PN | AJ36: =IF(AI36="PN",SUM(C36:R36),0) -> 5477 | AK36: =IF(AI36="PF",SUM(C36:T36),0) -> 0
A37: ='plan de data'!A37 -> 35 | B37: ='plan de data'!B37 -> 45822 | C37: 342 | D37: 341 | E37: 344 | F37: 345 | G37: 341 | H37: 346 | I37: 343 | J37: 344 | K37: 345 | L37: 345 | M37: 346 | N37: 344 | O37: 347 | P37: 350 | Q37: 348 | R37: 347 | Y37: 1062153482 | Z37: =IF(Y37="","-",VLOOKUP(Y37,'CERT. COR'!$A$4:$E$2200,3,0)) -> 45716 | AA37: =IF(Y37="","-",VLOOKUP(Y37,'CERT. COR'!$A$4:$E$2200,2,0)) -> 81795 | AB37: 1062266407 | AC37: =IF(AB37="","-",VLOOKUP(AB37,'CERT. COR'!$A$4:$E$2200,3,0)) -> 45716 | AD37: =IF(AB37="","-",VLOOKUP(AB37,'CERT. COR'!$A$4:$E$2200,2,0)) -> 81795 | AE37: =IF(Y37="","-",VLOOKUP(Y37,'CERT. COR'!$A$4:$E$2200,5,0)) -> 99.7 | AF37: =IF(Y37="","-",VLOOKUP(Y37,'CERT. COR'!$A$4:$E$2200,4,0)) -> 198.7 | AG37: =IF(AB37="","-",VLOOKUP(AB37,'CERT. COR'!$A$4:$E$2200,5,0)) -> 100 | AH37: =IF(AB37="","-",VLOOKUP(AB37,'CERT. COR'!$A$4:$E$2200,4,0)) -> 201.5 | AI37: =IF(T37="","PN","PF") -> PN | AJ37: =IF(AI37="PN",SUM(C37:R37),0) -> 5518 | AK37: =IF(AI37="PF",SUM(C37:T37),0) -> 0
A38: ='plan de data'!A38 -> 36 | B38: ='plan de data'!B38 -> 45825 | C38: 117 | D38: 115 | E38: 115 | F38: 114 | G38: 115 | H38: 114 | I38: 115 | J38: 115 | K38: 115 | L38: 116 | M38: 116 | N38: 116 | O38: 117 | P38: 117 | Q38: 117 | R38: 116 | S38: 117 | T38: 118 | Y38: 1062266407 | Z38: =IF(Y38="","-",VLOOKUP(Y38,'CERT. COR'!$A$4:$E$2200,3,0)) -> 45716 | AA38: =IF(Y38="","-",VLOOKUP(Y38,'CERT. COR'!$A$4:$E$2200,2,0)) -> 81795 | AC38: =IF(AB38="","-",VLOOKUP(AB38,'CERT. COR'!$A$4:$E$2200,3,0)) -> - | AD38: =IF(AB38="","-",VLOOKUP(AB38,'CERT. COR'!$A$4:$E$2200,2,0)) -> - | AE38: =IF(Y38="","-",VLOOKUP(Y38,'CERT. COR'!$A$4:$E$2200,5,0)) -> 100 | AF38: =IF(Y38="","-",VLOOKUP(Y38,'CERT. COR'!$A$4:$E$2200,4,0)) -> 201.5 | AG38: =IF(AB38="","-",VLOOKUP(AB38,'CERT. COR'!$A$4:$E$2200,5,0)) -> - | AH38: =IF(AB38="","-",VLOOKUP(AB38,'CERT. COR'!$A$4:$E$2200,4,0)) -> - | AI38: =IF(T38="","PN","PF") -> PF | AJ38: =IF(AI38="PN",SUM(C38:R38),0) -> 0 | AK38: =IF(AI38="PF",SUM(C38:T38),0) -> 2085
A39: ='plan de data'!A39 -> 37 | B39: ='plan de data'!B39 -> 45827 | C39: 348 | D39: 347 | E39: 345 | F39: 345 | G39: 345 | H39: 345 | I39: 346 | J39: 345 | K39: 346 | L39: 344 | M39: 344 | N39: 344 | O39: 345 | P39: 344 | Q39: 346 | R39: 345 | Y39: 1062266407 | Z39: =IF(Y39="","-",VLOOKUP(Y39,'CERT. COR'!$A$4:$E$2200,3,0)) -> 45716 | AA39: =IF(Y39="","-",VLOOKUP(Y39,'CERT. COR'!$A$4:$E$2200,2,0)) -> 81795 | AC39: =IF(AB39="","-",VLOOKUP(AB39,'CERT. COR'!$A$4:$E$2200,3,0)) -> - | AD39: =IF(AB39="","-",VLOOKUP(AB39,'CERT. COR'!$A$4:$E$2200,2,0)) -> - | AE39: =IF(Y39="","-",VLOOKUP(Y39,'CERT. COR'!$A$4:$E$2200,5,0)) -> 100 | AF39: =IF(Y39="","-",VLOOKUP(Y39,'CERT. COR'!$A$4:$E$2200,4,0)) -> 201.5 | AG39: =IF(AB39="","-",VLOOKUP(AB39,'CERT. COR'!$A$4:$E$2200,5,0)) -> - | AH39: =IF(AB39="","-",VLOOKUP(AB39,'CERT. COR'!$A$4:$E$2200,4,0)) -> - | AI39: =IF(T39="","PN","PF") -> PN | AJ39: =IF(AI39="PN",SUM(C39:R39),0) -> 5524 | AK39: =IF(AI39="PF",SUM(C39:T39),0) -> 0
A40: ='plan de data'!A40 -> 38 | B40: ='plan de data'!B40 -> 45833 | C40: 350 | D40: 345 | E40: 344 | F40: 343 | G40: 345 | H40: 346 | I40: 345 | J40: 345 | K40: 345 | L40: 345 | M40: 347 | N40: 344 | O40: 348 | P40: 345 | Q40: 348 | R40: 348 | Y40: 1062266407 | Z40: =IF(Y40="","-",VLOOKUP(Y40,'CERT. COR'!$A$4:$E$2200,3,0)) -> 45716 | AA40: =IF(Y40="","-",VLOOKUP(Y40,'CERT. COR'!$A$4:$E$2200,2,0)) -> 81795 | AC40: =IF(AB40="","-",VLOOKUP(AB40,'CERT. COR'!$A$4:$E$2200,3,0)) -> - | AD40: =IF(AB40="","-",VLOOKUP(AB40,'CERT. COR'!$A$4:$E$2200,2,0)) -> - | AE40: =IF(Y40="","-",VLOOKUP(Y40,'CERT. COR'!$A$4:$E$2200,5,0)) -> 100 | AF40: =IF(Y40="","-",VLOOKUP(Y40,'CERT. COR'!$A$4:$E$2200,4,0)) -> 201.5 | AG40: =IF(AB40="","-",VLOOKUP(AB40,'CERT. COR'!$A$4:$E$2200,5,0)) -> - | AH40: =IF(AB40="","-",VLOOKUP(AB40,'CERT. COR'!$A$4:$E$2200,4,0)) -> - | AI40: =IF(T40="","PN","PF") -> PN | AJ40: =IF(AI40="PN",SUM(C40:R40),0) -> 5533 | AK40: =IF(AI40="PF",SUM(C40:T40),0) -> 0
...

Sheet CERT. COR
A3: numero da bobina | B3: cert. | C3: data fab | D3: elasticidade | E3: area
A4: 1062072197 | B4: 81985 | C4: 45737 | D4: 197.1 | E4: 100
A5: 1062076102 | B5: 81985 | C5: 45737 | D5: 198.8 | E5: 100
A6: 1062393027 | B6: 81985 | C6: 45737 | D6: 201.7 | E6: 99.5
A7: 1062437954 | B7: 81985 | C7: 45737 | D7: 201.6 | E7: 100
A8: 1061132929 | B8: 109623 | C8: 45539 | D8: 198 | E8: 100
A9: 1062153482 | B9: 81795 | C9: 45716 | D9: 198.7 | E9: 99.7
A10: 1062265533 | B10: 81795 | C10: 45716 | D10: 192.3 | E10: 100
A11: 1062266407 | B11: 81795 | C11: 45716 | D11: 201.5 | E11: 100
A12: 1062279616 | B12: 81795 | C12: 45716 | D12: 200.9 | E12: 99.9
A13: 1062149086 | B13: 81902 | C13: 45730 | D13: 197.9 | E13: 99.7
A14: 1062265764 | B14: 81902 | C14: 45730 | D14: 199.3 | E14: 99.6
A15: 1062269468 | B15: 81902 | C15: 45730 | D15: 200.9 | E15: 100
... A31: 1062870714 | B31: 83027 | C31: 45873 | D31: 194.8 | E31: 100

Sheet PF
L1: CONTROLE DE QUALIDADE | AD1: registro nº: | AH1: FTQ- | AJ1: 1 | AM1: - | AN1: 83 | BD1: SC-6 | BM1: Normal | BU1: P
L2: Cliente: | P2: =VLOOKUP($AN$1,'plan de data'!$A$3:$AF$289,32,0) -> CONSÓRCIO NOVA ETE - PARQUE NOVO MUNDO | AD2: Local: | AG2: VIANA - ES | AW2: PN-001 | BD2: SC-10 | BM2: Especial
L3: Obra: | P3: =VLOOKUP($AN$1,'plan de data'!$A$3:$AG$289,33,0) -> ETE - PARQUE NOVO MUNDO | AW3: PF-001 | BD3: SC-14
A5: filtre "X" | B5: Data de fabricação: | I5: Descrição do tanque: | AD5: Linha de fabricação:
B6: =VLOOKUP($AN$1,'plan de data'!$A$3:$B$189,2,0) -> 45909 | I6: =VLOOKUP($AN$1,'plan de data'!$A$3:$AH$189,34,0) -> REATORES NEREDA | AD6: Sistema: | AG6: SC-10 | AJ6: Mesa: | AM6: =VLOOKUP(AN1,'plan de data'!A3:$AE$500,31,0) -> PF-001 | AR6: marcar com "X" para definir quantidade de formas:
A7: x
A8: =IF($CC$9>0,"X",0) -> X | B8: Nº da forma : | G8: =IF(G9=0,"",AR8) -> 1 | J8: =IF(J9=0,"",AU8) | M8: =IF(M9=0,"",AX8) | P8: =IF(P9=0,"",BA8) | S8: =IF(S9=0,"",BD8) | V8: =IF(V9=0,"",BG8) | Y8: =IF(Y9=0,"",BJ8) | AB8: =IF(AB9=0,"",BM8) | AE8: =IF(AE9=0,"",BP8) | AH8: =IF(AH9=0,"",BS8) | AK8: =IF(AK9=0,"",BV8) | AN8: =IF(AN9=0,"",BY8) | AR8: 1 | AU8: 2 | AX8: 3 | BA8: 4 | BD8: 5 | BG8: 6 | BJ8: 7 | BM8: 8 | BP8: 9 | BS8: 10 | BV8: 11 | BY8: 12 | CC8: total
A9: =IF($CC$9>0,"X",0) -> X | B9: Nº do painel: | G9: =VLOOKUP($AN$1,'plan de data'!$A$3:$V$189,4,0) -> PF-373 | J9: =VLOOKUP($AN$1,'plan de data'!$A$3:$V$189,6,0) -> 0 | M9: =VLOOKUP($AN$1,'plan de data'!$A$3:$V$189,8,0) -> 0 | P9: =VLOOKUP($AN$1,'plan de data'!$A$3:$V$189,10,0) -> 0 | S9: =VLOOKUP($AN$1,'plan de data'!$A$3:$V$189,12,0) -> 0 | V9: =VLOOKUP($AN$1,'plan de data'!$A$3:$V$189,14,0) -> 0 | Y9: =VLOOKUP($AN$1,'plan de data'!$A$3:$V$189,16,0) -> 0 | AB9: =VLOOKUP($AN$1,'plan de data'!$A$3:$V$189,18,0) -> 0 | AE9: =VLOOKUP($AN$1,'plan de data'!$A$3:$V$189,20,0) -> 0 | AH9: =VLOOKUP($AN$1,'plan de data'!$A$3:$AA$189,22,0) -> 0 | AK9: =VLOOKUP($AN$1,'plan de data'!$A$3:$AA$189,24,0) -> 0 | AN9: =VLOOKUP($AN$1,'plan de data'!$A$3:$AA$189,26,0) -> 0 | AR9: X | AU9: X | AX9: X | BA9: x | BD9: x | BG9: x | BJ9: x | BM9: X | CC9: =COUNTIF(AR9:CA9,"X") -> 8
B10: Tipo de Inserto: | G10: =IF(G9="","",VLOOKUP($AN$1,'plan de data'!$A$3:$V$189,5,0)) -> PF | AE10: =VLOOKUP($AN$1,'plan de data'!$A$3:$V$189,21,0) -> 0 | AH10: =VLOOKUP($AN$1,'plan de data'!$A$3:$V$189,21,0) -> 0 | AK10: =VLOOKUP($AN$1,'plan de data'!$A$3:$V$189,21,0) -> 0 | AN10: =VLOOKUP($AN$1,'plan de data'!$A$3:$V$189,21,0) -> 0
A11: =IF($CC$9>0,"X",0) -> X | B11: Tipo do painel: | G11: =IF(G10="","",IF(G10="P","Normal","Especial")) -> Especial
A12: =IF($CC$9>0,"X",0) -> X
A13: =IF($CC$14>0,"X",0) -> 0 | B13: Nº da forma : | G13: =IF(AR14="X",AR13,0) -> 0 | J13: =IF(AU14="X",AU13,0) -> 0 | M13: =IF(AX14="X",AX13,0) -> 0 | P13: =IF(BA14="X",BA13,0) -> 0 | S13: =IF(BD14="X",BD13,0) -> 0 | V13: =IF(BG14="X",BG13,0) -> 0 | Y13: =IF(BJ14="X",BJ13,0) -> 0 | AB13: =IF(BM14="X",BM13,0) -> 0 | AE13: =IF(BP14="X",BP13,0) -> 0 | AH13: =IF(BS14="X",BS13,0) -> 0 | AK13: =IF(BV14="X",BV13,0) -> 0 | AN13: =IF(BY14="X",BY13,0) -> 0 | AR13: 13 | AU13: 14 | AX13: 15 | BA13: 16 | BD13: 17 | BG13: 18 | BJ13: 19 | BM13: 20 | BP13: 21 | BS13: 22 | BV13: 23 | BY13: 24 | CC13: total
A14: =IF($CC$14>0,"X",0) -> 0 | B14: Nº do painel: | CC14: =COUNTIF(AR14:CA14,"X") -> 0
A15: =IF($CC$14>0,"X",0) -> 0 | B15: Tipo do painel:
A16: =IF($CC$14>0,"X",0) -> 0
A17: =IF($CC$18>0,"X",0) -> 0 | B17: Nº da forma : | G17: =IF(AR18="X",AR17,0) -> 0 | J17: =IF(AU18="X",AU17,0) -> 0 | M17: =IF(AX18="X",AX17,0) -> 0 | P17: =IF(BA18="X",BA17,0) -> 0 | S17: =IF(BD18="X",BD17,0) -> 0 | V17: =IF(BG18="X",BG17,0) -> 0 | Y17: =IF(BJ18="X",BJ17,0) -> 0 | AB17: =IF(BM18="X",BM17,0) -> 0 | AE17: =IF(BP18="X",BP17,0) -> 0 | AH17: =IF(BS18="X",BS17,0) -> 0 | AK17: =IF(BV18="X",BV17,0) -> 0 | AN17: =IF(BY18="X",BY17,0) -> 0 | AR17: 25 | AU17: 26 | AX17: 27 | BA17: 28 | BD17: 29 | BG17: 30 | BJ17: 31 | BM17: 32 | BP17: 33 | BS17: 34 | BV17: 35 | BY17: 36 | CC17: total
A18: =IF($CC$18>0,"X",0) -> 0 | B18: Nº do painel: | CC18: =COUNTIF(AR18:CA18,"X") -> 0
A19: =IF($CC$18>0,"X",0) -> 0 | B19: Tipo do painel:
B21: INSPEÇÃO NAS FORMAS | AE21: CONFORMIDADE:
C22: A geometria dos formas está em conformidade com os projetos; | AG22: X | AH22: Jsim | AM22: Lnão
C23: As formas estão limpas e com desmoldante ; | AE23: painel não conforme:
C24: As bainhas estão com dimensionais e posicionamento conforme projeto;
B25: NÃO CONFORMIDADE: | AE25: DECISÃO:
AF26: rejeitar | AJ26: corrigir | AN26: aceitar
B28: INSPEÇÃO NAS ARMADURAS | N28: Certificado (s): | AE28: CONFORMIDADE:
B29: Certificado (s): | G29: 916100/25 - 9139854/25 - 9142107/25 - 9142134/25 | Y29: As armaduras estão em conformidade com os requisitos definidos em projeto; | AG29: X | AH29: Jsim | AM29: Lnão
B30: 79369/25 - 914000/25 - 9108767/25 - 9108804/25 - 9142457/25 - 9108839/25 | AE30: painel não conforme:
B31: 9123538/25 - 9133306/25 - 9140467/25 - 9194366/25 - 9205525/25 - 9194366/25
B32: 9212242/25 - 9188331/25 - 921005/25 - 9142143/25 - 9209652/2025 - 9188331/25
B33: 9201005/25 - 9205525/25 - 9209652/25 - 9212242/25
B34: NÃO CONFORMIDADE: | AE34: DECISÃO:
AF35: rejeitar | AJ35: corrigir | AN35: aceitar
B37: INSPEÇÃO NOS ACESSÓRIOS | AE37: CONFORMIDADE: | AV37: área: | AY37: E: | CQ37: área: | CT37: E:
B38: =IF(A38="X","Embutidos FTK e chapas inox estão com dimensionais e posições conforme pré-estabelecido","Embutidos FTK estão com dimensionais e posições conforme pré-estabelecido") -> Embutidos FTK estão com dimensionais e posições conforme pré-estabelecido | AG38: X | AH38: Jsim | AM38: Lnão | AV38: =VLOOKUP($B$46,CA!$Y$3:$AF$188,8,0) -> 197.9 | AY38: =VLOOKUP($B$46,CA!$Y$3:$AF$188,7,0) -> 99.7 | CQ38: =IF(AV38=0,AY46,AV38) -> 197.9 | CT38: =IF(AY38=0,AY45,AY38) -> 99.7
B39: As chapas e aço CA-25 de aterramento estão com dimensionais e posições conf. Projeto | AE39: painel não conforme:
B40: Obs. As placas com chapas de aterramento tem na identificação a letra "I"
B41: NÃO CONFORMIDADE: | AE41: DECISÃO: | BA41: 197.7
AF42: rejeitar | AJ42: corrigir | AN42: aceitar | BA42: 99.9
B44: CABOS DE PRÉ-ESFORÇO | M44: BITOLA: | P44: 12.7 | S44: mm | V44: FORNECEDOR: | AB44: BELGO BEKAERT | AU44: dados passados para João Romba para calculo de alogamento teórico
B45: Nº DA BOBINA: | M45: DATA DE FABRICAÇÃO: | V45: Nº DA BOBINA: | AG45: DATA DE FABRICAÇÃO: | AV45: E= | AY45: - | BD45: KN/mm2
...

Sheet PN1
L1: CONTROLE DE QUALIDADE | AD1: registro nº: | AH1: FTQ- | AJ1: 1 | AM1: - | AN1: 56 | BD1: SC-6 | BM1: Normal | BU1: P
L2: Cliente: | P2: =VLOOKUP($AN$1,'plan de data'!$A$3:$AF$289,32,0) -> CONSÓRCIO NOVA ETE - PARQUE NOVO MUNDO | AD2: Local: | AG2: VIANA - ES | AW2: PN-001 | BD2: SC-10 | BM2: Especial
L3: Obra: | P3: =VLOOKUP($AN$1,'plan de data'!$A$3:$AG$289,33,0) -> ETE - PARQUE NOVO MUNDO | AW3: PF-001 | BD3: SC-14
A5: filtre "X" | B5: Data de fabricação: | I5: Descrição do tanque: | AD5: Linha de fabricação:
B6: =VLOOKUP($AN$1,'plan de data'!$A$3:$B$189,2,0) -> 45868 | I6: =VLOOKUP($AN$1,'plan de data'!$A$3:$AH$189,34,0) -> REATORES NEREDA | AD6: Sistema: | AG6: SC-10 | AJ6: Mesa: | AM6: =VLOOKUP(AN1,'plan de data'!A3:$AE$500,31,0) -> PN-002 | AR6: marcar com "X" para definir quantidade de formas:
A7: x
A8: =IF($CC$9>0,"X",0) -> X | B8: Nº da forma : | G8: =IF(G9=0,"",AR8) | J8: =IF(J9=0,"",AU8) -> 2 | M8: =IF(M9=0,"",AX8) -> 3 | P8: =IF(P9=0,"",BA8) -> 4 | S8: =IF(S9=0,"",BD8) -> 5 | V8: =IF(V9=0,"",BG8) -> 6 | Y8: =IF(Y9=0,"",BJ8) -> 7 | AB8: =IF(AB9=0,"",BM8) -> 8 | AE8: =IF(AE9=0,"",BP8) | AH8: =IF(AH9=0,"",BS8) | AK8: =IF(AK9=0,"",BV8) | AN8: =IF(AN9=0,"",BY8) | AR8: 1 | AU8: 2 | AX8: 3 | BA8: 4 | BD8: 5 | BG8: 6 | BJ8: 7 | BM8: 8 | BP8: 9 | BS8: 10 | BV8: 11 | BY8: 12 | CC8: total
A9: =IF($CC$9>0,"X",0) -> X | B9: Nº do painel: | G9: =VLOOKUP($AN$1,'plan de data'!$A$3:$V$189,4,0) -> 0 | J9: =VLOOKUP($AN$1,'plan de data'!$A$3:$V$189,6,0) -> PN-354 | M9: =VLOOKUP($AN$1,'plan de data'!$A$3:$V$189,8,0) -> PN-355 | P9: =VLOOKUP($AN$1,'plan de data'!$A$3:$V$189,10,0) -> PN-356 | S9: =VLOOKUP($AN$1,'plan de data'!$A$3:$V$189,12,0) -> PN-357 | V9: =VLOOKUP($AN$1,'plan de data'!$A$3:$V$189,14,0) -> PN-358 | Y9: =VLOOKUP($AN$1,'plan de data'!$A$3:$V$189,16,0) -> PN-359 | AB9: =VLOOKUP($AN$1,'plan de data'!$A$3:$V$189,18,0) -> PN-360 | AE9: =VLOOKUP($AN$1,'plan de data'!$A$3:$V$189,20,0) -> 0 | AH9: =VLOOKUP($AN$1,'plan de data'!$A$3:$AA$189,22,0) -> 0 | AK9: =VLOOKUP($AN$1,'plan de data'!$A$3:$AA$189,24,0) -> 0 | AN9: =VLOOKUP($AN$1,'plan de data'!$A$3:$AA$189,26,0) -> 0 | AR9: X | AU9: X | AX9: X | BA9: x | BD9: x | BG9: x | BJ9: x | BM9: X | CC9: =COUNTIF(AR9:CA9,"X") -> 8
