Workbook

Sheet CAPA DAS OBRAS
B1: NEREDA | C1: PROJETO | D1: EXECUÇÃO (concretado) | F1: ACABAMENTO (PRONTO) | H1: TRANSPORTE (EM VIAGEM)
C2: NEREDA | D2: QTDE | E2: % | F2: QTDE | G2: % | H2: QTDE | I2: % | P2: 1 concretagem nereda | Q2: dias | R2: placa/dia
B3: TOTAL DE PLACAS NORMAIS | C3: =COUNTIF(' CADASTRO'!$F$2:$F$745,"PN") -> 637 | D3: =SUMIFS(' CADASTRO'!$D$2:$D$745,' CADASTRO'!$F$2:$F$745,"PN") -> 637 | E3: =D3/C3 -> 1 | F3: =SUMIFS(' CADASTRO'!$T$2:$T$745,' CADASTRO'!$F$2:$F$745,"PN") -> 616 | G3: =F3/C3 -> 0.96703297 | H3: =SUMIFS(' CADASTRO'!$X$2:$X$745,' CADASTRO'!$F$2:$F$745,"PN") -> 623 | I3: =H3/C3 -> 0.97802198 | L3: tota roduzido | M3: total transportado | N3: lotação do estoque | P3: 45733 | Q3: =P4-P3 -> 274 | R3: =L4/Q3 -> 3.8759124
B4: TOTAL PLACAS ESPECIAIS | C4: =COUNTIF(' CADASTRO'!$F$2:$F$745,"PE") -> 83 | D4: =SUMIFS(' CADASTRO'!$D$2:$D$745,' CADASTRO'!$F$2:$F$745,"PE") -> 83 | E4: =D4/C4 -> 1 | F4: =SUMIFS(' CADASTRO'!$T$2:$T$745,' CADASTRO'!$F$2:$F$745,"PE") -> 82 | G4: =F4/C4 -> 0.98795181 | H4: =SUMIFS(' CADASTRO'!$X$2:$X$745,' CADASTRO'!$F$2:$F$745,"PE") -> 82 | I4: =H4/C4 -> 0.98795181 | L4: =D6+D14+D21 -> 1062 | M4: =H6+H14+H21 -> 927 | N4: =L4-M4 -> 135 | P4: =TODAY() -> 46007
B5: TOTAL DE PLACAS FECHO | C5: =COUNTIF(' CADASTRO'!$F$2:$F$745,"PF") -> 24 | D5: =SUMIFS(' CADASTRO'!$D$2:$D$745,' CADASTRO'!$F$2:$F$745,"PF") -> 24 | E5: =D5/C5 -> 1 | F5: =SUMIFS(' CADASTRO'!$T$2:$T$745,' CADASTRO'!$F$2:$F$745,"PF") -> 23 | G5: =F5/C5 -> 0.95833333 | H5: =SUMIFS(' CADASTRO'!$X$2:$X$745,' CADASTRO'!$F$2:$F$745,"PF") -> 23 | I5: =H5/C5 -> 0.95833333
B6: TOTAIS | C6: =SUM(C3:C5) -> 744 | D6: =SUM(D3:D5) -> 744 | E6: =D6/C6 -> 1 | F6: =SUM(F3:F5) -> 721 | H6: =SUM(H3:H5) -> 728
B9: PRIMARIO | C9: PROJETO | D9: EXECUÇÃO (concretado) | F9: ACABAMENTO (PRONTO) | H9: TRANSPORTE (EM VIAGEM)
C10: PRIMARIO | D10: QTDE | E10: % | F10: QTDE | G10: % | H10: QTDE | I10: %
B11: TOTAL DE PLACAS NORMAIS | C11: =COUNTIF(' CADASTRO'!$F$746:$F$893,"PN") -> 104 | D11: ='CALCULOS '!D4 -> 104 | E11: =D11/C11 -> 1 | F11: ='CALCULOS '!E4 -> 57 | G11: =F11/C11 -> 0.54807692 | H11: ='CALCULOS '!F4 -> 52 | I11: =H11/C11 -> 0.5
B12: TOTAL PLACAS ESPECIAIS | C12: =SUM('CALCULOS '!B5:$B$10) -> 38 | D12: =SUM('CALCULOS '!D5:$D$10) -> 38 | E12: =D12/C12 -> 1 | F12: =SUM('CALCULOS '!$E$5:$E$10) -> 16 | G12: =F12/C12 -> 0.42105263 | H12: =SUM('CALCULOS '!$F$5:$F$10) -> 12 | I12: =H12/C12 -> 0.31578947
B13: TOTAL DE PLACAS FECHO | C13: =COUNTIF(' CADASTRO'!$F$746:$F$894,"PF") -> 6 | D13: ='CALCULOS '!D3 -> 6 | E13: =D13/C13 -> 1 | F13: ='CALCULOS '!E3 -> 1 | G13: =F13/C13 -> 0.16666667 | H13: ='CALCULOS '!F3 -> 0 | I13: =H13/C13 -> 0
B14: TOTAIS | C14: =SUM(C11:C13) -> 148 | D14: =SUM(D11:D13) -> 148 | E14: =D14/C14 -> 1 | F14: =SUM(F11:F13) -> 74 | H14: =SUM(H11:H13) -> 64
B16: TANQUE AERADOR | C16: PROJETO | D16: EXECUÇÃO (concretado) | F16: ACABAMENTO (PRONTO) | H16: TRANSPORTE (EM VIAGEM)
C17: AERADOR | D17: QTDE | E17: % | F17: QTDE | G17: % | H17: QTDE | I17: %
B18: TOTAL DE PLACAS NORMAIS (PN) | C18: ='CALCULOS '!B21 -> 229 | D18: ='CALCULOS '!D21 -> 129 | E18: =D18/C18 -> 0.56331878 | F18: ='CALCULOS '!$E$21 -> 102 | G18: =F18/D18 -> 0.79069767 | H18: ='CALCULOS '!F21 -> 100 | I18: =H18/C18 -> 0.43668122
B19: TOTAL DE PLACAS (PE E PNI) | C19: =SUM('CALCULOS '!$B$22:$B$27) -> 47 | D19: =SUM('CALCULOS '!D22:D27) -> 36 | E19: =D19/C19 -> 0.76595745 | F19: =SUM('CALCULOS '!$E$22:$E$27) -> 31 | G19: =F19/D19 -> 0.86111111 | H19: =SUM('CALCULOS '!$F$22:$F$27) -> 31 | I19: =H19/C19 -> 0.65957447
B20: TOTAL DE PLACAS FECHO (PF) | C20: ='CALCULOS '!B20 -> 6 | D20: ='CALCULOS '!D20 -> 5 | E20: =D20/C20 -> 0.83333333 | F20: ='CALCULOS '!E20 -> 4 | G20: =IF(D20=0,0,F20/D20) -> 0.8 | H20: ='CALCULOS '!F20 -> 4 | I20: =H20/C20 -> 0.66666667
B21: TOTAIS | C21: =SUM(C18:C20) -> 282 | D21: =SUM(D18:D20) -> 170 | E21: =D21/C21 -> 0.60283688 | F21: =SUM(F18:F20) -> 137 | H21: =SUM(H18:H20) -> 135
F23: =F21-F20 -> 133

Sheet  CADASTRO
A1: ITEM | B1: data | C1: se concretada marque "x" | D1: se concretado | E1: IDENT. TANQUE | F1: PLACA | J1: TIPO | K1: #3/8-1620X1620 | L1: #3/8-1120X1120 | M1: #3/8-1200X1200 | N1: #3/8-530X530 | O1: #3/8 X150X150 | P1: A DEFINIR | Q1: DESCRIÇÃO DE CHAPAS OU NÃO | R1: data do acabamento finalizado | S1: pista | T1: se | U1: DATA TRANS. | V1: PLACA CARRETA | W1: NF: | X1: SE TRANSPORTADO | Y1: altura de escora | Z1: obs: | AA1: MES ACABAMENTO
A2: 1 | B2: 45797 | C2: 29 | D2: =IF(B2>0,1,"") -> 1 | E2: REATOR 1 | F2: PF | G2: - | H2: 01 | I2: =_xlfn.CONCAT(F2,G2,H2) -> PF-01 | J2: PF | K2: =IF(J2="","SEM #CH",VLOOKUP(J2,#REF!,2,0)) -> #REF! | L2: =IF(J2="","SEM #CH",VLOOKUP(J2,#REF!,3,0)) -> #REF! | M2: =IF(J2="","SEM #CH",VLOOKUP(J2,#REF!,4,0)) -> #REF! | N2: =IF(J2="","SEM #CH",VLOOKUP(J2,#REF!,5,0)) -> #REF! | O2: =IF(J2="","SEM #CH",VLOOKUP(J2,#REF!,6,0)) -> #REF! | P2: =IF(J2="","SEM #CH",VLOOKUP(J2,#REF!,7,0)) -> #REF! | Q2: =VLOOKUP(J2,'p1'!$B$2:$C$30,2,0) -> SEM CHAPA | R2: 45799 | S2: PN-001 | T2: =IF(R2="",0,1) -> 1 | U2: 45824 | V2: - | W2: 2387 | X2: =IF(U2>0,1,"") -> 1 | AA2: =TEXT(R2,"mmm/aaaa") -> mai/2025
A3: 2 | B3: 45733 | C3: 1 | D3: =IF(B3>0,1,"") -> 1 | E3: REATOR 1 | F3: PN | G3: - | H3: 02 | I3: =_xlfn.CONCAT(F3,G3,H3) -> PN-02 | J3: P | K3: =IF(J3="","SEM #CH",VLOOKUP(J3,#REF!,2,0)) -> #REF! | L3: =IF(J3="","SEM #CH",VLOOKUP(J3,#REF!,3,0)) -> #REF! | M3: =IF(J3="","SEM #CH",VLOOKUP(J3,#REF!,4,0)) -> #REF! | N3: =IF(J3="","SEM #CH",VLOOKUP(J3,#REF!,5,0)) -> #REF! | O3: =IF(J3="","SEM #CH",VLOOKUP(J3,#REF!,6,0)) -> #REF! | P3: =IF(J3="","SEM #CH",VLOOKUP(J3,#REF!,7,0)) -> #REF! | Q3: =VLOOKUP(J3,'p1'!$B$2:$C$30,2,0) -> NÃO TEM CHAPA | R3: 45738 | S3: PN-001 | T3: =IF(R3="",0,1) -> 1 | U3: 45818 | V3: - | W3: 2373 | X3: =IF(U3>0,1,"") -> 1 | AA3: =TEXT(R3,"mmm/aaaa") -> mar/2025
A4: 3 | B4: 45733 | C4: 1 | D4: =IF(B4>0,1,"") -> 1 | E4: REATOR 1 | F4: PN | G4: - | H4: 03 | I4: =_xlfn.CONCAT(F4,G4,H4) -> PN-03 | J4: P | K4: =IF(J4="","SEM #CH",VLOOKUP(J4,#REF!,2,0)) -> #REF! | L4: =IF(J4="","SEM #CH",VLOOKUP(J4,#REF!,3,0)) -> #REF! | M4: =IF(J4="","SEM #CH",VLOOKUP(J4,#REF!,4,0)) -> #REF! | N4: =IF(J4="","SEM #CH",VLOOKUP(J4,#REF!,5,0)) -> #REF! | O4: =IF(J4="","SEM #CH",VLOOKUP(J4,#REF!,6,0)) -> #REF! | P4: =IF(J4="","SEM #CH",VLOOKUP(J4,#REF!,7,0)) -> #REF! | Q4: =VLOOKUP(J4,'p1'!$B$2:$C$30,2,0) -> NÃO TEM CHAPA | R4: 45738 | S4: PN-001 | T4: =IF(R4="",0,1) -> 1 | U4: 45818 | V4: - | W4: 2373 | X4: =IF(U4>0,1,"") -> 1 | AA4: =TEXT(R4,"mmm/aaaa") -> mar/2025
A5: 4 | B5: 45733 | C5: 1 | D5: =IF(B5>0,1,"") -> 1 | E5: REATOR 1 | F5: PN | G5: - | H5: 04 | I5: =_xlfn.CONCAT(F5,G5,H5) -> PN-04 | J5: P | K5: =IF(J5="","SEM #CH",VLOOKUP(J5,#REF!,2,0)) -> #REF! | L5: =IF(J5="","SEM #CH",VLOOKUP(J5,#REF!,3,0)) -> #REF! | M5: =IF(J5="","SEM #CH",VLOOKUP(J5,#REF!,4,0)) -> #REF! | N5: =IF(J5="","SEM #CH",VLOOKUP(J5,#REF!,5,0)) -> #REF! | O5: =IF(J5="","SEM #CH",VLOOKUP(J5,#REF!,6,0)) -> #REF! | P5: =IF(J5="","SEM #CH",VLOOKUP(J5,#REF!,7,0)) -> #REF! | Q5: =VLOOKUP(J5,'p1'!$B$2:$C$30,2,0) -> NÃO TEM CHAPA | R5: 45743 | S5: PN-001 | T5: =IF(R5="",0,1) -> 1 | U5: 45824 | V5: - | W5: 2387 | X5: =IF(U5>0,1,"") -> 1 | AA5: =TEXT(R5,"mmm/aaaa") -> mar/2025
A6: 5 | B6: 45733 | C6: 1 | D6: =IF(B6>0,1,"") -> 1 | E6: REATOR 1 | F6: PN | G6: - | H6: 05 | I6: =_xlfn.CONCAT(F6,G6,H6) -> PN-05 | J6: P | K6: =IF(J6="","SEM #CH",VLOOKUP(J6,#REF!,2,0)) -> #REF! | L6: =IF(J6="","SEM #CH",VLOOKUP(J6,#REF!,3,0)) -> #REF! | M6: =IF(J6="","SEM #CH",VLOOKUP(J6,#REF!,4,0)) -> #REF! | N6: =IF(J6="","SEM #CH",VLOOKUP(J6,#REF!,5,0)) -> #REF! | O6: =IF(J6="","SEM #CH",VLOOKUP(J6,#REF!,6,0)) -> #REF! | P6: =IF(J6="","SEM #CH",VLOOKUP(J6,#REF!,7,0)) -> #REF! | Q6: =VLOOKUP(J6,'p1'!$B$2:$C$30,2,0) -> NÃO TEM CHAPA | R6: 45741 | S6: PN-001 | T6: =IF(R6="",0,1) -> 1 | U6: 45818 | V6: - | W6: 2373 | X6: =IF(U6>0,1,"") -> 1 | AA6: =TEXT(R6,"mmm/aaaa") -> mar/2025
A7: 6 | B7: 45733 | C7: 1 | D7: =IF(B7>0,1,"") -> 1 | E7: REATOR 1 | F7: PN | G7: - | H7: 06 | I7: =_xlfn.CONCAT(F7,G7,H7) -> PN-06 | J7: P | K7: =IF(J7="","SEM #CH",VLOOKUP(J7,#REF!,2,0)) -> #REF! | L7: =IF(J7="","SEM #CH",VLOOKUP(J7,#REF!,3,0)) -> #REF! | M7: =IF(J7="","SEM #CH",VLOOKUP(J7,#REF!,4,0)) -> #REF! | N7: =IF(J7="","SEM #CH",VLOOKUP(J7,#REF!,5,0)) -> #REF! | O7: =IF(J7="","SEM #CH",VLOOKUP(J7,#REF!,6,0)) -> #REF! | P7: =IF(J7="","SEM #CH",VLOOKUP(J7,#REF!,7,0)) -> #REF! | Q7: =VLOOKUP(J7,'p1'!$B$2:$C$30,2,0) -> NÃO TEM CHAPA | R7: 45741 | S7: PN-001 | T7: =IF(R7="",0,1) -> 1 | U7: 45818 | V7: - | W7: 2372 | X7: =IF(U7>0,1,"") -> 1 | AA7: =TEXT(R7,"mmm/aaaa") -> mar/2025
A8: 7 | B8: 45806 | C8: 31 | D8: =IF(B8>0,1,"") -> 1 | E8: REATOR 1 | F8: PE | G8: - | H8: 07 | I8: =_xlfn.CONCAT(F8,G8,H8) -> PE-07 | J8: T2 | K8: =IF(J8="","SEM #CH",VLOOKUP(J8,#REF!,2,0)) -> #REF! | L8: =IF(J8="","SEM #CH",VLOOKUP(J8,#REF!,3,0)) -> #REF! | M8: =IF(J8="","SEM #CH",VLOOKUP(J8,#REF!,4,0)) -> #REF! | N8: =IF(J8="","SEM #CH",VLOOKUP(J8,#REF!,5,0)) -> #REF! | O8: =IF(J8="","SEM #CH",VLOOKUP(J8,#REF!,6,0)) -> #REF! | P8: =IF(J8="","SEM #CH",VLOOKUP(J8,#REF!,7,0)) -> #REF! | Q8: =VLOOKUP(J8,'p1'!$B$2:$C$30,2,0) -> #3/8-1315X1315 | R8: 45812 | S8: PN-001 | T8: =IF(R8="",0,1) -> 1 | U8: 45821 | V8: - | W8: 2383 | X8: =IF(U8>0,1,"") -> 1 | AA8: =TEXT(R8,"mmm/aaaa") -> jun/2025
A9: 8 | B9: 45806 | C9: 31 | D9: =IF(B9>0,1,"") -> 1 | E9: REATOR 1 | F9: PE | G9: - | H9: 08 | I9: =_xlfn.CONCAT(F9,G9,H9) -> PE-08 | J9: T1 | K9: =IF(J9="","SEM #CH",VLOOKUP(J9,#REF!,2,0)) -> #REF! | L9: =IF(J9="","SEM #CH",VLOOKUP(J9,#REF!,3,0)) -> #REF! | M9: =IF(J9="","SEM #CH",VLOOKUP(J9,#REF!,4,0)) -> #REF! | N9: =IF(J9="","SEM #CH",VLOOKUP(J9,#REF!,5,0)) -> #REF! | O9: =IF(J9="","SEM #CH",VLOOKUP(J9,#REF!,6,0)) -> #REF! | P9: =IF(J9="","SEM #CH",VLOOKUP(J9,#REF!,7,0)) -> #REF! | Q9: =VLOOKUP(J9,'p1'!$B$2:$C$30,2,0) -> #3/8-1620X1620 | R9: 45813 | S9: PN-001 | T9: =IF(R9="",0,1) -> 1 | U9: 45814 | V9: IOO3D34 | W9: 2367 | X9: =IF(U9>0,1,"") -> 1 | AA9: =TEXT(R9,"mmm/aaaa") -> jun/2025
A10: 9 | B10: 45806 | C10: 31 | D10: =IF(B10>0,1,"") -> 1 | E10: REATOR 1 | F10: PE | G10: - | H10: 09 | I10: =_xlfn.CONCAT(F10,G10,H10) -> PE-09 | J10: T3 | K10: =IF(J10="","SEM #CH",VLOOKUP(J10,#REF!,2,0)) -> #REF! | L10: =IF(J10="","SEM #CH",VLOOKUP(J10,#REF!,3,0)) -> #REF! | M10: =IF(J10="","SEM #CH",VLOOKUP(J10,#REF!,4,0)) -> #REF! | N10: =IF(J10="","SEM #CH",VLOOKUP(J10,#REF!,5,0)) -> #REF! | O10: =IF(J10="","SEM #CH",VLOOKUP(J10,#REF!,6,0)) -> #REF! | P10: =IF(J10="","SEM #CH",VLOOKUP(J10,#REF!,7,0)) -> #REF! | Q10: =VLOOKUP(J10,'p1'!$B$2:$C$30,2,0) -> #3/8-1200X1200 | R10: 45810 | S10: PN-001 | T10: =IF(R10="",0,1) -> 1 | U10: 45817 | V10: - | W10: 2370 | X10: =IF(U10>0,1,"") -> 1 | AA10: =TEXT(R10,"mmm/aaaa") -> jun/2025
A11: 10 | B11: 45733 | C11: 1 | D11: =IF(B11>0,1,"") -> 1 | E11: REATOR 1 | F11: PN | G11: - | H11: 10 | I11: =_xlfn.CONCAT(F11,G11,H11) -> PN-10 | J11: P | K11: =IF(J11="","SEM #CH",VLOOKUP(J11,#REF!,2,0)) -> #REF! | L11: =IF(J11="","SEM #CH",VLOOKUP(J11,#REF!,3,0)) -> #REF! | M11: =IF(J11="","SEM #CH",VLOOKUP(J11,#REF!,4,0)) -> #REF! | N11: =IF(J11="","SEM #CH",VLOOKUP(J11,#REF!,5,0)) -> #REF! | O11: =IF(J11="","SEM #CH",VLOOKUP(J11,#REF!,6,0)) -> #REF! | P11: =IF(J11="","SEM #CH",VLOOKUP(J11,#REF!,7,0)) -> #REF! | Q11: =VLOOKUP(J11,'p1'!$B$2:$C$30,2,0) -> NÃO TEM CHAPA | R11: 45740 | S11: PN-001 | T11: =IF(R11="",0,1) -> 1 | U11: 45818 | V11: - | W11: 2372 | X11: =IF(U11>0,1,"") -> 1 | AA11: =TEXT(R11,"mmm/aaaa") -> mar/2025
A12: 11 | B12: 45733 | C12: 1 | D12: =IF(B12>0,1,"") -> 1 | E12: REATOR 1 | F12: PN | G12: - | H12: 11 | I12: =_xlfn.CONCAT(F12,G12,H12) -> PN-11 | J12: P | K12: =IF(J12="","SEM #CH",VLOOKUP(J12,#REF!,2,0)) -> #REF! | L12: =IF(J12="","SEM #CH",VLOOKUP(J12,#REF!,3,0)) -> #REF! | M12: =IF(J12="","SEM #CH",VLOOKUP(J12,#REF!,4,0)) -> #REF! | N12: =IF(J12="","SEM #CH",VLOOKUP(J12,#REF!,5,0)) -> #REF! | O12: =IF(J12="","SEM #CH",VLOOKUP(J12,#REF!,6,0)) -> #REF! | P12: =IF(J12="","SEM #CH",VLOOKUP(J12,#REF!,7,0)) -> #REF! | Q12: =VLOOKUP(J12,'p1'!$B$2:$C$30,2,0) -> NÃO TEM CHAPA | R12: 45740 | S12: PN-001 | T12: =IF(R12="",0,1) -> 1 | U12: 45759 | V12: - | W12: 2373 | X12: =IF(U12>0,1,"") -> 1 | AA12: =TEXT(R12,"mmm/aaaa") -> mar/2025
A13: 12 | B13: 45741 | C13: 2 | D13: =IF(B13>0,1,"") -> 1 | E13: REATOR 1 | F13: PN | G13: - | H13: 12 | I13: =_xlfn.CONCAT(F13,G13,H13) -> PN-12 | J13: P | K13: =IF(J13="","SEM #CH",VLOOKUP(J13,#REF!,2,0)) -> #REF! | L13: =IF(J13="","SEM #CH",VLOOKUP(J13,#REF!,3,0)) -> #REF! | M13: =IF(J13="","SEM #CH",VLOOKUP(J13,#REF!,4,0)) -> #REF! | N13: =IF(J13="","SEM #CH",VLOOKUP(J13,#REF!,5,0)) -> #REF! | O13: =IF(J13="","SEM #CH",VLOOKUP(J13,#REF!,6,0)) -> #REF! | P13: =IF(J13="","SEM #CH",VLOOKUP(J13,#REF!,7,0)) -> #REF! | Q13: =VLOOKUP(J13,'p1'!$B$2:$C$30,2,0) -> NÃO TEM CHAPA | R13: 45743 | S13: PN-001 | T13: =IF(R13="",0,1) -> 1 | U13: 45831 | V13: - | W13: 2405 | X13: =IF(U13>0,1,"") -> 1 | AA13: =TEXT(R13,"mmm/aaaa") -> mar/2025
... A99: 98 | B99: 45757 | C99: 12 | D99: =IF(B99>0,1,"") -> 1 | E99: REATOR 2 | F99: PN | G99: - | H99: 98 | I99: =_xlfn.CONCAT(F99,G99,H99) -> PN-98 | J99: P | K99: =IF(J99="","SEM #CH",VLOOKUP(J99,#REF!,2,0)) -> #REF! | L99: =IF(J99="","SEM #CH",VLOOKUP(J99,#REF!,3,0)) -> #REF! | M99: =IF(J99="","SEM #CH",VLOOKUP(J99,#REF!,4,0)) -> #REF! | N99: =IF(J99="","SEM #CH",VLOOKUP(J99,#REF!,5,0)) -> #REF! | O99: =IF(J99="","SEM #CH",VLOOKUP(J99,#REF!,6,0)) -> #REF! | P99: =IF(J99="","SEM #CH",VLOOKUP(J99,#REF!,7,0)) -> #REF! | Q99: =VLOOKUP(J99,'p1'!$B$2:$C$30,2,0) -> NÃO TEM CHAPA | R99: 45769 | S99: PN-001 | T99: =IF(R99="",0,1) -> 1 | U99: 45820 | V99: - | W99: 2382 | X99: =IF(U99>0,1,"") -> 1 | AA99: =TEXT(R99,"mmm/aaaa") -> abr/2025
A100: 99 | B100: 45758 | C100: 13 | D100: =IF(B100>0,1,"") -> 1 | E100: REATOR 2 | F100: PN | G100: - | H100: 99 | I100: =_xlfn.CONCAT(F100,G100,H100) -> PN-99 | J100: P | K100: =IF(J100="","SEM #CH",VLOOKUP(J100,#REF!,2,0)) -> #REF! | L100: =IF(J100="","SEM #CH",VLOOKUP(J100,#REF!,3,0)) -> #REF! | M100: =IF(J100="","SEM #CH",VLOOKUP(J100,#REF!,4,0)) -> #REF! | N100: =IF(J100="","SEM #CH",VLOOKUP(J100,#REF!,5,0)) -> #REF! | O100: =IF(J100="","SEM #CH",VLOOKUP(J100,#REF!,6,0)) -> #REF! | P100: =IF(J100="","SEM #CH",VLOOKUP(J100,#REF!,7,0)) -> #REF! | Q100: =VLOOKUP(J100,'p1'!$B$2:$C$30,2,0) -> NÃO TEM CHAPA | R100: 45887 | S100: PN-001 | T100: =IF(R100="",0,1) -> 1 | U100: 45887 | W100: 2480 | X100: =IF(U100>0,1,"") -> 1 | AA100: =TEXT(R100,"mmm/aaaa") -> ago/2025
A101: 100 | B101: 45758 | C101: 13 | D101: =IF(B101>0,1,"") -> 1 | E101: REATOR 2 | F101: PN | G101: - | H101: 100 | I101: =_xlfn.CONCAT(F101,G101,H101) -> PN-100 | J101: P | K101: =IF(J101="","SEM #CH",VLOOKUP(J101,#REF!,2,0)) -> #REF! | L101: =IF(J101="","SEM #CH",VLOOKUP(J101,#REF!,3,0)) -> #REF! | M101: =IF(J101="","SEM #CH",VLOOKUP(J101,#REF!,4,0)) -> #REF! | N101: =IF(J101="","SEM #CH",VLOOKUP(J101,#REF!,5,0)) -> #REF! | O101: =IF(J101="","SEM #CH",VLOOKUP(J101,#REF!,6,0)) -> #REF! | P101: =IF(J101="","SEM #CH",VLOOKUP(J101,#REF!,7,0)) -> #REF! | Q101: =VLOOKUP(J101,'p1'!$B$2:$C$30,2,0) -> NÃO TEM CHAPA | R101: 45852 | S101: PN-001 | T101: =IF(R101="",0,1) -> 1 | U101: 45852 | V101: - | W101: 2443 | X101: =IF(U101>0,1,"") -> 1 | AA101: =TEXT(R101,"mmm/aaaa") -> jul/2025
A102: 101 | B102: 45812 | C102: 32 | D102: =IF(B102>0,1,"") -> 1 | E102: REATOR 2 | F102: PE | G102: - | H102: 101 | I102: =_xlfn.CONCAT(F102,G102,H102) -> PE-101 | J102: T2 | K102: =IF(J102="","SEM #CH",VLOOKUP(J102,#REF!,2,0)) -> #REF! | L102: =IF(J102="","SEM #CH",VLOOKUP(J102,#REF!,3,0)) -> #REF! | M102: =IF(J102="","SEM #CH",VLOOKUP(J102,#REF!,4,0)) -> #REF! | N102: =IF(J102="","SEM #CH",VLOOKUP(J102,#REF!,5,0)) -> #REF! | O102: =IF(J102="","SEM #CH",VLOOKUP(J102,#REF!,6,0)) -> #REF! | P102: =IF(J102="","SEM #CH",VLOOKUP(J102,#REF!,7,0)) -> #REF! | Q102: =VLOOKUP(J102,'p1'!$B$2:$C$30,2,0) -> #3/8-1315X1315 | R102: 45821 | S102: PN-001 | T102: =IF(R102="",0,1) -> 1 | U102: 45835 | V102: - | W102: 2422 | X102: =IF(U102>0,1,"") -> 1 | AA102: =TEXT(R102,"mmm/aaaa") -> jun/2025
A103: 102 | B103: 45758 | C103: 13 | D103: =IF(B103>0,1,"") -> 1 | E103: REATOR 2 | F103: PN | G103: - | H103: 102 | I103: =_xlfn.CONCAT(F103,G103,H103) -> PN-102 | J103: P | K103: =IF(J103="","SEM #CH",VLOOKUP(J103,#REF!,2,0)) -> #REF! | L103: =IF(J103="","SEM #CH",VLOOKUP(J103,#REF!,3,0)) -> #REF! | M103: =IF(J103="","SEM #CH",VLOOKUP(J103,#REF!,4,0)) -> #REF! | N103: =IF(J103="","SEM #CH",VLOOKUP(J103,#REF!,5,0)) -> #REF! | O103: =IF(J103="","SEM #CH",VLOOKUP(J103,#REF!,6,0)) -> #REF! | P103: =IF(J103="","SEM #CH",VLOOKUP(J103,#REF!,7,0)) -> #REF! | Q103: =VLOOKUP(J103,'p1'!$B$2:$C$30,2,0) -> NÃO TEM CHAPA | R103: 45849 | S103: PN-001 | T103: =IF(R103="",0,1) -> 1 | U103: 45852 | V103: - | W103: 2443 | X103: =IF(U103>0,1,"") -> 1 | AA103: =TEXT(R103,"mmm/aaaa") -> jul/2025
A104: 103 | B104: 45758 | C104: 13 | D104: =IF(B104>0,1,"") -> 1 | E104: REATOR 2 | F104: PN | G104: - | H104: 103 | I104: =_xlfn.CONCAT(F104,G104,H104) -> PN-103 | J104: P | K104: =IF(J104="","SEM #CH",VLOOKUP(J104,#REF!,2,0)) -> #REF! | L104: =IF(J104="","SEM #CH",VLOOKUP(J104,#REF!,3,0)) -> #REF! | M104: =IF(J104="","SEM #CH",VLOOKUP(J104,#REF!,4,0)) -> #REF! | N104: =IF(J104="","SEM #CH",VLOOKUP(J104,#REF!,5,0)) -> #REF! | O104: =IF(J104="","SEM #CH",VLOOKUP(J104,#REF!,6,0)) -> #REF! | P104: =IF(J104="","SEM #CH",VLOOKUP(J104,#REF!,7,0)) -> #REF! | Q104: =VLOOKUP(J104,'p1'!$B$2:$C$30,2,0) -> NÃO TEM CHAPA | R104: 45827 | S104: PN-001 | T104: =IF(R104="",0,1) -> 1 | U104: 45835 | V104: - | W104: 2422 | X104: =IF(U104>0,1,"") -> 1 | AA104: =TEXT(R104,"mmm/aaaa") -> jun/2025
A105: 104 | B105: 45758 | C105: 13 | D105: =IF(B105>0,1,"") -> 1 | E105: REATOR 2 | F105: PN | G105: - | H105: 104 | I105: =_xlfn.CONCAT(F105,G105,H105) -> PN-104 | J105: P | K105: =IF(J105="","SEM #CH",VLOOKUP(J105,#REF!,2,0)) -> #REF! | L105: =IF(J105="","SEM #CH",VLOOKUP(J105,#REF!,3,0)) -> #REF! | M105: =IF(J105="","SEM #CH",VLOOKUP(J105,#REF!,4,0)) -> #REF! | N105: =IF(J105="","SEM #CH",VLOOKUP(J105,#REF!,5,0)) -> #REF! | O105: =IF(J105="","SEM #CH",VLOOKUP(J105,#REF!,6,0)) -> #REF! | P105: =IF(J105="","SEM #CH",VLOOKUP(J105,#REF!,7,0)) -> #REF! | Q105: =VLOOKUP(J105,'p1'!$B$2:$C$30,2,0) -> NÃO TEM CHAPA | R105: 45791 | S105: PN-001 | T105: =IF(R105="",0,1) -> 1 | U105: 45854 | V105: - | W105: 2445 | X105: =IF(U105>0,1,"") -> 1 | AA105: =TEXT(R105,"mmm/aaaa") -> mai/2025
A106: 105 | B106: 45758 | C106: 13 | D106: =IF(B106>0,1,"") -> 1 | E106: REATOR 2 | F106: PN | G106: - | H106: 105 | I106: =_xlfn.CONCAT(F106,G106,H106) -> PN-105 | J106: P | K106: =IF(J106="","SEM #CH",VLOOKUP(J106,#REF!,2,0)) -> #REF! | L106: =IF(J106="","SEM #CH",VLOOKUP(J106,#REF!,3,0)) -> #REF! | M106: =IF(J106="","SEM #CH",VLOOKUP(J106,#REF!,4,0)) -> #REF! | N106: =IF(J106="","SEM #CH",VLOOKUP(J106,#REF!,5,0)) -> #REF! | O106: =IF(J106="","SEM #CH",VLOOKUP(J106,#REF!,6,0)) -> #REF! | P106: =IF(J106="","SEM #CH",VLOOKUP(J106,#REF!,7,0)) -> #REF! | Q106: =VLOOKUP(J106,'p1'!$B$2:$C$30,2,0) -> NÃO TEM CHAPA | R106: 45769 | S106: PN-001 | T106: =IF(R106="",0,1) -> 1 | U106: 45854 | V106: - | W106: 2448 | X106: =IF(U106>0,1,"") -> 1 | AA106: =TEXT(R106,"mmm/aaaa") -> abr/2025
A107: 106 | B107: 45758 | C107: 13 | D107: =IF(B107>0,1,"") -> 1 | E107: REATOR 2 | F107: PN | G107: - | H107: 106 | I107: =_xlfn.CONCAT(F107,G107,H107) -> PN-106 | J107: P | K107: =IF(J107="","SEM #CH",VLOOKUP(J107,#REF!,2,0)) -> #REF! | L107: =IF(J107="","SEM #CH",VLOOKUP(J107,#REF!,3,0)) -> #REF! | M107: =IF(J107="","SEM #CH",VLOOKUP(J107,#REF!,4,0)) -> #REF! | N107: =IF(J107="","SEM #CH",VLOOKUP(J107,#REF!,5,0)) -> #REF! | O107: =IF(J107="","SEM #CH",VLOOKUP(J107,#REF!,6,0)) -> #REF! | P107: =IF(J107="","SEM #CH",VLOOKUP(J107,#REF!,7,0)) -> #REF! | Q107: =VLOOKUP(J107,'p1'!$B$2:$C$30,2,0) -> NÃO TEM CHAPA | R107: 45769 | S107: PN-001 | T107: =IF(R107="",0,1) -> 1 | U107: 45856 | V107: - | W107: 2452 | X107: =IF(U107>0,1,"") -> 1 | AA107: =TEXT(R107,"mmm/aaaa") -> abr/2025
A108: 107 | B108: 45762 | C108: 15 | D108: =IF(B108>0,1,"") -> 1 | E108: REATOR 2 | F108: PN | G108: - | H108: 107 | I108: =_xlfn.CONCAT(F108,G108,H108) -> PN-107 | J108: P | K108: =IF(J108="","SEM #CH",VLOOKUP(J108,#REF!,2,0)) -> #REF! | L108: =IF(J108="","SEM #CH",VLOOKUP(J108,#REF!,3,0)) -> #REF! | M108: =IF(J108="","SEM #CH",VLOOKUP(J108,#REF!,4,0)) -> #REF! | N108: =IF(J108="","SEM #CH",VLOOKUP(J108,#REF!,5,0)) -> #REF! | O108: =IF(J108="","SEM #CH",VLOOKUP(J108,#REF!,6,0)) -> #REF! | P108: =IF(J108="","SEM #CH",VLOOKUP(J108,#REF!,7,0)) -> #REF! | Q108: =VLOOKUP(J108,'p1'!$B$2:$C$30,2,0) -> NÃO TEM CHAPA | R108: 45803 | S108: PN-002 | T108: =IF(R108="",0,1) -> 1 | U108: 45828 | V108: - | W108: 2398 | X108: =IF(U108>0,1,"") -> 1 | AA108: =TEXT(R108,"mmm/aaaa") -> mai/2025
A109: 108 | B109: 45761 | C109: 14 | D109: =IF(B109>0,1,"") -> 1 | E109: REATOR 2 | F109: PN | G109: - | H109: 108 | I109: =_xlfn.CONCAT(F109,G109,H109) -> PN-108 | J109: P | K109: =IF(J109="","SEM #CH",VLOOKUP(J109,#REF!,2,0)) -> #REF! | L109: =IF(J109="","SEM #CH",VLOOKUP(J109,#REF!,3,0)) -> #REF! | M109: =IF(J109="","SEM #CH",VLOOKUP(J109,#REF!,4,0)) -> #REF! | N109: =IF(J109="","SEM #CH",VLOOKUP(J109,#REF!,5,0)) -> #REF! | O109: =IF(J109="","SEM #CH",VLOOKUP(J109,#REF!,6,0)) -> #REF! | P109: =IF(J109="","SEM #CH",VLOOKUP(J109,#REF!,7,0)) -> #REF! | Q109: =VLOOKUP(J109,'p1'!$B$2:$C$30,2,0) -> NÃO TEM CHAPA | R109: 45773 | S109: PN-001 | T109: =IF(R109="",0,1) -> 1 | U109: 45848 | V109: qrk3e99 | W109: 2440 | X109: =IF(U109>0,1,"") -> 1 | AA109: =TEXT(R109,"mmm/aaaa") -> abr/2025
A110: 109 | B110: 45761 | C110: 14 | D110: =IF(B110>0,1,"") -> 1 | E110: REATOR 2 | F110: PN | G110: - | H110: 109 | I110: =_xlfn.CONCAT(F110,G110,H110) -> PN-109 | J110: P | K110: =IF(J110="","SEM #CH",VLOOKUP(J110,#REF!,2,0)) -> #REF! | L110: =IF(J110="","SEM #CH",VLOOKUP(J110,#REF!,3,0)) -> #REF! | M110: =IF(J110="","SEM #CH",VLOOKUP(J110,#REF!,4,0)) -> #REF! | N110: =IF(J110="","SEM #CH",VLOOKUP(J110,#REF!,5,0)) -> #REF! | O110: =IF(J110="","SEM #CH",VLOOKUP(J110,#REF!,6,0)) -> #REF! | P110: =IF(J110="","SEM #CH",VLOOKUP(J110,#REF!,7,0)) -> #REF! | Q110: =VLOOKUP(J110,'p1'!$B$2:$C$30,2,0) -> NÃO TEM CHAPA | R110: 45864 | S110: PN-001 | T110: =IF(R110="",0,1) -> 1 | U110: 45881 | V110: SEV8E92 | W110: 2467 | X110: =IF(U110>0,1,"") -> 1 | AA110: =TEXT(R110,"mmm/aaaa") -> jul/2025
A111: 110 | B111: 45761 | C111: 14 | D111: =IF(B111>0,1,"") -> 1 | E111: REATOR 2 | F111: PN | G111: - | H111: 110 | I111: =_xlfn.CONCAT(F111,G111,H111) -> PN-110 | J111: P | K111: =IF(J111="","SEM #CH",VLOOKUP(J111,#REF!,2,0)) -> #REF! | L111: =IF(J111="","SEM #CH",VLOOKUP(J111,#REF!,3,0)) -> #REF! | M111: =IF(J111="","SEM #CH",VLOOKUP(J111,#REF!,4,0)) -> #REF! | N111: =IF(J111="","SEM #CH",VLOOKUP(J111,#REF!,5,0)) -> #REF! | O111: =IF(J111="","SEM #CH",VLOOKUP(J111,#REF!,6,0)) -> #REF! | P111: =IF(J111="","SEM #CH",VLOOKUP(J111,#REF!,7,0)) -> #REF! | Q111: =VLOOKUP(J111,'p1'!$B$2:$C$30,2,0) -> NÃO TEM CHAPA | R111: 45864 | S111: PN-001 | T111: =IF(R111="",0,1) -> 1 | U111: 45881 | V111: - | W111: 2468 | X111: =IF(U111>0,1,"") -> 1 | AA111: =TEXT(R111,"mmm/aaaa") -> jul/2025
A112: 111 | B112: 45761 | C112: 14 | D112: =IF(B112>0,1,"") -> 1 | E112: REATOR 2 | F112: PN | G112: - | H112: 111 | I112: =_xlfn.CONCAT(F112,G112,H112) -> PN-111 | J112: P | K112: =IF(J112="","SEM #CH",VLOOKUP(J112,#REF!,2,0)) -> #REF! | L112: =IF(J112="","SEM #CH",VLOOKUP(J112,#REF!,3,0)) -> #REF! | M112: =IF(J112="","SEM #CH",VLOOKUP(J112,#REF!,4,0)) -> #REF! | N112: =IF(J112="","SEM #CH",VLOOKUP(J112,#REF!,5,0)) -> #REF! | O112: =IF(J112="","SEM #CH",VLOOKUP(J112,#REF!,6,0)) -> #REF! | P112: =IF(J112="","SEM #CH",VLOOKUP(J112,#REF!,7,0)) -> #REF! | Q112: =VLOOKUP(J112,'p1'!$B$2:$C$30,2,0) -> NÃO TEM CHAPA | R112: 45910 | S112: PN-001 | T112: =IF(R112="",0,1) -> 1 | U112: 45912 | V112: - | W112: 2520 | X112: =IF(U112>0,1,"") -> 1 | AA112: =TEXT(R112,"mmm/aaaa") -> set/2025
... A148: 147 | B148: 45771 | C148: 19 | D148: =IF(B148>0,1,"") -> 1 | E148: REATOR 3 | F148: PN | G148: - | H148: 147 | I148: =_xlfn.CONCAT(F148,G148,H148) -> PN-147 | J148: P | K148: =IF(J148="","SEM #CH",VLOOKUP(J148,#REF!,2,0)) -> #REF! | L148: =IF(J148="","SEM #CH",VLOOKUP(J148,#REF!,3,0)) -> #REF! | M148: =IF(J148="","SEM #CH",VLOOKUP(J148,#REF!,4,0)) -> #REF! | N148: =IF(J148="","SEM #CH",VLOOKUP(J148,#REF!,5,0)) -> #REF! | O148: =IF(J148="","SEM #CH",VLOOKUP(J148,#REF!,6,0)) -> #REF! | P148: =IF(J148="","SEM #CH",VLOOKUP(J148,#REF!,7,0)) -> #REF! | Q148: =VLOOKUP(J148,'p1'!$B$2:$C$30,2,0) -> NÃO TEM CHAPA | R148: 45922 | S148: PN-001 | T148: =IF(R148="",0,1) -> 1 | U148: 45924 | V148: - | W148: 2541 | X148: =IF(U148>0,1,"") -> 1 | AA148: =TEXT(R148,"mmm/aaaa") -> set/2025
A149: 148 | B149: 45818 | C149: 34 | D149: =IF(B149>0,1,"") -> 1 | E149: REATOR 3 | F149: PE | G149: - | H149: 148 | I149: =_xlfn.CONCAT(F149,G149,H149) -> PE-148 | J149: T3 | K149: =IF(J149="","SEM #CH",VLOOKUP(J149,#REF!,2,0)) -> #REF! | L149: =IF(J149="","SEM #CH",VLOOKUP(J149,#REF!,3,0)) -> #REF! | M149: =IF(J149="","SEM #CH",VLOOKUP(J149,#REF!,4,0)) -> #REF! | N149: =IF(J149="","SEM #CH",VLOOKUP(J149,#REF!,5,0)) -> #REF! | O149: =IF(J149="","SEM #CH",VLOOKUP(J149,#REF!,6,0)) -> #REF! | P149: =IF(J149="","SEM #CH",VLOOKUP(J149,#REF!,7,0)) -> #REF! | Q149: =VLOOKUP(J149,'p1'!$B$2:$C$30,2,0) -> #3/8-1200X1200 | R149: 45878 | S149: PN-001 | T149: =IF(R149="",0,1) -> 1 | U149: 45887 | W149: 2480 | X149: =IF(U149>0,1,"") -> 1 | AA149: =TEXT(R149,"mmm/aaaa") -> ago/2025
A150: 149 | B150: 45818 | C150: 34 | D150: =IF(B150>0,1,"") -> 1 | E150: REATOR 3 | F150: PE | G150: - | H150: 149 | I150: =_xlfn.CONCAT(F150,G150,H150) -> PE-149 | J150: T1 | K150: =IF(J150="","SEM #CH",VLOOKUP(J150,#REF!,2,0)) -> #REF! | L150: =IF(J150="","SEM #CH",VLOOKUP(J150,#REF!,3,0)) -> #REF! | M150: =IF(J150="","SEM #CH",VLOOKUP(J150,#REF!,4,0)) -> #REF! | N150: =IF(J150="","SEM #CH",VLOOKUP(J150,#REF!,5,0)) -> #REF! | O150: =IF(J150="","SEM #CH",VLOOKUP(J150,#REF!,6,0)) -> #REF! | P150: =IF(J150="","SEM #CH",VLOOKUP(J150,#REF!,7,0)) -> #REF! | Q150: =VLOOKUP(J150,'p1'!$B$2:$C$30,2,0) -> #3/8-1620X1620 | R150: 45875 | S150: PN-001 | T150: =IF(R150="",0,1) -> 1 | U150: 45887 | V150: FOH8658 | W150: 2481 | X150: =IF(U150>0,1,"") -> 1 | AA150: =TEXT(R150,"mmm/aaaa") -> ago/2025
A151: 150 | B151: 45818 | C151: 34 | D151: =IF(B151>0,1,"") -> 1 | E151: REATOR 3 | F151: PE | G151: - | H151: 150 | I151: =_xlfn.CONCAT(F151,G151,H151) -> PE-150 | J151: T2 | K151: =IF(J151="","SEM #CH",VLOOKUP(J151,#REF!,2,0)) -> #REF! | L151: =IF(J151="","SEM #CH",VLOOKUP(J151,#REF!,3,0)) -> #REF! | M151: =IF(J151="","SEM #CH",VLOOKUP(J151,#REF!,4,0)) -> #REF! | N151: =IF(J151="","SEM #CH",VLOOKUP(J151,#REF!,5,0)) -> #REF! | O151: =IF(J151="","SEM #CH",VLOOKUP(J151,#REF!,6,0)) -> #REF! | P151: =IF(J151="","SEM #CH",VLOOKUP(J151,#REF!,7,0)) -> #REF! | Q151: =VLOOKUP(J151,'p1'!$B$2:$C$30,2,0) -> #3/8-1315X1315 | R151: 45873 | S151: PN-001 | T151: =IF(R151="",0,1) -> 1 | U151: 45887 | W151: 2480 | X151: =IF(U151>0,1,"") -> 1 | AA151: =TEXT(R151,"mmm/aaaa") -> ago/2025
A152: 151 | B152: 45771 | C152: 19 | D152: =IF(B152>0,1,"") -> 1 | E152: REATOR 3 | F152: PN | G152: - | H152: 151 | I152: =_xlfn.CONCAT(F152,G152,H152) -> PN-151 | J152: P | K152: =IF(J152="","SEM #CH",VLOOKUP(J152,#REF!,2,0)) -> #REF! | L152: =IF(J152="","SEM #CH",VLOOKUP(J152,#REF!,3,0)) -> #REF! | M152: =IF(J152="","SEM #CH",VLOOKUP(J152,#REF!,4,0)) -> #REF! | N152: =IF(J152="","SEM #CH",VLOOKUP(J152,#REF!,5,0)) -> #REF! | O152: =IF(J152="","SEM #CH",VLOOKUP(J152,#REF!,6,0)) -> #REF! | P152: =IF(J152="","SEM #CH",VLOOKUP(J152,#REF!,7,0)) -> #REF! | Q152: =VLOOKUP(J152,'p1'!$B$2:$C$30,2,0) -> NÃO TEM CHAPA | R152: 45905 | S152: PN-001 | T152: =IF(R152="",0,1) -> 1 | U152: 45905 | V152: - | W152: 2506 | X152: =IF(U152>0,1,"") -> 1 | AA152: =TEXT(R152,"mmm/aaaa") -> set/2025
A153: 152 | B153: 45771 | C153: 19 | D153: =IF(B153>0,1,"") -> 1 | E153: REATOR 3 | F153: PN | G153: - | H153: 152 | I153: =_xlfn.CONCAT(F153,G153,H153) -> PN-152 | J153: P | K153: =IF(J153="","SEM #CH",VLOOKUP(J153,#REF!,2,0)) -> #REF! | L153: =IF(J153="","SEM #CH",VLOOKUP(J153,#REF!,3,0)) -> #REF! | M153: =IF(J153="","SEM #CH",VLOOKUP(J153,#REF!,4,0)) -> #REF! | N153: =IF(J153="","SEM #CH",VLOOKUP(J153,#REF!,5,0)) -> #REF! | O153: =IF(J153="","SEM #CH",VLOOKUP(J153,#REF!,6,0)) -> #REF! | P153: =IF(J153="","SEM #CH",VLOOKUP(J153,#REF!,7,0)) -> #REF! | Q153: =VLOOKUP(J153,'p1'!$B$2:$C$30,2,0) -> NÃO TEM CHAPA | R153: 45904 | S153: PN-001 | T153: =IF(R153="",0,1) -> 1 | U153: 45916 | V153: - | W153: 2525 | X153: =IF(U153>0,1,"") -> 1 | AA153: =TEXT(R153,"mmm/aaaa") -> set/2025
A154: 153 | B154: 45771 | C154: 19 | D154: =IF(B154>0,1,"") -> 1 | E154: REATOR 3 | F154: PN | G154: - | H154: 153 | I154: =_xlfn.CONCAT(F154,G154,H154) -> PN-153 | J154: P | K154: =IF(J154="","SEM #CH",VLOOKUP(J154,#REF!,2,0)) -> #REF! | L154: =IF(J154="","SEM #CH",VLOOKUP(J154,#REF!,3,0)) -> #REF! | M154: =IF(J154="","SEM #CH",VLOOKUP(J154,#REF!,4,0)) -> #REF! | N154: =IF(J154="","SEM #CH",VLOOKUP(J154,#REF!,5,0)) -> #REF! | O154: =IF(J154="","SEM #CH",VLOOKUP(J154,#REF!,6,0)) -> #REF! | P154: =IF(J154="","SEM #CH",VLOOKUP(J154,#REF!,7,0)) -> #REF! | Q154: =VLOOKUP(J154,'p1'!$B$2:$C$30,2,0) -> NÃO TEM CHAPA | R154: 45911 | S154: PN-001 | T154: =IF(R154="",0,1) -> 1 | U154: 45912 | V154: - | W154: 2521 | X154: =IF(U154>0,1,"") -> 1 | AA154: =TEXT(R154,"mmm/aaaa") -> set/2025
A155: 154 | B155: 45773 | C155: 20 | D155: =IF(B155>0,1,"") -> 1 | E155: REATOR 3 | F155: PN | G155: - | H155: 154 | I155: =_xlfn.CONCAT(F155,G155,H155) -> PN-154 | J155: P | K155: =IF(J155="","SEM #CH",VLOOKUP(J155,#REF!,2,0)) -> #REF! | L155: =IF(J155="","SEM #CH",VLOOKUP(J155,#REF!,3,0)) -> #REF! | M155: =IF(J155="","SEM #CH",VLOOKUP(J155,#REF!,4,0)) -> #REF! | N155: =IF(J155="","SEM #CH",VLOOKUP(J155,#REF!,5,0)) -> #REF! | O155: =IF(J155="","SEM #CH",VLOOKUP(J155,#REF!,6,0)) -> #REF! | P155: =IF(J155="","SEM #CH",VLOOKUP(J155,#REF!,7,0)) -> #REF! | Q155: =VLOOKUP(J155,'p1'!$B$2:$C$30,2,0) -> NÃO TEM CHAPA | R155: 45822 | S155: PN-002 | T155: =IF(R155="",0,1) -> 1 | U155: 45824 | V155: - | W155: 2389 | X155: =IF(U155>0,1,"") -> 1 | AA155: =TEXT(R155,"mmm/aaaa") -> jun/2025
A156: 155 | B156: 45773 | C156: 20 | D156: =IF(B156>0,1,"") -> 1 | E156: REATOR 3 | F156: PN | G156: - | H156: 155 | I156: =_xlfn.CONCAT(F156,G156,H156) -> PN-155 | J156: P | K156: =IF(J156="","SEM #CH",VLOOKUP(J156,#REF!,2,0)) -> #REF! | L156: =IF(J156="","SEM #CH",VLOOKUP(J156,#REF!,3,0)) -> #REF! | M156: =IF(J156="","SEM #CH",VLOOKUP(J156,#REF!,4,0)) -> #REF! | N156: =IF(J156="","SEM #CH",VLOOKUP(J156,#REF!,5,0)) -> #REF! | O156: =IF(J156="","SEM #CH",VLOOKUP(J156,#REF!,6,0)) -> #REF! | P156: =IF(J156="","SEM #CH",VLOOKUP(J156,#REF!,7,0)) -> #REF! | Q156: =VLOOKUP(J156,'p1'!$B$2:$C$30,2,0) -> NÃO TEM CHAPA | R156: 45822 | S156: PN-002 | T156: =IF(R156="",0,1) -> 1 | U156: 45824 | V156: - | W156: 2389 | X156: =IF(U156>0,1,"") -> 1 | AA156: =TEXT(R156,"mmm/aaaa") -> jun/2025
A157: 156 | B157: 45839 | C157: 43 | D157: =IF(B157>0,1,"") -> 1 | E157: REATOR 3 | F157: PF | G157: - | H157: 156 | I157: =_xlfn.CONCAT(F157,G157,H157) -> PF-156 | J157: PF | K157: =IF(J157="","SEM #CH",VLOOKUP(J157,#REF!,2,0)) -> #REF! | L157: =IF(J157="","SEM #CH",VLOOKUP(J157,#REF!,3,0)) -> #REF! | M157: =IF(J157="","SEM #CH",VLOOKUP(J157,#REF!,4,0)) -> #REF! | N157: =IF(J157="","SEM #CH",VLOOKUP(J157,#REF!,5,0)) -> #REF! | O157: =IF(J157="","SEM #CH",VLOOKUP(J157,#REF!,6,0)) -> #REF! | P157: =IF(J157="","SEM #CH",VLOOKUP(J157,#REF!,7,0)) -> #REF! | Q157: =VLOOKUP(J157,'p1'!$B$2:$C$30,2,0) -> SEM CHAPA | R157: 45845 | S157: PN-001 | T157: =IF(R157="",0,1) -> 1 | U157: 45852 | V157: - | W157: 2441 | X157: =IF(U157>0,1,"") -> 1 | AA157: =TEXT(R157,"mmm/aaaa") -> jul/2025
A158: 157 | B158: 45773 | C158: 20 | D158: =IF(B158>0,1,"") -> 1 | E158: REATOR 3 | F158: PN | G158: - | H158: 157 | I158: =_xlfn.CONCAT(F158,G158,H158) -> PN-157 | J158: P | K158: =IF(J158="","SEM #CH",VLOOKUP(J158,#REF!,2,0)) -> #REF! | L158: =IF(J158="","SEM #CH",VLOOKUP(J158,#REF!,3,0)) -> #REF! | M158: =IF(J158="","SEM #CH",VLOOKUP(J158,#REF!,4,0)) -> #REF! | N158: =IF(J158="","SEM #CH",VLOOKUP(J158,#REF!,5,0)) -> #REF! | O158: =IF(J158="","SEM #CH",VLOOKUP(J158,#REF!,6,0)) -> #REF! | P158: =IF(J158="","SEM #CH",VLOOKUP(J158,#REF!,7,0)) -> #REF! | Q158: =VLOOKUP(J158,'p1'!$B$2:$C$30,2,0) -> NÃO TEM CHAPA | R158: 45822 | S158: PN-002 | T158: =IF(R158="",0,1) -> 1 | U158: 45824 | V158: - | W158: 2389 | X158: =IF(U158>0,1,"") -> 1 | AA158: =TEXT(R158,"mmm/aaaa") -> jun/2025
A159: 158 | B159: 45773 | C159: 20 | D159: =IF(B159>0,1,"") -> 1 | E159: REATOR 3 | F159: PN | G159: - | H159: 158 | I159: =_xlfn.CONCAT(F159,G159,H159) -> PN-158 | J159: P | K159: =IF(J159="","SEM #CH",VLOOKUP(J159,#REF!,2,0)) -> #REF! | L159: =IF(J159="","SEM #CH",VLOOKUP(J159,#REF!,3,0)) -> #REF! | M159: =IF(J159="","SEM #CH",VLOOKUP(J159,#REF!,4,0)) -> #REF! | N159: =IF(J159="","SEM #CH",VLOOKUP(J159,#REF!,5,0)) -> #REF! | O159: =IF(J159="","SEM #CH",VLOOKUP(J159,#REF!,6,0)) -> #REF! | P159: =IF(J159="","SEM #CH",VLOOKUP(J159,#REF!,7,0)) -> #REF! | Q159: =VLOOKUP(J159,'p1'!$B$2:$C$30,2,0) -> NÃO TEM CHAPA | R159: 45824 | S159: PN-002 | T159: =IF(R159="",0,1) -> 1 | U159: 45828 | V159: - | W159: 2402 | X159: =IF(U159>0,1,"") -> 1 | AA159: =TEXT(R159,"mmm/aaaa") -> jun/2025
A160: 159 | B160: 45773 | C160: 20 | D160: =IF(B160>0,1,"") -> 1 | E160: REATOR 3 | F160: PN | G160: - | H160: 159 | I160: =_xlfn.CONCAT(F160,G160,H160) -> PN-159 | J160: P | K160: =IF(J160="","SEM #CH",VLOOKUP(J160,#REF!,2,0)) -> #REF! | L160: =IF(J160="","SEM #CH",VLOOKUP(J160,#REF!,3,0)) -> #REF! | M160: =IF(J160="","SEM #CH",VLOOKUP(J160,#REF!,4,0)) -> #REF! | N160: =IF(J160="","SEM #CH",VLOOKUP(J160,#REF!,5,0)) -> #REF! | O160: =IF(J160="","SEM #CH",VLOOKUP(J160,#REF!,6,0)) -> #REF! | P160: =IF(J160="","SEM #CH",VLOOKUP(J160,#REF!,7,0)) -> #REF! | Q160: =VLOOKUP(J160,'p1'!$B$2:$C$30,2,0) -> NÃO TEM CHAPA | R160: 45824 | S160: PN-002 | T160: =IF(R160="",0,1) -> 1 | U160: 45828 | V160: - | W160: 2402 | X160: =IF(U160>0,1,"") -> 1 | AA160: =TEXT(R160,"mmm/aaaa") -> jun/2025
...

Sheet CALCULOS 
A1: PRIMARIO
B2: TOTAL DE PROJETO | C2: TAG | D2: TOTAL CONCRETADO | E2: TOTAL ACABADO | F2: TOTAL TRANSPORTADO
B3: =COUNTIF(' CADASTRO'!$F$746:$F$893,C3) -> 6 | C3: PF | D3: =SUMIF(' CADASTRO'!$F$746:$F$893,'CALCULOS '!C3,' CADASTRO'!$D$746:$D$893) -> 6 | E3: =SUMIF(' CADASTRO'!$F$746:$F$893,C3,' CADASTRO'!$T$746:$T$893) -> 1 | F3: =SUMIF(' CADASTRO'!$F$746:$F$893,C3,' CADASTRO'!$X$746:$X$893) -> 0
B4: =COUNTIF(' CADASTRO'!$F$746:$F$893,C4) -> 104 | C4: PN | D4: =SUMIF(' CADASTRO'!$F$746:$F$893,'CALCULOS '!C4,' CADASTRO'!$D$746:$D$893) -> 104 | E4: =SUMIF(' CADASTRO'!$F$746:$F$893,C4,' CADASTRO'!$T$746:$T$893) -> 57 | F4: =SUMIF(' CADASTRO'!$F$746:$F$893,C4,' CADASTRO'!$X$746:$X$893) -> 52
B5: =COUNTIF(' CADASTRO'!$F$746:$F$893,C5) -> 12 | C5: PE | D5: =SUMIF(' CADASTRO'!$F$746:$F$893,'CALCULOS '!C5,' CADASTRO'!$D$746:$D$893) -> 12 | E5: =SUMIF(' CADASTRO'!$F$746:$F$893,C5,' CADASTRO'!$T$746:$T$893) -> 0 | F5: =SUMIF(' CADASTRO'!$F$746:$F$893,C5,' CADASTRO'!$X$746:$X$893) -> 0
B6: =COUNTIF(' CADASTRO'!$F$746:$F$893,C6) -> 1 | C6: PE(I) | D6: =SUMIF(' CADASTRO'!$F$746:$F$893,'CALCULOS '!C6,' CADASTRO'!$D$746:$D$893) -> 1 | E6: =SUMIF(' CADASTRO'!$F$746:$F$893,C6,' CADASTRO'!$T$746:$T$893) -> 0 | F6: =SUMIF(' CADASTRO'!$F$746:$F$893,C6,' CADASTRO'!$X$746:$X$893) -> 0
B7: =COUNTIF(' CADASTRO'!$F$746:$F$893,C7) -> 3 | C7: PEI(V) | D7: =SUMIF(' CADASTRO'!$F$746:$F$893,'CALCULOS '!C7,' CADASTRO'!$D$746:$D$893) -> 3 | E7: =SUMIF(' CADASTRO'!$F$746:$F$893,C7,' CADASTRO'!$T$746:$T$893) -> 0 | F7: =SUMIF(' CADASTRO'!$F$746:$F$893,C7,' CADASTRO'!$X$746:$X$893) -> 0
B8: =COUNTIF(' CADASTRO'!$F$746:$F$893,C8) -> 0 | C8: PEV | D8: =SUMIF(' CADASTRO'!$F$746:$F$893,'CALCULOS '!C8,' CADASTRO'!$D$746:$D$893) -> 0 | E8: =SUMIF(' CADASTRO'!$F$746:$F$893,C8,' CADASTRO'!$T$746:$T$893) -> 0 | F8: =SUMIF(' CADASTRO'!$F$746:$F$893,C8,' CADASTRO'!$X$746:$X$893) -> 0
B9: =COUNTIF(' CADASTRO'!$F$746:$F$893,C9) -> 0 | C9: TEB | D9: =SUMIF(' CADASTRO'!$F$746:$F$893,'CALCULOS '!C9,' CADASTRO'!$D$746:$D$893) -> 0 | E9: =SUMIF(' CADASTRO'!$F$746:$F$893,C9,' CADASTRO'!$T$746:$T$893) -> 0 | F9: =SUMIF(' CADASTRO'!$F$746:$F$893,C9,' CADASTRO'!$X$746:$X$893) -> 0
B10: =COUNTIF(' CADASTRO'!$F$746:$F$893,C10) -> 22 | C10: PNI | D10: =SUMIF(' CADASTRO'!$F$746:$F$893,'CALCULOS '!C10,' CADASTRO'!$D$746:$D$893) -> 22 | E10: =SUMIF(' CADASTRO'!$F$746:$F$893,C10,' CADASTRO'!$T$746:$T$893) -> 16 | F10: =SUMIF(' CADASTRO'!$F$746:$F$893,C10,' CADASTRO'!$X$746:$X$893) -> 12
A11: TOTAIS | B11: =SUM(B3:B10) -> 148 | D11: =SUM(D3:D10) -> 148 | E11: =SUM(E3:E10) -> 74 | F11: =SUM(F3:F10) -> 64
A18: AERADORES
B19: TOTAL DE PROJETO | C19: TAG | D19: TOTAL CONCRETADO | E19: TOTAL ACABADO | F19: TOTAL TRANSPORTADO
B20: =COUNTIF(' CADASTRO'!$F$894:$F$1175,C20) -> 6 | C20: PF | D20: =SUMIF(' CADASTRO'!$F$894:$F$1175,'CALCULOS '!C20,' CADASTRO'!$D$894:$D$1175) -> 5 | E20: =SUMIF(' CADASTRO'!$F$894:$F$1175,C20,' CADASTRO'!$T$894:$T$1175) -> 4 | F20: =SUMIF(' CADASTRO'!$F$894:$F$1175,C20,' CADASTRO'!$X$894:$X$1175) -> 4
B21: =COUNTIF(' CADASTRO'!$F$894:$F$1175,C21) -> 229 | C21: PN | D21: =SUMIF(' CADASTRO'!$F$894:$F$1175,'CALCULOS '!C21,' CADASTRO'!$D$894:$D$1175) -> 129 | E21: =SUMIF(' CADASTRO'!$F$894:$F$1175,C21,' CADASTRO'!$T$894:$T$1175) -> 102 | F21: =SUMIF(' CADASTRO'!$F$894:$F$1175,C21,' CADASTRO'!$X$894:$X$1175) -> 100
B22: =COUNTIF(' CADASTRO'!$F$894:$F$1175,C22) -> 15 | C22: PE | D22: =SUMIF(' CADASTRO'!$F$894:$F$1175,'CALCULOS '!C22,' CADASTRO'!$D$894:$D$1175) -> 10 | E22: =SUMIF(' CADASTRO'!$F$894:$F$1175,C22,' CADASTRO'!$T$894:$T$1175) -> 7 | F22: =SUMIF(' CADASTRO'!$F$894:$F$1175,C22,' CADASTRO'!$X$894:$X$1175) -> 7
B23: =COUNTIF(' CADASTRO'!$F$894:$F$1175,C23) -> 0 | C23: PE(I) | D23: =SUMIF(' CADASTRO'!$F$894:$F$1175,'CALCULOS '!C23,' CADASTRO'!$D$894:$D$1175) -> 0 | E23: =SUMIF(' CADASTRO'!$F$894:$F$1175,C23,' CADASTRO'!$T$894:$T$1175) -> 0 | F23: =SUMIF(' CADASTRO'!$F$894:$F$1175,C23,' CADASTRO'!$X$894:$X$1175) -> 0
B24: =COUNTIF(' CADASTRO'!$F$894:$F$1175,C24) -> 0 | C24: PEI(V) | D24: =SUMIF(' CADASTRO'!$F$894:$F$1175,'CALCULOS '!C24,' CADASTRO'!$D$894:$D$1175) -> 0 | E24: =SUMIF(' CADASTRO'!$F$894:$F$1175,C24,' CADASTRO'!$T$894:$T$1175) -> 0 | F24: =SUMIF(' CADASTRO'!$F$894:$F$1175,C24,' CADASTRO'!$X$894:$X$1175) -> 0
B25: =COUNTIF(' CADASTRO'!$F$894:$F$1175,C25) -> 0 | C25: PEV | D25: =SUMIF(' CADASTRO'!$F$894:$F$1175,'CALCULOS '!C25,' CADASTRO'!$D$894:$D$1175) -> 0 | E25: =SUMIF(' CADASTRO'!$F$894:$F$1175,C25,' CADASTRO'!$T$894:$T$1175) -> 0 | F25: =SUMIF(' CADASTRO'!$F$894:$F$1175,C25,' CADASTRO'!$X$894:$X$1175) -> 0
B26: =COUNTIF(' CADASTRO'!$F$894:$F$1175,C26) -> 0 | C26: TEB | D26: =SUMIF(' CADASTRO'!$F$894:$F$1175,'CALCULOS '!C26,' CADASTRO'!$D$894:$D$1175) -> 0 | E26: =SUMIF(' CADASTRO'!$F$894:$F$1175,C26,' CADASTRO'!$T$894:$T$1175) -> 0 | F26: =SUMIF(' CADASTRO'!$F$894:$F$1175,C26,' CADASTRO'!$X$894:$X$1175) -> 0
B27: =COUNTIF(' CADASTRO'!$F$894:$F$1175,C27) -> 32 | C27: PNI | D27: =SUMIF(' CADASTRO'!$F$894:$F$1175,'CALCULOS '!C27,' CADASTRO'!$D$894:$D$1175) -> 26 | E27: =SUMIF(' CADASTRO'!$F$894:$F$1175,C27,' CADASTRO'!$T$894:$T$1175) -> 24 | F27: =SUMIF(' CADASTRO'!$F$894:$F$1175,C27,' CADASTRO'!$X$894:$X$1175) -> 24
A28: TOTAIS | B28: =SUM(B20:B27) -> 282 | D28: =SUM(D20:D27) -> 170 | E28: =SUM(E20:E27) -> 137 | F28: =SUM(F20:F27) -> 135

Sheet SC-10 PN1 AERADOR
E1: BETONEIRA | Q1: BT1
Q2: NF=> | S2: =S3-378 -> 1259 | U2: FLOW=> | X2: vol(m³) | Z2: 1 | AA2: X
B3: NUMERO CONCRETAGEM | D3: =MAX(' CADASTRO'!C:C) -> 169 | E3: Placa n° => | F3: AER 2_PN-175 | H3: AER 2_PN-176 | J3: AER 2_PN-177 | L3: AER 2_PN-179 | N3: AER 2_PE-162 | Q3: SERIE=> | S3: 1637 | U3: HORA LANÇ => | Z3: 2 | AA3: X
A4: data: | C4: =TODAY() -> 46007 | E4: OBRA | F4: AERADOR 2 | H4: AERADOR 2 | J4: , | L4: AERADOR 2 | N4: AERADOR 1 | Q4: HORA ROMP. | S4: CP1 (20H) | U4: CP2 (20H) | W4: CP3 (28D) | X4: CP4 (28D) | Z4: 3 | AA4: X
E5: TIPO | N5: ARRANQUES CENTRAL EM BAIXO VAZADO | Q5: RESIST. | Z5: 4 | AA5: X
A6: HORA INICIO | E6: INSERTS | Q6: BT2 | Z6: 5 | AA6: X
C7: PISTA -001 | Z7: 6
E8: FORMAS | F8: F1 | H8: F2 | J8: F3 | L8: F4 | N8: F5 | Q8: NF=> | S8: =IF(S9="","",S9-378) -> 1260 | U8: FLOW=> | X8: vol(m³)
B9: item | C9: descrição das inspeções | F9: ok | G9: corrigir | H9: ok | I9: corrigir | J9: ok | K9: corrigir | L9: ok | M9: corrigir | N9: ok | O9: corrigir | Q9: SERIE=> | S9: =IF(AA3="X",S3+1,"") -> 1638 | U9: HORA LANÇ =>
Q10: HORA ROMP. | S10: CP1 (20H) | U10: CP2 (20H) | W10: CP3 (28D) | X10: CP4 (28D)
B11: 1 | C11: QTDE DE CABOS E ALONGAMENTOS 18 C 321A356 | Q11: RESIST.
B12: 2 | C12: PÉ 2X M36 | Q12: BT3
B13: 3 | C13: INJETOR 1X | Q13: NF=> | S13: =IF(S14="","",S14-378) -> 1261 | X13: vol(m³)
B14: 4 | C14: TELA VIVEIRO E REFORÇO 20MM EM CIMA DOS PINOS IÇAMENTOS 4X 7,5 TON/300 3 "u" 10 MM E 1 BARRA 1 MTS | Q14: SERIE=> | S14: =IF(AA4="X",$S$3+2,"") -> 1639 | U14: HORA LANÇ =>
B15: 5 | C15: JUNÇÃO 3/8 X 25 MM FLUTUADOR 2X | Q15: HORA ROMP. | S15: CP1 (20H) | U15: CP2 (20H) | W15: CP3 (28D) | X15: CP4 (28D)
B16: 6 | C16: ESCORA 6,00 DO PÉ 5/8 PARAF. SUPERIOR | Q16: RESIST.
B17: 7 | C17: RECOBRIMENTO SUPERIOR/ INFERIOR E LATERIAS
B18: 8 | C18: VIGAS LATERAIAS (ESTRIBOS E BARRAS) | Q18: BT4
B19: 9 | C19: ÂNGULO DE A CADA 5 CONCRETAGEM | Q19: NF=> | S19: =IF(S20="","",S20-378) -> 1262 | U19: FLOW=> | X19: vol(m³)
B20: 10 | C20: REFORÇO DE CABEÇA E PE | Q20: SERIE => | S20: =IF(AA5="X",$S$3+3,"") -> 1640 | U20: HORA LANÇ =>
B21: 11 | C21: ESPAÇADOR DE TELA A TELA E VIGA | Q21: HORA ROMP. | S21: CP1 (20H) | U21: CP2 (20H) | W21: CP3 (28D) | X21: CP4 (28D)
B22: 12 | C22: FECHAMENTO FORMA LATERAL (PINAGEM) (dois lados) | Q22: RESIST.
B23: 13 | C23: DIMENSÕES DA PLACA (DIVISORIA ESCOSTADAS NA TRAVA)
B24: 14 | C24: TELAS SUPERIOR E INFERIOR ESTAO ATADAS | Q24: BT5
B25: 15 | C25: QTDE DE BAINHAS 28 BAINHAS | Q25: NF=> | S25: =IF(S26="","",S26-378) -> 1263 | U25: FLOW=> | X25: vol(m³)
B26: 16 | C26: MEDIDAS DE TOPO DE FORMA 2378 MM | Q26: SERIE=> | S26: =IF(AA6="X",$S$3+4,"") -> 1641 | U26: HORA LANÇ =>
B27: 17 | C27: CHAPAS DE INSERTOS | Q27: HORA ROMP. | S27: CP1 (20H) | U27: CP2 (20H) | W27: CP3 (28D) | X27: CP4 (28D)
B28: 18 | C28: SIKASWELL CHAPA DE TUBULAÇÃO | Q28: RESIST.
B29: 19 | C29: LIMPEZA : SOPRAGEM E COLETA DE ARRAMES
B30: 20 | C30: MOV: 4 X 10TON X 125CB | Q30: BT6
B31: 21 | C31: FERRO DE ATERRAMENTO PE PLACAS | Q31: NF => | S31: =IF(S32="","",S32-378) | U31: FLOW=> | X31: vol(m³)
B32: 22 | C32: EMENDAS | Q32: SERIE=> | S32: =IF(AA7="X",$S$3+5,"") | U32: HORA LANÇ =>
F33: CABO 1 | G33: CABO 2 | H33: CABO 3 | I33: CABO 4 | J33: CABO 5 | K33: CABO 6 | L33: CABO 7 | M33: CABO 8 | N33: CABO 9 | Q33: HORA ROMP. | S33: CP1 (20H) | U33: CP2 (20H) | W33: CP3 (28D) | X33: CP4 (28D)
Q34: RESIST.
F36: CABO 10 | G36: CABO 11 | H36: CABO 12 | I36: CABO 13 | J36: CABO 14 | K36: CABO 15 | L36: CABO 16 | M36: CABO 17 | N36: CABO 18
F38: BOBINA N° | J38: 1063497359
F39: DATA: | J39: 45932
B41: NUMERO CONCRETAGEM | D41: =D3 -> 169 | E41: QUAL É A OBRA | F41: =F3 -> AER 2_PN-175 | H41: =H3 -> AER 2_PN-176 | J41: =J3 -> AER 2_PN-177 | L41: =L3 -> AER 2_PN-179 | N41: =N3 -> AER 2_PE-162
A42: data: | E42: Placa n° =>
E43: TIPO
...

Sheet SC-10 PN1
E1: BETONEIRA | W1: BT1
W2: NF=> | Y2: =Y3-378 -> 942 | AA2: FLOW=> | AD2: vol(m³) | AF2: 1 | AG2: X
B3: NUMERO CONCRETAGEM | D3: =MAX(' CADASTRO'!C2:C999) -> 169 | E3: QUAL É A OBRA | F3: NEREDA | H3: NEREDA | J3: NEREDA | L3: NEREDA | N3: NEREDA | P3: NEREDA | R3: NEREDA | T3: PRIMARIO | W3: SERIE=> | Y3: 1320 | AA3: HORA LANÇ => | AF3: 2 | AG3: X
A4: data: | C4: =TODAY() -> 46007 | E4: Placa n° => | F4: PN-501 | H4: PN-502 | J4: PN-503 | L4: PN-504 | N4: PN-505 | P4: PN-506 | R4: PN-507 | T4: PR_PN-135 | W4: HORA ROMP. | Y4: CP1 (20H) | AA4: CP2 (20H) | AC4: CP3 (28D) | AD4: CP4 (28D) | AF4: 3 | AG4: X
E5: TIPO | F5: =VLOOKUP(F4,' CADASTRO'!$I$2:$J$999,2,0) -> P | H5: =VLOOKUP(H4,' CADASTRO'!$I$2:$J$999,2,0) -> P | J5: =VLOOKUP(J4,' CADASTRO'!$I$2:$J$999,2,0) -> P | L5: =VLOOKUP(L4,' CADASTRO'!$I$2:$J$999,2,0) -> P | N5: =VLOOKUP(N4,' CADASTRO'!$I$2:$J$999,2,0) -> P | P5: =VLOOKUP(P4,' CADASTRO'!$I$2:$J$999,2,0) -> P | R5: =VLOOKUP(R4,' CADASTRO'!$I$2:$J$999,2,0) -> P | T5: =VLOOKUP(T4,' CADASTRO'!$I$2:$J$999,2,0) -> P | W5: RESIST. | AF5: 4 | AG5: X
A6: HORA INICIO | E6: INSERTS | F6: =VLOOKUP(F4,' CADASTRO'!$I$2:$Q$993,9,0) -> NÃO TEM CHAPA | H6: =VLOOKUP(H4,' CADASTRO'!$I$2:$Q$993,9,0) -> NÃO TEM CHAPA | J6: =VLOOKUP(J4,' CADASTRO'!$I$2:$Q$993,9,0) -> NÃO TEM CHAPA | L6: =VLOOKUP(L4,' CADASTRO'!$I$2:$Q$993,9,0) -> NÃO TEM CHAPA | N6: =VLOOKUP(N4,' CADASTRO'!$I$2:$Q$993,9,0) -> NÃO TEM CHAPA | P6: =VLOOKUP(P4,' CADASTRO'!$I$2:$Q$993,9,0) -> NÃO TEM CHAPA | R6: =VLOOKUP(R4,' CADASTRO'!$I$2:$Q$993,9,0) -> NÃO TEM CHAPA | T6: =VLOOKUP(T4,' CADASTRO'!$I$2:$Q$993,9,0) -> NÃO TEM CHAPA | W6: BT2 | AF6: 5 | AG6: X
C7: PISTA -001 | AF7: 6
E8: FORMAS | F8: F1 | H8: F2 | J8: F3 | L8: F4 | N8: F5 | P8: F6 | R8: F7 | T8: F8 | W8: NF=> | Y8: =IF(Y9="","",Y9-378) -> 943 | AA8: FLOW=> | AD8: vol(m³)
B9: item | C9: descrição das inspeções | F9: ok | G9: corrigir | H9: ok | I9: corrigir | J9: ok | K9: corrigir | L9: ok | M9: corrigir | N9: ok | O9: corrigir | P9: ok | Q9: corrigir | R9: ok | S9: corrigir | T9: ok | U9: corrigir | W9: SERIE=> | Y9: =IF(AG3="X",Y3+1,"") -> 1321 | AA9: HORA LANÇ =>
W10: HORA ROMP. | Y10: CP1 (20H) | AA10: CP2 (20H) | AC10: CP3 (28D) | AD10: CP4 (28D)
B11: 1 | C11: QTDE DE CABOS E ALONGAMENTOS 16 C 321A356 | W11: RESIST.
B12: 2 | C12: PÉ 2X M24 | W12: BT3
B13: 3 | C13: INJETOR 1X | W13: NF=> | Y13: =IF(Y14="","",Y14-378) -> 944 | AD13: vol(m³)
B14: 4 | C14: TELA VIVEIRO E REFORÇO 16 MM EM CIMA DOS PINOS IÇAMENTOS 2X 7,5 TON/300 3 "u" 10 MM E 1 BARRA 1 MTS | W14: SERIE=> | Y14: =IF(AG4="X",$Y$3+2,"") -> 1322 | AA14: HORA LANÇ =>
B15: 5 | C15: JUNÇÃO 3/8 X 25 MM FLUTUADOR 2X | W15: HORA ROMP. | Y15: CP1 (20H) | AA15: CP2 (20H) | AC15: CP3 (28D) | AD15: CP4 (28D)
B16: 6 | C16: ESCORA 5,50 DO PÉ 5/8 | W16: RESIST.
B17: 7 | C17: RECOBRIMENTO SUPERIOR/ INFERIOR E LATERIAS
B18: 8 | C18: VIGAS LATERAIAS (ESTRIBOS E BARRAS) | W18: BT4
B19: 9 | C19: ÂNGULO DE A CADA 5 CONCRETAGEM | W19: NF=> | Y19: =IF(Y20="","",Y20-378) -> 945 | AA19: FLOW=> | AD19: vol(m³)
B20: 10 | C20: REFORÇO DE CABEÇA E PE | W20: SERIE => | Y20: =IF(AG5="X",$Y$3+3,"") -> 1323 | AA20: HORA LANÇ =>
B21: 11 | C21: ESPAÇADOR DE TELA A TELA E VIGA (36X) | W21: HORA ROMP. | Y21: CP1 (20H) | AA21: CP2 (20H) | AC21: CP3 (28D) | AD21: CP4 (28D)
B22: 12 | C22: FECHAMENTO FORMA LATERAL (PINAGEM) (dois lados) | W22: RESIST.
B23: 13 | C23: DIMENSÕES DA PLACA (DIVISORIA ESCOSTADAS NA TRAVA)
B24: 14 | C24: TELAS SUPERIOR E INFERIOR ESTAO ATADAS | W24: BT5
B25: 15 | C25: QTDE DE BAINHAS (12 NO NEREDA E 6 NO PRIMARIO) E SE ESTAO ATADAS NA ZONA | W25: NF=> | Y25: =IF(Y26="","",Y26-378) -> 946 | AA25: FLOW=> | AD25: vol(m³)
B26: 16 | C26: MEDIDAS DE TOPO DE FORMA (2380 NO PRIMARIO); (2375 NO NEREDA) | W26: SERIE=> | Y26: =IF(AG6="X",$Y$3+4,"") -> 1324 | AA26: HORA LANÇ =>
B27: 17 | C27: CHAPAS DE INSERTOS | W27: HORA ROMP. | Y27: CP1 (20H) | AA27: CP2 (20H) | AC27: CP3 (28D) | AD27: CP4 (28D)
B28: 18 | C28: SIKASWELL CHAPA DE TUBULAÇÃO | W28: RESIST.
B29: 19 | C29: LIMPEZA : SOPRAGEM E COLETA DE ARRAMES
B30: 20 | C30: MOV: 4 X 5TON X 125CB - NEREDA | W30: BT6
B31: 21 | C31: MOV: 4 X 5TON X 125CB + 4 X 5TON X 125ESF. PRIMARIO | W31: NF => | Y31: =IF(Y32="","",Y32-378) | AA31: FLOW=> | AD31: vol(m³)
B32: 22 | C32: EMENDAS | W32: SERIE=> | Y32: =IF(AG7="X",$Y$3+5,"") | AA32: HORA LANÇ =>
F33: CABO 1 | H33: CABO 2 | J33: CABO 3 | L33: CABO 4 | N33: CABO 5 | P33: CABO 6 | R33: CABO 7 | T33: CABO 8 | W33: HORA ROMP. | Y33: CP1 (20H) | AA33: CP2 (20H) | AC33: CP3 (28D) | AD33: CP4 (28D)
W34: RESIST.
F36: CABO 09 | H36: CABO 10 | J36: CABO 11 | L36: CABO 12 | N36: CABO 13 | P36: CABO 14 | R36: CABO 15 | T36: CABO 16
F38: BOBINA N° | J38: 1063497359
F39: DATA: | J39: 45932
J40: 3
B41: NUMERO CONCRETAGEM | D41: =D3 -> 169 | E41: QUAL É A OBRA | F41: NEREDA | H41: NEREDA | J41: NEREDA | L41: NEREDA | N41: NEREDA | P41: NEREDA | R41: NEREDA | T41: PRIMARIO
A42: data: | E42: Placa n° => | F42: =F4 -> PN-501 | H42: =H4 -> PN-502 | J42: =J4 -> PN-503 | L42: =L4 -> PN-504 | N42: =N4 -> PN-505 | P42: =P4 -> PN-506 | R42: =R4 -> PN-507 | T42: =T4 -> PR_PN-135
...

Sheet SC-10 PN2
E1: BETONEIRA | W1: BT1 | AI1: data | AJ1: se concretada marque "x" | AK1: se concretado | AL1: IDENT. TANQUE | AM1: PLACA | AQ1: TIPO
W2: NF=> | Y2: =Y3-378 -> 1255 | AA2: FLOW=> | AD2: vol(m³) | AF2: 1 | AG2: X | AH2: 51 | AI2: {=_xlfn._xlws.FILTER(' CADASTRO'!B:J,' CADASTRO'!C:C='SC-10 PN2'!AH2,)} -> 45856 | AJ2: 51 | AK2: 1 | AL2: REATOR 5 | AM2: PN | AN2: - | AO2: 285 | AP2: PN-285 | AQ2: P
B3: NUMERO CONCRETAGEM | D3: =MAX(' CADASTRO'!C2:C999) -> 169 | E3: QUAL É A OBRA | F3: PRIMARIO | H3: NEREDA | J3: NEREDA | W3: SERIE=> | Y3: 1633 | AA3: HORA LANÇ => | AF3: 2 | AG3: X | AI3: 45856 | AJ3: 51 | AK3: 1 | AL3: REATOR 5 | AM3: PN | AN3: - | AO3: 286 | AP3: PN-286 | AQ3: P
A4: data: | C4: =TODAY() -> 46007 | E4: Placa n° => | F4: PR_PE-98 | H4: PN-292-A | J4: PLACA TESTE | W4: HORA ROMP. | AA4: CP2 (20H) | AC4: CP3 (28D) | AD4: CP4 (28D) | AF4: 3 | AG4: X | AI4: 45856 | AJ4: 51 | AK4: 1 | AL4: REATOR 5 | AM4: PN | AN4: - | AO4: 287 | AP4: PN-287 | AQ4: P
E5: TIPO | F5: =VLOOKUP(F4,' CADASTRO'!$I$2:$J$999,2,0) -> PEV | H5: =VLOOKUP(H4,' CADASTRO'!$I$2:$J$999,2,0) -> #N/A | J5: =VLOOKUP(J4,' CADASTRO'!$I$2:$J$999,2,0) -> #N/A | L5: =VLOOKUP(L4,' CADASTRO'!$I$2:$J$999,2,0) -> #N/A | N5: =VLOOKUP(N4,' CADASTRO'!$I$2:$J$999,2,0) -> #N/A | P5: =VLOOKUP(P4,' CADASTRO'!$I$2:$J$999,2,0) -> #N/A | R5: =VLOOKUP(R4,' CADASTRO'!$I$2:$J$999,2,0) -> #N/A | T5: =VLOOKUP(T4,' CADASTRO'!$I$2:$J$999,2,0) -> #N/A | W5: RESIST. | AF5: 4 | AG5: X | AI5: 45856 | AJ5: 51 | AK5: 1 | AL5: REATOR 5 | AM5: PN | AN5: - | AO5: 289 | AP5: PN-289 | AQ5: P
A6: HORA INICIO | E6: INSERTS | F6: =VLOOKUP(F4,' CADASTRO'!$I$2:$Q$993,9,0) -> ARM. CANAL SAIDA | H6: =VLOOKUP(H4,' CADASTRO'!$I$2:$Q$993,9,0) -> #N/A | J6: =VLOOKUP(J4,' CADASTRO'!$I$2:$Q$993,9,0) -> #N/A | L6: =VLOOKUP(L4,' CADASTRO'!$I$2:$Q$993,9,0) -> #N/A | N6: =VLOOKUP(N4,' CADASTRO'!$I$2:$Q$993,9,0) -> #N/A | P6: =VLOOKUP(P4,' CADASTRO'!$I$2:$Q$993,9,0) -> #N/A | R6: =VLOOKUP(R4,' CADASTRO'!$I$2:$Q$993,9,0) -> #N/A | T6: =VLOOKUP(T4,' CADASTRO'!$I$2:$Q$993,9,0) -> #N/A | W6: BT2 | AF6: 5 | AG6: X | AI6: 45856 | AJ6: 51 | AK6: 1 | AL6: REATOR 5 | AM6: PN | AN6: - | AO6: 290 | AP6: PN-290 | AQ6: P
C7: PISTA -002 | AF7: 6 | AG7: X | AI7: 45856 | AJ7: 51 | AK7: 1 | AL7: REATOR 5 | AM7: PN | AN7: - | AO7: 291 | AP7: PN-291 | AQ7: P
E8: FORMAS | F8: F1 | H8: F2 | J8: F3 | L8: F4 | N8: F5 | P8: F6 | R8: F7 | T8: F8 | W8: NF=> | Y8: =IF(Y9="","",Y9-378) -> 1256 | AA8: FLOW=> | AD8: vol(m³) | AI8: 45856 | AJ8: 51 | AK8: 1 | AL8: REATOR 5 | AM8: PN | AN8: - | AO8: 292 | AP8: PN-292 | AQ8: P
B9: item | C9: descrição das inspeções | F9: ok | G9: corrigir | H9: ok | I9: corrigir | J9: ok | K9: corrigir | L9: ok | M9: corrigir | N9: ok | O9: corrigir | P9: ok | Q9: corrigir | R9: ok | S9: corrigir | T9: ok | U9: corrigir | W9: SERIE=> | Y9: =IF(AG3="X",Y3+1,"") -> 1634 | AA9: HORA LANÇ => | AI9: 45856 | AJ9: 51 | AK9: 1 | AL9: PRIMARIO 2 | AM9: PNI | AN9: - | AO9: 87 | AP9: PR_PNI-87 | AQ9: PNI
W10: HORA ROMP. | Y10: CP1 (20H) | AA10: CP2 (20H) | AC10: CP3 (28D) | AD10: CP4 (28D)
B11: 1 | C11: QTDE DE CABOS E ALONGAMENTOS 16 C 321A356 | W11: RESIST.
B12: 2 | C12: PÉ 2X M24 | W12: BT3 | Y12: PN-002
B13: 3 | C13: INJETOR 1X | W13: NF=> | Y13: =IF(Y14="","",Y14-378) -> 1257 | AA13: FLOW=> | AD13: vol(m³)
B14: 4 | C14: TELA VIVEIRO E REFORÇO 16 MM EM CIMA DOS PINOS IÇAMENTOS 2X 7,5 TON/300 3 "u" 10 MM E 1 BARRA 1 MTS | W14: SERIE=> | Y14: =IF(AG4="X",$Y$3+2,"") -> 1635 | AA14: HORA LANÇ =>
B15: 5 | C15: JUNÇÃO 3/8 X 25 MM FLUTUADOR 2X | W15: HORA ROMP. | Y15: CP1 (20H) | AA15: CP2 (20H) | AC15: CP3 (28D) | AD15: CP4 (28D)
B16: 6 | C16: ESCORA 5,50 DO PÉ 5/8 | W16: RESIST.
B17: 7 | C17: RECOBRIMENTO SUPERIOR/ INFERIOR E LATERIAS
B18: 8 | C18: VIGAS LATERAIAS (ESTRIBOS E BARRAS) | W18: BT4
B19: 9 | C19: ÂNGULO DE A CADA 5 CONCRETAGEM | W19: NF=> | Y19: =IF(Y20="","",Y20-378) -> 1258 | AA19: FLOW=> | AD19: vol(m³)
B20: 10 | C20: REFORÇO DE CABEÇA E PE | W20: SERIE => | Y20: =IF(AG5="X",$Y$3+3,"") -> 1636 | AA20: HORA LANÇ =>
B21: 11 | C21: ESPAÇADOR DE TELA A TELA E VIGA (36X) | W21: HORA ROMP. | Y21: CP1 (20H) | AA21: CP2 (20H) | AC21: CP3 (28D) | AD21: CP4 (28D)
B22: 12 | C22: FECHAMENTO FORMA LATERAL (PINAGEM) (dois lados) | W22: RESIST.
B23: 13 | C23: DIMENSÕES DA PLACA (DIVISORIA ESCOSTADAS NA TRAVA)
B24: 14 | C24: TELAS SUPERIOR E INFERIOR ESTAO ATADAS | W24: BT5
B25: 15 | C25: QTDE DE BAINHAS (12 NO NEREDA E 6 NO PRIMARIO) E SE ESTAO ATADAS NA ZONA | W25: NF=> | Y25: =IF(Y26="","",Y26-378) -> 1259 | AA25: FLOW=> | AD25: vol(m³)
B26: 16 | C26: MEDIDAS DE TOPO DE FORMA (2380 NO PRIMARIO); (2375 NO NEREDA) | W26: SERIE=> | Y26: =IF(AG6="X",$Y$3+4,"") -> 1637 | AA26: HORA LANÇ =>
B27: 17 | C27: CHAPAS DE INSERTOS / SIKASWELL CHAPA DE TUBULAÇÃO | W27: HORA ROMP. | Y27: CP1 (20H) | AA27: CP2 (20H) | AC27: CP3 (28D) | AD27: CP4 (28D)
B28: 18 | C28: VERIFICAR SE ESTA VIBRANDO EM BAIXO DA TELINHA, EVITAR BROCA NO PINO | W28: RESIST.
B29: 19 | C29: LIMPEZA : SOPRAGEM E COLETA DE ARRAMES
B30: 20 | C30: MOV: 4 X 5TON X 125CB - NEREDA | W30: BT6
B31: 21 | C31: MOV: 4 X 5TON X 125CB + 4 X 5TON X 125ESF. PRIMARIO | H31: = | W31: NF => | Y31: =IF(Y32="","",Y32-378) -> 1260 | AA31: FLOW=> | AD31: vol(m³)
B32: 22 | C32: EMENDAS | W32: SERIE=> | Y32: =IF(AG7="X",$Y$3+5,"") -> 1638 | AA32: HORA LANÇ =>
F33: CABO 1 | H33: CABO 2 | J33: CABO 3 | L33: CABO 4 | N33: CABO 5 | P33: CABO 6 | R33: CABO 7 | T33: CABO 8 | W33: HORA ROMP. | Y33: CP1 (20H) | AA33: CP2 (20H) | AC33: CP3 (28D) | AD33: CP4 (28D)
C34: COLETAR CABOS | W34: RESIST.
F36: CABO 09 | H36: CABO 10 | J36: CABO 11 | L36: CABO 12 | N36: CABO 13 | P36: CABO 14 | R36: CABO 15 | T36: CABO 16
C37: COLETAR CABOS
F39: BOBINA N° | J39: 1063123216
F40: DATA: | J40: 45860
J41: 3
B42: NUMERO CONCRETAGEM | D42: =D3 -> 169 | E42: QUAL É A OBRA | F42: NEREDA | H42: NEREDA | J42: NEREDA | L42: NEREDA | N42: NEREDA | P42: NEREDA | R42: NEREDA | T42: PRIMARIO
...

Sheet SC-10 PN2 PRIMARIO
E1: BETONEIRA | AE1: BT1 | AQ1: data | AR1: se concretada marque "x" | AS1: se concretado | AT1: IDENT. TANQUE | AU1: PLACA | AY1: TIPO
AE2: NF=> | AG2: =AG3-378 -> 791 | AI2: FLOW=> | AL2: vol(m³) | AN2: 1 | AO2: X
B3: NUMERO CONCRETAGEM | D3: =MAX(' CADASTRO'!C2:C999) -> 169 | E3: QUAL É A OBRA | F3: PRIMARIO | H3: PRIMARIO | J3: PRIMARIO | L3: PRIMARIO | N3: PRIMARIO | P3: PRIMARIO | R3: PRIMARIO | T3: PRIMARIO | V3: PRIMARIO | X3: PRIMARIO | Z3: PRIMARIO | AB3: PRIMARIO | AE3: SERIE=> | AG3: 1169 | AI3: HORA LANÇ => | AN3: 2 | AO3: X
A4: data: | C4: =TODAY()+1 -> 46008 | E4: Placa n° => | F4: PR_PN-89 | H4: PR_PN-90 | J4: PR_PN-91 | L4: PR_PN-92 | N4: PR_PN-94 | P4: PR_PN-96 | R4: PR_PN-100 | T4: PR_PN-101 | V4: PR_PNI-63 | X4: PR_PN-102 | Z4: PR_PNI-69 | AB4: PR_PNI-75 | AE4: HORA ROMP. | AG4: CP1 (20H) | AI4: CP2 (20H) | AK4: CP3 (28D) | AL4: CP4 (28D) | AN4: 3 | AO4: X
E5: TIPO | F5: =VLOOKUP(F4,' CADASTRO'!$I$2:$J$999,2,0) -> P | H5: =VLOOKUP(H4,' CADASTRO'!$I$2:$J$999,2,0) -> P | J5: =VLOOKUP(J4,' CADASTRO'!$I$2:$J$999,2,0) -> P | L5: =VLOOKUP(L4,' CADASTRO'!$I$2:$J$999,2,0) -> P | N5: =VLOOKUP(N4,' CADASTRO'!$I$2:$J$999,2,0) -> P | P5: =VLOOKUP(P4,' CADASTRO'!$I$2:$J$999,2,0) -> P | R5: =VLOOKUP(R4,' CADASTRO'!$I$2:$J$999,2,0) -> P | T5: =VLOOKUP(T4,' CADASTRO'!$I$2:$J$999,2,0) -> P | V5: =VLOOKUP(V4,' CADASTRO'!$I$2:$J$999,2,0) -> PNI | X5: =VLOOKUP(X4,' CADASTRO'!$I$2:$J$999,2,0) -> P | Z5: =VLOOKUP(Z4,' CADASTRO'!$I$2:$J$999,2,0) -> PNI | AB5: =VLOOKUP(AB4,' CADASTRO'!$I$2:$J$999,2,0) -> PNI | AE5: RESIST. | AN5: 4 | AO5: X
A6: HORA INICIO | E6: INSERTS | F6: =VLOOKUP(F4,' CADASTRO'!$I$2:$Q$993,9,0) -> NÃO TEM CHAPA | H6: =VLOOKUP(H4,' CADASTRO'!$I$2:$Q$993,9,0) -> NÃO TEM CHAPA | J6: =VLOOKUP(J4,' CADASTRO'!$I$2:$Q$993,9,0) -> NÃO TEM CHAPA | L6: =VLOOKUP(L4,' CADASTRO'!$I$2:$Q$993,9,0) -> NÃO TEM CHAPA | N6: =VLOOKUP(N4,' CADASTRO'!$I$2:$Q$993,9,0) -> NÃO TEM CHAPA | P6: =VLOOKUP(P4,' CADASTRO'!$I$2:$Q$993,9,0) -> NÃO TEM CHAPA | R6: =VLOOKUP(R4,' CADASTRO'!$I$2:$Q$993,9,0) -> NÃO TEM CHAPA | T6: =VLOOKUP(T4,' CADASTRO'!$I$2:$Q$993,9,0) -> NÃO TEM CHAPA | V6: =VLOOKUP(V4,' CADASTRO'!$I$2:$Q$993,9,0) -> 02- 150X150 #3/8 | X6: =VLOOKUP(X4,' CADASTRO'!$I$2:$Q$993,9,0) -> NÃO TEM CHAPA | Z6: =VLOOKUP(Z4,' CADASTRO'!$I$2:$Q$993,9,0) -> 02- 150X150 #3/8 | AB6: =VLOOKUP(AB4,' CADASTRO'!$I$2:$Q$993,9,0) -> 02- 150X150 #3/8 | AE6: BT2 | AN6: 5 | AO6: X
C7: PISTA -002 | AN7: 6 | AO7: X
E8: FORMAS | F8: F1 | H8: F2 | J8: F3 | L8: F4 | N8: F5 | P8: F6 | R8: F7 | T8: F8 | V8: F9 | X8: F10 | Z8: F11 | AB8: F12 | AE8: NF=> | AG8: =IF(AG9="","",AG9-378) -> 792 | AI8: FLOW=> | AL8: vol(m³)
B9: item | C9: descrição das inspeções | F9: ok | G9: corrigir | H9: ok | I9: corrigir | J9: ok | K9: corrigir | L9: ok | M9: corrigir | N9: ok | O9: corrigir | P9: ok | Q9: corrigir | R9: ok | S9: corrigir | T9: ok | U9: corrigir | V9: ok | W9: corrigir | X9: ok | Y9: corrigir | Z9: ok | AA9: corrigir | AB9: ok | AC9: corrigir | AE9: SERIE=> | AG9: =IF(AO3="X",AG3+1,"") -> 1170 | AI9: HORA LANÇ =>
AE10: HORA ROMP. | AG10: CP1 (20H) | AI10: CP2 (20H) | AK10: CP3 (28D) | AL10: CP4 (28D)
B11: 1 | C11: QTDE DE CABOS E ALONGAMENTOS 16 C 321A356 | AE11: RESIST.
B12: 2 | C12: PÉ 2X M24 | AE12: BT3
B13: 3 | C13: INJETOR 1X | AE13: NF=> | AG13: =IF(AG14="","",AG14-378) -> 793 | AI13: FLOW=> | AL13: vol(m³)
B14: 4 | C14: VERIFICAR MEDIDA TPO PLACA ATE CANALETA 1,225 | AE14: SERIE=> | AG14: =IF(AO4="X",$AG$3+2,"") -> 1171 | AI14: HORA LANÇ =>
B15: 5 | C15: JUNÇÃO 3/8 X 25 MM FLUTUADOR 2X | AE15: HORA ROMP. | AG15: CP1 (20H) | AI15: CP2 (20H) | AK15: CP3 (28D) | AL15: CP4 (28D)
B16: 6 | C16: ESCORA 5,50 DO PÉ 5/8 | AE16: RESIST.
B17: 7 | C17: RECOBRIMENTO SUPERIOR/ INFERIOR E LATERIAS
B18: 8 | C18: VIGAS LATERAIAS (ESTRIBOS E BARRAS) | AE18: BT4
B19: 9 | C19: ÂNGULO DE A CADA 5 CONCRETAGEM | AE19: NF=> | AG19: =IF(AG20="","",AG20-378) -> 794 | AI19: FLOW=> | AL19: vol(m³)
B20: 10 | C20: REFORÇO DE CABEÇA E PE | AE20: SERIE => | AG20: =IF(AO5="X",$AG$3+3,"") -> 1172 | AI20: HORA LANÇ =>
B21: 11 | C21: ESPAÇADOR DE TELA A TELA E VIGA | AE21: HORA ROMP. | AG21: CP1 (20H) | AI21: CP2 (20H) | AK21: CP3 (28D) | AL21: CP4 (28D)
B22: 12 | C22: FECHAMENTO FORMA LATERAL (PINAGEM) (dois lados) | AE22: RESIST.
B23: 13 | C23: DIMENSÕES DA PLACA (DIVISORIA ESCOSTADAS NA TRAVA)
B24: 14 | C24: TELAS SUPERIOR E INFERIOR ESTAO ATADAS | AE24: BT5
B25: 15 | C25: QTDE DE BAINHAS (12 NO NEREDA E 6 NO PRIMARIO) E SE ESTAO ATADAS NA ZONA | AE25: NF=> | AI25: FLOW=> | AL25: vol(m³)
B26: 16 | C26: MEDIDAS DE TOPO DE FORMA (2380 NO PRIMARIO); (2375 NO NEREDA) | AE26: SERIE=> | AI26: HORA LANÇ =>
B27: 17 | C27: CHAPAS DE INSERTOS | AE27: HORA ROMP. | AG27: CP1 (20H) | AI27: CP2 (20H) | AK27: CP3 (28D) | AL27: CP4 (28D)
B28: 18 | C28: SIKASWELL CHAPA DE TUBULAÇÃO | AE28: RESIST.
B29: 19 | C29: LIMPEZA : SOPRAGEM E COLETA DE ARRAMES
B30: 20 | AE30: BT6
B31: 21 | C31: MOV: 4 X 5TON X 125CB + 4 X 5TON X 125ESF. PRIMARIO | AE31: NF => | AI31: FLOW=> | AL31: vol(m³)
B32: 22 | C32: EMENDAS | AE32: SERIE=> | AI32: HORA LANÇ =>
F33: CABO 1 | H33: CABO 2 | J33: CABO 3 | L33: CABO 4 | N33: CABO 5 | P33: CABO 6 | R33: CABO 7 | T33: CABO 8 | AE33: HORA ROMP. | AG33: CP1 (20H) | AI33: CP2 (20H) | AK33: CP3 (28D) | AL33: CP4 (28D)
AE34: RESIST.
F36: CABO 09 | H36: CABO 10 | J36: CABO 11 | L36: CABO 12 | N36: CABO 13 | P36: CABO 14 | R36: CABO 15 | T36: CABO 16
F39: BOBINA N° | J39: 1062631306 | R39: BOBINA N° | V39: 1062631306
F40: DATA: | J40: 45760 | R40: DATA: | V40: 45760
