Workbook

Sheet ENTRADAS
A1: 46752 | E1: SISTEMA SC-6 , SC-10 e SC-14 ORÇAMENTO DADOS DE ENTRADA E CÁLCULOS | M1: DATA: | O1: 45638 | BJ1: J
M2: REVISÃO: | O2: 3 | BJ2: S
E3: CLIENTE: | F3: Passarelli | M3: =IF(H11=0,0,"LOCAL:") -> LOCAL:
E4: OBRA: | F4: 12 tqs Nereda | M4: =H11 -> São Paulo - Tatuapé | P4: =IF(H11=0,0,VLOOKUP(E11,BI1292:BJ1318,2,0)) -> SP
C8: DADOS DE ENTRADA GERAL | BJ8: X
B10: LOCALIZAÇÃO DA OBRA: | E10: ESTADO: | H10: MUNICÍPIO: | M10: DISTÂNCIA RODOVIÁRIA
E11: São Paulo | H11: São Paulo - Tatuapé | M11: 1000 | O11: km
D13: =IF(E15>14,"ALTURA DO PAINEL MAIOR QUE 14,00 m ! PLANILHA NÃO ATENDE !",0) -> 0 | BJ13: Y
C15: ALTURA DO TANQUE (Ht) | E15: 7.15 | F15: m | G15: =IF(G18=0,0,"altura do painel = ") -> altura do painel = | I15: =IF(E15=0,0,E15+G18) -> 7.3 | J15: =IF(E15=0,0,"m") -> m | BJ15: 1
C16: ALTURA DE USO (Hu) | E16: 6.4 | F16: m (de projeto) | BJ16: 2
C17: MUDAR DIMENSÃO (Hu) | F17: m (caso queira alterar o Hu somente nos cálculos)
C18: ALTURA DE ANCORAGEM NA BASE ( h1) | G18: =IF(J18=0,0.15,J18) -> 0.15 | H18: m ( para alterar ) | BJ18: 3
BJ19: 4
F20: 1 | G20: 2 | H20: 3 | BJ20: 5
C21: QUANTIDADE DE TANQUES= | F21: 12 | G21: =IF(F21=1,"unidade","unidades") -> unidades
C22: QUANTIDADE DE TANQUES= | F22: =IF(F21>4,4,F21) -> 4 | G22: =IF(F22=1,"unidade","unidades") -> unidades
C25: DIÂMETRO INTERNO DO TANQUE ( PROJETO ): | G25: 47 | H25: m
G26: =IF(C37+C41+C45=0,0,VLOOKUP(BJ8,D37:O45,11,0)) -> 47.041151 | H26: =IF(G26=0,0,"m ( novo valor do diâmetro )") -> m ( novo valor do diâmetro )
D28: VOLUME ÚTIL DE PROJETO= | G28: =PI()*(G25/2)^2*E16 -> 11103.645 | H28: m³ | Q28: =IF(OR(G25>'TABELA SC-10 e 14'!B83,G25>'TABELA SC-10 e 14'!C83),10,0) -> 0
D30: VOLUME ÚTIL ADEQUADO= | G30: =RELATÓRIO!W10 -> 11132.918 | H30: m³ | I30: =IF(C32<>0,0,IF(I32<>0,"ALERTA !",0)) -> 0 | Q30: =IF(OR(G25>'TABELA SC-10 e 14'!B83,G25>'TABELA SC-10 e 14'!C83),10,0) -> 0
C32: =IF(G25=0,0,IF(ENTRADAS!G25<O32+O33+O35,"O DIÂMETRO MÍNIMO É "&O32+O33+O35&" m",0)) -> 0 | I32: =IF(C32<>0,0,IF(AND(E15<=6,G25<='TABELA SC-10 e 14'!D33),0,IF(AND(E15<=7,G25<='TABELA SC-10 e 14'!B68),0,IF(AND(E15<=8,G25<='TABELA SC-10 e 14'!B83),0,IF(G25=0,0,IF(Q35=110,"OS CÁLCULOS ESTÃO SENDO FEITOS, PORÉM ",IF(AND(E15<=6,G25>'TABELA SC-10 e 14'!D33,G25<='TABELA SC-10 e 14'!C126),0,IF('TABELA SC-10 e 14'!C2>'TABELA SC-10 e 14'!A125,"EXCEDEU O LIMITE MÁXIMO PERMITIDO,",IF(OR('TABELA SC-10 e 14'!H84=0,'TABELA SC-10 e 14'!C2>'TABELA SC-10 e 14'!A83),"OS CÁLCULOS ESTÃO SENDO FEITOS, PORÉM ",0))))))))) -> 0 | O32: =IF('TABELA SC-10 e 14'!A2="SC6",'TABELA SC-10 e 14'!D5,0) -> 0 | Q32: =IF(G25<='TABELA SC-10 e 14'!C125,100,0) -> 100 | BF32: =IF(AND(E15<=8,G25<='TABELA SC-10 e 14'!B83),0,I32) -> 0
I33: =IF('TABELA SC-10 e 14'!C2>'TABELA SC-10 e 14'!A103,"VERIFICAR COM ENGENHARIA",IF('TABELA SC-10 e 14'!C2>'TABELA SC-10 e 14'!A83,"O DIÂMETRO ESTÁ ALÉM DA TABELA PADRÃO, ",0)) -> 0 | O33: =IF('TABELA SC-10 e 14'!A2="SC10",'TABELA SC-10 e 14'!B5,0) -> 8.5142424
C35: DIÂMETRO INTERNO DO TANQUE NO SISTEMA ( marcar "X" ): | I35: =IF(C32<>0,0,IF(AND(E15<=6,G25<='TABELA SC-10 e 14'!D33),0,IF(AND(E15<=7,G25<='TABELA SC-10 e 14'!B68),0,IF(AND(E15<=8,G25<='TABELA SC-10 e 14'!B83),0,IF(G25=0,0,IF(Q35=110,"CONFIRMAR COM ENGENHARIA SE É POSSÍVEL.",IF(AND(E15<=6,G25>'TABELA SC-10 e 14'!D33,G25<='TABELA SC-10 e 14'!C126),0,IF('TABELA SC-10 e 14'!C2>'TABELA SC-10 e 14'!A125,"",IF(OR('TABELA SC-10 e 14'!H84=0,'TABELA SC-10 e 14'!C2>'TABELA SC-10 e 14'!A83),"CONFIRMAR COM ENGENHARIA SE É POSSÍVEL.",0))))))))) -> 0 | O35: =IF('TABELA SC-10 e 14'!A2="SC14",'TABELA SC-10 e 14'!C5,0) -> 0 | Q35: =Q30+Q32 -> 100
C36: as quantidade são para apenas 1 tanque | Q36: =IF(G66="X","SC6",IF(G60="X","SC10",IF(I60="X","SC14",0))) -> 0
C37: =IF(D37="X",1,0) -> 0 | E37: =IF(O42=10,0,IF(G25=0,0,IF(N45=0," OPÇÃO 1 - - - PARA MENOS - - -",0))) -> OPÇÃO 1 - - - PARA MENOS - - - | H37: =IF(O42=10,0,IF('TABELA SC-10 e 14'!D2=11,0,IF(G25=0,0,IF(N45=0,'TABELA SC-10 e 14'!D2,0)))) -> 61 | I37: =IF(O42=10,0,IF(G25=0,0,IF('TABELA SC-10 e 14'!D2=11,0,IF(N45=0,"PAINÉIS E DIÂMETRO PASSA PARA =",0)))) -> PAINÉIS E DIÂMETRO PASSA PARA = | N37: =IF(O42=10,0,IF(N45=0,IF(G25=0,0,'TABELA SC-10 e 14'!K2),0)) -> 46.273356 | O37: =IF(O42=10,0,IF(G25=0,0,IF(N45=0,"m",0))) -> m
I38: =IF(O42=10,0,IF(N37=0,0," O DIÂMETRO DIMINUI =")) -> O DIÂMETRO DIMINUI = | M38: =IF(O42=10,0,IF(N37=0,0,G25-N37)) -> 0.72664384 | N38: =IF(O42=10,0,IF(N37=0,0,"m")) -> m
E39: =IF(E15=0,0,IF(O42=10,"esta não",IF(N37=0,"esta não",IF(M38=0,0,"marque 'X' somente na opção 1 e veja quanto -------")))) -> marque 'X' somente na opção 1 e veja quanto ------- | I39: =IF(O42=10,0,IF(N37=0,0,"--------------- O VOLUME DIMINUI =")) -> --------------- O VOLUME DIMINUI = | M39: =IF(D37="x",IF(O42=10,0,IF(N37=0,0,G28-F131)),0) -> 0 | N39: =IF(O42=10,0,IF(N37=0,0,"m³")) -> m³
C41: =IF(D41="X",1,0) -> 1 | D41: x | E41: =IF(E15=0,0,IF(O42=10," MARCAR ESTA OPÇÃO ---------------",IF(G25=0,0,IF(N45=0," OPÇÃO 2 - - - PARA MAIS - - - - - -"," OPÇÃO 1 - - - PARA MENOS - - - - - -")))) -> OPÇÃO 2 - - - PARA MAIS - - - - - - | H41: =IF(G25=0,0,'TABELA SC-10 e 14'!I2) -> 62 | I41: =IF(G25=0,0,"PAINÉIS E DIÂMETRO PASSA PARA =") -> PAINÉIS E DIÂMETRO PASSA PARA = | N41: =IF(G25=0,0,'TABELA SC-10 e 14'!L2) -> 47.041151 | O41: =IF(G25=0,0,"m") -> m
I42: =IF(G25=0,0,IF(N41=G25,"O DIÂMETRO ZEROU",IF(N41=0,0,IF(G25>N41," O DIÂMETRO DIMINUI ="," O DIÂMETRO AUMENTA =")))) -> O DIÂMETRO AUMENTA = | M42: =IF(N41=0,0,IF(G25-N41<0,(G25-N41)*-1,G25-N41)) -> 0.041150642 | N42: =IF(N41=0,0,"m") -> m | O42: =IF(M42<0.01,10,0) -> 0
E43: =IF(E15=0,0,IF(N45=0,"marque 'X' somente na opção 2 e veja quanto","marque 'X' somente na opção 1 e veja quanto --------")) -> marque 'X' somente na opção 2 e veja quanto | I43: =IF(G25=0,0,IF(N41=G25,"O VOLUME ZEROU",IF(N41=0,0,IF(G25>N41,"--------------- O VOLUME DIMINUI =","--------------- O VOLUME AUMENTA =")))) -> --------------- O VOLUME AUMENTA = | M43: =IF(D41="x",IF(N41=0,0,IF(G25-N41<0,(G28-F131)*-1,G25-N41)),0) -> 29.27304 | N43: =IF(N41=0,0,"m³") -> m³
C45: =IF(D45="X",1,0) -> 0 | E45: =IF(N45=0,0," OPÇÃO 2 - - - PARA MAIS - - - - - -") -> 0 | H45: =IF(O42=10,0,IF(G25=0,0,'TABELA SC-10 e 14'!J2)) -> 0 | I45: =IF(O42=10,0,IF(N45=0,0,"PAINÉIS E DIÂMETRO PASSA PARA =")) -> 0 | N45: =IF(O42=10,0,IF(G25=0,0,'TABELA SC-10 e 14'!M2)) -> 0 | O45: =IF(O42=10,0,IF(H45=0,0,"m")) -> 0
I46: =IF(O42=10,0,IF(N45=0,0," O DIÂMETRO AUMENTA =")) -> 0 | M46: =IF(O42=10,0,IF(N45=0,0,N45-G25)) -> 0 | N46: =IF(O42=10,0,IF(N45=0,0,"m")) -> 0
E47: =IF(E15=0,0,IF(M46=0,"esta não","marque 'X' somente na opção 2 e veja quanto")) -> esta não | I47: =IF(O42=10,0,IF(N45=0,0," O VOLUME AUMENTA =")) -> 0 | M47: =IF(D45="x",IF(O42=10,0,IF(N45=0,0,(G28-F131)*-1)),0) -> 0 | N47: =IF(O42=10,0,IF(N45=0,0,"m³")) -> 0
C50: =IF(F21<>4,"PAREDES DO TANQUE --------- AS QUANTIDADES NA PLANILHA INSUMOS SÃO PARA 4 TANQUES","PAREDES DO TANQUE") -> PAREDES DO TANQUE --------- AS QUANTIDADES NA PLANILHA INSUMOS SÃO PARA 4 TANQUES
L52: observações ( caso necessário ): | BJ52: 6
C53: TIPO DE SISTEMA ( analisado apenas 1 tanque )
C54: =IF(I15=0,0,IF(AND(E15<=4,G25>'TABELA SC-10 e 14'!B83,G25<='TABELA SC-10 e 14'!B89),0,IF(OR('TABELA SC-10 e 14'!AB12<>0,'TABELA SC-10 e 14'!AB13<>0,'TABELA SC-10 e 14'!AC13<>0),"X",0))) -> 0 | D54: =IF(AND(E15<=4,G25>'TABELA SC-10 e 14'!B83,G25<='TABELA SC-10 e 14'!B89),0,IF('TABELA SC-10 e 14'!AB12="SC10","PELA TABELA SOPLACAS ESTE DÂMETRO E ESSA ALTURA NÃO PERMITEM O SC-6 !",IF('TABELA SC-10 e 14'!AB13="SC14","PELA TABELA SOPLACAS ESTE DÂMETRO E ESSA ALTURA NÃO PERMITEM O SC-10 !",IF('TABELA SC-10 e 14'!AC13="SC14","PELA TABELA SOPLACAS ESTE DÂMETRO E ESSA ALTURA NÃO PERMITEM O SC-10 !",0)))) -> 0
D55: =IF(AND(E15<=4,G25>'TABELA SC-10 e 14'!B83,G25<='TABELA SC-10 e 14'!B89),0,IF('TABELA SC-10 e 14'!AB12="SC10","LOGO, MARQUE 'X' NA CAIXA À DIREITA ( SC-10)",IF('TABELA SC-10 e 14'!AB13="SC14","LOGO, MARQUE 'X' NA CAIXA À DIREITA ( SC-14)",IF('TABELA SC-10 e 14'!AC13="SC14","LOGO, MARQUE 'X' NA CAIXA À DIREITA ( SC-14)",0)))) -> 0
D56: =IF(AND(E15<=4,G25>'TABELA SC-10 e 14'!B83,G25<='TABELA SC-10 e 14'!B89),0,IF('TABELA SC-10 e 14'!AB12="SC10","MAS, SE QUISER CONTINUAR COM O SISTEMA DA REGRA AUTOMÁTICA, ",IF('TABELA SC-10 e 14'!AB13="SC14","MAS, SE QUISER CONTINUAR COM O SISTEMA DA REGRA AUTOMÁTICA, ",IF('TABELA SC-10 e 14'!AC13="SC14","MAS, SE QUISER CONTINUAR COM O SISTEMA DA REGRA AUTOMÁTICA, ",0)))) -> 0
D57: =IF(AND(E15<=4,G25>'TABELA SC-10 e 14'!B83,G25<='TABELA SC-10 e 14'!B89),0,IF('TABELA SC-10 e 14'!AB12="SC10"," ENTÃO MARQUE 'X' NA CAIXA À DIREITA ( SC-10) CONFIRMANDO ESTE SISTEMA",IF('TABELA SC-10 e 14'!AB13="SC14"," ENTÃO MARQUE 'X' NA CAIXA À DIREITA ( SC-10) CONFIRMANDO ESTE SISTEMA",IF('TABELA SC-10 e 14'!AC13="SC14"," ENTÃO MARQUE 'X' NA CAIXA À DIREITA ( SC-10) CONFIRMANDO ESTE SISTEMA",0)))) -> 0
...

Sheet TABELA SC-10 e 14
A1: SISTEMA | B1: diâmentro de projeto | C1: quant. painéis real | D1: quant. painéis para baixo | I1: quant. painéis para cima | J1: quant. painéis extra | K1: diâmentro para baixo | L1: diâmentro para cima | M1: diâmentro extra | O1: maior diâmetro possível | T1: 0.03939 | V1: ANTES ERA =ENTRADAS!G59
A2: =IF(AND(ENTRADAS!Q35=110,ENTRADAS!Q36<>0),IF(ENTRADAS!G66="X","SC6",IF(CÁLCULOS!C19="X","SC10",IF(CÁLCULOS!E19="X","SC14",0))),IF(ENTRADAS!Q35=110,"SC14",IF(ENTRADAS!G66="X","SC6",IF(CÁLCULOS!C19="X","SC10",IF(CÁLCULOS!E19="X","SC14",0))))) -> SC10 | B2: =CÁLCULOS!G23 -> 47 | C2: =IF(B2=0,0,IF(A2="SC6",PI()*(B2+0.09)/2.1,IF(A2="SC10",PI()*(B2+0.24)/2.4,IF(A2="SC14",PI()*(B2+0.3)/2.4,0)))) -> 61.837015 | D2: =ROUNDDOWN(IF(B2=0,0,IF(A2="SC6",PI()*(B2+0.09)/2.1,IF(A2="SC10",PI()*(B2+0.24)/2.4,IF(A2="SC14",PI()*(B2+0.3)/2.4,0)))),0) -> 61 | I2: =ROUNDUP(IF(B2=0,0,IF(A2="SC6",PI()*(B2+0.09)/2.1,IF(A2="SC10",PI()*(B2+0.24)/2.4,IF(A2="SC14",PI()*(B2+0.3)/2.4,0)))),0) -> 62 | J2: =IF(L2=0,0,IF(L2<B2,I2+1,0)) -> 0 | K2: =IF(D2<A5,0,IF(D2>A125,0,IF(B2=0,0,IF(A2="SC6",VLOOKUP(D2,A5:D125,4,0),IF(A2="SC10",VLOOKUP(D2,A5:B125,2,0),IF(A2="SC14",VLOOKUP(D2,A5:C125,3,0),0)))))) -> 46.273356 | L2: =IF(I2>A125,0,IF(B2=0,0,IF(A2="SC6",VLOOKUP(I2,A5:D125,4,0),IF(A2="SC10",VLOOKUP(I2,A5:B125,2,0),IF(A2="SC14",VLOOKUP(I2,A5:C125,3,0),0))))) -> 47.041151 | M2: =IF(J2=0,0,IF(J2>A125,0,IF(L2<B2,N2,0))) -> 0 | N2: =IF(A2="SC6",VLOOKUP(I2+1,A5:D125,4,0),IF(A2="SC10",VLOOKUP(I2+1,A5:D125,2,0),IF(A2="SC14",VLOOKUP(I2+1,A5:D125,3,0),0))) -> 47.808924 | O2: =LARGE(B5:D189,1) -> 101.52889
B3: Diâm. Interno no meio do painel | C3: Diâm. Interno no meio do painel | D3: Diâm. Interno no meio do painel | I3: Ângulo teta p/ confecção | J3: área à 90° | K3: altura h à 90° | L3: a= | M3: c= | N3: b= | O3: distância superior entre formas | P3: desconto dos triangulos | Q3: desconto da parte superior | R3: área desconto lateral(2X) | S3: área do miolo inferior | T3: área Real final da secção SEM miolo inferior | U3: % redução
A4: Nº PAINÉIS | B4: SC10 | C4: SC14 | D4: SC6 | E4: altura max | F4: diâm min | G4: diâm max | AB4: Como a capacidade de carga de carretas é definida pelo semi-reboque acoplado ao cavalo mecânico, os tipos diferentes são:
A5: 12 | B5: =(1.205/TAN(PI()/A5)-0.24)*2 -> 8.5142424 | C5: =(1.205/TAN(PI()/A5)-0.295)*2 -> 8.4042424 | D5: =((2.1+0.006-0.005)/2/TAN(PI()/A5)-0.07)*2 -> 7.7010387 | E5: =IF(AND(ENTRADAS!$E$15>13,ENTRADAS!$E$15<=14),14,0) -> 0 | F5: =IF(E5>0,$C$5,0) -> 0 | G5: =IF(E5>0,$C$63,0) -> 0 | H5: =IF(E5=0,0,IF(AND(ENTRADAS!$G$25>=F5,ENTRADAS!$G$25<=G5),1,0)) -> 0 | I5: =180/A5 -> 15 | J5: 0.479 | K5: 0.24328 | L5: =K5*TAN(PI()*I5/180) -> 0.06518668 | M5: =L5*SIN(PI()*(I5/2)/180) -> 0.0085085691 | N5: =M5*COS(PI()*(I5)/180) -> 0.0082186466 | O5: =CÁLCULOS!$F$79 -> 2.3856884 | P5: =L5*K5 -> 0.015858615 | Q5: =(O5-(2*L5))*N5 -> 0.018535637 | R5: =P5+Q5 -> 0.034394253 | S5: =$T$1 -> 0.03939 | T5: =IF($U$1="X",J5-R5-S5,J5-R5) -> 0.44460575 | U5: =(J5-T5)/J5*100 -> 7.1804285 | W5: nº painéis | X5: diâmetro | Y5: lógica | Z5: tipo sistema | AB5: Carreta 2 eixos: semi reboque com 2 eixos. Comprimento máximo de 18,15 metros. Capacidade de carga: 23 toneladas. Peso bruto máximo de 33 toneladas. Peso máximo permitido por eixo: 6 no eixo dianteiro, 10 no eixo central, 17 no eixo traseiro.
A6: 13 | B6: =(1.205/TAN(PI()/A6)-0.24)*2 -> 9.2977544 | C6: =(1.205/TAN(PI()/A6)-0.295)*2 -> 9.1877544 | D6: =((2.1+0.006-0.005)/2/TAN(PI()/A6)-0.07)*2 -> 8.3840921 | E6: =IF(AND(ENTRADAS!$E$15>13,ENTRADAS!$E$15<=14),14,0) -> 0 | F6: =IF(E6>0,$C$5,0) -> 0 | G6: =IF(E6>0,$C$63,0) -> 0 | H6: =IF(E6=0,0,IF(AND(ENTRADAS!$G$25>=F6,ENTRADAS!$G$25<=G6),1,0)) -> 0 | I6: =180/A6 -> 13.846154 | J6: 0.479 | K6: 0.24328 | L6: =K6*TAN(PI()*I6/180) -> 0.059963135 | M6: =L6*SIN(PI()*(I6/2)/180) -> 0.0072277572 | N6: =M6*COS(PI()*(I6)/180) -> 0.0070177317 | O6: =CÁLCULOS!$F$79 -> 2.3856884 | P6: =L6*K6 -> 0.014587831 | Q6: =(O6-(2*L6))*N6 -> 0.015900511 | R6: =P6+Q6 -> 0.030488342 | S6: =$T$1 -> 0.03939 | T6: =IF($U$1="X",J6-R6-S6,J6-R6) -> 0.44851166 | U6: =(J6-T6)/J6*100 -> 6.3649983 | W6: =IF(ENTRADAS!D37="X",'TABELA SC-10 e 14'!D2,IF(ENTRADAS!D41="X",'TABELA SC-10 e 14'!I2,IF(ENTRADAS!D45="X",'TABELA SC-10 e 14'!J2,0))) -> 62 | X6: =IF(W6=0,0,VLOOKUP(W6,$A$5:$B$126,2,0)) -> 47.041151 | Y6: =IF(AND(ENTRADAS!E15<=6,X6<=B75),100,IF(AND(ENTRADAS!E15>6,ENTRADAS!E15<7,X6>=B68,X6<=B76),1000,IF(AND(ENTRADAS!E15>=6,ENTRADAS!E15<7,X6>=B68),1000,100))) -> 100 | Z6: =IF(ENTRADAS!E15>10,"SC14",IF(ENTRADAS!Q35=110,"SC14",IF(AND(Y11>=100,Y11<=500),"SC10",IF(AND(Y11>=1000,Y11<=5000),"SC14",0)))) -> SC10 | AB6: Carreta 3 eixos: semi reboque com 3 eixos. Comprimento máximo: 18,15 metros. Capacidade de carga: até 25 toneladas. Peso bruto máximo: 41,5 toneladas. Peso máximo permitido por eixo: 6 toneladas no eixo dianteiro, 10 no eixo central, 25,5 no eixo traseiro.
A7: 14 | B7: =(1.205/TAN(PI()/A7)-0.24)*2 -> 10.0789 | C7: =(1.205/TAN(PI()/A7)-0.295)*2 -> 9.9688999 | D7: =((2.1+0.006-0.005)/2/TAN(PI()/A7)-0.07)*2 -> 9.0650824 | E7: =IF(AND(ENTRADAS!$E$15>13,ENTRADAS!$E$15<=14),14,0) -> 0 | F7: =IF(E7>0,$C$5,0) -> 0 | G7: =IF(E7>0,$C$63,0) -> 0 | H7: =IF(E7=0,0,IF(AND(ENTRADAS!$G$25>=F7,ENTRADAS!$G$25<=G7),1,0)) -> 0 | I7: =180/A7 -> 12.857143 | J7: 0.479 | K7: 0.24328 | L7: =K7*TAN(PI()*I7/180) -> 0.055527072 | M7: =L7*SIN(PI()*(I7/2)/180) -> 0.0062170596 | N7: =M7*COS(PI()*(I7)/180) -> 0.0060611849 | O7: =CÁLCULOS!$F$79 -> 2.3856884 | P7: =L7*K7 -> 0.013508626 | Q7: =(O7-(2*L7))*N7 -> 0.013786979 | R7: =P7+Q7 -> 0.027295605 | S7: =$T$1 -> 0.03939 | T7: =IF($U$1="X",J7-R7-S7,J7-R7) -> 0.45170439 | U7: =(J7-T7)/J7*100 -> 5.6984562 | Y7: =IF(AND(ENTRADAS!E15<=7,X6<=B67),100,IF(AND(ENTRADAS!E15>7,ENTRADAS!E15<8,X6>=B61,X6<=B68),1000,IF(AND(ENTRADAS!E15>=7,ENTRADAS!E15<8,X6>=B61),1000,100))) -> 100 | AB7: Carreta cavalo trucado: um cavalo mecânico trucado e semi reboque com 3 eixos. Comprimento máximo: 18,15 metros. Capacidade de carga: até 30,50 toneladas. Peso bruto máximo: 45 a 46 toneladas. Peso máximo permitido por eixo: 6 toneladas no eixo dianteiro, 10 no primeiro eixo, 10 no segundo eixo, 17 no eixo traseiro.
A8: 15 | B8: =(1.205/TAN(PI()/A8)-0.24)*2 -> 10.858159 | C8: =(1.205/TAN(PI()/A8)-0.295)*2 -> 10.748159 | D8: =((2.1+0.006-0.005)/2/TAN(PI()/A8)-0.07)*2 -> 9.7444279 | E8: =IF(AND(ENTRADAS!$E$15>13,ENTRADAS!$E$15<=14),14,0) -> 0 | F8: =IF(E8>0,$C$5,0) -> 0 | G8: =IF(E8>0,$C$63,0) -> 0 | H8: =IF(E8=0,0,IF(AND(ENTRADAS!$G$25>=F8,ENTRADAS!$G$25<=G8),1,0)) -> 0 | I8: =180/A8 -> 12 | J8: 0.479 | K8: 0.24328 | L8: =K8*TAN(PI()*I8/180) -> 0.05171076 | M8: =L8*SIN(PI()*(I8/2)/180) -> 0.0054052463 | N8: =M8*COS(PI()*(I8)/180) -> 0.0052871287 | O8: =CÁLCULOS!$F$79 -> 2.3856884 | P8: =L8*K8 -> 0.012580194 | Q8: =(O8-(2*L8))*N8 -> 0.012066639 | R8: =P8+Q8 -> 0.024646833 | S8: =$T$1 -> 0.03939 | T8: =IF($U$1="X",J8-R8-S8,J8-R8) -> 0.45435317 | U8: =(J8-T8)/J8*100 -> 5.1454765 | Y8: =IF(AND(ENTRADAS!E15<=8,X6<=B60),100,IF(AND(ENTRADAS!E15>8,ENTRADAS!E15<9,X6>=B55,X6<=B61),1000,IF(AND(ENTRADAS!E15>=8,ENTRADAS!E15<9,X6>=B55),1000,100))) -> 100
A9: 16 | B9: =(1.205/TAN(PI()/A9)-0.24)*2 -> 11.635888 | C9: =(1.205/TAN(PI()/A9)-0.295)*2 -> 11.525888 | D9: =((2.1+0.006-0.005)/2/TAN(PI()/A9)-0.07)*2 -> 10.42244 | E9: =IF(AND(ENTRADAS!$E$15>13,ENTRADAS!$E$15<=14),14,0) -> 0 | F9: =IF(E9>0,$C$5,0) -> 0 | G9: =IF(E9>0,$C$63,0) -> 0 | H9: =IF(E9=0,0,IF(AND(ENTRADAS!$G$25>=F9,ENTRADAS!$G$25<=G9),1,0)) -> 0 | I9: =180/A9 -> 11.25 | J9: 0.479 | K9: 0.24328 | L9: =K9*TAN(PI()*I9/180) -> 0.048391401 | M9: =L9*SIN(PI()*(I9/2)/180) -> 0.0047431867 | N9: =M9*COS(PI()*(I9)/180) -> 0.0046520477 | O9: =CÁLCULOS!$F$79 -> 2.3856884 | P9: =L9*K9 -> 0.01177266 | Q9: =(O9-(2*L9))*N9 -> 0.010648098 | R9: =P9+Q9 -> 0.022420758 | S9: =$T$1 -> 0.03939 | T9: =IF($U$1="X",J9-R9-S9,J9-R9) -> 0.45657924 | U9: =(J9-T9)/J9*100 -> 4.6807428 | Y9: =IF(AND(ENTRADAS!E15<=9,X6<=B54),100,IF(AND(ENTRADAS!E15>9,ENTRADAS!E15<10,X6>=B50,X6<=B55),1000,IF(AND(ENTRADAS!E15>=9,ENTRADAS!E15<10,X6>=B50),1000,100))) -> 100 | AA9: =IF(AND(Z6="SC10",Z14="xiii"),500,0) -> 500 | AB9: =IF(AND(A2="SC6",Z6="SC10"),500,0) -> 0 | AC9: =AA9+AB9 -> 500
A10: 17 | B10: =(1.205/TAN(PI()/A10)-0.24)*2 -> 12.412361 | C10: =(1.205/TAN(PI()/A10)-0.295)*2 -> 12.302361 | D10: =((2.1+0.006-0.005)/2/TAN(PI()/A10)-0.07)*2 -> 11.099357 | E10: =IF(AND(ENTRADAS!$E$15>13,ENTRADAS!$E$15<=14),14,0) -> 0 | F10: =IF(E10>0,$C$5,0) -> 0 | G10: =IF(E10>0,$C$63,0) -> 0 | H10: =IF(E10=0,0,IF(AND(ENTRADAS!$G$25>=F10,ENTRADAS!$G$25<=G10),1,0)) -> 0 | I10: =180/A10 -> 10.588235 | J10: 0.479 | K10: 0.24328 | L10: =K10*TAN(PI()*I10/180) -> 0.045476914 | M10: =L10*SIN(PI()*(I10/2)/180) -> 0.0041960802 | N10: =M10*COS(PI()*(I10)/180) -> 0.004124634 | O10: =CÁLCULOS!$F$79 -> 2.3856884 | P10: =L10*K10 -> 0.011063624 | Q10: =(O10-(2*L10))*N10 -> 0.0094649402 | R10: =P10+Q10 -> 0.020528564 | S10: =$T$1 -> 0.03939 | T10: =IF($U$1="X",J10-R10-S10,J10-R10) -> 0.45847144 | U10: =(J10-T10)/J10*100 -> 4.2857127 | Y10: =IF(ENTRADAS!E15>10,1000,IF(AND(ENTRADAS!E15=10,X6>B49),1000,100)) -> 100 | AA10: =IF(AND(Z6="SC14",Z14="xiii"),1000,0) -> 0 | AB10: =IF(AND(A2="SC6",Z6="SC14"),1000,0) -> 0 | AC10: =AA10+AB10 -> 0
A11: 18 | B11: =(1.205/TAN(PI()/A11)-0.24)*2 -> 13.187789 | C11: =(1.205/TAN(PI()/A11)-0.295)*2 -> 13.077789 | D11: =((2.1+0.006-0.005)/2/TAN(PI()/A11)-0.07)*2 -> 11.775363 | E11: =IF(AND(ENTRADAS!$E$15>13,ENTRADAS!$E$15<=14),14,0) -> 0 | F11: =IF(E11>0,$C$5,0) -> 0 | G11: =IF(E11>0,$C$63,0) -> 0 | H11: =IF(E11=0,0,IF(AND(ENTRADAS!$G$25>=F11,ENTRADAS!$G$25<=G11),1,0)) -> 0 | I11: =180/A11 -> 10 | J11: 0.479 | K11: 0.24328 | L11: =K11*TAN(PI()*I11/180) -> 0.042896828 | M11: =L11*SIN(PI()*(I11/2)/180) -> 0.0037387049 | N11: =M11*COS(PI()*(I11)/180) -> 0.0036819056 | O11: =CÁLCULOS!$F$79 -> 2.3856884 | P11: =L11*K11 -> 0.01043594 | Q11: =(O11-(2*L11))*N11 -> 0.0084679953 | R11: =P11+Q11 -> 0.018903936 | S11: =$T$1 -> 0.03939 | T11: =IF($U$1="X",J11-R11-S11,J11-R11) -> 0.46009606 | U11: =(J11-T11)/J11*100 -> 3.9465419 | X11: soma= | Y11: =SUM(Y6:Y10) -> 500
A12: 19 | B12: =(1.205/TAN(PI()/A12)-0.24)*2 -> 13.962338 | C12: =(1.205/TAN(PI()/A12)-0.295)*2 -> 13.852338 | D12: =((2.1+0.006-0.005)/2/TAN(PI()/A12)-0.07)*2 -> 12.450603 | E12: =IF(AND(ENTRADAS!$E$15>13,ENTRADAS!$E$15<=14),14,0) -> 0 | F12: =IF(E12>0,$C$5,0) -> 0 | G12: =IF(E12>0,$C$63,0) -> 0 | H12: =IF(E12=0,0,IF(AND(ENTRADAS!$G$25>=F12,ENTRADAS!$G$25<=G12),1,0)) -> 0 | I12: =180/A12 -> 9.4736842 | J12: 0.479 | K12: 0.24328 | L12: =K12*TAN(PI()*I12/180) -> 0.040596252 | M12: =L12*SIN(PI()*(I12/2)/180) -> 0.0033524119 | N12: =M12*COS(PI()*(I12)/180) -> 0.0033066894 | O12: =CÁLCULOS!$F$79 -> 2.3856884 | P12: =L12*K12 -> 0.0098762562 | Q12: =(O12-(2*L12))*N12 -> 0.0076202521 | R12: =P12+Q12 -> 0.017496508 | S12: =$T$1 -> 0.03939 | T12: =IF($U$1="X",J12-R12-S12,J12-R12) -> 0.46150349 | U12: =(J12-T12)/J12*100 -> 3.6527157 | AB12: =IF(AC9=1000,"SC10",0) -> 0
A13: 20 | B13: =(1.205/TAN(PI()/A13)-0.24)*2 -> 14.736141 | C13: =(1.205/TAN(PI()/A13)-0.295)*2 -> 14.626141 | D13: =((2.1+0.006-0.005)/2/TAN(PI()/A13)-0.07)*2 -> 13.125192 | E13: =IF(AND(ENTRADAS!$E$15>13,ENTRADAS!$E$15<=14),14,0) -> 0 | F13: =IF(E13>0,$C$5,0) -> 0 | G13: =IF(E13>0,$C$63,0) -> 0 | H13: =IF(E13=0,0,IF(AND(ENTRADAS!$G$25>=F13,ENTRADAS!$G$25<=G13),1,0)) -> 0 | I13: =180/A13 -> 9 | J13: 0.479 | K13: 0.24328 | L13: =K13*TAN(PI()*I13/180) -> 0.038531767 | M13: =L13*SIN(PI()*(I13/2)/180) -> 0.0030231676 | N13: =M13*COS(PI()*(I13)/180) -> 0.0029859474 | O13: =CÁLCULOS!$F$79 -> 2.3856884 | P13: =L13*K13 -> 0.0093740082 | Q13: =(O13-(2*L13))*N13 -> 0.0068934323 | R13: =P13+Q13 -> 0.016267441 | S13: =$T$1 -> 0.03939 | T13: =IF($U$1="X",J13-R13-S13,J13-R13) -> 0.46273256 | U13: =(J13-T13)/J13*100 -> 3.3961254 | W13: nº painéis | X13: diâmetro | Y13: lógica | Z13: tipo sistema | AB13: =IF(ENTRADAS!E15>10,0,IF(ENTRADAS!Q35=110,"SC14",IF(AC10=2000,"SC14",0))) -> 0 | AC13: =IF(AND(Z6="SC14",A2="SC10"),"SC14",0) -> 0
A14: 21 | B14: =(1.205/TAN(PI()/A14)-0.24)*2 -> 15.509305 | C14: =(1.205/TAN(PI()/A14)-0.295)*2 -> 15.399305 | D14: =((2.1+0.006-0.005)/2/TAN(PI()/A14)-0.07)*2 -> 13.799224 | E14: =IF(AND(ENTRADAS!$E$15>13,ENTRADAS!$E$15<=14),14,0) -> 0 | F14: =IF(E14>0,$C$5,0) -> 0 | G14: =IF(E14>0,$C$63,0) -> 0 | H14: =IF(E14=0,0,IF(AND(ENTRADAS!$G$25>=F14,ENTRADAS!$G$25<=G14),1,0)) -> 0 | I14: =180/A14 -> 8.5714286 | J14: 0.479 | K14: 0.24328 | L14: =K14*TAN(PI()*I14/180) -> 0.03666856 | M14: =L14*SIN(PI()*(I14/2)/180) -> 0.0027402449 | N14: =M14*COS(PI()*(I14)/180) -> 0.0027096387 | O14: =CÁLCULOS!$F$79 -> 2.3856884 | P14: =L14*K14 -> 0.0089207273 | Q14: =(O14-(2*L14))*N14 -> 0.0062656364 | R14: =P14+Q14 -> 0.015186364 | S14: =$T$1 -> 0.03939 | T14: =IF($U$1="X",J14-R14-S14,J14-R14) -> 0.46381364 | U14: =(J14-T14)/J14*100 -> 3.1704308 | W14: =IF(ENTRADAS!D37="X",'TABELA SC-10 e 14'!D2,IF(ENTRADAS!D41="X",'TABELA SC-10 e 14'!I2,IF(ENTRADAS!D45="X",'TABELA SC-10 e 14'!J2,0))) -> 62 | X14: =IF(W14=0,0,VLOOKUP(W14,$A$5:$D$126,4,0)) -> 0 | Y14: =IF(X14=0,0,IF(AND(ENTRADAS!E15<=6,X14<=D33),1000,100)) -> 0 | Z14: =IF(A2="SC6","SC6",IF(Y14=1000,"SC6","xiii")) -> xiii
A15: 22 | B15: =(1.205/TAN(PI()/A15)-0.24)*2 -> 16.281918 | C15: =(1.205/TAN(PI()/A15)-0.295)*2 -> 16.171918 | D15: =((2.1+0.006-0.005)/2/TAN(PI()/A15)-0.07)*2 -> 14.472776 | E15: =IF(AND(ENTRADAS!$E$15>13,ENTRADAS!$E$15<=14),14,0) -> 0 | F15: =IF(E15>0,$C$5,0) -> 0 | G15: =IF(E15>0,$C$63,0) -> 0 | H15: =IF(E15=0,0,IF(AND(ENTRADAS!$G$25>=F15,ENTRADAS!$G$25<=G15),1,0)) -> 0 | I15: =180/A15 -> 8.1818182 | J15: 0.479 | K15: 0.24328 | L15: =K15*TAN(PI()*I15/180) -> 0.034978383 | M15: =L15*SIN(PI()*(I15/2)/180) -> 0.0024953293 | N15: =M15*COS(PI()*(I15)/180) -> 0.0024699304 | O15: =CÁLCULOS!$F$79 -> 2.3856884 | P15: =L15*K15 -> 0.0085095411 | Q15: =(O15-(2*L15))*N15 -> 0.0057196961 | R15: =P15+Q15 -> 0.014229237 | S15: =$T$1 -> 0.03939 | T15: =IF($U$1="X",J15-R15-S15,J15-R15) -> 0.46477076 | U15: =(J15-T15)/J15*100 -> 2.9706132 | Y15: antigo | Z15: =IF(Y14=1000,"SC6","xiii") -> xiii
A16: 23 | B16: =(1.205/TAN(PI()/A16)-0.24)*2 -> 17.054052 | C16: =(1.205/TAN(PI()/A16)-0.295)*2 -> 16.944052 | D16: =((2.1+0.006-0.005)/2/TAN(PI()/A16)-0.07)*2 -> 15.14591 | E16: =IF(AND(ENTRADAS!$E$15>13,ENTRADAS!$E$15<=14),14,0) -> 0 | F16: =IF(E16>0,$C$5,0) -> 0 | G16: =IF(E16>0,$C$63,0) -> 0 | H16: =IF(E16=0,0,IF(AND(ENTRADAS!$G$25>=F16,ENTRADAS!$G$25<=G16),1,0)) -> 0 | I16: =180/A16 -> 7.826087 | J16: 0.479 | K16: 0.24328 | L16: =K16*TAN(PI()*I16/180) -> 0.033438066 | M16: =L16*SIN(PI()*(I16/2)/180) -> 0.0022818943 | N16: =M16*COS(PI()*(I16)/180) -> 0.0022606407 | O16: =CÁLCULOS!$F$79 -> 2.3856884 | P16: =L16*K16 -> 0.0081348128 | Q16: =(O16-(2*L16))*N16 -> 0.0052420013 | R16: =P16+Q16 -> 0.013376814 | S16: =$T$1 -> 0.03939 | T16: =IF($U$1="X",J16-R16-S16,J16-R16) -> 0.46562319 | U16: =(J16-T16)/J16*100 -> 2.7926543
A17: 24 | B17: =(1.205/TAN(PI()/A17)-0.24)*2 -> 17.825767 | C17: =(1.205/TAN(PI()/A17)-0.295)*2 -> 17.715767 | D17: =((2.1+0.006-0.005)/2/TAN(PI()/A17)-0.07)*2 -> 15.818679 | E17: =IF(AND(ENTRADAS!$E$15>13,ENTRADAS!$E$15<=14),14,0) -> 0 | F17: =IF(E17>0,$C$5,0) -> 0 | G17: =IF(E17>0,$C$63,0) -> 0 | H17: =IF(E17=0,0,IF(AND(ENTRADAS!$G$25>=F17,ENTRADAS!$G$25<=G17),1,0)) -> 0 | I17: =180/A17 -> 7.5 | J17: 0.479 | K17: 0.24328 | L17: =K17*TAN(PI()*I17/180) -> 0.03202842 | M17: =L17*SIN(PI()*(I17/2)/180) -> 0.0020947589 | N17: =M17*COS(PI()*(I17)/180) -> 0.0020768379 | O17: =CÁLCULOS!$F$79 -> 2.3856884 | P17: =L17*K17 -> 0.0077918739 | Q17: =(O17-(2*L17))*N17 -> 0.0048216524 | R17: =P17+Q17 -> 0.012613526 | S17: =$T$1 -> 0.03939 | T17: =IF($U$1="X",J17-R17-S17,J17-R17) -> 0.46638647 | U17: =(J17-T17)/J17*100 -> 2.633304
A18: 25 | B18: =(1.205/TAN(PI()/A18)-0.24)*2 -> 18.597114 | C18: =(1.205/TAN(PI()/A18)-0.295)*2 -> 18.487114 | D18: =((2.1+0.006-0.005)/2/TAN(PI()/A18)-0.07)*2 -> 16.491128 | E18: =IF(AND(ENTRADAS!$E$15>13,ENTRADAS!$E$15<=14),14,0) -> 0 | F18: =IF(E18>0,$C$5,0) -> 0 | G18: =IF(E18>0,$C$63,0) -> 0 | H18: =IF(E18=0,0,IF(AND(ENTRADAS!$G$25>=F18,ENTRADAS!$G$25<=G18),1,0)) -> 0 | I18: =180/A18 -> 7.2 | J18: 0.479 | K18: 0.24328 | L18: =K18*TAN(PI()*I18/180) -> 0.030733411 | M18: =L18*SIN(PI()*(I18/2)/180) -> 0.0019297669 | N18: =M18*COS(PI()*(I18)/180) -> 0.0019145501 | O18: =CÁLCULOS!$F$79 -> 2.3856884 | P18: =L18*K18 -> 0.0074768243 | Q18: =(O18-(2*L18))*N18 -> 0.0044498386 | R18: =P18+Q18 -> 0.011926663 | S18: =$T$1 -> 0.03939 | T18: =IF($U$1="X",J18-R18-S18,J18-R18) -> 0.46707334 | U18: =(J18-T18)/J18*100 -> 2.4899087
A19: 26 | B19: =(1.205/TAN(PI()/A19)-0.24)*2 -> 19.368136 | C19: =(1.205/TAN(PI()/A19)-0.295)*2 -> 19.258136 | D19: =((2.1+0.006-0.005)/2/TAN(PI()/A19)-0.07)*2 -> 17.163292 | E19: =IF(AND(ENTRADAS!$E$15>13,ENTRADAS!$E$15<=14),14,0) -> 0 | F19: =IF(E19>0,$C$5,0) -> 0 | G19: =IF(E19>0,$C$63,0) -> 0 | H19: =IF(E19=0,0,IF(AND(ENTRADAS!$G$25>=F19,ENTRADAS!$G$25<=G19),1,0)) -> 0 | I19: =180/A19 -> 6.9230769 | J19: 0.479 | K19: 0.24328 | L19: =K19*TAN(PI()*I19/180) -> 0.02953954 | M19: =L19*SIN(PI()*(I19/2)/180) -> 0.001783553 | N19: =M19*COS(PI()*(I19)/180) -> 0.0017705489 | O19: =CÁLCULOS!$F$79 -> 2.3856884 | P19: =L19*K19 -> 0.0071863793 | Q19: =(O19-(2*L19))*N19 -> 0.0041193757 | R19: =P19+Q19 -> 0.011305755 | S19: =$T$1 -> 0.03939 | T19: =IF($U$1="X",J19-R19-S19,J19-R19) -> 0.46769425 | U19: =(J19-T19)/J19*100 -> 2.3602829
A20: 27 | B20: =(1.205/TAN(PI()/A20)-0.24)*2 -> 20.138868 | C20: =(1.205/TAN(PI()/A20)-0.295)*2 -> 20.028868 | D20: =((2.1+0.006-0.005)/2/TAN(PI()/A20)-0.07)*2 -> 17.835204 | E20: =IF(AND(ENTRADAS!$E$15>13,ENTRADAS!$E$15<=14),14,0) -> 0 | F20: =IF(E20>0,$C$5,0) -> 0 | G20: =IF(E20>0,$C$63,0) -> 0 | H20: =IF(E20=0,0,IF(AND(ENTRADAS!$G$25>=F20,ENTRADAS!$G$25<=G20),1,0)) -> 0 | I20: =180/A20 -> 6.6666667 | J20: 0.479 | K20: 0.24328 | L20: =K20*TAN(PI()*I20/180) -> 0.028435354 | M20: =L20*SIN(PI()*(I20/2)/180) -> 0.0016533688 | N20: =M20*COS(PI()*(I20)/180) -> 0.0016421893 | O20: =CÁLCULOS!$F$79 -> 2.3856884 | P20: =L20*K20 -> 0.0069177529 | Q20: =(O20-(2*L20))*N20 -> 0.0038243595 | R20: =P20+Q20 -> 0.010742112 | S20: =$T$1 -> 0.03939 | T20: =IF($U$1="X",J20-R20-S20,J20-R20) -> 0.46825789 | U20: =(J20-T20)/J20*100 -> 2.2426122
A21: 28 | B21: =(1.205/TAN(PI()/A21)-0.24)*2 -> 20.909342 | C21: =(1.205/TAN(PI()/A21)-0.295)*2 -> 20.799342 | D21: =((2.1+0.006-0.005)/2/TAN(PI()/A21)-0.07)*2 -> 18.506891 | E21: =IF(AND(ENTRADAS!$E$15>13,ENTRADAS!$E$15<=14),14,0) -> 0 | F21: =IF(E21>0,$C$5,0) -> 0 | G21: =IF(E21>0,$C$63,0) -> 0 | H21: =IF(E21=0,0,IF(AND(ENTRADAS!$G$25>=F21,ENTRADAS!$G$25<=G21),1,0)) -> 0 | I21: =180/A21 -> 6.4285714 | J21: 0.479 | K21: 0.24328 | L21: =K21*TAN(PI()*I21/180) -> 0.027411073 | M21: =L21*SIN(PI()*(I21/2)/180) -> 0.0015369511 | N21: =M21*COS(PI()*(I21)/180) -> 0.0015272871 | O21: =CÁLCULOS!$F$79 -> 2.3856884 | P21: =L21*K21 -> 0.0066685658 | Q21: =(O21-(2*L21))*N21 -> 0.0035599019 | R21: =P21+Q21 -> 0.010228468 | S21: =$T$1 -> 0.03939 | T21: =IF($U$1="X",J21-R21-S21,J21-R21) -> 0.46877153 | U21: =(J21-T21)/J21*100 -> 2.1353795
A22: 29 | B22: =(1.205/TAN(PI()/A22)-0.24)*2 -> 21.679584 | C22: =(1.205/TAN(PI()/A22)-0.295)*2 -> 21.569584 | D22: =((2.1+0.006-0.005)/2/TAN(PI()/A22)-0.07)*2 -> 19.178376 | E22: =IF(AND(ENTRADAS!$E$15>13,ENTRADAS!$E$15<=14),14,0) -> 0 | F22: =IF(E22>0,$C$5,0) -> 0 | G22: =IF(E22>0,$C$63,0) -> 0 | H22: =IF(E22=0,0,IF(AND(ENTRADAS!$G$25>=F22,ENTRADAS!$G$25<=G22),1,0)) -> 0 | I22: =180/A22 -> 6.2068966 | J22: 0.479 | K22: 0.24328 | L22: =K22*TAN(PI()*I22/180) -> 0.026458294 | M22: =L22*SIN(PI()*(I22/2)/180) -> 0.0014324232 | N22: =M22*COS(PI()*(I22)/180) -> 0.0014240263 | O22: =CÁLCULOS!$F$79 -> 2.3856884 | P22: =L22*K22 -> 0.0064367739 | Q22: =(O22-(2*L22))*N22 -> 0.0033219283 | R22: =P22+Q22 -> 0.0097587022 | S22: =$T$1 -> 0.03939 | T22: =IF($U$1="X",J22-R22-S22,J22-R22) -> 0.4692413 | U22: =(J22-T22)/J22*100 -> 2.0373073
A23: 30 | B23: =(1.205/TAN(PI()/A23)-0.24)*2 -> 22.449618 | C23: =(1.205/TAN(PI()/A23)-0.295)*2 -> 22.339618 | D23: =((2.1+0.006-0.005)/2/TAN(PI()/A23)-0.07)*2 -> 19.84968 | E23: =IF(AND(ENTRADAS!$E$15>13,ENTRADAS!$E$15<=14),14,0) -> 0 | F23: =IF(E23>0,$C$5,0) -> 0 | G23: =IF(E23>0,$C$63,0) -> 0 | H23: =IF(E23=0,0,IF(AND(ENTRADAS!$G$25>=F23,ENTRADAS!$G$25<=G23),1,0)) -> 0 | I23: =180/A23 -> 6 | J23: 0.479 | K23: 0.24328 | L23: =K23*TAN(PI()*I23/180) -> 0.025569758 | M23: =L23*SIN(PI()*(I23/2)/180) -> 0.0013382178 | N23: =M23*COS(PI()*(I23)/180) -> 0.0013308869 | O23: =CÁLCULOS!$F$79 -> 2.3856884 | P23: =L23*K23 -> 0.0062206108 | Q23: =(O23-(2*L23))*N23 -> 0.0031070204 | R23: =P23+Q23 -> 0.0093276312 | S23: =$T$1 -> 0.03939 | T23: =IF($U$1="X",J23-R23-S23,J23-R23) -> 0.46967237 | U23: =(J23-T23)/J23*100 -> 1.9473134
A24: 31 | B24: =(1.205/TAN(PI()/A24)-0.24)*2 -> 23.219465 | C24: =(1.205/TAN(PI()/A24)-0.295)*2 -> 23.109465 | D24: =((2.1+0.006-0.005)/2/TAN(PI()/A24)-0.07)*2 -> 20.52082 | E24: =IF(AND(ENTRADAS!$E$15>13,ENTRADAS!$E$15<=14),14,0) -> 0 | F24: =IF(E24>0,$C$5,0) -> 0 | G24: =IF(E24>0,$C$63,0) -> 0 | H24: =IF(E24=0,0,IF(AND(ENTRADAS!$G$25>=F24,ENTRADAS!$G$25<=G24),1,0)) -> 0 | I24: =180/A24 -> 5.8064516 | J24: 0.479 | K24: 0.24328 | L24: =K24*TAN(PI()*I24/180) -> 0.024739158 | M24: =L24*SIN(PI()*(I24/2)/180) -> 0.0012530178 | N24: =M24*COS(PI()*(I24)/180) -> 0.001246589 | O24: =CÁLCULOS!$F$79 -> 2.3856884 | P24: =L24*K24 -> 0.0060185424 | Q24: =(O24-(2*L24))*N24 -> 0.0029122937 | R24: =P24+Q24 -> 0.0089308361 | S24: =$T$1 -> 0.03939 | T24: =IF($U$1="X",J24-R24-S24,J24-R24) -> 0.47006916 | U24: =(J24-T24)/J24*100 -> 1.8644752
A25: 32 | B25: =(1.205/TAN(PI()/A25)-0.24)*2 -> 23.989141 | C25: =(1.205/TAN(PI()/A25)-0.295)*2 -> 23.879141 | D25: =((2.1+0.006-0.005)/2/TAN(PI()/A25)-0.07)*2 -> 21.191811 | E25: =IF(AND(ENTRADAS!$E$15>13,ENTRADAS!$E$15<=14),14,0) -> 0 | F25: =IF(E25>0,$C$5,0) -> 0 | G25: =IF(E25>0,$C$63,0) -> 0 | H25: =IF(E25=0,0,IF(AND(ENTRADAS!$G$25>=F25,ENTRADAS!$G$25<=G25),1,0)) -> 0 | I25: =180/A25 -> 5.625 | J25: 0.479 | K25: 0.24328 | L25: =K25*TAN(PI()*I25/180) -> 0.023960989 | M25: =L25*SIN(PI()*(I25/2)/180) -> 0.00117571 | N25: =M25*COS(PI()*(I25)/180) -> 0.0011700486 | O25: =CÁLCULOS!$F$79 -> 2.3856884 | P25: =L25*K25 -> 0.0058292293 | Q25: =(O25-(2*L25))*N25 -> 0.0027353004 | R25: =P25+Q25 -> 0.0085645297 | S25: =$T$1 -> 0.03939 | T25: =IF($U$1="X",J25-R25-S25,J25-R25) -> 0.47043547 | U25: =(J25-T25)/J25*100 -> 1.788002
A26: 33 | B26: =(1.205/TAN(PI()/A26)-0.24)*2 -> 24.758662 | C26: =(1.205/TAN(PI()/A26)-0.295)*2 -> 24.648662 | D26: =((2.1+0.006-0.005)/2/TAN(PI()/A26)-0.07)*2 -> 21.862667 | E26: =IF(AND(ENTRADAS!$E$15>13,ENTRADAS!$E$15<=14),14,0) -> 0 | F26: =IF(E26>0,$C$5,0) -> 0 | G26: =IF(E26>0,$C$63,0) -> 0 | H26: =IF(E26=0,0,IF(AND(ENTRADAS!$G$25>=F26,ENTRADAS!$G$25<=G26),1,0)) -> 0 | I26: =180/A26 -> 5.4545455 | J26: 0.479 | K26: 0.24328 | L26: =K26*TAN(PI()*I26/180) -> 0.023230423 | M26: =L26*SIN(PI()*(I26/2)/180) -> 0.001105348 | N26: =M26*COS(PI()*(I26)/180) -> 0.0011003429 | O26: =CÁLCULOS!$F$79 -> 2.3856884 | P26: =L26*K26 -> 0.0056514974 | Q26: =(O26-(2*L26))*N26 -> 0.0025739525 | R26: =P26+Q26 -> 0.0082254499 | S26: =$T$1 -> 0.03939 | T26: =IF($U$1="X",J26-R26-S26,J26-R26) -> 0.47077455 | U26: =(J26-T26)/J26*100 -> 1.7172129
A27: 34 | B27: =(1.205/TAN(PI()/A27)-0.24)*2 -> 25.528042 | C27: =(1.205/TAN(PI()/A27)-0.295)*2 -> 25.418042 | D27: =((2.1+0.006-0.005)/2/TAN(PI()/A27)-0.07)*2 -> 22.533401 | E27: =IF(AND(ENTRADAS!$E$15>13,ENTRADAS!$E$15<=14),14,0) -> 0 | F27: =IF(E27>0,$C$5,0) -> 0 | G27: =IF(E27>0,$C$63,0) -> 0 | H27: =IF(E27=0,0,IF(AND(ENTRADAS!$G$25>=F27,ENTRADAS!$G$25<=G27),1,0)) -> 0 | I27: =180/A27 -> 5.2941176 | J27: 0.479 | K27: 0.24328 | L27: =K27*TAN(PI()*I27/180) -> 0.022543212 | M27: =L27*SIN(PI()*(I27/2)/180) -> 0.0010411235 | N27: =M27*COS(PI()*(I27)/180) -> 0.0010366822 | O27: =CÁLCULOS!$F$79 -> 2.3856884 | P27: =L27*K27 -> 0.0054843126 | Q27: =(O27-(2*L27))*N27 -> 0.0024264605 | R27: =P27+Q27 -> 0.0079107731 | S27: =$T$1 -> 0.03939 | T27: =IF($U$1="X",J27-R27-S27,J27-R27) -> 0.47108923 | U27: =(J27-T27)/J27*100 -> 1.6515184
... A33: 40 | B33: =(1.205/TAN(PI()/A33)-0.24)*2 -> 30.141953 | C33: =(1.205/TAN(PI()/A33)-0.295)*2 -> 30.031953 | D33: =((2.1+0.006-0.005)/2/TAN(PI()/A33)-0.07)*2 -> 26.555736 | E33: =IF(AND(ENTRADAS!$E$15>13,ENTRADAS!$E$15<=14),14,0) -> 0 | F33: =IF(E33>0,$C$5,0) -> 0 | G33: =IF(E33>0,$C$63,0) -> 0 | H33: =IF(E33=0,0,IF(AND(ENTRADAS!$G$25>=F33,ENTRADAS!$G$25<=G33),1,0)) -> 0 | I33: =180/A33 -> 4.5 | J33: 0.479 | K33: 0.24328 | L33: =K33*TAN(PI()*I33/180) -> 0.019146551 | M33: =L33*SIN(PI()*(I33/2)/180) -> 0.00075169007 | N33: =M33*COS(PI()*(I33)/180) -> 0.00074937286 | O33: =CÁLCULOS!$F$79 -> 2.3856884 | P33: =L33*K33 -> 0.004657973 | Q33: =(O33-(2*L33))*N33 -> 0.0017590743 | R33: =P33+Q33 -> 0.0064170473 | S33: =$T$1 -> 0.03939 | T33: =IF($U$1="X",J33-R33-S33,J33-R33) -> 0.47258295 | U33: =(J33-T33)/J33*100 -> 1.3396759
A34: 41 | B34: =(1.205/TAN(PI()/A34)-0.24)*2 -> 30.910621 | C34: =(1.205/TAN(PI()/A34)-0.295)*2 -> 30.800621 | E34: =IF(AND(ENTRADAS!$E$15>13,ENTRADAS!$E$15<=14),14,0) -> 0 | F34: =IF(E34>0,$C$5,0) -> 0 | G34: =IF(E34>0,$C$63,0) -> 0 | H34: =IF(E34=0,0,IF(AND(ENTRADAS!$G$25>=F34,ENTRADAS!$G$25<=G34),1,0)) -> 0 | I34: =180/A34 -> 4.3902439 | J34: 0.479 | K34: 0.24328 | L34: =K34*TAN(PI()*I34/180) -> 0.018677706 | M34: =L34*SIN(PI()*(I34/2)/180) -> 0.00071540721 | N34: =M34*COS(PI()*(I34)/180) -> 0.00071330806 | O34: =CÁLCULOS!$F$79 -> 2.3856884 | P34: =L34*K34 -> 0.0045439124 | Q34: =(O34-(2*L34))*N34 -> 0.0016750849 | R34: =P34+Q34 -> 0.0062189973 | S34: =$T$1 -> 0.03939 | T34: =IF($U$1="X",J34-R34-S34,J34-R34) -> 0.472781 | U34: =(J34-T34)/J34*100 -> 1.2983293
A35: 42 | B35: =(1.205/TAN(PI()/A35)-0.24)*2 -> 31.679215 | C35: =(1.205/TAN(PI()/A35)-0.295)*2 -> 31.569215 | E35: =IF(AND(ENTRADAS!$E$15>13,ENTRADAS!$E$15<=14),14,0) -> 0 | F35: =IF(E35>0,$C$5,0) -> 0 | G35: =IF(E35>0,$C$63,0) -> 0 | H35: =IF(E35=0,0,IF(AND(ENTRADAS!$G$25>=F35,ENTRADAS!$G$25<=G35),1,0)) -> 0 | I35: =180/A35 -> 4.2857143 | J35: 0.479 | K35: 0.24328 | L35: =K35*TAN(PI()*I35/180) -> 0.018231316 | M35: =L35*SIN(PI()*(I35/2)/180) -> 0.00068169066 | N35: =M35*COS(PI()*(I35)/180) -> 0.00067978452 | O35: =CÁLCULOS!$F$79 -> 2.3856884 | P35: =L35*K35 -> 0.0044353145 | Q35: =(O35-(2*L35))*N35 -> 0.0015969673 | R35: =P35+Q35 -> 0.0060322818 | S35: =$T$1 -> 0.03939 | T35: =IF($U$1="X",J35-R35-S35,J35-R35) -> 0.47296772 | U35: =(J35-T35)/J35*100 -> 1.259349
A36: 43 | B36: =(1.205/TAN(PI()/A36)-0.24)*2 -> 32.447741 | C36: =(1.205/TAN(PI()/A36)-0.295)*2 -> 32.337741 | E36: =IF(AND(ENTRADAS!$E$15>13,ENTRADAS!$E$15<=14),14,0) -> 0 | F36: =IF(E36>0,$C$5,0) -> 0 | G36: =IF(E36>0,$C$63,0) -> 0 | H36: =IF(E36=0,0,IF(AND(ENTRADAS!$G$25>=F36,ENTRADAS!$G$25<=G36),1,0)) -> 0 | I36: =180/A36 -> 4.1860465 | J36: 0.479 | K36: 0.24328 | L36: =K36*TAN(PI()*I36/180) -> 0.017805801 | M36: =L36*SIN(PI()*(I36/2)/180) -> 0.00065030387 | N36: =M36*COS(PI()*(I36)/180) -> 0.00064856905 | O36: =CÁLCULOS!$F$79 -> 2.3856884 | P36: =L36*K36 -> 0.0043317953 | Q36: =(O36-(2*L36))*N36 -> 0.0015241871 | R36: =P36+Q36 -> 0.0058559823 | S36: =$T$1 -> 0.03939 | T36: =IF($U$1="X",J36-R36-S36,J36-R36) -> 0.47314402 | U36: =(J36-T36)/J36*100 -> 1.2225433
A37: 44 | B37: =(1.205/TAN(PI()/A37)-0.24)*2 -> 33.216203 | C37: =(1.205/TAN(PI()/A37)-0.295)*2 -> 33.106203 | E37: =IF(AND(ENTRADAS!$E$15>13,ENTRADAS!$E$15<=14),14,0) -> 0 | F37: =IF(E37>0,$C$5,0) -> 0 | G37: =IF(E37>0,$C$63,0) -> 0 | H37: =IF(E37=0,0,IF(AND(ENTRADAS!$G$25>=F37,ENTRADAS!$G$25<=G37),1,0)) -> 0 | I37: =180/A37 -> 4.0909091 | J37: 0.479 | K37: 0.24328 | L37: =K37*TAN(PI()*I37/180) -> 0.017399729 | M37: =L37*SIN(PI()*(I37/2)/180) -> 0.00062103694 | N37: =M37*COS(PI()*(I37)/180) -> 0.00061945461 | O37: =CÁLCULOS!$F$79 -> 2.3856884 | P37: =L37*K37 -> 0.0042330061 | Q37: =(O37-(2*L37))*N37 -> 0.001456269 | R37: =P37+Q37 -> 0.0056892751 | S37: =$T$1 -> 0.03939 | T37: =IF($U$1="X",J37-R37-S37,J37-R37) -> 0.47331072 | U37: =(J37-T37)/J37*100 -> 1.1877401
A38: 45 | B38: =(1.205/TAN(PI()/A38)-0.24)*2 -> 33.984606 | C38: =(1.205/TAN(PI()/A38)-0.295)*2 -> 33.874606 | E38: =IF(AND(ENTRADAS!$E$15>13,ENTRADAS!$E$15<=14),14,0) -> 0 | F38: =IF(E38>0,$C$5,0) -> 0 | G38: =IF(E38>0,$C$63,0) -> 0 | H38: =IF(E38=0,0,IF(AND(ENTRADAS!$G$25>=F38,ENTRADAS!$G$25<=G38),1,0)) -> 0 | I38: =180/A38 -> 4 | J38: 0.479 | K38: 0.24328 | L38: =K38*TAN(PI()*I38/180) -> 0.017011795 | M38: =L38*SIN(PI()*(I38/2)/180) -> 0.00059370308 | N38: =M38*COS(PI()*(I38)/180) -> 0.00059225685 | O38: =CÁLCULOS!$F$79 -> 2.3856884 | P38: =L38*K38 -> 0.0041386294 | Q38: =(O38-(2*L38))*N38 -> 0.0013927896 | R38: =P38+Q38 -> 0.005531419 | S38: =$T$1 -> 0.03939 | T38: =IF($U$1="X",J38-R38-S38,J38-R38) -> 0.47346858 | U38: =(J38-T38)/J38*100 -> 1.1547848
A39: 46 | B39: =(1.205/TAN(PI()/A39)-0.24)*2 -> 34.752953 | C39: =(1.205/TAN(PI()/A39)-0.295)*2 -> 34.642953 | E39: =IF(AND(ENTRADAS!$E$15>13,ENTRADAS!$E$15<=14),14,0) -> 0 | F39: =IF(E39>0,$C$5,0) -> 0 | G39: =IF(E39>0,$C$63,0) -> 0 | H39: =IF(E39=0,0,IF(AND(ENTRADAS!$G$25>=F39,ENTRADAS!$G$25<=G39),1,0)) -> 0 | I39: =180/A39 -> 3.9130435 | J39: 0.479 | K39: 0.24328 | L39: =K39*TAN(PI()*I39/180) -> 0.016640808 | M39: =L39*SIN(PI()*(I39/2)/180) -> 0.00056813566 | N39: =M39*COS(PI()*(I39)/180) -> 0.0005668112 | O39: =CÁLCULOS!$F$79 -> 2.3856884 | P39: =L39*K39 -> 0.0040483757 | Q39: =(O39-(2*L39))*N39 -> 0.0013333705 | R39: =P39+Q39 -> 0.0053817463 | S39: =$T$1 -> 0.03939 | T39: =IF($U$1="X",J39-R39-S39,J39-R39) -> 0.47361825 | U39: =(J39-T39)/J39*100 -> 1.1235378
A40: 47 | B40: =(1.205/TAN(PI()/A40)-0.24)*2 -> 35.521248 | C40: =(1.205/TAN(PI()/A40)-0.295)*2 -> 35.411248 | E40: =IF(AND(ENTRADAS!$E$15>13,ENTRADAS!$E$15<=14),14,0) -> 0 | F40: =IF(E40>0,$C$5,0) -> 0 | G40: =IF(E40>0,$C$63,0) -> 0 | H40: =IF(E40=0,0,IF(AND(ENTRADAS!$G$25>=F40,ENTRADAS!$G$25<=G40),1,0)) -> 0 | I40: =180/A40 -> 3.8297872 | J40: 0.479 | K40: 0.24328 | L40: =K40*TAN(PI()*I40/180) -> 0.01628568 | M40: =L40*SIN(PI()*(I40/2)/180) -> 0.00054418562 | N40: =M40*COS(PI()*(I40)/180) -> 0.00054297038 | O40: =CÁLCULOS!$F$79 -> 2.3856884 | P40: =L40*K40 -> 0.0039619802 | Q40: =(O40-(2*L40))*N40 -> 0.0012776729 | R40: =P40+Q40 -> 0.0052396531 | S40: =$T$1 -> 0.03939 | T40: =IF($U$1="X",J40-R40-S40,J40-R40) -> 0.47376035 | U40: =(J40-T40)/J40*100 -> 1.0938733
A41: 48 | B41: =(1.205/TAN(PI()/A41)-0.24)*2 -> 36.289495 | C41: =(1.205/TAN(PI()/A41)-0.295)*2 -> 36.179495 | E41: =IF(AND(ENTRADAS!$E$15>13,ENTRADAS!$E$15<=14),14,0) -> 0 | F41: =IF(E41>0,$C$5,0) -> 0 | G41: =IF(E41>0,$C$63,0) -> 0 | H41: =IF(E41=0,0,IF(AND(ENTRADAS!$G$25>=F41,ENTRADAS!$G$25<=G41),1,0)) -> 0 | I41: =180/A41 -> 3.75 | J41: 0.479 | K41: 0.24328 | L41: =K41*TAN(PI()*I41/180) -> 0.015945414 | M41: =L41*SIN(PI()*(I41/2)/180) -> 0.00052171931 | N41: =M41*COS(PI()*(I41)/180) -> 0.00052060227 | O41: =CÁLCULOS!$F$79 -> 2.3856884 | P41: =L41*K41 -> 0.0038792002 | Q41: =(O41-(2*L41))*N41 -> 0.0012253924 | R41: =P41+Q41 -> 0.0051045926 | S41: =$T$1 -> 0.03939 | T41: =IF($U$1="X",J41-R41-S41,J41-R41) -> 0.47389541 | U41: =(J41-T41)/J41*100 -> 1.0656769
A42: 49 | B42: =(1.205/TAN(PI()/A42)-0.24)*2 -> 37.057695 | C42: =(1.205/TAN(PI()/A42)-0.295)*2 -> 36.947695 | E42: =IF(AND(ENTRADAS!$E$15>13,ENTRADAS!$E$15<=14),14,0) -> 0 | F42: =IF(E42>0,$C$5,0) -> 0 | G42: =IF(E42>0,$C$63,0) -> 0 | H42: =IF(E42=0,0,IF(AND(ENTRADAS!$G$25>=F42,ENTRADAS!$G$25<=G42),1,0)) -> 0 | I42: =180/A42 -> 3.6734694 | J42: 0.479 | K42: 0.24328 | L42: =K42*TAN(PI()*I42/180) -> 0.015619094 | M42: =L42*SIN(PI()*(I42/2)/180) -> 0.00050061661 | N42: =M42*COS(PI()*(I42)/180) -> 0.00049958804 | O42: =CÁLCULOS!$F$79 -> 2.3856884 | P42: =L42*K42 -> 0.0037998132 | Q42: =(O42-(2*L42))*N42 -> 0.0011762552 | R42: =P42+Q42 -> 0.0049760684 | S42: =$T$1 -> 0.03939 | T42: =IF($U$1="X",J42-R42-S42,J42-R42) -> 0.47402393 | U42: =(J42-T42)/J42*100 -> 1.0388452
A43: 50 | B43: =(1.205/TAN(PI()/A43)-0.24)*2 -> 37.825853 | C43: =(1.205/TAN(PI()/A43)-0.295)*2 -> 37.715853 | E43: =IF(AND(ENTRADAS!$E$15>13,ENTRADAS!$E$15<=14),14,0) -> 0 | F43: =IF(E43>0,$C$5,0) -> 0 | G43: =IF(E43>0,$C$63,0) -> 0 | H43: =IF(E43=0,0,IF(AND(ENTRADAS!$G$25>=F43,ENTRADAS!$G$25<=G43),1,0)) -> 0 | I43: =180/A43 -> 3.6 | J43: 0.479 | K43: 0.24328 | L43: =K43*TAN(PI()*I43/180) -> 0.01530588 | M43: =L43*SIN(PI()*(I43/2)/180) -> 0.00048076932 | N43: =M43*COS(PI()*(I43)/180) -> 0.00047982063 | O43: =CÁLCULOS!$F$79 -> 2.3856884 | P43: =L43*K43 -> 0.0037236145 | Q43: =(O43-(2*L43))*N43 -> 0.0011300144 | R43: =P43+Q43 -> 0.0048536289 | S43: =$T$1 -> 0.03939 | T43: =IF($U$1="X",J43-R43-S43,J43-R43) -> 0.47414637 | U43: =(J43-T43)/J43*100 -> 1.0132837
A44: 51 | B44: =(1.205/TAN(PI()/A44)-0.24)*2 -> 38.59397 | C44: =(1.205/TAN(PI()/A44)-0.295)*2 -> 38.48397 | E44: =IF(AND(ENTRADAS!$E$15>13,ENTRADAS!$E$15<=14),14,0) -> 0 | F44: =IF(E44>0,$C$5,0) -> 0 | G44: =IF(E44>0,$C$63,0) -> 0 | H44: =IF(E44=0,0,IF(AND(ENTRADAS!$G$25>=F44,ENTRADAS!$G$25<=G44),1,0)) -> 0 | I44: =180/A44 -> 3.5294118 | J44: 0.479 | K44: 0.24328 | L44: =K44*TAN(PI()*I44/180) -> 0.015004997 | M44: =L44*SIN(PI()*(I44/2)/180) -> 0.00046207975 | N44: =M44*COS(PI()*(I44)/180) -> 0.00046120334 | O44: =CÁLCULOS!$F$79 -> 2.3856884 | P44: =L44*K44 -> 0.0036504156 | Q44: =(O44-(2*L44))*N44 -> 0.0010864468 | R44: =P44+Q44 -> 0.0047368624 | S44: =$T$1 -> 0.03939 | T44: =IF($U$1="X",J44-R44-S44,J44-R44) -> 0.47426314 | U44: =(J44-T44)/J44*100 -> 0.98890655 | X44: 87 | Y44: 8
A45: 52 | B45: =(1.205/TAN(PI()/A45)-0.24)*2 -> 39.36205 | C45: =(1.205/TAN(PI()/A45)-0.295)*2 -> 39.25205 | E45: =IF(AND(ENTRADAS!$E$15>13,ENTRADAS!$E$15<=14),14,0) -> 0 | F45: =IF(E45>0,$C$5,0) -> 0 | G45: =IF(E45>0,$C$63,0) -> 0 | H45: =IF(E45=0,0,IF(AND(ENTRADAS!$G$25>=F45,ENTRADAS!$G$25<=G45),1,0)) -> 0 | I45: =180/A45 -> 3.4615385 | J45: 0.479 | K45: 0.24328 | L45: =K45*TAN(PI()*I45/180) -> 0.014715729 | M45: =L45*SIN(PI()*(I45/2)/180) -> 0.00044445957 | N45: =M45*COS(PI()*(I45)/180) -> 0.00044364868 | O45: =CÁLCULOS!$F$79 -> 2.3856884 | P45: =L45*K45 -> 0.0035800425 | Q45: =(O45-(2*L45))*N45 -> 0.0010453503 | R45: =P45+Q45 -> 0.0046253928 | S45: =$T$1 -> 0.03939 | T45: =IF($U$1="X",J45-R45-S45,J45-R45) -> 0.47437461 | U45: =(J45-T45)/J45*100 -> 0.96563524 | X45: 88 | Y45: 8
...

Sheet GUINDASTE
E2: GUINDASTES | M2: DATA: | O2: =CÁLCULOS!O1 -> 45638
M3: REVISÃO: | O3: =CÁLCULOS!O2 -> 3
E4: CLIENTE: | F4: =CÁLCULOS!F3 -> Passarelli | M4: LOCAL
E5: LOCAL: | F5: =CÁLCULOS!F4 -> 12 tqs Nereda | M5: =CÁLCULOS!M4 -> São Paulo - Tatuapé
C8: ANÁLISE DE TEMPO MÍNIMO DE GUINDASTE NA OBRA: ( verificar se o locador estipula mínimo de 30 dias para locação )
C10: GUINDASTE MENOR QUE 90 ton, considerar mínimo 30 dias ? | I10: x | J10: sim | M10: não | N10: =IF(I10="X",1,0) -> 1 | O10: =IF(L10="X",1,0) -> 0 | S10: =IF(OR(G77<90,G90<90,G103<90),"GUINDASTE MENOR QUE 90 ton, considerar mínimo 30 dias ?",0) -> GUINDASTE MENOR QUE 90 ton, considerar mínimo 30 dias ?
C12: GUINDASTE MAIOR ou IGUAL à 90 ton, considerar mínimo 30 dias ? | I12: x | J12: sim | M12: não | N12: =IF(I12="X",1,0) -> 1 | O12: =IF(L12="X",1,0) -> 0 | S12: =IF(OR(G77>=90,G90>=90,G103>=90),"GUINDASTE MAIOR ou IGUAL à 90 ton, considerar mínimo 30 dias ?",0) -> 0
D16: MONTAGEM DA PAREDE:
C19: UTILIZAR GIRADOR DE PLACAS ? | F19: x | G19: sim | J19: não
C20: =IF(ENTRADAS!I15=0,0,IF(ENTRADAS!I15<=7,"Altura do painel menor que 7,00 m, logo não há necessidade do GIRADOR DE PLACAS!",0)) -> 0
C22: GUINDASTE 1 (calculado) capacidade= | F22: =IF(L63>0,L63,CÁLCULOS!I279) -> 70 | G22: toneladas | I22: =IF(E62="X","guindaste era "&CÁLCULOS!O279&" ton., mas você optou por igualar ao da cobertura",0) -> 0
BJ23: X
C24: GUINDASTE 2 (calculado) capacidade= | F24: =CÁLCULOS!I280 -> 0 | G24: toneladas | I24: =IF(I29="X"," << Você marcou X para não utilizar este guind. 2 que era de "&CÁLCULOS!O280&" ton",0) -> 0
C26: CASO NÃO QUEIRA UTILIZAR OS GUINDASTES CALCULADOS, INSIRA ABAIXO OS NOVOS GUINDASTES:
C27: GUINDASTE 1 = | E27: 70 | F27: toneladas
C28: GUINDASTE 2 = | F28: toneladas
C29: =IF(F19="X",0,"CASO NÃO QUEIRA O GUINDASTE 2 CALCULADO, MARQUE X:") -> 0 | J29: =IF(I29="x",1000,0) -> 0 | L29: =IF(F23<>0,1000,0) -> 0
C31: MOBILIZAÇÃO do GUINDASTE 1 ( calculado )= | G31: =CÁLCULOS!L281 -> 1 | H31: ------------- | I31: MUDAR QUANT.= | M31: mobilizações de guindaste
F32: =IF(AND(G31>0,G31<1),"ESTE VALOR É DEVIDO AO RATEAMENTO ENTRE PAREDES E COBERTURAS",0) -> 0
C34: MOBILIZAÇÃO do GUINDASTE 2 ( calculado )= | G34: =CÁLCULOS!L282 -> 0 | H34: ------------- | I34: MUDAR QUANT.= | M34: mobilizações de guindaste
C36: PRAZO DE GUINDASTE À DISPOSIÇÃO:
D37: DURANTE CABEAMENTO / INJEÇÃO / ACABAMENTOS / FOLGAS DE CAMPO = | L37: =CÁLCULOS!L141 -> 46 | M37: dias | N37: =SUM(J386:J388)+SUM(J338:J340)+J498*H447 -> 0
D39: DURANTE INTERVALO ENTRE TANQUES = | H39: =CÁLCULOS!H143 -> 0 | I39: dias
E40: PARA DESCONSIDERAR GUINDASTE À DISPOSIÇÃO ( marcar "X" )
D46: =IF(ENTRADAS!D912="x","MONTAGEM DE COBERTURA","NÃO HÁ COBERTURAS") -> NÃO HÁ COBERTURAS
C48: =IF(ENTRADAS!D912="x","Em relação ao espaço para patolagem do guindaste externamente ao tanque ( percentual livre do perímetro):",0) -> 0
D50: =IF(ENTRADAS!D912="x","<= 50%",0) -> 0 | F50: =IF(ENTRADAS!D912="x",">51%",0) -> 0
C53: =IF(ENTRADAS!D912="x","a) GUINDASTE CALCULADO ---------------------------",0) -> 0 | F53: =IF(ENTRADAS!D912="x",IF(ENTRADAS!D912="X",IF(GUINDASTE!E57>0,GUINDASTE!E57,SUM(LAJES!AO154:AO158))),0)&" toneladas" -> 0 toneladas | G53: =IF(ENTRADAS!D912="x","( se for exclusivo para cobertura )",0) -> 0 | O53: =IF(E57>0,"(mudou para "&E57&" toneladas )",0) -> 0
C54: =IF(ENTRADAS!D912="x","b) GUINDASTE CALCULADO ---------------------------",0) -> 0 | F54: =IF(ENTRADAS!D912="x",G103&" toneladas",0) -> 0 | G54: =IF(ENTRADAS!D912="x","( se for cobertura junto com parede)",0) -> 0
C56: =IF(ENTRADAS!D912="x","CASO NÃO QUEIRA UTILIZAR O GUINDASTE CALCULADO no ítem a, INSIRA ABAIXO OS NOVO GUINDASTE:",0) -> 0
C57: =IF(ENTRADAS!D912="x"," GUINDASTE =",0) -> 0 | F57: =IF(ENTRADAS!D912="x","toneladas",0) -> 0
G58: =IF(ENTRADAS!D912="X",IF(L59>0,L59,IF(ENTRADAS!G91+ENTRADAS!G93+ENTRADAS!G97>40,2,1)),0) -> 0
C59: MOBILIZAÇÃO do GUINDASTE ( calculado )= | G59: =IF(ENTRADAS!D912="X",IF(L59>0,L59&" mobilização",IF(C123=1,I94&" mobilização",IF(C125=1,I107&" mobilização",0))),0) -> 0 | H59: ------------- | I59: MUDAR QUANT.= | M59: mobilizações de guindaste
C61: COMPARANDO ESTE GUINDASTE COM O GUINDASTE 1 DA MONTAGEM DAS PAREDES USAR O MAIOR NAS DUAS MONTAGENS ?
F62: SIM | H62: NÃO | I62: =IF(E62="X","o guindaste 1 das paredes e o da cobertura passaram para=","o guindaste 1 das paredes é=") -> o guindaste 1 das paredes é=
L63: =IF(E62="X",IF(E62="X",IF(CÁLCULOS!O279>SUM(LAJES!AO154:AO158),CÁLCULOS!O279,IF(SUM(LAJES!AO154:AO158)>CÁLCULOS!O279,SUM(LAJES!AO154:AO158),G90)),CÁLCULOS!O279),IF(D125="X",G103,0)) -> 0 | M63: toneladas
D68: ANÁLISE DE MOBILIZAÇÃO / DESMOBILIZAÇÃO:
C70: CASO SOMENTE PAREDES | F70: =IF(C72=0,0,1) -> 0 | G70: =IF(I73=0,0,1) -> 0 | H70: =IF(L73=0,0,1) -> 0 | I70: =IF(F70+G70+H70=1,"OBRIGATÓRIO DEFINIÇÃO, SIM OU NÃO !",0) -> 0 | N70: =IF(I70<>0,1,0) -> 0
O71: =IF($D$127<>0,1,0) -> 0
C72: =IF('cronograma unit.'!$E$381=0,0,IF('cronograma unit.'!$E$381=1,"Analisando o cronograma, existe "&'cronograma unit.'!$E$381&" intervalo de "&'cronograma unit.'!$E$380/'cronograma unit.'!$E$381&" dias entre as montagem de paredes. ","Analisando o cronograma, existem "&'cronograma unit.'!$E$381&" intervalos de "&'cronograma unit.'!$E$380/'cronograma unit.'!$E$381&" dias em média entre as montagem de paredes. ")) -> 0 | K72: =IF($D$127<>0,1,0) -> 0
...

Sheet X MPa 
C2: COMPOSIÇÃO DE PREÇO DE CONCRETO FABRICAÇÃO NA FORTANKS
B12: INSUMOS: | C12: UNID. | E12: PREÇO MATERIAL | F12: FRETE | G12: SERVIÇO
B13: CIMENTO CP3 | C13: tonelada | E13: 483 | F13: =36*1.1 -> 39.6 | G13: -
B14: CIMENTO CP5 | C14: tonelada | E14: 722.85 | G14: -
B15: BRITA 0 | C15: tonelada | E15: 128 | F15: =16*1.1 -> 17.6 | G15: -
B16: AREIA MÉDIA | C16: m³ | E16: 198.28 | G16: -
B17: SÍLICA ATIVA | C17: kg | E17: 1.58 | G17: -
B18: ADITIVO SUPER | C18: kg | E18: 11.05 | F18: =0.75*1.1 -> 0.825 | G18: -
B19: DIESEL | C19: Litro | E19: 8.5 | F19: - | G19: -
B20: SERVIÇO VILAMIX | C20: m³ | E20: - | F20: -
B22: TRAÇO À UTILIZAR: | C22: X
A23: =C23 -> 0 | B23: ='tabela traços'!C3 -> 30 MPa 24 h | D23: =IF(C23=0,0,1) -> 0
A24: =C24 -> 0 | B24: ='tabela traços'!C4 -> 28 MPa 24 h | D24: =IF(C24=0,0,1) -> 0
A25: =C25 -> 0 | B25: ='tabela traços'!C5 -> 25 MPa 24 h | D25: =IF(C25=0,0,1) -> 0
A26: =C26 -> x | B26: ='tabela traços'!C6 -> 20 MPa 24 h | C26: x | D26: =IF(C26=0,0,1) -> 1
A27: =C27 -> 0 | B27: ='tabela traços'!C7 -> 15 MPa 24 h | D27: =IF(C27=0,0,1) -> 0
B28: ='tabela traços'!C8 -> 10 MPa 24 h | D28: =IF(C28=0,0,1) -> 0
B29: ='tabela traços'!C9 -> 0 | D29: =IF(C29=0,0,1) -> 0
B30: ='tabela traços'!C10 -> 0 | D30: =IF(C30=0,0,1) -> 0
B32: =IF(SUM($D$23:$D$27)=0,0,"PREÇO POR m³ TRAÇO ref. Umidade da areia à 6%:") -> PREÇO POR m³ TRAÇO ref. Umidade da areia à 6%: | F32: =IF(SUM($D$23:$D$27)=0,0,VLOOKUP($C$22,$A$23:$B$27,2,0)) -> 20 MPa 24 h | I32: DATA: | J32: 44722
B34: Insumo | C34: unid. | D34: consumo /m³ | E34: preço unit. | F34: valor /m³ | H34: frete/ t | I34: material/ t | M34: % ICMS
B35: cimento CP3 | C35: t | D35: =IF(SUM($D$23:$D$30)=0,0,VLOOKUP($C$22,'tabela traços'!$A$3:$M$15,5,0)) -> 0.343 | E35: =IF(SUM($D$23:$D$30)=0,0,H35+I35) -> 522.6 | F35: =D35*E35 -> 179.2518 | H35: =F13 -> 39.6 | I35: =E13 -> 483 | J35: CP3 | M35: 0.17 | N35: =M35*F35 -> 30.472806
B36: cimento CP5 | C36: t | D36: =IF(SUM($D$23:$D$30)=0,0,VLOOKUP($C$22,'tabela traços'!$A$3:$M$15,6,0)) -> 0.184 | E36: =IF(SUM($D$23:$D$30)=0,0,E14) -> 722.85 | F36: =D36*E36 -> 133.0044 | M36: 0.07 | N36: =M36*F36 -> 9.310308
H37: frete/ t | I37: material/ t
B38: brita zero | C38: t | D38: =IF(SUM($D$23:$D$30)=0,0,VLOOKUP($C$22,'tabela traços'!$A$3:$M$15,7,0)) -> 0.859 | E38: =IF(SUM($D$23:$D$30)=0,0,H38+I38) -> 145.6 | F38: =D38*E38 -> 125.0704 | H38: =F15 -> 17.6 | I38: =E15 -> 128 | J38: BRITA ZERO | M38: 0.17 | N38: =M38*F38 -> 21.261968
H40: frete/ m3 | I40: material/m3 | J40: peso espec. (t/m³)
B41: areia média (umidade 6,4%) | C41: t | D41: =IF(SUM($D$23:$D$30)=0,0,VLOOKUP($C$22,'tabela traços'!$A$3:$M$15,8,0)) -> 0.846 | E41: =IF(SUM($D$23:$D$30)=0,0,(H41+I41)/J41) -> 123.925 | F41: =D41*E41 -> 104.84055 | H41: =F16 -> 0 | I41: =E16 -> 198.28 | J41: 1.6 | K41: AREIA | M41: 0.17 | N41: =M41*F41 -> 17.822894
B42: sílica | C42: kg | D42: =IF(SUM($D$23:$D$30)=0,0,VLOOKUP($C$22,'tabela traços'!$A$3:$M$15,11,0)) -> 30.77 | E42: =IF(SUM($D$23:$D$30)=0,0,E17+F17) -> 1.58 | F42: =D42*E42 -> 48.6166 | M42: 0.07 | N42: =M42*F42 -> 3.403162
B43: água | C43: litro | D43: =IF(SUM($D$23:$D$30)=0,0,VLOOKUP($C$22,'tabela traços'!$A$3:$M$15,10,0)) -> 144 | F43: =D43*E43 -> 0 | H43: frete/ kg | I43: material/kg
B44: aditivo super | C44: kg | D44: =IF(SUM($D$23:$D$30)=0,0,VLOOKUP($C$22,'tabela traços'!$A$3:$M$15,9,0)) -> 3.689 | E44: =IF(SUM($D$23:$D$30)=0,0,H44+I44) -> 11.875 | F44: =D44*E44 -> 43.806875 | H44: =F18 -> 0.825 | I44: =E18 -> 11.05 | J44: SUPER | M44: 0.07 | N44: =M44*F44 -> 3.0664813
B45: aditivo poli | C45: kg | F45: =D45*E45 -> 0 | M45: 0.07 | N45: =M45*F45 -> 0
B46: diesel | C46: litros | D46: =IF(SUM($D$23:$D$30)=0,0,VLOOKUP($C$22,'tabela traços'!$A$3:$M$15,12,0)) -> 2 | E46: =IF(SUM($D$23:$D$30)=0,0,E19) -> 8.5 | F46: =D46*E46 -> 17 | M46: 0.17 | N46: =M46*F46 -> 2.89
B47: serviço Vilamix | C47: m³ | E47: =IF(SUM($D$23:$D$30)=0,0,G20) -> 0 | F47: =D47*E47 -> 0
D50: TOTAL INSUMOS 1= | F50: =SUM(F35:F49) -> 651.59062 | G50: /m³ | M50: média pond.
M51: =N51/F50 -> 0.13540345 | N51: =SUM(N35:N46) -> 88.227619
B52: para o 30 MPa | C52: --------- | G52: /m³
B56: DEFINIÇÃO DA USINA DE CONCRETO: | I56: PARA DEFINIR VALOR m³
B59: produção média de concreto por mês= | E59: 400 | F59: m³/mês | H59: copiar valor abaixo e colar "só valores" em A.
B61: índice (proporcional ao volume real)= | E61: =IF(E59=0,0,I75/E59*100) -> 223.17072 | F61: % | H61: depois marcar "X" antes de B,
H63: copiar valor abaixo e colar "só valores" em B.
...

Sheet INSUMOS
C1: X | F1: SISTEMA SC-10 e SC-14 ORÇAMENTO INSUMOS E PREÇOS DE CUSTO | Q1: DATA: | R1: =CÁLCULOS!O1 -> 45638 | V1: X
Q2: REVISÃO: | R2: =CÁLCULOS!O2 -> 3
F3: CLIENTE: | G3: =CÁLCULOS!F3 -> Passarelli | Q3: LOCAL:
F4: OBRA: | G4: =CÁLCULOS!F4 -> 12 tqs Nereda | Q4: =FECHAMENTO!M5 -> São Paulo - Tatuapé - SP
E12: COTAÇÃO DO EURO= | G12: 6.15
D14: ANTES DE FINALIZAR FAÇA UMA CONFERÊNCIA NOS ITENS ABAIXO, INDO NESTES ITENS E VERIFICANDO SE FOI LANÇADO OS PREÇOS
E15: UNITÁRIOS OU ALTERAÇÃO DE QUANTIDADE ( CASO ALGUM INSUMO REALMENTE NÃO PRECISAR DE PREÇO MARCAR "X" NO ÍTEM ) :
D17: coluna/ÍTEM | E17: CONFERIDO ? | I17: col./ÍTEM | J17: CONFERIDO ?
C18: =VLOOKUP(D18,$B$40:$AC$277,16,0) -> 750 | D18: Q15 | F18: =IF(C18>0,"SIM",IF(E18="x","SIM","NÃO")) -> SIM | H18: =VLOOKUP(I18,$B$40:$AC$277,16,0) -> 2300 | I18: Q67 | K18: =IF(H18>0,"SIM",IF(J18="x","SIM","NÃO")) -> SIM
C19: =VLOOKUP(D19,$B$40:$AC$277,16,0) -> 2000 | D19: Q16 | F19: =IF(C19>0,"SIM",IF(E19="x","SIM","NÃO")) -> SIM | H19: =VLOOKUP(I19,$B$40:$AC$277,16,0) -> 180 | I19: Q69 | K19: =IF(H19>0,"SIM",IF(J19="x","SIM","NÃO")) -> SIM
C20: =VLOOKUP(D20,$B$40:$AC$277,16,0) -> 3700 | D20: Q17 | F20: =IF(C20>0,"SIM",IF(E20="x","SIM","NÃO")) -> SIM | H20: =VLOOKUP(I20,$B$40:$AC$277,16,0) -> 30 | I20: Q71 | K20: =IF(H20>0,"SIM",IF(J20="x","SIM","NÃO")) -> SIM
C21: =VLOOKUP(D21,$B$40:$AC$277,16,0) -> 0 | D21: Q18 | F21: =IF(C21>0,"SIM",IF(E21="x","SIM","NÃO")) -> NÃO | H21: =VLOOKUP(I21,$B$40:$AC$277,16,0) -> 35 | I21: Q72 | K21: =IF(H21>0,"SIM",IF(J21="x","SIM","NÃO")) -> SIM
C22: =VLOOKUP(D22,$B$40:$AC$277,16,0) -> 0 | D22: Q19 | F22: =IF(C22>0,"SIM",IF(E22="x","SIM","NÃO")) -> NÃO | H22: =VLOOKUP(I22,$B$40:$AC$277,16,0) -> 35 | I22: Q73 | K22: =IF(H22>0,"SIM",IF(J22="x","SIM","NÃO")) -> SIM
C23: =VLOOKUP(D23,$B$40:$AC$277,16,0) -> 5000 | D23: Q20 | F23: =IF(C23>0,"SIM",IF(E23="x","SIM","NÃO")) -> SIM | H23: =VLOOKUP(I23,$B$40:$AC$277,16,0) -> 7.5 | I23: Q74 | K23: =IF(H23>0,"SIM",IF(J23="x","SIM","NÃO")) -> SIM
C24: =VLOOKUP(D24,$B$40:$AC$277,16,0) -> 0 | D24: Q21 | F24: =IF(C24>0,"SIM",IF(E24="x","SIM","NÃO")) -> NÃO | H24: =VLOOKUP(I24,$B$40:$AC$277,16,0) -> 7.5 | I24: Q75 | K24: =IF(H24>0,"SIM",IF(J24="x","SIM","NÃO")) -> SIM
C25: =VLOOKUP(D25,$B$40:$AC$277,16,0) -> 0 | D25: Q22 | F25: =IF(C25>0,"SIM",IF(E25="x","SIM","NÃO")) -> NÃO | H25: =VLOOKUP(I25,$B$40:$AC$277,16,0) -> 4 | I25: Q143 | K25: =IF(H25>0,"SIM",IF(J25="x","SIM","NÃO")) -> SIM
C26: =VLOOKUP(D26,$B$40:$AC$277,16,0) -> 2220 | D26: Q23 | F26: =IF(C26>0,"SIM",IF(E26="x","SIM","NÃO")) -> SIM | H26: =VLOOKUP(I26,$B$40:$AC$277,16,0) -> 41 | I26: Q144 | K26: =IF(H26>0,"SIM",IF(J26="x","SIM","NÃO")) -> SIM
C27: =VLOOKUP(D27,$B$40:$AC$277,16,0) -> 0 | D27: Q24 | F27: =IF(C27>0,"SIM",IF(E27="x","SIM","NÃO")) -> NÃO | H27: =VLOOKUP(I27,$B$40:$AC$277,16,0) -> 4.8 | I27: Q145 | K27: =IF(H27>0,"SIM",IF(J27="x","SIM","NÃO")) -> SIM
C28: =VLOOKUP(D28,$B$40:$AC$277,23,0) -> 10502 | D28: X25 | F28: =IF(C28>0,"SIM",IF(E28="x","SIM","NÃO")) -> SIM | H28: =VLOOKUP(I28,$B$40:$AC$277,16,0) -> 999.998 | I28: Q146 | K28: =IF(H28>0,"SIM",IF(J28="x","SIM","NÃO")) -> SIM
C29: =VLOOKUP(D29,$B$40:$AC$277,23,0) -> 10502 | D29: X26 | F29: =IF(C29>0,"SIM",IF(E29="x","SIM","NÃO")) -> SIM | I29: Q156 a Q157 | K29: =IF(H29>0,"SIM",IF(J29="x","SIM","NÃO")) -> NÃO
C30: =VLOOKUP(D30,$B$40:$AC$277,23,0) -> 0 | D30: X27 | F30: =IF(C30>0,"SIM",IF(E30="x","SIM","NÃO")) -> NÃO | I30: Q158 a Q170 | K30: =IF(H30>0,"SIM",IF(J30="x","SIM","NÃO")) -> NÃO
C31: =VLOOKUP(D31,$B$40:$AC$277,23,0) -> 0 | D31: X28 | F31: =IF(C31>0,"SIM",IF(E31="x","SIM","NÃO")) -> NÃO | I31: EURO | K31: =IF(H30>0,"SIM",IF(J31="x","SIM","NÃO")) -> NÃO | P31: verificar "AQUI" célula G12
C32: =VLOOKUP(D32,$B$40:$AC$277,23,0) -> 14002.667 | D32: X29 | F32: =IF(C32>0,"SIM",IF(E32="x","SIM","NÃO")) -> SIM | I32: LUCRO | K32: =IF(H31>0,"SIM",IF(J32="x","SIM","NÃO")) -> NÃO | P32: verificar na aba "FECHAMENTO" célula G17
C33: =VLOOKUP(D33,$B$40:$AC$277,16,0) -> 4.8 | D33: Q65 | F33: =IF(C33>0,"SIM",IF(E33="x","SIM","NÃO")) -> SIM | I33: INVESTIMENTO | K33: =IF(H32>0,"SIM",IF(J33="x","SIM","NÃO")) -> NÃO | P33: verificar na aba "FECHAMENTO" célula U34
C34: =VLOOKUP(D34,$B$40:$AC$277,16,0) -> 180 | D34: Q66 | F34: =IF(C34>0,"SIM",IF(E34="x","SIM","NÃO")) -> SIM | G34: =IF(G35=0,0,"informado ?") -> 0 | I34: FATURAMENTO | K34: =IF(H33>0,"SIM",IF(J34="x","SIM","NÃO")) -> NÃO | P34: verificar na aba "FECHAMENTO" célula H106 e l106
D35: =IF(FECHAMENTO!X115<>0,"informar faturamento direto FORTES",IF(FECHAMENTO!X98<>0,"informar faturamento direto para CLIENTE",0)) -> 0 | G35: =IF(D35=0,0,IF(C35>0,"SIM",IF(F35="x","SIM","NÃO"))) -> 0 | I35: ICMS / ISS | K35: =IF(H34>0,"SIM",IF(J35="x","SIM","NÃO")) -> NÃO | P35: verificar na aba "FECHAMENTO" célula D62 e I62
I36: % vendedor | K36: =IF(H32>0,"SIM",IF(J36="x","SIM","NÃO")) -> NÃO | P36: verificar na aba "FECHAMENTO" célula I87
C38: ítem | D38: MONTAGEM - MATERIAIS, FERRAM., EQUIPAM. e LOCAÇÕES | K38: QUANT. | O38: UNID. | Q38: Preço unit. | R38: Preço Total
C39: =IF(ENTRADAS!F21>4,"AS QUANTIDADES DOS INSUMOS SÃO PARA 4 TANQUES","AS QUANTIDADES DOS INSUMOS SÃO PARA "&ENTRADAS!F21&" TANQUES") -> AS QUANTIDADES DOS INSUMOS SÃO PARA 4 TANQUES | V39: PARAFUSO Escora | W39: preço unit.
B40: Q1 | C40: Q1 | D40: =CÁLCULOS!C233 -> CHAPA AÇO 500 x 300 x 3/16' | I40: percentual redução: | J40: 0.7 | K40: =CÁLCULOS!L233 -> 248 | O40: =CÁLCULOS!M233 -> unid. | Q40: =IF(K40=0,0,IF(J40>0,J40*CÁLCULOS!P233*Q159*2.7,CÁLCULOS!P233*Q159*2.7)) -> 62.4456 | R40: =K40*Q40 -> 15486.509 | V40: M16 x 1 1/2" | W40: 8 | AC40: =Q40 -> 62.4456
A41: cimento | B41: Q2 | C41: Q2 | D41: =CÁLCULOS!C234 -> CIMENTO PORTLAND ( SACO 50 kg ) | K41: =CÁLCULOS!L234 -> 22 | O41: =CÁLCULOS!M234 -> sacos | Q41: 40 | R41: =K41*Q41 -> 880 | V41: M16 x 1 3/4" | W41: 9 | AC41: =Q41 -> 40
A42: areia | B42: Q3 | C42: Q3 | D42: =CÁLCULOS!C235 -> AREIA MÉDIA | K42: =CÁLCULOS!L235 -> 3.3 | O42: =CÁLCULOS!M235 -> m³ | Q42: 200 | R42: =K42*Q42 -> 660 | AC42: =Q42 -> 200
A43: parabolt | B43: Q4 | C43: Q4 | D43: =CÁLCULOS!C236 -> PARABOLT 5/8" x 6" | H43: =CÁLCULOS!G236 -> para fixar escora na base | K43: =CÁLCULOS!L236 -> 124 | O43: =CÁLCULOS!M236 -> unid. | Q43: 12.8 | R43: =K43*Q43 -> 1587.2 | AC43: =Q43 -> 12.8
A44: parabolt | B44: Q5 | C44: Q5 | D44: =CÁLCULOS!C237 -> PARABOLT 5/8" x 6" | H44: =CÁLCULOS!G237 -> para fixar escora 9 m aproveitadas | K44: =CÁLCULOS!L237 -> 80 | O44: =CÁLCULOS!M237 -> unid. | Q44: 12.8 | R44: =K44*Q44 -> 1024 | V44: PARAFUSO Nivelam.(ton) | W44: preço unit. | AC44: =Q44 -> 12.8
A45: parafuso | B45: Q6 | C45: Q6 | D45: =CÁLCULOS!C238 -> PARAFUSO p/ escora M16 x 1 3/4" | H45: =CÁLCULOS!G238 -> para fixar escora no painel | K45: =CÁLCULOS!L238 -> 496 | O45: =CÁLCULOS!M238 -> unid. | Q45: =IF(D45="PARAFUSO p/ escora M16 x 1 1/2""",W40,IF(D45="PARAFUSO p/ escora M16 x 1 3/4""",W41,0)) -> 9 | R45: =K45*Q45 -> 4464 | AC45: =Q45 -> 9
